{"local_timestamp": 1782707765.3691509, "slug": "will-lionel-messi-be-the-top-goalscorer-at-the-2026-fifa-world-cup", "data": {"market": "0xd2a8caba5559bc21e14f6b2aa504cb14a1782751658b71409e25b82e432c0a97", "price_changes": [{"asset_id": "19214394437683566921750936876376421489271269944393354497977881791256347396217", "price": "0.26", "size": "0", "side": "BUY", "hash": "9b5ad1cec057025728172037d4dfe23182bb97b5", "best_bid": "0.519", "best_ask": "0.52"}, {"asset_id": "36586667785814641857008731622413716797407337292495614620493145114086484487337", "price": "0.74", "size": "0", "side": "SELL", "hash": "a10051813a61a7cb344dd0daf9dd57b6ad35cdc4", "best_bid": "0.48", "best_ask": "0.481"}], "timestamp": "1782707766601", "event_type": "price_change"}}
{"local_timestamp": 1782707765.5492258, "slug": "will-lionel-messi-be-the-top-goalscorer-at-the-2026-fifa-world-cup", "data": {"market": "0xd2a8caba5559bc21e14f6b2aa504cb14a1782751658b71409e25b82e432c0a97", "price_changes": [{"asset_id": "19214394437683566921750936876376421489271269944393354497977881791256347396217", "price": "0.478", "size": "500", "side": "BUY", "hash": "0d80d224f11353127d91fc75e5fa49b7ae0bb235", "best_bid": "0.519", "best_ask": "0.52"}, {"asset_id": "36586667785814641857008731622413716797407337292495614620493145114086484487337", "price": "0.522", "size": "500", "side": "SELL", "hash": "873ee2a4e9d99ead54b9271476a5b5b74adee09f", "best_bid": "0.48", "best_ask": "0.481"}], "timestamp": "1782707766781", "event_type": "price_change"}}
{"local_timestamp": 1782707765.5548692, "slug": "will-lionel-messi-be-the-top-goalscorer-at-the-2026-fifa-world-cup", "data": {"market": "0xd2a8caba5559bc21e14f6b2aa504cb14a1782751658b71409e25b82e432c0a97", "price_changes": [{"asset_id": "36586667785814641857008731622413716797407337292495614620493145114086484487337", "price": "0.454", "size": "2000", "side": "BUY", "hash": "c46f103802b6e66a6d3eb7759995301a614b1f97", "best_bid": "0.48", "best_ask": "0.481"}, {"asset_id": "19214394437683566921750936876376421489271269944393354497977881791256347396217", "price": "0.546", "size": "2000", "side": "SELL", "hash": "32b3f3803aa1502660fe26324c0e74486d06f9e4", "best_bid": "0.519", "best_ask": "0.52"}], "timestamp": "1782707766788", "event_type": "price_change"}}
{"local_timestamp": 1782707766.0136232, "slug": "will-lionel-messi-be-the-top-goalscorer-at-the-2026-fifa-world-cup", "data": {"market": "0xd2a8caba5559bc21e14f6b2aa504cb14a1782751658b71409e25b82e432c0a97", "price_changes": [{"asset_id": "36586667785814641857008731622413716797407337292495614620493145114086484487337", "price": "0.232", "size": "0", "side": "BUY", "hash": "861a1f7bd49d20e9344488cac3be745fd64e8efe", "best_bid": "0.48", "best_ask": "0.481"}, {"asset_id": "19214394437683566921750936876376421489271269944393354497977881791256347396217", "price": "0.768", "size": "0", "side": "SELL", "hash": "02c79583043642eaa3adbea22b267a5e476f3981", "best_bid": "0.519", "best_ask": "0.52"}], "timestamp": "1782707767246", "event_type": "price_change"}}
{"local_timestamp": 1782707766.1675406, "slug": "will-lionel-messi-be-the-top-goalscorer-at-the-2026-fifa-world-cup", "data": {"market": "0xd2a8caba5559bc21e14f6b2aa504cb14a1782751658b71409e25b82e432c0a97", "price_changes": [{"asset_id": "19214394437683566921750936876376421489271269944393354497977881791256347396217", "price": "0.521", "size": "4780.19", "side": "SELL", "hash": "802ccfae0eab370e2c01bba824a6457561c73963", "best_bid": "0.519", "best_ask": "0.52"}, {"asset_id": "36586667785814641857008731622413716797407337292495614620493145114086484487337", "price": "0.479", "size": "4780.19", "side": "BUY", "hash": "244f059a3e54961e27d67c152f7775d2d9e43c88", "best_bid": "0.48", "best_ask": "0.481"}], "timestamp": "1782707767400", "event_type": "price_change"}}
{"local_timestamp": 1782707766.9366138, "slug": "will-lionel-messi-be-the-top-goalscorer-at-the-2026-fifa-world-cup", "data": {"market": "0xd2a8caba5559bc21e14f6b2aa504cb14a1782751658b71409e25b82e432c0a97", "price_changes": [{"asset_id": "36586667785814641857008731622413716797407337292495614620493145114086484487337", "price": "0.35", "size": "3200", "side": "BUY", "hash": "d607256d4f5a7b83b80e558a5b17c5878b762417", "best_bid": "0.48", "best_ask": "0.481"}, {"asset_id": "19214394437683566921750936876376421489271269944393354497977881791256347396217", "price": "0.65", "size": "3200", "side": "SELL", "hash": "50c94431aa29b88cd1dfea60cf4b84f921ae544f", "best_bid": "0.519", "best_ask": "0.52"}], "timestamp": "1782707768169", "event_type": "price_change"}}
{"local_timestamp": 1782707766.960124, "slug": "will-lionel-messi-be-the-top-goalscorer-at-the-2026-fifa-world-cup", "data": {"market": "0xd2a8caba5559bc21e14f6b2aa504cb14a1782751658b71409e25b82e432c0a97", "price_changes": [{"asset_id": "19214394437683566921750936876376421489271269944393354497977881791256347396217", "price": "0.26", "size": "3000", "side": "BUY", "hash": "69c192c3845c0c1ac95276b3a9a7ee2b65707d9b", "best_bid": "0.519", "best_ask": "0.52"}, {"asset_id": "36586667785814641857008731622413716797407337292495614620493145114086484487337", "price": "0.74", "size": "3000", "side": "SELL", "hash": "2216662fe31ecd4f950ca16ff4c502635faf763a", "best_bid": "0.48", "best_ask": "0.481"}], "timestamp": "1782707768192", "event_type": "price_change"}}
{"local_timestamp": 1782707768.4038138, "slug": "will-lionel-messi-be-the-top-goalscorer-at-the-2026-fifa-world-cup", "data": {"market": "0xd2a8caba5559bc21e14f6b2aa504cb14a1782751658b71409e25b82e432c0a97", "price_changes": [{"asset_id": "36586667785814641857008731622413716797407337292495614620493145114086484487337", "price": "0.35", "size": "200", "side": "BUY", "hash": "fc87628a828f1e8e5b62b1280d54c998a95a1377", "best_bid": "0.48", "best_ask": "0.481"}, {"asset_id": "19214394437683566921750936876376421489271269944393354497977881791256347396217", "price": "0.65", "size": "200", "side": "SELL", "hash": "72822df54881a738c493435fbcdcb3d86c37a967", "best_bid": "0.519", "best_ask": "0.52"}], "timestamp": "1782707769636", "event_type": "price_change"}}
{"local_timestamp": 1782707768.404651, "slug": "will-lionel-messi-be-the-top-goalscorer-at-the-2026-fifa-world-cup", "data": {"market": "0xd2a8caba5559bc21e14f6b2aa504cb14a1782751658b71409e25b82e432c0a97", "price_changes": [{"asset_id": "19214394437683566921750936876376421489271269944393354497977881791256347396217", "price": "0.26", "size": "0", "side": "BUY", "hash": "700b09f2fea8fcd7fb4a4e51c1aa8de18d87fd27", "best_bid": "0.519", "best_ask": "0.52"}, {"asset_id": "36586667785814641857008731622413716797407337292495614620493145114086484487337", "price": "0.74", "size": "0", "side": "SELL", "hash": "1c6ed4772a6def6853c12094d9fa00c92687f752", "best_bid": "0.48", "best_ask": "0.481"}], "timestamp": "1782707769637", "event_type": "price_change"}}
{"local_timestamp": 1782707768.6690626, "slug": "will-lionel-messi-be-the-top-goalscorer-at-the-2026-fifa-world-cup", "data": {"market": "0xd2a8caba5559bc21e14f6b2aa504cb14a1782751658b71409e25b82e432c0a97", "price_changes": [{"asset_id": "19214394437683566921750936876376421489271269944393354497977881791256347396217", "price": "0.521", "size": "4683.1", "side": "SELL", "hash": "ac79504e54103a6855fcbbdca19dd78ce1be7920", "best_bid": "0.519", "best_ask": "0.52"}, {"asset_id": "36586667785814641857008731622413716797407337292495614620493145114086484487337", "price": "0.479", "size": "4683.1", "side": "BUY", "hash": "a02a4885b1323c9c3b2888ddddab84c3c0420de9", "best_bid": "0.48", "best_ask": "0.481"}], "timestamp": "1782707769899", "event_type": "price_change"}}
{"local_timestamp": 1782707769.9314306, "slug": "will-lionel-messi-be-the-top-goalscorer-at-the-2026-fifa-world-cup", "data": {"market": "0xd2a8caba5559bc21e14f6b2aa504cb14a1782751658b71409e25b82e432c0a97", "price_changes": [{"asset_id": "19214394437683566921750936876376421489271269944393354497977881791256347396217", "price": "0.26", "size": "3000", "side": "BUY", "hash": "8003d223d70b4d00e76459cdd81c7d848db410d1", "best_bid": "0.519", "best_ask": "0.52"}, {"asset_id": "36586667785814641857008731622413716797407337292495614620493145114086484487337", "price": "0.74", "size": "3000", "side": "SELL", "hash": "bca09dda1d7f3f970529df1e56accb7fdc53f4a5", "best_bid": "0.48", "best_ask": "0.481"}], "timestamp": "1782707771164", "event_type": "price_change"}}
{"local_timestamp": 1782707769.93428, "slug": "will-lionel-messi-be-the-top-goalscorer-at-the-2026-fifa-world-cup", "data": {"market": "0xd2a8caba5559bc21e14f6b2aa504cb14a1782751658b71409e25b82e432c0a97", "price_changes": [{"asset_id": "36586667785814641857008731622413716797407337292495614620493145114086484487337", "price": "0.35", "size": "3200", "side": "BUY", "hash": "b174b561483670cada1379eb14ffbb84b3fbcff6", "best_bid": "0.48", "best_ask": "0.481"}, {"asset_id": "19214394437683566921750936876376421489271269944393354497977881791256347396217", "price": "0.65", "size": "3200", "side": "SELL", "hash": "0fe82fb1a738361697c324fdefcbe400862f68e4", "best_bid": "0.519", "best_ask": "0.52"}], "timestamp": "1782707771168", "event_type": "price_change"}}
{"local_timestamp": 1782707770.179654, "slug": "will-lionel-messi-be-the-top-goalscorer-at-the-2026-fifa-world-cup", "data": {"market": "0xd2a8caba5559bc21e14f6b2aa504cb14a1782751658b71409e25b82e432c0a97", "price_changes": [{"asset_id": "36586667785814641857008731622413716797407337292495614620493145114086484487337", "price": "0.472", "size": "994", "side": "BUY", "hash": "d0d661dca70047b5faca0e8cf6a8ec61fea5d53e", "best_bid": "0.48", "best_ask": "0.481"}, {"asset_id": "19214394437683566921750936876376421489271269944393354497977881791256347396217", "price": "0.528", "size": "994", "side": "SELL", "hash": "6ce9c7c1fbcd9755f09be45c232c82ef4337e4fc", "best_bid": "0.519", "best_ask": "0.52"}], "timestamp": "1782707771412", "event_type": "price_change"}}
{"local_timestamp": 1782707770.1963067, "slug": "will-lionel-messi-be-the-top-goalscorer-at-the-2026-fifa-world-cup", "data": {"market": "0xd2a8caba5559bc21e14f6b2aa504cb14a1782751658b71409e25b82e432c0a97", "price_changes": [{"asset_id": "19214394437683566921750936876376421489271269944393354497977881791256347396217", "price": "0.511", "size": "2961.5", "side": "BUY", "hash": "bea80d9fa2caf4182344c3fae4d8985e11dc3121", "best_bid": "0.519", "best_ask": "0.52"}, {"asset_id": "36586667785814641857008731622413716797407337292495614620493145114086484487337", "price": "0.489", "size": "2961.5", "side": "SELL", "hash": "c8dc7098ef2ee87f4f0c917c2b3febf92b35867d", "best_bid": "0.48", "best_ask": "0.481"}], "timestamp": "1782707771429", "event_type": "price_change"}}
{"local_timestamp": 1782707770.7754436, "slug": "will-lionel-messi-be-the-top-goalscorer-at-the-2026-fifa-world-cup", "data": {"market": "0xd2a8caba5559bc21e14f6b2aa504cb14a1782751658b71409e25b82e432c0a97", "price_changes": [{"asset_id": "19214394437683566921750936876376421489271269944393354497977881791256347396217", "price": "0.5", "size": "29764", "side": "BUY", "hash": "5bbbb2914fe9c88281d0ea0754772931255cad75", "best_bid": "0.519", "best_ask": "0.52"}, {"asset_id": "36586667785814641857008731622413716797407337292495614620493145114086484487337", "price": "0.5", "size": "29764", "side": "SELL", "hash": "ecbf8e664e642096df4c72c1103e8e5e60e7ee9d", "best_bid": "0.48", "best_ask": "0.481"}], "timestamp": "1782707772002", "event_type": "price_change"}}
{"local_timestamp": 1782707771.2154858, "slug": "will-lionel-messi-be-the-top-goalscorer-at-the-2026-fifa-world-cup", "data": {"market": "0xd2a8caba5559bc21e14f6b2aa504cb14a1782751658b71409e25b82e432c0a97", "price_changes": [{"asset_id": "19214394437683566921750936876376421489271269944393354497977881791256347396217", "price": "0.521", "size": "4780.19", "side": "SELL", "hash": "e148d74edc57e7e4f74b50b03d468b58398ae8ad", "best_bid": "0.519", "best_ask": "0.52"}, {"asset_id": "36586667785814641857008731622413716797407337292495614620493145114086484487337", "price": "0.479", "size": "4780.19", "side": "BUY", "hash": "f6784a4d6550db3f9a2dccf4d06fce0031e9df1d", "best_bid": "0.48", "best_ask": "0.481"}], "timestamp": "1782707772447", "event_type": "price_change"}}
{"local_timestamp": 1782707771.3608468, "slug": "will-lionel-messi-be-the-top-goalscorer-at-the-2026-fifa-world-cup", "data": {"market": "0xd2a8caba5559bc21e14f6b2aa504cb14a1782751658b71409e25b82e432c0a97", "price_changes": [{"asset_id": "36586667785814641857008731622413716797407337292495614620493145114086484487337", "price": "0.35", "size": "200", "side": "BUY", "hash": "c14a817730f3e836628059fc92e83df71e6e2de5", "best_bid": "0.48", "best_ask": "0.481"}, {"asset_id": "19214394437683566921750936876376421489271269944393354497977881791256347396217", "price": "0.65", "size": "200", "side": "SELL", "hash": "c6993061f5e2844b35335813996c0fd71ae50c99", "best_bid": "0.519", "best_ask": "0.52"}], "timestamp": "1782707772594", "event_type": "price_change"}}
{"local_timestamp": 1782707771.362088, "slug": "will-lionel-messi-be-the-top-goalscorer-at-the-2026-fifa-world-cup", "data": {"market": "0xd2a8caba5559bc21e14f6b2aa504cb14a1782751658b71409e25b82e432c0a97", "price_changes": [{"asset_id": "19214394437683566921750936876376421489271269944393354497977881791256347396217", "price": "0.26", "size": "0", "side": "BUY", "hash": "a6aa2868dbec0cea58d61ea2c10be3582fd5253c", "best_bid": "0.519", "best_ask": "0.52"}, {"asset_id": "36586667785814641857008731622413716797407337292495614620493145114086484487337", "price": "0.74", "size": "0", "side": "SELL", "hash": "3f648e3c019527259b263d20ce5814178eb2c411", "best_bid": "0.48", "best_ask": "0.481"}], "timestamp": "1782707772594", "event_type": "price_change"}}
{"local_timestamp": 1782707771.773031, "slug": "will-lionel-messi-be-the-top-goalscorer-at-the-2026-fifa-world-cup", "data": {"market": "0xd2a8caba5559bc21e14f6b2aa504cb14a1782751658b71409e25b82e432c0a97", "price_changes": [{"asset_id": "19214394437683566921750936876376421489271269944393354497977881791256347396217", "price": "0.518", "size": "18263.33", "side": "BUY", "hash": "118cc219225bc13585c1593d02ae61b2d9f3b5ac", "best_bid": "0.519", "best_ask": "0.52"}, {"asset_id": "36586667785814641857008731622413716797407337292495614620493145114086484487337", "price": "0.482", "size": "18263.33", "side": "SELL", "hash": "8344cfece6ca13de60c7f38f7aee17d2fa8aa6b7", "best_bid": "0.48", "best_ask": "0.481"}], "timestamp": "1782707773003", "event_type": "price_change"}}
{"local_timestamp": 1782707771.7736125, "slug": "will-lionel-messi-be-the-top-goalscorer-at-the-2026-fifa-world-cup", "data": {"market": "0xd2a8caba5559bc21e14f6b2aa504cb14a1782751658b71409e25b82e432c0a97", "price_changes": [{"asset_id": "36586667785814641857008731622413716797407337292495614620493145114086484487337", "price": "0.479", "size": "4365.09", "side": "BUY", "hash": "b70ad4d65cfdb8d3eb11d80acb67fea122e3a096", "best_bid": "0.48", "best_ask": "0.481"}, {"asset_id": "19214394437683566921750936876376421489271269944393354497977881791256347396217", "price": "0.521", "size": "4365.09", "side": "SELL", "hash": "fde36e4aafeb9778c07543f669ed0d005ec9f913", "best_bid": "0.519", "best_ask": "0.52"}], "timestamp": "1782707773004", "event_type": "price_change"}}
{"local_timestamp": 1782707772.6509128, "slug": "will-lionel-messi-be-the-top-goalscorer-at-the-2026-fifa-world-cup", "data": {"market": "0xd2a8caba5559bc21e14f6b2aa504cb14a1782751658b71409e25b82e432c0a97", "price_changes": [{"asset_id": "36586667785814641857008731622413716797407337292495614620493145114086484487337", "price": "0.231", "size": "200", "side": "BUY", "hash": "6b336f38fbafca90b23371be36a45cfb92a41a19", "best_bid": "0.48", "best_ask": "0.481"}, {"asset_id": "19214394437683566921750936876376421489271269944393354497977881791256347396217", "price": "0.769", "size": "200", "side": "SELL", "hash": "0aaf6e7ce7c29210a0fa51f1b5d8712c40334fb4", "best_bid": "0.519", "best_ask": "0.52"}], "timestamp": "1782707773884", "event_type": "price_change"}}
{"local_timestamp": 1782707772.799159, "slug": "will-lionel-messi-be-the-top-goalscorer-at-the-2026-fifa-world-cup", "data": {"market": "0xd2a8caba5559bc21e14f6b2aa504cb14a1782751658b71409e25b82e432c0a97", "price_changes": [{"asset_id": "19214394437683566921750936876376421489271269944393354497977881791256347396217", "price": "0.521", "size": "4268", "side": "SELL", "hash": "00ef7d84d4bdae009d9ce4c3c9d94acb5b8d4a1a", "best_bid": "0.519", "best_ask": "0.52"}, {"asset_id": "36586667785814641857008731622413716797407337292495614620493145114086484487337", "price": "0.479", "size": "4268", "side": "BUY", "hash": "c79da390c825737afafbe18ce28215796e8a9eb9", "best_bid": "0.48", "best_ask": "0.481"}], "timestamp": "1782707774032", "event_type": "price_change"}}
{"local_timestamp": 1782707772.9067695, "slug": "will-lionel-messi-be-the-top-goalscorer-at-the-2026-fifa-world-cup", "data": {"market": "0xd2a8caba5559bc21e14f6b2aa504cb14a1782751658b71409e25b82e432c0a97", "price_changes": [{"asset_id": "19214394437683566921750936876376421489271269944393354497977881791256347396217", "price": "0.26", "size": "3000", "side": "BUY", "hash": "d6d1fb1d20aea8b6dec481300d5f593fae036f8b", "best_bid": "0.519", "best_ask": "0.52"}, {"asset_id": "36586667785814641857008731622413716797407337292495614620493145114086484487337", "price": "0.74", "size": "3000", "side": "SELL", "hash": "aea6f69feb1ea43137a31e33f4279e6bc1f291e9", "best_bid": "0.48", "best_ask": "0.481"}], "timestamp": "1782707774139", "event_type": "price_change"}}
{"local_timestamp": 1782707772.9377275, "slug": "will-lionel-messi-be-the-top-goalscorer-at-the-2026-fifa-world-cup", "data": {"market": "0xd2a8caba5559bc21e14f6b2aa504cb14a1782751658b71409e25b82e432c0a97", "price_changes": [{"asset_id": "36586667785814641857008731622413716797407337292495614620493145114086484487337", "price": "0.35", "size": "3200", "side": "BUY", "hash": "6ca4b6cb724a357744336f8df209e18db82e9d75", "best_bid": "0.48", "best_ask": "0.481"}, {"asset_id": "19214394437683566921750936876376421489271269944393354497977881791256347396217", "price": "0.65", "size": "3200", "side": "SELL", "hash": "988420d7b521b0ef863518447ec6e83d834ef432", "best_bid": "0.519", "best_ask": "0.52"}], "timestamp": "1782707774162", "event_type": "price_change"}}
{"local_timestamp": 1782707773.3678384, "slug": "will-lionel-messi-be-the-top-goalscorer-at-the-2026-fifa-world-cup", "data": {"market": "0xd2a8caba5559bc21e14f6b2aa504cb14a1782751658b71409e25b82e432c0a97", "price_changes": [{"asset_id": "19214394437683566921750936876376421489271269944393354497977881791256347396217", "price": "0.516", "size": "968", "side": "BUY", "hash": "313af7efd5775ac8c2809f838c051cdd66486d8f", "best_bid": "0.519", "best_ask": "0.52"}, {"asset_id": "36586667785814641857008731622413716797407337292495614620493145114086484487337", "price": "0.484", "size": "968", "side": "SELL", "hash": "8842b73903421c074345bc845137e4d3853897c4", "best_bid": "0.48", "best_ask": "0.481"}], "timestamp": "1782707774600", "event_type": "price_change"}}
{"local_timestamp": 1782707773.3685906, "slug": "will-lionel-messi-be-the-top-goalscorer-at-the-2026-fifa-world-cup", "data": {"market": "0xd2a8caba5559bc21e14f6b2aa504cb14a1782751658b71409e25b82e432c0a97", "price_changes": [{"asset_id": "36586667785814641857008731622413716797407337292495614620493145114086484487337", "price": "0.477", "size": "0", "side": "BUY", "hash": "01cf475bbad589a49fadffbb946e7c99ec6902c5", "best_bid": "0.48", "best_ask": "0.481"}, {"asset_id": "19214394437683566921750936876376421489271269944393354497977881791256347396217", "price": "0.523", "size": "0", "side": "SELL", "hash": "063d38f73bf48ad658202c2b70f57b49f5fd432d", "best_bid": "0.519", "best_ask": "0.52"}], "timestamp": "1782707774600", "event_type": "price_change"}}
{"local_timestamp": 1782707773.439563, "slug": "will-lionel-messi-be-the-top-goalscorer-at-the-2026-fifa-world-cup", "data": {"market": "0xd2a8caba5559bc21e14f6b2aa504cb14a1782751658b71409e25b82e432c0a97", "price_changes": [{"asset_id": "19214394437683566921750936876376421489271269944393354497977881791256347396217", "price": "0.514", "size": "250", "side": "BUY", "hash": "929adc87bcb95ae941dfe7852b578b8f3c452d99", "best_bid": "0.519", "best_ask": "0.52"}, {"asset_id": "36586667785814641857008731622413716797407337292495614620493145114086484487337", "price": "0.486", "size": "250", "side": "SELL", "hash": "23f7e45fae54eb7a2a1d619ed9e9a8bc3c6f9362", "best_bid": "0.48", "best_ask": "0.481"}], "timestamp": "1782707774672", "event_type": "price_change"}}
{"local_timestamp": 1782707773.4434187, "slug": "will-lionel-messi-be-the-top-goalscorer-at-the-2026-fifa-world-cup", "data": {"market": "0xd2a8caba5559bc21e14f6b2aa504cb14a1782751658b71409e25b82e432c0a97", "price_changes": [{"asset_id": "36586667785814641857008731622413716797407337292495614620493145114086484487337", "price": "0.475", "size": "7187.77", "side": "BUY", "hash": "db49c521605bb2d2f9b6ee56117469edbc0d6651", "best_bid": "0.48", "best_ask": "0.481"}, {"asset_id": "19214394437683566921750936876376421489271269944393354497977881791256347396217", "price": "0.525", "size": "7187.77", "side": "SELL", "hash": "a81c44c72b3a60f59108c855a1f9c454c8e5e9a3", "best_bid": "0.519", "best_ask": "0.52"}], "timestamp": "1782707774676", "event_type": "price_change"}}
{"local_timestamp": 1782707773.912283, "slug": "will-lionel-messi-be-the-top-goalscorer-at-the-2026-fifa-world-cup", "data": {"market": "0xd2a8caba5559bc21e14f6b2aa504cb14a1782751658b71409e25b82e432c0a97", "price_changes": [{"asset_id": "36586667785814641857008731622413716797407337292495614620493145114086484487337", "price": "0.473", "size": "550", "side": "BUY", "hash": "2e82d716195b6bef576f8fb4f47fb0949eb72a38", "best_bid": "0.48", "best_ask": "0.481"}, {"asset_id": "19214394437683566921750936876376421489271269944393354497977881791256347396217", "price": "0.527", "size": "550", "side": "SELL", "hash": "5175bd143ba18a6c7bceb4846738d3d4f7dd6b73", "best_bid": "0.519", "best_ask": "0.52"}], "timestamp": "1782707775134", "event_type": "price_change"}}
{"local_timestamp": 1782707774.1634414, "slug": "will-lionel-messi-be-the-top-goalscorer-at-the-2026-fifa-world-cup", "data": {"market": "0xd2a8caba5559bc21e14f6b2aa504cb14a1782751658b71409e25b82e432c0a97", "price_changes": [{"asset_id": "36586667785814641857008731622413716797407337292495614620493145114086484487337", "price": "0.473", "size": "250", "side": "BUY", "hash": "189fd42f957e4c39372650318616a61c1ffe0652", "best_bid": "0.48", "best_ask": "0.481"}, {"asset_id": "19214394437683566921750936876376421489271269944393354497977881791256347396217", "price": "0.527", "size": "250", "side": "SELL", "hash": "e358617ecf664f19998c4ba2ef473768f16c6bc1", "best_bid": "0.519", "best_ask": "0.52"}], "timestamp": "1782707775396", "event_type": "price_change"}}
{"local_timestamp": 1782707774.2135217, "slug": "will-lionel-messi-be-the-top-goalscorer-at-the-2026-fifa-world-cup", "data": {"market": "0xd2a8caba5559bc21e14f6b2aa504cb14a1782751658b71409e25b82e432c0a97", "price_changes": [{"asset_id": "19214394437683566921750936876376421489271269944393354497977881791256347396217", "price": "0.518", "size": "18589.26", "side": "BUY", "hash": "5377ca6871ea22670a6096fca8f87342ada24681", "best_bid": "0.519", "best_ask": "0.52"}, {"asset_id": "36586667785814641857008731622413716797407337292495614620493145114086484487337", "price": "0.482", "size": "18589.26", "side": "SELL", "hash": "f791e525ff40d2360109464dcc96f8448b8db361", "best_bid": "0.48", "best_ask": "0.481"}], "timestamp": "1782707775433", "event_type": "price_change"}}
{"local_timestamp": 1782707774.2589397, "slug": "will-lionel-messi-be-the-top-goalscorer-at-the-2026-fifa-world-cup", "data": {"market": "0xd2a8caba5559bc21e14f6b2aa504cb14a1782751658b71409e25b82e432c0a97", "price_changes": [{"asset_id": "36586667785814641857008731622413716797407337292495614620493145114086484487337", "price": "0.479", "size": "4487.5", "side": "BUY", "hash": "b429b37cea821b20347397b0f0e913f87f880609", "best_bid": "0.48", "best_ask": "0.481"}, {"asset_id": "19214394437683566921750936876376421489271269944393354497977881791256347396217", "price": "0.521", "size": "4487.5", "side": "SELL", "hash": "82dd4a997e18985a8c64995695ae16a846aa0169", "best_bid": "0.519", "best_ask": "0.52"}], "timestamp": "1782707775492", "event_type": "price_change"}}
{"local_timestamp": 1782707774.3248618, "slug": "will-lionel-messi-be-the-top-goalscorer-at-the-2026-fifa-world-cup", "data": {"market": "0xd2a8caba5559bc21e14f6b2aa504cb14a1782751658b71409e25b82e432c0a97", "price_changes": [{"asset_id": "36586667785814641857008731622413716797407337292495614620493145114086484487337", "price": "0.35", "size": "200", "side": "BUY", "hash": "3738dc8975d079b0820bc7543acf28a81b4c6ab9", "best_bid": "0.48", "best_ask": "0.481"}, {"asset_id": "19214394437683566921750936876376421489271269944393354497977881791256347396217", "price": "0.65", "size": "200", "side": "SELL", "hash": "7b54fda98b898f3050b6ef3c49c72f0deb9a5664", "best_bid": "0.519", "best_ask": "0.52"}], "timestamp": "1782707775553", "event_type": "price_change"}}
{"local_timestamp": 1782707774.3258123, "slug": "will-lionel-messi-be-the-top-goalscorer-at-the-2026-fifa-world-cup", "data": {"market": "0xd2a8caba5559bc21e14f6b2aa504cb14a1782751658b71409e25b82e432c0a97", "price_changes": [{"asset_id": "19214394437683566921750936876376421489271269944393354497977881791256347396217", "price": "0.26", "size": "0", "side": "BUY", "hash": "00d2e25af88250b96253866391ef9e2c4e92d9ad", "best_bid": "0.519", "best_ask": "0.52"}, {"asset_id": "36586667785814641857008731622413716797407337292495614620493145114086484487337", "price": "0.74", "size": "0", "side": "SELL", "hash": "fa4368c05d44baa466761b6a567eb90731d1aacb", "best_bid": "0.48", "best_ask": "0.481"}], "timestamp": "1782707775553", "event_type": "price_change"}}
{"local_timestamp": 1782707774.4579866, "slug": "will-lionel-messi-be-the-top-goalscorer-at-the-2026-fifa-world-cup", "data": {"market": "0xd2a8caba5559bc21e14f6b2aa504cb14a1782751658b71409e25b82e432c0a97", "price_changes": [{"asset_id": "36586667785814641857008731622413716797407337292495614620493145114086484487337", "price": "0.34", "size": "3199.99", "side": "BUY", "hash": "851420fa64e810b0fbfb76decc6fd8e2cfe2fd11", "best_bid": "0.48", "best_ask": "0.481"}, {"asset_id": "19214394437683566921750936876376421489271269944393354497977881791256347396217", "price": "0.66", "size": "3199.99", "side": "SELL", "hash": "b4584cf3b4db0a5017f5a7682611598f094e7e74", "best_bid": "0.519", "best_ask": "0.52"}], "timestamp": "1782707775685", "event_type": "price_change"}}
{"local_timestamp": 1782707774.4634893, "slug": "will-lionel-messi-be-the-top-goalscorer-at-the-2026-fifa-world-cup", "data": {"market": "0xd2a8caba5559bc21e14f6b2aa504cb14a1782751658b71409e25b82e432c0a97", "price_changes": [{"asset_id": "19214394437683566921750936876376421489271269944393354497977881791256347396217", "price": "0.26", "size": "3000", "side": "BUY", "hash": "5d7bd1315468a2a9a4e1138ad4758892614a7547", "best_bid": "0.519", "best_ask": "0.52"}, {"asset_id": "36586667785814641857008731622413716797407337292495614620493145114086484487337", "price": "0.74", "size": "3000", "side": "SELL", "hash": "853bbf56d1d753b583943fb92b6afaeba40247f7", "best_bid": "0.48", "best_ask": "0.481"}], "timestamp": "1782707775695", "event_type": "price_change"}}
{"local_timestamp": 1782707774.4893847, "slug": "will-lionel-messi-be-the-top-goalscorer-at-the-2026-fifa-world-cup", "data": {"market": "0xd2a8caba5559bc21e14f6b2aa504cb14a1782751658b71409e25b82e432c0a97", "price_changes": [{"asset_id": "19214394437683566921750936876376421489271269944393354497977881791256347396217", "price": "0.32", "size": "0", "side": "BUY", "hash": "e38bcf56b7142754715903b26371c0dacd4b954c", "best_bid": "0.519", "best_ask": "0.52"}, {"asset_id": "36586667785814641857008731622413716797407337292495614620493145114086484487337", "price": "0.68", "size": "0", "side": "SELL", "hash": "889100331dd87aa972e7854aef2272a2a91d3a0b", "best_bid": "0.48", "best_ask": "0.481"}], "timestamp": "1782707775720", "event_type": "price_change"}}
{"local_timestamp": 1782707775.2104356, "slug": "will-lionel-messi-be-the-top-goalscorer-at-the-2026-fifa-world-cup", "data": {"market": "0xd2a8caba5559bc21e14f6b2aa504cb14a1782751658b71409e25b82e432c0a97", "price_changes": [{"asset_id": "19214394437683566921750936876376421489271269944393354497977881791256347396217", "price": "0.521", "size": "4584.59", "side": "SELL", "hash": "745bbe3e6b5cdfd9eacfe6cea968408b91360a50", "best_bid": "0.519", "best_ask": "0.52"}, {"asset_id": "36586667785814641857008731622413716797407337292495614620493145114086484487337", "price": "0.479", "size": "4584.59", "side": "BUY", "hash": "5531c61155fd2815f656f6bfdfc550b4732e0c54", "best_bid": "0.48", "best_ask": "0.481"}], "timestamp": "1782707776442", "event_type": "price_change"}}
{"local_timestamp": 1782707775.8655562, "slug": "will-lionel-messi-be-the-top-goalscorer-at-the-2026-fifa-world-cup", "data": {"market": "0xd2a8caba5559bc21e14f6b2aa504cb14a1782751658b71409e25b82e432c0a97", "price_changes": [{"asset_id": "19214394437683566921750936876376421489271269944393354497977881791256347396217", "price": "0.26", "size": "0", "side": "BUY", "hash": "d79fc2f490d4857f4bb672aa06750932ef2b4fc8", "best_bid": "0.519", "best_ask": "0.52"}, {"asset_id": "36586667785814641857008731622413716797407337292495614620493145114086484487337", "price": "0.74", "size": "0", "side": "SELL", "hash": "6faa666356db417fb748d9ae33b24971e9f09934", "best_bid": "0.48", "best_ask": "0.481"}], "timestamp": "1782707777093", "event_type": "price_change"}}
{"local_timestamp": 1782707775.8662443, "slug": "will-lionel-messi-be-the-top-goalscorer-at-the-2026-fifa-world-cup", "data": {"market": "0xd2a8caba5559bc21e14f6b2aa504cb14a1782751658b71409e25b82e432c0a97", "price_changes": [{"asset_id": "36586667785814641857008731622413716797407337292495614620493145114086484487337", "price": "0.34", "size": "199.99", "side": "BUY", "hash": "780326500757f23e0b5e67de9a71101e3d4ff923", "best_bid": "0.48", "best_ask": "0.481"}, {"asset_id": "19214394437683566921750936876376421489271269944393354497977881791256347396217", "price": "0.66", "size": "199.99", "side": "SELL", "hash": "767bb269a48547efa09b8a5ee5e3903048af72e2", "best_bid": "0.519", "best_ask": "0.52"}], "timestamp": "1782707777093", "event_type": "price_change"}}
{"local_timestamp": 1782707776.926287, "slug": "will-lionel-messi-be-the-top-goalscorer-at-the-2026-fifa-world-cup", "data": {"market": "0xd2a8caba5559bc21e14f6b2aa504cb14a1782751658b71409e25b82e432c0a97", "price_changes": [{"asset_id": "36586667785814641857008731622413716797407337292495614620493145114086484487337", "price": "0.361", "size": "0", "side": "BUY", "hash": "edd1141a737f83b325839bfc5fe8d862576a67a8", "best_bid": "0.48", "best_ask": "0.481"}, {"asset_id": "19214394437683566921750936876376421489271269944393354497977881791256347396217", "price": "0.639", "size": "0", "side": "SELL", "hash": "d2b1b3ca8b3f393db96a90713a7330e44935bc6a", "best_bid": "0.519", "best_ask": "0.52"}], "timestamp": "1782707778158", "event_type": "price_change"}}
{"local_timestamp": 1782707777.470303, "slug": "will-lionel-messi-be-the-top-goalscorer-at-the-2026-fifa-world-cup", "data": {"market": "0xd2a8caba5559bc21e14f6b2aa504cb14a1782751658b71409e25b82e432c0a97", "price_changes": [{"asset_id": "19214394437683566921750936876376421489271269944393354497977881791256347396217", "price": "0.26", "size": "3000", "side": "BUY", "hash": "fdbcbed177ca1258ff2e5bb78d4cc66c9ebbf172", "best_bid": "0.519", "best_ask": "0.52"}, {"asset_id": "36586667785814641857008731622413716797407337292495614620493145114086484487337", "price": "0.74", "size": "3000", "side": "SELL", "hash": "d6ad39cfbfcdee8cfaa96ebb532181fd9f220a30", "best_bid": "0.48", "best_ask": "0.481"}], "timestamp": "1782707778703", "event_type": "price_change"}}
{"local_timestamp": 1782707777.476699, "slug": "will-lionel-messi-be-the-top-goalscorer-at-the-2026-fifa-world-cup", "data": {"market": "0xd2a8caba5559bc21e14f6b2aa504cb14a1782751658b71409e25b82e432c0a97", "price_changes": [{"asset_id": "36586667785814641857008731622413716797407337292495614620493145114086484487337", "price": "0.35", "size": "3200", "side": "BUY", "hash": "d398e44ec410051a8288c96ffe49f90424b1b7b5", "best_bid": "0.48", "best_ask": "0.481"}, {"asset_id": "19214394437683566921750936876376421489271269944393354497977881791256347396217", "price": "0.65", "size": "3200", "side": "SELL", "hash": "6fbc2115e16b90b3be4bd24ac90ce7681eac0257", "best_bid": "0.519", "best_ask": "0.52"}], "timestamp": "1782707778709", "event_type": "price_change"}}
{"local_timestamp": 1782707777.7852352, "slug": "will-lionel-messi-be-the-top-goalscorer-at-the-2026-fifa-world-cup", "data": {"market": "0xd2a8caba5559bc21e14f6b2aa504cb14a1782751658b71409e25b82e432c0a97", "price_changes": [{"asset_id": "36586667785814641857008731622413716797407337292495614620493145114086484487337", "price": "0.46", "size": "44561", "side": "BUY", "hash": "3883f229bde0b90d841c1009679805b093280843", "best_bid": "0.48", "best_ask": "0.481"}, {"asset_id": "19214394437683566921750936876376421489271269944393354497977881791256347396217", "price": "0.54", "size": "44561", "side": "SELL", "hash": "78c3df728e0260739c44766810d4e8435a733d36", "best_bid": "0.519", "best_ask": "0.52"}], "timestamp": "1782707779010", "event_type": "price_change"}}
{"local_timestamp": 1782707777.7857928, "slug": "will-lionel-messi-be-the-top-goalscorer-at-the-2026-fifa-world-cup", "data": {"market": "0xd2a8caba5559bc21e14f6b2aa504cb14a1782751658b71409e25b82e432c0a97", "price_changes": [{"asset_id": "36586667785814641857008731622413716797407337292495614620493145114086484487337", "price": "0.47", "size": "19172", "side": "BUY", "hash": "3883f229bde0b90d841c1009679805b093280843", "best_bid": "0.48", "best_ask": "0.481"}, {"asset_id": "19214394437683566921750936876376421489271269944393354497977881791256347396217", "price": "0.53", "size": "19172", "side": "SELL", "hash": "78c3df728e0260739c44766810d4e8435a733d36", "best_bid": "0.519", "best_ask": "0.52"}], "timestamp": "1782707779010", "event_type": "price_change"}}
{"local_timestamp": 1782707778.3639815, "slug": "will-lionel-messi-be-the-top-goalscorer-at-the-2026-fifa-world-cup", "data": {"market": "0xd2a8caba5559bc21e14f6b2aa504cb14a1782751658b71409e25b82e432c0a97", "price_changes": [{"asset_id": "19214394437683566921750936876376421489271269944393354497977881791256347396217", "price": "0.521", "size": "4487.5", "side": "SELL", "hash": "ce9ea854b44bc6224d22dc71cd3bc554a6c53645", "best_bid": "0.519", "best_ask": "0.52"}, {"asset_id": "36586667785814641857008731622413716797407337292495614620493145114086484487337", "price": "0.479", "size": "4487.5", "side": "BUY", "hash": "35840d6d6b5470b4a5e97909fe18c1fbcf95f6a6", "best_bid": "0.48", "best_ask": "0.481"}], "timestamp": "1782707779596", "event_type": "price_change"}}
{"local_timestamp": 1782707778.8584213, "slug": "will-lionel-messi-be-the-top-goalscorer-at-the-2026-fifa-world-cup", "data": {"market": "0xd2a8caba5559bc21e14f6b2aa504cb14a1782751658b71409e25b82e432c0a97", "price_changes": [{"asset_id": "19214394437683566921750936876376421489271269944393354497977881791256347396217", "price": "0.26", "size": "0", "side": "BUY", "hash": "0d36063e8c3a259ca43b910bba5ebbfb977ed15f", "best_bid": "0.519", "best_ask": "0.52"}, {"asset_id": "36586667785814641857008731622413716797407337292495614620493145114086484487337", "price": "0.74", "size": "0", "side": "SELL", "hash": "22ea043a5a6a1745a8deb6dc7a984023984b7716", "best_bid": "0.48", "best_ask": "0.481"}], "timestamp": "1782707780089", "event_type": "price_change"}}
{"local_timestamp": 1782707778.8590152, "slug": "will-lionel-messi-be-the-top-goalscorer-at-the-2026-fifa-world-cup", "data": {"market": "0xd2a8caba5559bc21e14f6b2aa504cb14a1782751658b71409e25b82e432c0a97", "price_changes": [{"asset_id": "36586667785814641857008731622413716797407337292495614620493145114086484487337", "price": "0.35", "size": "200", "side": "BUY", "hash": "99332c2ecc5e7b4c2116a46e467ba511d04647fc", "best_bid": "0.48", "best_ask": "0.481"}, {"asset_id": "19214394437683566921750936876376421489271269944393354497977881791256347396217", "price": "0.65", "size": "200", "side": "SELL", "hash": "097d852a7c6d61244335987a1d8feb35d8adb6c4", "best_bid": "0.519", "best_ask": "0.52"}], "timestamp": "1782707780089", "event_type": "price_change"}}
{"local_timestamp": 1782707779.039113, "slug": "will-lionel-messi-be-the-top-goalscorer-at-the-2026-fifa-world-cup", "data": {"market": "0xd2a8caba5559bc21e14f6b2aa504cb14a1782751658b71409e25b82e432c0a97", "price_changes": [{"asset_id": "36586667785814641857008731622413716797407337292495614620493145114086484487337", "price": "0.46", "size": "44771", "side": "BUY", "hash": "f4500c6bf41691f4b3903f309a8006a0506aff5f", "best_bid": "0.48", "best_ask": "0.481"}, {"asset_id": "19214394437683566921750936876376421489271269944393354497977881791256347396217", "price": "0.54", "size": "44771", "side": "SELL", "hash": "561361c8d8b634b7b3dc4fe3eb78f42bfb958171", "best_bid": "0.519", "best_ask": "0.52"}], "timestamp": "1782707780272", "event_type": "price_change"}}
{"local_timestamp": 1782707779.3948905, "slug": "will-lionel-messi-be-the-top-goalscorer-at-the-2026-fifa-world-cup", "data": {"market": "0xd2a8caba5559bc21e14f6b2aa504cb14a1782751658b71409e25b82e432c0a97", "price_changes": [{"asset_id": "36586667785814641857008731622413716797407337292495614620493145114086484487337", "price": "0.312", "size": "2000", "side": "BUY", "hash": "03dc03bde179715c1a3cee8083b4296f1ba57129", "best_bid": "0.48", "best_ask": "0.481"}, {"asset_id": "19214394437683566921750936876376421489271269944393354497977881791256347396217", "price": "0.688", "size": "2000", "side": "SELL", "hash": "3e81826140883bb6008b8fc6da2d2903f00b1ad5", "best_bid": "0.519", "best_ask": "0.52"}], "timestamp": "1782707780621", "event_type": "price_change"}}
{"local_timestamp": 1782707779.773149, "slug": "will-lionel-messi-be-the-top-goalscorer-at-the-2026-fifa-world-cup", "data": {"market": "0xd2a8caba5559bc21e14f6b2aa504cb14a1782751658b71409e25b82e432c0a97", "price_changes": [{"asset_id": "19214394437683566921750936876376421489271269944393354497977881791256347396217", "price": "0.5", "size": "29558", "side": "BUY", "hash": "c82b3459b8a1a98ff52cdb9c82c252c929b5d259", "best_bid": "0.519", "best_ask": "0.52"}, {"asset_id": "36586667785814641857008731622413716797407337292495614620493145114086484487337", "price": "0.5", "size": "29558", "side": "SELL", "hash": "76b9983e6ed108dc023a992a4d492cf4c0dc6c76", "best_bid": "0.48", "best_ask": "0.481"}], "timestamp": "1782707781001", "event_type": "price_change"}}
{"local_timestamp": 1782707780.4134657, "slug": "will-lionel-messi-be-the-top-goalscorer-at-the-2026-fifa-world-cup", "data": {"market": "0xd2a8caba5559bc21e14f6b2aa504cb14a1782751658b71409e25b82e432c0a97", "price_changes": [{"asset_id": "36586667785814641857008731622413716797407337292495614620493145114086484487337", "price": "0.35", "size": "3200", "side": "BUY", "hash": "da304df1452b426433b94d0c43a7aec2c474dbf4", "best_bid": "0.48", "best_ask": "0.481"}, {"asset_id": "19214394437683566921750936876376421489271269944393354497977881791256347396217", "price": "0.65", "size": "3200", "side": "SELL", "hash": "5ed558c4a9133c66e8aa6692fc90e137cacc1b23", "best_bid": "0.519", "best_ask": "0.52"}], "timestamp": "1782707781640", "event_type": "price_change"}}
{"local_timestamp": 1782707780.414054, "slug": "will-lionel-messi-be-the-top-goalscorer-at-the-2026-fifa-world-cup", "data": {"market": "0xd2a8caba5559bc21e14f6b2aa504cb14a1782751658b71409e25b82e432c0a97", "price_changes": [{"asset_id": "19214394437683566921750936876376421489271269944393354497977881791256347396217", "price": "0.26", "size": "3000", "side": "BUY", "hash": "b7cabaadf7b766a0b7f6259468d1ad633dffad7d", "best_bid": "0.519", "best_ask": "0.52"}, {"asset_id": "36586667785814641857008731622413716797407337292495614620493145114086484487337", "price": "0.74", "size": "3000", "side": "SELL", "hash": "db1b497ff8c9985ffea87257e63f02ebf4407d46", "best_bid": "0.48", "best_ask": "0.481"}], "timestamp": "1782707781642", "event_type": "price_change"}}
{"local_timestamp": 1782707781.053223, "slug": "will-lionel-messi-be-the-top-goalscorer-at-the-2026-fifa-world-cup", "data": {"market": "0xd2a8caba5559bc21e14f6b2aa504cb14a1782751658b71409e25b82e432c0a97", "price_changes": [{"asset_id": "36586667785814641857008731622413716797407337292495614620493145114086484487337", "price": "0.312", "size": "2100", "side": "BUY", "hash": "d31b12c8130a0d72c64721d7661bb16ff0857c13", "best_bid": "0.48", "best_ask": "0.481"}, {"asset_id": "19214394437683566921750936876376421489271269944393354497977881791256347396217", "price": "0.688", "size": "2100", "side": "SELL", "hash": "860597f30d239087a3044a105d2544a729c3f4c3", "best_bid": "0.519", "best_ask": "0.52"}], "timestamp": "1782707782285", "event_type": "price_change"}}
{"local_timestamp": 1782707781.7850754, "slug": "will-lionel-messi-be-the-top-goalscorer-at-the-2026-fifa-world-cup", "data": {"market": "0xd2a8caba5559bc21e14f6b2aa504cb14a1782751658b71409e25b82e432c0a97", "price_changes": [{"asset_id": "19214394437683566921750936876376421489271269944393354497977881791256347396217", "price": "0.318", "size": "200", "side": "BUY", "hash": "43ad0ed3820f1543b7dffa1f791cf8866fc9af78", "best_bid": "0.519", "best_ask": "0.52"}, {"asset_id": "36586667785814641857008731622413716797407337292495614620493145114086484487337", "price": "0.682", "size": "200", "side": "SELL", "hash": "7fb966bd811b3bb74b5b2a3d1427665d7bbad8b0", "best_bid": "0.48", "best_ask": "0.481"}], "timestamp": "1782707783016", "event_type": "price_change"}}
{"local_timestamp": 1782707781.8973932, "slug": "will-lionel-messi-be-the-top-goalscorer-at-the-2026-fifa-world-cup", "data": {"market": "0xd2a8caba5559bc21e14f6b2aa504cb14a1782751658b71409e25b82e432c0a97", "price_changes": [{"asset_id": "19214394437683566921750936876376421489271269944393354497977881791256347396217", "price": "0.26", "size": "0", "side": "BUY", "hash": "415e12d0babae05eb20d5035af13b83b7b9aa94e", "best_bid": "0.519", "best_ask": "0.52"}, {"asset_id": "36586667785814641857008731622413716797407337292495614620493145114086484487337", "price": "0.74", "size": "0", "side": "SELL", "hash": "dc2bdb2aa924ff1e6efc076141febf37b42700b8", "best_bid": "0.48", "best_ask": "0.481"}], "timestamp": "1782707783127", "event_type": "price_change"}}
{"local_timestamp": 1782707781.898166, "slug": "will-lionel-messi-be-the-top-goalscorer-at-the-2026-fifa-world-cup", "data": {"market": "0xd2a8caba5559bc21e14f6b2aa504cb14a1782751658b71409e25b82e432c0a97", "price_changes": [{"asset_id": "36586667785814641857008731622413716797407337292495614620493145114086484487337", "price": "0.35", "size": "200", "side": "BUY", "hash": "53702a9112d66402e468dbdf56e2290a28ef1b4a", "best_bid": "0.48", "best_ask": "0.481"}, {"asset_id": "19214394437683566921750936876376421489271269944393354497977881791256347396217", "price": "0.65", "size": "200", "side": "SELL", "hash": "1566e8aa7f980c9d699cc3d4cbb2b71d8aa18593", "best_bid": "0.519", "best_ask": "0.52"}], "timestamp": "1782707783128", "event_type": "price_change"}}
{"local_timestamp": 1782707782.6079063, "slug": "will-lionel-messi-be-the-top-goalscorer-at-the-2026-fifa-world-cup", "data": {"market": "0xd2a8caba5559bc21e14f6b2aa504cb14a1782751658b71409e25b82e432c0a97", "price_changes": [{"asset_id": "19214394437683566921750936876376421489271269944393354497977881791256347396217", "price": "0.521", "size": "4584.59", "side": "SELL", "hash": "2c97997b24697e79e5396b299664b36716d68158", "best_bid": "0.519", "best_ask": "0.52"}, {"asset_id": "36586667785814641857008731622413716797407337292495614620493145114086484487337", "price": "0.479", "size": "4584.59", "side": "BUY", "hash": "dfb418046f959ee375cf6ac83ca0d99c508702e1", "best_bid": "0.48", "best_ask": "0.481"}], "timestamp": "1782707783839", "event_type": "price_change"}}
{"local_timestamp": 1782707783.4554272, "slug": "will-lionel-messi-be-the-top-goalscorer-at-the-2026-fifa-world-cup", "data": {"market": "0xd2a8caba5559bc21e14f6b2aa504cb14a1782751658b71409e25b82e432c0a97", "price_changes": [{"asset_id": "19214394437683566921750936876376421489271269944393354497977881791256347396217", "price": "0.26", "size": "3000", "side": "BUY", "hash": "1c50766b4da606773fc85eeee04201b990bef4fb", "best_bid": "0.519", "best_ask": "0.52"}, {"asset_id": "36586667785814641857008731622413716797407337292495614620493145114086484487337", "price": "0.74", "size": "3000", "side": "SELL", "hash": "10361379dec1fee772f52cb73c0c7f7cef6bebe7", "best_bid": "0.48", "best_ask": "0.481"}], "timestamp": "1782707784681", "event_type": "price_change"}}
{"local_timestamp": 1782707783.4571676, "slug": "will-lionel-messi-be-the-top-goalscorer-at-the-2026-fifa-world-cup", "data": {"market": "0xd2a8caba5559bc21e14f6b2aa504cb14a1782751658b71409e25b82e432c0a97", "price_changes": [{"asset_id": "36586667785814641857008731622413716797407337292495614620493145114086484487337", "price": "0.35", "size": "3200", "side": "BUY", "hash": "4a6fbaa548af75b8c5e83c737163e552c4cf4662", "best_bid": "0.48", "best_ask": "0.481"}, {"asset_id": "19214394437683566921750936876376421489271269944393354497977881791256347396217", "price": "0.65", "size": "3200", "side": "SELL", "hash": "8e52561609d6160b2d88bf4d3c5370185feefe87", "best_bid": "0.519", "best_ask": "0.52"}], "timestamp": "1782707784689", "event_type": "price_change"}}
{"local_timestamp": 1782707784.3328342, "slug": "will-lionel-messi-be-the-top-goalscorer-at-the-2026-fifa-world-cup", "data": {"market": "0xd2a8caba5559bc21e14f6b2aa504cb14a1782751658b71409e25b82e432c0a97", "price_changes": [{"asset_id": "36586667785814641857008731622413716797407337292495614620493145114086484487337", "price": "0.361", "size": "50", "side": "BUY", "hash": "7b2a98fe63e90a1957ba764ace76799c4363666d", "best_bid": "0.48", "best_ask": "0.481"}, {"asset_id": "19214394437683566921750936876376421489271269944393354497977881791256347396217", "price": "0.639", "size": "50", "side": "SELL", "hash": "2f2b493ab567d6509a3b3fa1ff46c8957e5f3af1", "best_bid": "0.519", "best_ask": "0.52"}], "timestamp": "1782707785565", "event_type": "price_change"}}
{"local_timestamp": 1782707784.5305998, "slug": "will-lionel-messi-be-the-top-goalscorer-at-the-2026-fifa-world-cup", "data": {"market": "0xd2a8caba5559bc21e14f6b2aa504cb14a1782751658b71409e25b82e432c0a97", "price_changes": [{"asset_id": "19214394437683566921750936876376421489271269944393354497977881791256347396217", "price": "0.521", "size": "4487.5", "side": "SELL", "hash": "5256dce5553f9e92d763a3753366167ac4661f87", "best_bid": "0.519", "best_ask": "0.52"}, {"asset_id": "36586667785814641857008731622413716797407337292495614620493145114086484487337", "price": "0.479", "size": "4487.5", "side": "BUY", "hash": "fabe69529f492bb16090919f9449f82865339623", "best_bid": "0.48", "best_ask": "0.481"}], "timestamp": "1782707785759", "event_type": "price_change"}}
{"local_timestamp": 1782707784.8850253, "slug": "will-lionel-messi-be-the-top-goalscorer-at-the-2026-fifa-world-cup", "data": {"market": "0xd2a8caba5559bc21e14f6b2aa504cb14a1782751658b71409e25b82e432c0a97", "price_changes": [{"asset_id": "36586667785814641857008731622413716797407337292495614620493145114086484487337", "price": "0.35", "size": "200", "side": "BUY", "hash": "38e242064a8454347d5340e9c50b16524db608dd", "best_bid": "0.48", "best_ask": "0.481"}, {"asset_id": "19214394437683566921750936876376421489271269944393354497977881791256347396217", "price": "0.65", "size": "200", "side": "SELL", "hash": "516fcbd67ec03c207748396da0cb306e5415d0ab", "best_bid": "0.519", "best_ask": "0.52"}], "timestamp": "1782707786118", "event_type": "price_change"}}
{"local_timestamp": 1782707784.8859997, "slug": "will-lionel-messi-be-the-top-goalscorer-at-the-2026-fifa-world-cup", "data": {"market": "0xd2a8caba5559bc21e14f6b2aa504cb14a1782751658b71409e25b82e432c0a97", "price_changes": [{"asset_id": "19214394437683566921750936876376421489271269944393354497977881791256347396217", "price": "0.26", "size": "0", "side": "BUY", "hash": "b539fa0ae722ad9cd8044af9cbffc2c353d45723", "best_bid": "0.519", "best_ask": "0.52"}, {"asset_id": "36586667785814641857008731622413716797407337292495614620493145114086484487337", "price": "0.74", "size": "0", "side": "SELL", "hash": "9cdeac24435062f5c2174b964f8b9a8dee43f2fe", "best_bid": "0.48", "best_ask": "0.481"}], "timestamp": "1782707786118", "event_type": "price_change"}}
{"local_timestamp": 1782707786.678425, "slug": "will-lionel-messi-be-the-top-goalscorer-at-the-2026-fifa-world-cup", "data": {"market": "0xd2a8caba5559bc21e14f6b2aa504cb14a1782751658b71409e25b82e432c0a97", "price_changes": [{"asset_id": "36586667785814641857008731622413716797407337292495614620493145114086484487337", "price": "0.35", "size": "3200", "side": "BUY", "hash": "12530706dd4e2374254ef3f2fefa8ca5691914c0", "best_bid": "0.48", "best_ask": "0.481"}, {"asset_id": "19214394437683566921750936876376421489271269944393354497977881791256347396217", "price": "0.65", "size": "3200", "side": "SELL", "hash": "7f2ced0568470b2949b4f4795c8e461a7fb1ed03", "best_bid": "0.519", "best_ask": "0.52"}], "timestamp": "1782707787910", "event_type": "price_change"}}
{"local_timestamp": 1782707786.9871993, "slug": "will-lionel-messi-be-the-top-goalscorer-at-the-2026-fifa-world-cup", "data": {"market": "0xd2a8caba5559bc21e14f6b2aa504cb14a1782751658b71409e25b82e432c0a97", "price_changes": [{"asset_id": "19214394437683566921750936876376421489271269944393354497977881791256347396217", "price": "0.26", "size": "3000", "side": "BUY", "hash": "fac4a2498070a1534cc4402677bc2f1b53da38ec", "best_bid": "0.519", "best_ask": "0.52"}, {"asset_id": "36586667785814641857008731622413716797407337292495614620493145114086484487337", "price": "0.74", "size": "3000", "side": "SELL", "hash": "d8189bba458e996ca07fa2cbb07cf89655a7dc7e", "best_bid": "0.48", "best_ask": "0.481"}], "timestamp": "1782707787916", "event_type": "price_change"}}
{"local_timestamp": 1782707787.3410068, "slug": "will-lionel-messi-be-the-top-goalscorer-at-the-2026-fifa-world-cup", "data": {"market": "0xd2a8caba5559bc21e14f6b2aa504cb14a1782751658b71409e25b82e432c0a97", "price_changes": [{"asset_id": "19214394437683566921750936876376421489271269944393354497977881791256347396217", "price": "0.521", "size": "4584.59", "side": "SELL", "hash": "50e1120537fadf1236f7f5f583b99c912219129f", "best_bid": "0.519", "best_ask": "0.52"}, {"asset_id": "36586667785814641857008731622413716797407337292495614620493145114086484487337", "price": "0.479", "size": "4584.59", "side": "BUY", "hash": "e53a5cd33296303fd23a96504bfc757fcb7ef28f", "best_bid": "0.48", "best_ask": "0.481"}], "timestamp": "1782707788570", "event_type": "price_change"}}
{"local_timestamp": 1782707787.8211489, "slug": "will-lionel-messi-be-the-top-goalscorer-at-the-2026-fifa-world-cup", "data": {"market": "0xd2a8caba5559bc21e14f6b2aa504cb14a1782751658b71409e25b82e432c0a97", "price_changes": [{"asset_id": "19214394437683566921750936876376421489271269944393354497977881791256347396217", "price": "0.26", "size": "0", "side": "BUY", "hash": "a02771734bbfd7b5022e6d1b4951722285e37dde", "best_bid": "0.519", "best_ask": "0.52"}, {"asset_id": "36586667785814641857008731622413716797407337292495614620493145114086484487337", "price": "0.74", "size": "0", "side": "SELL", "hash": "c53e015ae5eb5fdf7d3be3eeb109d38ec1a4c4b4", "best_bid": "0.48", "best_ask": "0.481"}], "timestamp": "1782707789054", "event_type": "price_change"}}
{"local_timestamp": 1782707787.8401606, "slug": "will-lionel-messi-be-the-top-goalscorer-at-the-2026-fifa-world-cup", "data": {"market": "0xd2a8caba5559bc21e14f6b2aa504cb14a1782751658b71409e25b82e432c0a97", "price_changes": [{"asset_id": "36586667785814641857008731622413716797407337292495614620493145114086484487337", "price": "0.35", "size": "200", "side": "BUY", "hash": "eea8d59bad6f84541594c1e9c74c92629bf5e7a9", "best_bid": "0.48", "best_ask": "0.481"}, {"asset_id": "19214394437683566921750936876376421489271269944393354497977881791256347396217", "price": "0.65", "size": "200", "side": "SELL", "hash": "114759d8d447719918d90317bf6abaf9d5e6e3cc", "best_bid": "0.519", "best_ask": "0.52"}], "timestamp": "1782707789063", "event_type": "price_change"}}
{"local_timestamp": 1782707787.978442, "slug": "will-lionel-messi-be-the-top-goalscorer-at-the-2026-fifa-world-cup", "data": {"market": "0xd2a8caba5559bc21e14f6b2aa504cb14a1782751658b71409e25b82e432c0a97", "price_changes": [{"asset_id": "36586667785814641857008731622413716797407337292495614620493145114086484487337", "price": "0.35", "size": "3200", "side": "BUY", "hash": "7064c172ee8113785002ed9c3649b97ee2a2e0a3", "best_bid": "0.48", "best_ask": "0.481"}, {"asset_id": "19214394437683566921750936876376421489271269944393354497977881791256347396217", "price": "0.65", "size": "3200", "side": "SELL", "hash": "dbc5196664e2ef56b33a08f03e6b03bdfa021216", "best_bid": "0.519", "best_ask": "0.52"}], "timestamp": "1782707789211", "event_type": "price_change"}}
{"local_timestamp": 1782707787.9898033, "slug": "will-lionel-messi-be-the-top-goalscorer-at-the-2026-fifa-world-cup", "data": {"market": "0xd2a8caba5559bc21e14f6b2aa504cb14a1782751658b71409e25b82e432c0a97", "price_changes": [{"asset_id": "19214394437683566921750936876376421489271269944393354497977881791256347396217", "price": "0.26", "size": "3000", "side": "BUY", "hash": "8b38219796d1d5dbe5ba2f6348a9f2f59fe2136b", "best_bid": "0.519", "best_ask": "0.52"}, {"asset_id": "36586667785814641857008731622413716797407337292495614620493145114086484487337", "price": "0.74", "size": "3000", "side": "SELL", "hash": "ef5c6d88efa8720fb73e8cb401538e10f7d59604", "best_bid": "0.48", "best_ask": "0.481"}], "timestamp": "1782707789222", "event_type": "price_change"}}
{"local_timestamp": 1782707788.8166852, "slug": "will-lionel-messi-be-the-top-goalscorer-at-the-2026-fifa-world-cup", "data": {"market": "0xd2a8caba5559bc21e14f6b2aa504cb14a1782751658b71409e25b82e432c0a97", "price_changes": [{"asset_id": "19214394437683566921750936876376421489271269944393354497977881791256347396217", "price": "0.521", "size": "4487.5", "side": "SELL", "hash": "e26ebeb404807ccf016fac370d92283508ea76b1", "best_bid": "0.519", "best_ask": "0.52"}, {"asset_id": "36586667785814641857008731622413716797407337292495614620493145114086484487337", "price": "0.479", "size": "4487.5", "side": "BUY", "hash": "3b53b0c2c52e0a27426b243cf6ebfb49f8fb1b50", "best_bid": "0.48", "best_ask": "0.481"}], "timestamp": "1782707790049", "event_type": "price_change"}}
{"local_timestamp": 1782707789.4172943, "slug": "will-lionel-messi-be-the-top-goalscorer-at-the-2026-fifa-world-cup", "data": {"market": "0xd2a8caba5559bc21e14f6b2aa504cb14a1782751658b71409e25b82e432c0a97", "price_changes": [{"asset_id": "19214394437683566921750936876376421489271269944393354497977881791256347396217", "price": "0.26", "size": "0", "side": "BUY", "hash": "d590d7d927e1d857d10f879f328f61c6684a95f9", "best_bid": "0.519", "best_ask": "0.52"}, {"asset_id": "36586667785814641857008731622413716797407337292495614620493145114086484487337", "price": "0.74", "size": "0", "side": "SELL", "hash": "ce8a8264d56bc8b8feaf38b233f0c8c71694d662", "best_bid": "0.48", "best_ask": "0.481"}], "timestamp": "1782707790650", "event_type": "price_change"}}
{"local_timestamp": 1782707789.4180036, "slug": "will-lionel-messi-be-the-top-goalscorer-at-the-2026-fifa-world-cup", "data": {"market": "0xd2a8caba5559bc21e14f6b2aa504cb14a1782751658b71409e25b82e432c0a97", "price_changes": [{"asset_id": "36586667785814641857008731622413716797407337292495614620493145114086484487337", "price": "0.35", "size": "200", "side": "BUY", "hash": "606a37d31fed4c3a9b9c416ff93a9b06034cb3c2", "best_bid": "0.48", "best_ask": "0.481"}, {"asset_id": "19214394437683566921750936876376421489271269944393354497977881791256347396217", "price": "0.65", "size": "200", "side": "SELL", "hash": "a3c5b5d0c19f9308d8c51aa5f5660c83e20d8434", "best_bid": "0.519", "best_ask": "0.52"}], "timestamp": "1782707790651", "event_type": "price_change"}}
{"local_timestamp": 1782707789.7701225, "slug": "will-lionel-messi-be-the-top-goalscorer-at-the-2026-fifa-world-cup", "data": {"market": "0xd2a8caba5559bc21e14f6b2aa504cb14a1782751658b71409e25b82e432c0a97", "price_changes": [{"asset_id": "19214394437683566921750936876376421489271269944393354497977881791256347396217", "price": "0.5", "size": "29322", "side": "BUY", "hash": "affda66d11c7d98f5293501f64eaa946e1e1bf4e", "best_bid": "0.519", "best_ask": "0.52"}, {"asset_id": "36586667785814641857008731622413716797407337292495614620493145114086484487337", "price": "0.5", "size": "29322", "side": "SELL", "hash": "19f1c1dfb347cba2b6ccd5d2ca2b562338d33bbe", "best_bid": "0.48", "best_ask": "0.481"}], "timestamp": "1782707791000", "event_type": "price_change"}}
{"local_timestamp": 1782707790.1027327, "slug": "will-lionel-messi-be-the-top-goalscorer-at-the-2026-fifa-world-cup", "data": {"market": "0xd2a8caba5559bc21e14f6b2aa504cb14a1782751658b71409e25b82e432c0a97", "price_changes": [{"asset_id": "19214394437683566921750936876376421489271269944393354497977881791256347396217", "price": "0.319", "size": "200", "side": "BUY", "hash": "23888326c0bd3f23e3b63c198f36d928e909b9dd", "best_bid": "0.519", "best_ask": "0.52"}, {"asset_id": "36586667785814641857008731622413716797407337292495614620493145114086484487337", "price": "0.681", "size": "200", "side": "SELL", "hash": "085739f57ef8f008bf7860e0ab994864410ed2ac", "best_bid": "0.48", "best_ask": "0.481"}], "timestamp": "1782707791332", "event_type": "price_change"}}
{"local_timestamp": 1782707790.4504056, "slug": "will-lionel-messi-be-the-top-goalscorer-at-the-2026-fifa-world-cup", "data": {"market": "0xd2a8caba5559bc21e14f6b2aa504cb14a1782751658b71409e25b82e432c0a97", "price_changes": [{"asset_id": "19214394437683566921750936876376421489271269944393354497977881791256347396217", "price": "0.318", "size": "0", "side": "BUY", "hash": "f27935991b26106e686d2eabec580ba43d41f39b", "best_bid": "0.519", "best_ask": "0.52"}, {"asset_id": "36586667785814641857008731622413716797407337292495614620493145114086484487337", "price": "0.682", "size": "0", "side": "SELL", "hash": "6317e14b8e3023042d200263b55fdfdc25e96b2f", "best_bid": "0.48", "best_ask": "0.481"}], "timestamp": "1782707791434", "event_type": "price_change"}}
{"local_timestamp": 1782707790.8799293, "slug": "will-lionel-messi-be-the-top-goalscorer-at-the-2026-fifa-world-cup", "data": {"market": "0xd2a8caba5559bc21e14f6b2aa504cb14a1782751658b71409e25b82e432c0a97", "price_changes": [{"asset_id": "36586667785814641857008731622413716797407337292495614620493145114086484487337", "price": "0.35", "size": "3200", "side": "BUY", "hash": "8e65dd0f1540ebbf1e93cdb29f6de83d9ad9a0a4", "best_bid": "0.48", "best_ask": "0.481"}, {"asset_id": "19214394437683566921750936876376421489271269944393354497977881791256347396217", "price": "0.65", "size": "3200", "side": "SELL", "hash": "c77e2030ed6093cffdff0745c07df192b0de8329", "best_bid": "0.519", "best_ask": "0.52"}], "timestamp": "1782707792112", "event_type": "price_change"}}
{"local_timestamp": 1782707790.8885646, "slug": "will-lionel-messi-be-the-top-goalscorer-at-the-2026-fifa-world-cup", "data": {"market": "0xd2a8caba5559bc21e14f6b2aa504cb14a1782751658b71409e25b82e432c0a97", "price_changes": [{"asset_id": "19214394437683566921750936876376421489271269944393354497977881791256347396217", "price": "0.26", "size": "3000", "side": "BUY", "hash": "60158bf4d3b32daeff0bb3d25d3f18fa833801b2", "best_bid": "0.519", "best_ask": "0.52"}, {"asset_id": "36586667785814641857008731622413716797407337292495614620493145114086484487337", "price": "0.74", "size": "3000", "side": "SELL", "hash": "dd0126cac74f6f97c0a92237bcf998a521acc082", "best_bid": "0.48", "best_ask": "0.481"}], "timestamp": "1782707792122", "event_type": "price_change"}}
{"local_timestamp": 1782707791.2653923, "slug": "will-lionel-messi-be-the-top-goalscorer-at-the-2026-fifa-world-cup", "data": {"market": "0xd2a8caba5559bc21e14f6b2aa504cb14a1782751658b71409e25b82e432c0a97", "price_changes": [{"asset_id": "19214394437683566921750936876376421489271269944393354497977881791256347396217", "price": "0.521", "size": "4584.59", "side": "SELL", "hash": "aa975b49e16462f0a40d39c43761d28cceeba319", "best_bid": "0.519", "best_ask": "0.52"}, {"asset_id": "36586667785814641857008731622413716797407337292495614620493145114086484487337", "price": "0.479", "size": "4584.59", "side": "BUY", "hash": "5836e91c4277219c4107c0854d7381e92f1335d4", "best_bid": "0.48", "best_ask": "0.481"}], "timestamp": "1782707792498", "event_type": "price_change"}}
{"local_timestamp": 1782707792.3971121, "slug": "will-lionel-messi-be-the-top-goalscorer-at-the-2026-fifa-world-cup", "data": {"market": "0xd2a8caba5559bc21e14f6b2aa504cb14a1782751658b71409e25b82e432c0a97", "price_changes": [{"asset_id": "19214394437683566921750936876376421489271269944393354497977881791256347396217", "price": "0.26", "size": "0", "side": "BUY", "hash": "c987e4e51ea9bc67e0084c9d11675e4629ad9363", "best_bid": "0.519", "best_ask": "0.52"}, {"asset_id": "36586667785814641857008731622413716797407337292495614620493145114086484487337", "price": "0.74", "size": "0", "side": "SELL", "hash": "5aa014d3c42435763f084f9fd487b8ac97e12b9f", "best_bid": "0.48", "best_ask": "0.481"}], "timestamp": "1782707793614", "event_type": "price_change"}}
{"local_timestamp": 1782707792.3976843, "slug": "will-lionel-messi-be-the-top-goalscorer-at-the-2026-fifa-world-cup", "data": {"market": "0xd2a8caba5559bc21e14f6b2aa504cb14a1782751658b71409e25b82e432c0a97", "price_changes": [{"asset_id": "36586667785814641857008731622413716797407337292495614620493145114086484487337", "price": "0.35", "size": "200", "side": "BUY", "hash": "73d37738bb730d8de158e79b60b1e40f804775f5", "best_bid": "0.48", "best_ask": "0.481"}, {"asset_id": "19214394437683566921750936876376421489271269944393354497977881791256347396217", "price": "0.65", "size": "200", "side": "SELL", "hash": "5ab73d8dbb0ccad45cb824ef609ba7afb3e329f4", "best_bid": "0.519", "best_ask": "0.52"}], "timestamp": "1782707793614", "event_type": "price_change"}}
{"local_timestamp": 1782707793.930806, "slug": "will-lionel-messi-be-the-top-goalscorer-at-the-2026-fifa-world-cup", "data": {"market": "0xd2a8caba5559bc21e14f6b2aa504cb14a1782751658b71409e25b82e432c0a97", "price_changes": [{"asset_id": "19214394437683566921750936876376421489271269944393354497977881791256347396217", "price": "0.521", "size": "4487.5", "side": "SELL", "hash": "64d5528d8cd3f205be3aacbd75d1358f92dc7bd7", "best_bid": "0.519", "best_ask": "0.52"}, {"asset_id": "36586667785814641857008731622413716797407337292495614620493145114086484487337", "price": "0.479", "size": "4487.5", "side": "BUY", "hash": "d2dcaf38671ad7e91cf1522f087fcc44f97fe05b", "best_bid": "0.48", "best_ask": "0.481"}], "timestamp": "1782707795155", "event_type": "price_change"}}
{"local_timestamp": 1782707793.9314203, "slug": "will-lionel-messi-be-the-top-goalscorer-at-the-2026-fifa-world-cup", "data": {"market": "0xd2a8caba5559bc21e14f6b2aa504cb14a1782751658b71409e25b82e432c0a97", "price_changes": [{"asset_id": "36586667785814641857008731622413716797407337292495614620493145114086484487337", "price": "0.35", "size": "3200", "side": "BUY", "hash": "98cacf19d73d8fe3f6729510100206daf255c427", "best_bid": "0.48", "best_ask": "0.481"}, {"asset_id": "19214394437683566921750936876376421489271269944393354497977881791256347396217", "price": "0.65", "size": "3200", "side": "SELL", "hash": "09037547b9e9ceb426dc93d8b90c0f109c69401c", "best_bid": "0.519", "best_ask": "0.52"}], "timestamp": "1782707795158", "event_type": "price_change"}}
{"local_timestamp": 1782707793.9318905, "slug": "will-lionel-messi-be-the-top-goalscorer-at-the-2026-fifa-world-cup", "data": {"market": "0xd2a8caba5559bc21e14f6b2aa504cb14a1782751658b71409e25b82e432c0a97", "price_changes": [{"asset_id": "19214394437683566921750936876376421489271269944393354497977881791256347396217", "price": "0.26", "size": "3000", "side": "BUY", "hash": "e1fec8457309da09f0a9e1f98f53588a7d713a7e", "best_bid": "0.519", "best_ask": "0.52"}, {"asset_id": "36586667785814641857008731622413716797407337292495614620493145114086484487337", "price": "0.74", "size": "3000", "side": "SELL", "hash": "6c7d51a4e02c367443f1d26e294cd9d860f6fa6f", "best_bid": "0.48", "best_ask": "0.481"}], "timestamp": "1782707795163", "event_type": "price_change"}}
{"local_timestamp": 1782707794.2474003, "slug": "will-lionel-messi-be-the-top-goalscorer-at-the-2026-fifa-world-cup", "data": {"market": "0xd2a8caba5559bc21e14f6b2aa504cb14a1782751658b71409e25b82e432c0a97", "price_changes": [{"asset_id": "19214394437683566921750936876376421489271269944393354497977881791256347396217", "price": "0.511", "size": "3261.5", "side": "BUY", "hash": "59b2dc9a2d192eae2be0a36268be5f894c3c31e5", "best_bid": "0.519", "best_ask": "0.52"}, {"asset_id": "36586667785814641857008731622413716797407337292495614620493145114086484487337", "price": "0.489", "size": "3261.5", "side": "SELL", "hash": "980b3f479bb897ebb148cea890402ec3a03059ae", "best_bid": "0.48", "best_ask": "0.481"}], "timestamp": "1782707795481", "event_type": "price_change"}}
{"local_timestamp": 1782707794.4891574, "slug": "will-lionel-messi-be-the-top-goalscorer-at-the-2026-fifa-world-cup", "data": {"market": "0xd2a8caba5559bc21e14f6b2aa504cb14a1782751658b71409e25b82e432c0a97", "price_changes": [{"asset_id": "36586667785814641857008731622413716797407337292495614620493145114086484487337", "price": "0.473", "size": "550", "side": "BUY", "hash": "2ae1f829fd22659557374221150dac95ddfce3a3", "best_bid": "0.48", "best_ask": "0.481"}, {"asset_id": "19214394437683566921750936876376421489271269944393354497977881791256347396217", "price": "0.527", "size": "550", "side": "SELL", "hash": "8422fe3587beb8a0df96aa9b393582e3ea5e86dd", "best_bid": "0.519", "best_ask": "0.52"}], "timestamp": "1782707795722", "event_type": "price_change"}}
{"local_timestamp": 1782707795.3618598, "slug": "will-lionel-messi-be-the-top-goalscorer-at-the-2026-fifa-world-cup", "data": {"market": "0xd2a8caba5559bc21e14f6b2aa504cb14a1782751658b71409e25b82e432c0a97", "price_changes": [{"asset_id": "19214394437683566921750936876376421489271269944393354497977881791256347396217", "price": "0.26", "size": "0", "side": "BUY", "hash": "d465457a4e5da68796e3fd06371c5a5b70199fef", "best_bid": "0.519", "best_ask": "0.52"}, {"asset_id": "36586667785814641857008731622413716797407337292495614620493145114086484487337", "price": "0.74", "size": "0", "side": "SELL", "hash": "a7663a9d692e837284a0eaff1a94adf34d36b308", "best_bid": "0.48", "best_ask": "0.481"}], "timestamp": "1782707796592", "event_type": "price_change"}}
{"local_timestamp": 1782707795.3632, "slug": "will-lionel-messi-be-the-top-goalscorer-at-the-2026-fifa-world-cup", "data": {"market": "0xd2a8caba5559bc21e14f6b2aa504cb14a1782751658b71409e25b82e432c0a97", "price_changes": [{"asset_id": "36586667785814641857008731622413716797407337292495614620493145114086484487337", "price": "0.35", "size": "200", "side": "BUY", "hash": "73af3cd2aa7cde862f3d91ceaeb2de67f06a3e28", "best_bid": "0.48", "best_ask": "0.481"}, {"asset_id": "19214394437683566921750936876376421489271269944393354497977881791256347396217", "price": "0.65", "size": "200", "side": "SELL", "hash": "d296e08753ef1b0d9f6d064fc78601bb8bf1fa57", "best_bid": "0.519", "best_ask": "0.52"}], "timestamp": "1782707796593", "event_type": "price_change"}}
{"local_timestamp": 1782707795.3871248, "slug": "will-lionel-messi-be-the-top-goalscorer-at-the-2026-fifa-world-cup", "data": {"market": "0xd2a8caba5559bc21e14f6b2aa504cb14a1782751658b71409e25b82e432c0a97", "price_changes": [{"asset_id": "19214394437683566921750936876376421489271269944393354497977881791256347396217", "price": "0.511", "size": "3561.5", "side": "BUY", "hash": "0835bb4fecfe67572db75b48fd5e9eefc7f7b210", "best_bid": "0.519", "best_ask": "0.52"}, {"asset_id": "36586667785814641857008731622413716797407337292495614620493145114086484487337", "price": "0.489", "size": "3561.5", "side": "SELL", "hash": "51b4aea25a1c9a94fa095554f1ad939ddafee0aa", "best_bid": "0.48", "best_ask": "0.481"}], "timestamp": "1782707796620", "event_type": "price_change"}}
{"local_timestamp": 1782707795.612304, "slug": "will-lionel-messi-be-the-top-goalscorer-at-the-2026-fifa-world-cup", "data": {"market": "0xd2a8caba5559bc21e14f6b2aa504cb14a1782751658b71409e25b82e432c0a97", "price_changes": [{"asset_id": "36586667785814641857008731622413716797407337292495614620493145114086484487337", "price": "0.473", "size": "850", "side": "BUY", "hash": "04ba9a4fd1331de5dd163cd14ef4db4d0a3a3f1d", "best_bid": "0.48", "best_ask": "0.481"}, {"asset_id": "19214394437683566921750936876376421489271269944393354497977881791256347396217", "price": "0.527", "size": "850", "side": "SELL", "hash": "e21091c7c7ae2f4587a38700ab06a73042c0edd6", "best_bid": "0.519", "best_ask": "0.52"}], "timestamp": "1782707796845", "event_type": "price_change"}}
{"local_timestamp": 1782707796.354689, "slug": "will-lionel-messi-be-the-top-goalscorer-at-the-2026-fifa-world-cup", "data": {"market": "0xd2a8caba5559bc21e14f6b2aa504cb14a1782751658b71409e25b82e432c0a97", "price_changes": [{"asset_id": "19214394437683566921750936876376421489271269944393354497977881791256347396217", "price": "0.521", "size": "4584.59", "side": "SELL", "hash": "a727a9f837a437366d85fc137d472c3faaec5edf", "best_bid": "0.519", "best_ask": "0.52"}, {"asset_id": "36586667785814641857008731622413716797407337292495614620493145114086484487337", "price": "0.479", "size": "4584.59", "side": "BUY", "hash": "b12272d87c68a3ed8dd0bab959c87d2dd39f84d6", "best_bid": "0.48", "best_ask": "0.481"}], "timestamp": "1782707797587", "event_type": "price_change"}}
{"local_timestamp": 1782707796.7688491, "slug": "will-lionel-messi-be-the-top-goalscorer-at-the-2026-fifa-world-cup", "data": {"market": "0xd2a8caba5559bc21e14f6b2aa504cb14a1782751658b71409e25b82e432c0a97", "price_changes": [{"asset_id": "36586667785814641857008731622413716797407337292495614620493145114086484487337", "price": "0.46", "size": "43685", "side": "BUY", "hash": "e527826792d60e5d9733427a47668406c52cc4fc", "best_bid": "0.48", "best_ask": "0.481"}, {"asset_id": "19214394437683566921750936876376421489271269944393354497977881791256347396217", "price": "0.54", "size": "43685", "side": "SELL", "hash": "689cd39e671ddc7cb15457a9da37523c0acf262f", "best_bid": "0.519", "best_ask": "0.52"}], "timestamp": "1782707798001", "event_type": "price_change"}}
{"local_timestamp": 1782707796.9721332, "slug": "will-lionel-messi-be-the-top-goalscorer-at-the-2026-fifa-world-cup", "data": {"market": "0xd2a8caba5559bc21e14f6b2aa504cb14a1782751658b71409e25b82e432c0a97", "price_changes": [{"asset_id": "19214394437683566921750936876376421489271269944393354497977881791256347396217", "price": "0.26", "size": "3000", "side": "BUY", "hash": "9de8853f5d2fd47a10c725c5319d0e62e6f1f842", "best_bid": "0.519", "best_ask": "0.52"}, {"asset_id": "36586667785814641857008731622413716797407337292495614620493145114086484487337", "price": "0.74", "size": "3000", "side": "SELL", "hash": "65ba5525ccee3e12fc4a82fd593bf17aa1bfcd66", "best_bid": "0.48", "best_ask": "0.481"}], "timestamp": "1782707798205", "event_type": "price_change"}}
{"local_timestamp": 1782707796.982864, "slug": "will-lionel-messi-be-the-top-goalscorer-at-the-2026-fifa-world-cup", "data": {"market": "0xd2a8caba5559bc21e14f6b2aa504cb14a1782751658b71409e25b82e432c0a97", "price_changes": [{"asset_id": "36586667785814641857008731622413716797407337292495614620493145114086484487337", "price": "0.35", "size": "3200", "side": "BUY", "hash": "cc8f60edd11b0898dbcfdf92e26357817f97f521", "best_bid": "0.48", "best_ask": "0.481"}, {"asset_id": "19214394437683566921750936876376421489271269944393354497977881791256347396217", "price": "0.65", "size": "3200", "side": "SELL", "hash": "41fbbd470533c96abc7f0624f337fc7fd3263f2b", "best_bid": "0.519", "best_ask": "0.52"}], "timestamp": "1782707798216", "event_type": "price_change"}}
{"local_timestamp": 1782707797.9559016, "slug": "will-lionel-messi-be-the-top-goalscorer-at-the-2026-fifa-world-cup", "data": {"market": "0xd2a8caba5559bc21e14f6b2aa504cb14a1782751658b71409e25b82e432c0a97", "price_changes": [{"asset_id": "19214394437683566921750936876376421489271269944393354497977881791256347396217", "price": "0.521", "size": "4487.5", "side": "SELL", "hash": "007a4a16d2cdeb39d121b60cf19590d5c2d6705d", "best_bid": "0.519", "best_ask": "0.52"}, {"asset_id": "36586667785814641857008731622413716797407337292495614620493145114086484487337", "price": "0.479", "size": "4487.5", "side": "BUY", "hash": "1ccb5771cabd7e0f450fdccce69d5e1055a1598f", "best_bid": "0.48", "best_ask": "0.481"}], "timestamp": "1782707799188", "event_type": "price_change"}}
{"local_timestamp": 1782707798.3036585, "slug": "will-lionel-messi-be-the-top-goalscorer-at-the-2026-fifa-world-cup", "data": {"market": "0xd2a8caba5559bc21e14f6b2aa504cb14a1782751658b71409e25b82e432c0a97", "price_changes": [{"asset_id": "19214394437683566921750936876376421489271269944393354497977881791256347396217", "price": "0.32", "size": "200", "side": "BUY", "hash": "ba08edbf1415426528cbf13c8510df8da97c409d", "best_bid": "0.519", "best_ask": "0.52"}, {"asset_id": "36586667785814641857008731622413716797407337292495614620493145114086484487337", "price": "0.68", "size": "200", "side": "SELL", "hash": "0645f28c6d7cb29bea83efb6e883974ad44c7e10", "best_bid": "0.48", "best_ask": "0.481"}], "timestamp": "1782707799536", "event_type": "price_change"}}
{"local_timestamp": 1782707798.3098583, "slug": "will-lionel-messi-be-the-top-goalscorer-at-the-2026-fifa-world-cup", "data": {"market": "0xd2a8caba5559bc21e14f6b2aa504cb14a1782751658b71409e25b82e432c0a97", "price_changes": [{"asset_id": "36586667785814641857008731622413716797407337292495614620493145114086484487337", "price": "0.623", "size": "434.96", "side": "SELL", "hash": "77b92ead8080df32d08585c735b034328b43b70c", "best_bid": "0.48", "best_ask": "0.481"}, {"asset_id": "19214394437683566921750936876376421489271269944393354497977881791256347396217", "price": "0.377", "size": "434.96", "side": "BUY", "hash": "3ed536dbb23ba88682dee0bd7e906b0a35f15fda", "best_bid": "0.519", "best_ask": "0.52"}], "timestamp": "1782707799543", "event_type": "price_change"}}
{"local_timestamp": 1782707798.3507333, "slug": "will-lionel-messi-be-the-top-goalscorer-at-the-2026-fifa-world-cup", "data": {"market": "0xd2a8caba5559bc21e14f6b2aa504cb14a1782751658b71409e25b82e432c0a97", "price_changes": [{"asset_id": "19214394437683566921750936876376421489271269944393354497977881791256347396217", "price": "0.319", "size": "0", "side": "BUY", "hash": "b06589344e2f889ff6a25992e892e5cbdee181c0", "best_bid": "0.519", "best_ask": "0.52"}, {"asset_id": "36586667785814641857008731622413716797407337292495614620493145114086484487337", "price": "0.681", "size": "0", "side": "SELL", "hash": "ffdbb316883eae5a7c4260dc53e828b51a652696", "best_bid": "0.48", "best_ask": "0.481"}], "timestamp": "1782707799584", "event_type": "price_change"}}
{"local_timestamp": 1782707798.362768, "slug": "will-lionel-messi-be-the-top-goalscorer-at-the-2026-fifa-world-cup", "data": {"market": "0xd2a8caba5559bc21e14f6b2aa504cb14a1782751658b71409e25b82e432c0a97", "price_changes": [{"asset_id": "36586667785814641857008731622413716797407337292495614620493145114086484487337", "price": "0.35", "size": "200", "side": "BUY", "hash": "b915a66a9dc2d8fc131cce7b00c2aec8c884464d", "best_bid": "0.48", "best_ask": "0.481"}, {"asset_id": "19214394437683566921750936876376421489271269944393354497977881791256347396217", "price": "0.65", "size": "200", "side": "SELL", "hash": "6ba97ccf35121df507782c85d92c1ed14a238441", "best_bid": "0.519", "best_ask": "0.52"}], "timestamp": "1782707799597", "event_type": "price_change"}}
{"local_timestamp": 1782707798.3636682, "slug": "will-lionel-messi-be-the-top-goalscorer-at-the-2026-fifa-world-cup", "data": {"market": "0xd2a8caba5559bc21e14f6b2aa504cb14a1782751658b71409e25b82e432c0a97", "price_changes": [{"asset_id": "19214394437683566921750936876376421489271269944393354497977881791256347396217", "price": "0.26", "size": "0", "side": "BUY", "hash": "047a4e67cdcfe851f755411ec5c5b39f0aa2cd7b", "best_bid": "0.519", "best_ask": "0.52"}, {"asset_id": "36586667785814641857008731622413716797407337292495614620493145114086484487337", "price": "0.74", "size": "0", "side": "SELL", "hash": "97ffa5a685c7e2b60427b664e6bb36f41f015e80", "best_bid": "0.48", "best_ask": "0.481"}], "timestamp": "1782707799597", "event_type": "price_change"}}
{"local_timestamp": 1782707799.770772, "slug": "will-lionel-messi-be-the-top-goalscorer-at-the-2026-fifa-world-cup", "data": {"market": "0xd2a8caba5559bc21e14f6b2aa504cb14a1782751658b71409e25b82e432c0a97", "price_changes": [{"asset_id": "36586667785814641857008731622413716797407337292495614620493145114086484487337", "price": "0.46", "size": "43485", "side": "BUY", "hash": "9303ea45ed8b58aae3a5431249ab6b1b97bf1c71", "best_bid": "0.48", "best_ask": "0.481"}, {"asset_id": "19214394437683566921750936876376421489271269944393354497977881791256347396217", "price": "0.54", "size": "43485", "side": "SELL", "hash": "9abde08e55634128106e21e5394ed230ca11bdfa", "best_bid": "0.519", "best_ask": "0.52"}], "timestamp": "1782707801000", "event_type": "price_change"}}
{"local_timestamp": 1782707799.942814, "slug": "will-lionel-messi-be-the-top-goalscorer-at-the-2026-fifa-world-cup", "data": {"market": "0xd2a8caba5559bc21e14f6b2aa504cb14a1782751658b71409e25b82e432c0a97", "price_changes": [{"asset_id": "19214394437683566921750936876376421489271269944393354497977881791256347396217", "price": "0.26", "size": "3000", "side": "BUY", "hash": "8e8264a43ec0c0d5d9827fbfb2e9e1d32be13075", "best_bid": "0.519", "best_ask": "0.52"}, {"asset_id": "36586667785814641857008731622413716797407337292495614620493145114086484487337", "price": "0.74", "size": "3000", "side": "SELL", "hash": "596ad62f4591fa30589615c7b07838c48785c207", "best_bid": "0.48", "best_ask": "0.481"}], "timestamp": "1782707801174", "event_type": "price_change"}}
{"local_timestamp": 1782707799.9487984, "slug": "will-lionel-messi-be-the-top-goalscorer-at-the-2026-fifa-world-cup", "data": {"market": "0xd2a8caba5559bc21e14f6b2aa504cb14a1782751658b71409e25b82e432c0a97", "price_changes": [{"asset_id": "36586667785814641857008731622413716797407337292495614620493145114086484487337", "price": "0.35", "size": "3200", "side": "BUY", "hash": "f16c1427c64f434ed0e5518fa78b400b9511211b", "best_bid": "0.48", "best_ask": "0.481"}, {"asset_id": "19214394437683566921750936876376421489271269944393354497977881791256347396217", "price": "0.65", "size": "3200", "side": "SELL", "hash": "c2bfc8e14dc6418c238237b94487af2511d56309", "best_bid": "0.519", "best_ask": "0.52"}], "timestamp": "1782707801179", "event_type": "price_change"}}
{"local_timestamp": 1782707800.5606046, "slug": "will-lionel-messi-be-the-top-goalscorer-at-the-2026-fifa-world-cup", "data": {"market": "0xd2a8caba5559bc21e14f6b2aa504cb14a1782751658b71409e25b82e432c0a97", "price_changes": [{"asset_id": "19214394437683566921750936876376421489271269944393354497977881791256347396217", "price": "0.521", "size": "4584.59", "side": "SELL", "hash": "3f6d641f2e22d6be20befbac138e4b129e25b965", "best_bid": "0.519", "best_ask": "0.52"}, {"asset_id": "36586667785814641857008731622413716797407337292495614620493145114086484487337", "price": "0.479", "size": "4584.59", "side": "BUY", "hash": "c47c3e6cfd1747268f09ffb95bdec6549a6c03c6", "best_bid": "0.48", "best_ask": "0.481"}], "timestamp": "1782707801794", "event_type": "price_change"}}
{"local_timestamp": 1782707801.3880148, "slug": "will-lionel-messi-be-the-top-goalscorer-at-the-2026-fifa-world-cup", "data": {"market": "0xd2a8caba5559bc21e14f6b2aa504cb14a1782751658b71409e25b82e432c0a97", "price_changes": [{"asset_id": "36586667785814641857008731622413716797407337292495614620493145114086484487337", "price": "0.35", "size": "200", "side": "BUY", "hash": "ee6e05a4b20c98d5dde0cbca927c00918d34abcf", "best_bid": "0.48", "best_ask": "0.481"}, {"asset_id": "19214394437683566921750936876376421489271269944393354497977881791256347396217", "price": "0.65", "size": "200", "side": "SELL", "hash": "b032e3f7f9e4c75e04b9d6ed06784bb34cd2dce2", "best_bid": "0.519", "best_ask": "0.52"}], "timestamp": "1782707802620", "event_type": "price_change"}}
{"local_timestamp": 1782707801.3890922, "slug": "will-lionel-messi-be-the-top-goalscorer-at-the-2026-fifa-world-cup", "data": {"market": "0xd2a8caba5559bc21e14f6b2aa504cb14a1782751658b71409e25b82e432c0a97", "price_changes": [{"asset_id": "19214394437683566921750936876376421489271269944393354497977881791256347396217", "price": "0.26", "size": "0", "side": "BUY", "hash": "dbc520d5022f95131c1c4cc15b43792298d8b6db", "best_bid": "0.519", "best_ask": "0.52"}, {"asset_id": "36586667785814641857008731622413716797407337292495614620493145114086484487337", "price": "0.74", "size": "0", "side": "SELL", "hash": "16e6c92212ab7c771ddca77235179a3dac964040", "best_bid": "0.48", "best_ask": "0.481"}], "timestamp": "1782707802620", "event_type": "price_change"}}
{"local_timestamp": 1782707802.1831226, "slug": "will-lionel-messi-be-the-top-goalscorer-at-the-2026-fifa-world-cup", "data": {"market": "0xd2a8caba5559bc21e14f6b2aa504cb14a1782751658b71409e25b82e432c0a97", "price_changes": [{"asset_id": "19214394437683566921750936876376421489271269944393354497977881791256347396217", "price": "0.521", "size": "4487.5", "side": "SELL", "hash": "6becfd4623adb3b6f9a5b7985ab86256ebb5cd2b", "best_bid": "0.519", "best_ask": "0.52"}, {"asset_id": "36586667785814641857008731622413716797407337292495614620493145114086484487337", "price": "0.479", "size": "4487.5", "side": "BUY", "hash": "13dd7289913e58bd17d69bf37beee672c00e22e0", "best_bid": "0.48", "best_ask": "0.481"}], "timestamp": "1782707803416", "event_type": "price_change"}}
{"local_timestamp": 1782707802.901835, "slug": "will-lionel-messi-be-the-top-goalscorer-at-the-2026-fifa-world-cup", "data": {"market": "0xd2a8caba5559bc21e14f6b2aa504cb14a1782751658b71409e25b82e432c0a97", "price_changes": [{"asset_id": "36586667785814641857008731622413716797407337292495614620493145114086484487337", "price": "0.35", "size": "3200", "side": "BUY", "hash": "07529f284a1f7b5f8da56fc91f3e2b15aaf1aaf4", "best_bid": "0.48", "best_ask": "0.481"}, {"asset_id": "19214394437683566921750936876376421489271269944393354497977881791256347396217", "price": "0.65", "size": "3200", "side": "SELL", "hash": "4d42d457c18bc3eb8e21e2012f653b95a8f68fdd", "best_bid": "0.519", "best_ask": "0.52"}], "timestamp": "1782707804135", "event_type": "price_change"}}
{"local_timestamp": 1782707802.9101822, "slug": "will-lionel-messi-be-the-top-goalscorer-at-the-2026-fifa-world-cup", "data": {"market": "0xd2a8caba5559bc21e14f6b2aa504cb14a1782751658b71409e25b82e432c0a97", "price_changes": [{"asset_id": "19214394437683566921750936876376421489271269944393354497977881791256347396217", "price": "0.26", "size": "3000", "side": "BUY", "hash": "5cb98df843993281cb5b80baf2a160238cb34d98", "best_bid": "0.519", "best_ask": "0.52"}, {"asset_id": "36586667785814641857008731622413716797407337292495614620493145114086484487337", "price": "0.74", "size": "3000", "side": "SELL", "hash": "5db273fd96447688146fdae0114f9203d0468f41", "best_bid": "0.48", "best_ask": "0.481"}], "timestamp": "1782707804142", "event_type": "price_change"}}
{"local_timestamp": 1782707804.384028, "slug": "will-lionel-messi-be-the-top-goalscorer-at-the-2026-fifa-world-cup", "data": {"market": "0xd2a8caba5559bc21e14f6b2aa504cb14a1782751658b71409e25b82e432c0a97", "price_changes": [{"asset_id": "36586667785814641857008731622413716797407337292495614620493145114086484487337", "price": "0.35", "size": "200", "side": "BUY", "hash": "fe034ccbb8e3c22786c07e91a4dc8c9a90639a72", "best_bid": "0.48", "best_ask": "0.481"}, {"asset_id": "19214394437683566921750936876376421489271269944393354497977881791256347396217", "price": "0.65", "size": "200", "side": "SELL", "hash": "27557703b469cd23b132c422e962414f0ec8f41a", "best_bid": "0.519", "best_ask": "0.52"}], "timestamp": "1782707805617", "event_type": "price_change"}}
{"local_timestamp": 1782707804.3867974, "slug": "will-lionel-messi-be-the-top-goalscorer-at-the-2026-fifa-world-cup", "data": {"market": "0xd2a8caba5559bc21e14f6b2aa504cb14a1782751658b71409e25b82e432c0a97", "price_changes": [{"asset_id": "19214394437683566921750936876376421489271269944393354497977881791256347396217", "price": "0.26", "size": "0", "side": "BUY", "hash": "fbdf99103077988dc31b168d5d46b90833f25dd6", "best_bid": "0.519", "best_ask": "0.52"}, {"asset_id": "36586667785814641857008731622413716797407337292495614620493145114086484487337", "price": "0.74", "size": "0", "side": "SELL", "hash": "c61653c3aec4f0e97639d07d73d725769ddfa002", "best_bid": "0.48", "best_ask": "0.481"}], "timestamp": "1782707805617", "event_type": "price_change"}}
{"local_timestamp": 1782707804.7743206, "slug": "will-lionel-messi-be-the-top-goalscorer-at-the-2026-fifa-world-cup", "data": {"market": "0xd2a8caba5559bc21e14f6b2aa504cb14a1782751658b71409e25b82e432c0a97", "price_changes": [{"asset_id": "36586667785814641857008731622413716797407337292495614620493145114086484487337", "price": "0.46", "size": "43285", "side": "BUY", "hash": "ffceb6bac3a025aee68fcef82c33edf878ba8d74", "best_bid": "0.48", "best_ask": "0.481"}, {"asset_id": "19214394437683566921750936876376421489271269944393354497977881791256347396217", "price": "0.54", "size": "43285", "side": "SELL", "hash": "c1f770b69a5010040fa03f380d8eb4fb315b04a8", "best_bid": "0.519", "best_ask": "0.52"}], "timestamp": "1782707806004", "event_type": "price_change"}}
{"local_timestamp": 1782707805.2244482, "slug": "will-lionel-messi-be-the-top-goalscorer-at-the-2026-fifa-world-cup", "data": {"market": "0xd2a8caba5559bc21e14f6b2aa504cb14a1782751658b71409e25b82e432c0a97", "price_changes": [{"asset_id": "36586667785814641857008731622413716797407337292495614620493145114086484487337", "price": "0.402", "size": "200", "side": "BUY", "hash": "1e35143fb3d66a352724c8dcc2f66844514ff246", "best_bid": "0.48", "best_ask": "0.481"}, {"asset_id": "19214394437683566921750936876376421489271269944393354497977881791256347396217", "price": "0.598", "size": "200", "side": "SELL", "hash": "130e532106dffdb87ac357d5ad2446d893d0db54", "best_bid": "0.519", "best_ask": "0.52"}], "timestamp": "1782707806458", "event_type": "price_change"}}
{"local_timestamp": 1782707805.3389812, "slug": "will-lionel-messi-be-the-top-goalscorer-at-the-2026-fifa-world-cup", "data": {"market": "0xd2a8caba5559bc21e14f6b2aa504cb14a1782751658b71409e25b82e432c0a97", "price_changes": [{"asset_id": "36586667785814641857008731622413716797407337292495614620493145114086484487337", "price": "0.402", "size": "350", "side": "BUY", "hash": "f85efefbc07210a9bb9de6a56bb497bc6d800ae9", "best_bid": "0.48", "best_ask": "0.481"}, {"asset_id": "19214394437683566921750936876376421489271269944393354497977881791256347396217", "price": "0.598", "size": "350", "side": "SELL", "hash": "1b1ce102c6574658e1e2bcbb0de98b89f82e3663", "best_bid": "0.519", "best_ask": "0.52"}], "timestamp": "1782707806571", "event_type": "price_change"}}
{"local_timestamp": 1782707805.5006206, "slug": "will-lionel-messi-be-the-top-goalscorer-at-the-2026-fifa-world-cup", "data": {"market": "0xd2a8caba5559bc21e14f6b2aa504cb14a1782751658b71409e25b82e432c0a97", "price_changes": [{"asset_id": "19214394437683566921750936876376421489271269944393354497977881791256347396217", "price": "0.521", "size": "4584.59", "side": "SELL", "hash": "683d490366c0b852924c7a431c127aa825c27b02", "best_bid": "0.519", "best_ask": "0.52"}, {"asset_id": "36586667785814641857008731622413716797407337292495614620493145114086484487337", "price": "0.479", "size": "4584.59", "side": "BUY", "hash": "c37d964e581dea0801af302d3b0a6db29cfc88bc", "best_bid": "0.48", "best_ask": "0.481"}], "timestamp": "1782707806734", "event_type": "price_change"}}
{"local_timestamp": 1782707805.9312453, "slug": "will-lionel-messi-be-the-top-goalscorer-at-the-2026-fifa-world-cup", "data": {"market": "0xd2a8caba5559bc21e14f6b2aa504cb14a1782751658b71409e25b82e432c0a97", "price_changes": [{"asset_id": "36586667785814641857008731622413716797407337292495614620493145114086484487337", "price": "0.35", "size": "3200", "side": "BUY", "hash": "38009da50da7e07a42d59e23a5d4a604361c348f", "best_bid": "0.48", "best_ask": "0.481"}, {"asset_id": "19214394437683566921750936876376421489271269944393354497977881791256347396217", "price": "0.65", "size": "3200", "side": "SELL", "hash": "60e8eb9d2af088711c423eda87b93133cb133a77", "best_bid": "0.519", "best_ask": "0.52"}], "timestamp": "1782707807163", "event_type": "price_change"}}
{"local_timestamp": 1782707805.943405, "slug": "will-lionel-messi-be-the-top-goalscorer-at-the-2026-fifa-world-cup", "data": {"market": "0xd2a8caba5559bc21e14f6b2aa504cb14a1782751658b71409e25b82e432c0a97", "price_changes": [{"asset_id": "19214394437683566921750936876376421489271269944393354497977881791256347396217", "price": "0.26", "size": "3000", "side": "BUY", "hash": "cda78e2d4675b5660094bea09970c588dceeada1", "best_bid": "0.519", "best_ask": "0.52"}, {"asset_id": "36586667785814641857008731622413716797407337292495614620493145114086484487337", "price": "0.74", "size": "3000", "side": "SELL", "hash": "e375603df8345573384837c092980482292dd7b4", "best_bid": "0.48", "best_ask": "0.481"}], "timestamp": "1782707807176", "event_type": "price_change"}}
{"local_timestamp": 1782707807.186233, "slug": "will-lionel-messi-be-the-top-goalscorer-at-the-2026-fifa-world-cup", "data": {"market": "0xd2a8caba5559bc21e14f6b2aa504cb14a1782751658b71409e25b82e432c0a97", "price_changes": [{"asset_id": "19214394437683566921750936876376421489271269944393354497977881791256347396217", "price": "0.521", "size": "4487.5", "side": "SELL", "hash": "7c38ddd07d18c5fd1ea7493eac84bf5aa759ce8b", "best_bid": "0.519", "best_ask": "0.52"}, {"asset_id": "36586667785814641857008731622413716797407337292495614620493145114086484487337", "price": "0.479", "size": "4487.5", "side": "BUY", "hash": "0e038bd801f8978d0ba589d83693ea2c5782722e", "best_bid": "0.48", "best_ask": "0.481"}], "timestamp": "1782707808419", "event_type": "price_change"}}
{"local_timestamp": 1782707807.3332684, "slug": "will-lionel-messi-be-the-top-goalscorer-at-the-2026-fifa-world-cup", "data": {"market": "0xd2a8caba5559bc21e14f6b2aa504cb14a1782751658b71409e25b82e432c0a97", "price_changes": [{"asset_id": "19214394437683566921750936876376421489271269944393354497977881791256347396217", "price": "0.26", "size": "0", "side": "BUY", "hash": "07eb09ca3c554733c6ff60fe1ddbfa7081f594be", "best_bid": "0.519", "best_ask": "0.52"}, {"asset_id": "36586667785814641857008731622413716797407337292495614620493145114086484487337", "price": "0.74", "size": "0", "side": "SELL", "hash": "085637b75dc0812a3c545c5d6aa91fcf4e07721b", "best_bid": "0.48", "best_ask": "0.481"}], "timestamp": "1782707808566", "event_type": "price_change"}}
{"local_timestamp": 1782707807.3354104, "slug": "will-lionel-messi-be-the-top-goalscorer-at-the-2026-fifa-world-cup", "data": {"market": "0xd2a8caba5559bc21e14f6b2aa504cb14a1782751658b71409e25b82e432c0a97", "price_changes": [{"asset_id": "36586667785814641857008731622413716797407337292495614620493145114086484487337", "price": "0.35", "size": "200", "side": "BUY", "hash": "55c042915c7f8fb6cff913874e2668cebb401b09", "best_bid": "0.48", "best_ask": "0.481"}, {"asset_id": "19214394437683566921750936876376421489271269944393354497977881791256347396217", "price": "0.65", "size": "200", "side": "SELL", "hash": "a5f9b91e25fdd91975a4a594d535f7f579e529b4", "best_bid": "0.519", "best_ask": "0.52"}], "timestamp": "1782707808566", "event_type": "price_change"}}
{"local_timestamp": 1782707807.4635637, "slug": "will-lionel-messi-be-the-top-goalscorer-at-the-2026-fifa-world-cup", "data": {"market": "0xd2a8caba5559bc21e14f6b2aa504cb14a1782751658b71409e25b82e432c0a97", "price_changes": [{"asset_id": "19214394437683566921750936876376421489271269944393354497977881791256347396217", "price": "0.321", "size": "200", "side": "BUY", "hash": "9e01b6dbaceef121ac84c2fa7d25e18bc107da22", "best_bid": "0.519", "best_ask": "0.52"}, {"asset_id": "36586667785814641857008731622413716797407337292495614620493145114086484487337", "price": "0.679", "size": "200", "side": "SELL", "hash": "82d668498235fb2ee282ae20e5976aad804fd942", "best_bid": "0.48", "best_ask": "0.481"}], "timestamp": "1782707808697", "event_type": "price_change"}}
{"local_timestamp": 1782707807.5738215, "slug": "will-lionel-messi-be-the-top-goalscorer-at-the-2026-fifa-world-cup", "data": {"market": "0xd2a8caba5559bc21e14f6b2aa504cb14a1782751658b71409e25b82e432c0a97", "price_changes": [{"asset_id": "19214394437683566921750936876376421489271269944393354497977881791256347396217", "price": "0.32", "size": "0", "side": "BUY", "hash": "5c4e6c6cc50e2d9ac54431ffe580cbce4d1b5cf4", "best_bid": "0.519", "best_ask": "0.52"}, {"asset_id": "36586667785814641857008731622413716797407337292495614620493145114086484487337", "price": "0.68", "size": "0", "side": "SELL", "hash": "849c910715947220529ccbb144f7bb0dd1a1b525", "best_bid": "0.48", "best_ask": "0.481"}], "timestamp": "1782707808806", "event_type": "price_change"}}
{"local_timestamp": 1782707808.9327972, "slug": "will-lionel-messi-be-the-top-goalscorer-at-the-2026-fifa-world-cup", "data": {"market": "0xd2a8caba5559bc21e14f6b2aa504cb14a1782751658b71409e25b82e432c0a97", "price_changes": [{"asset_id": "19214394437683566921750936876376421489271269944393354497977881791256347396217", "price": "0.26", "size": "3000", "side": "BUY", "hash": "8f9ed1608788c9faaf320039a9a6194a7ab077e0", "best_bid": "0.519", "best_ask": "0.52"}, {"asset_id": "36586667785814641857008731622413716797407337292495614620493145114086484487337", "price": "0.74", "size": "3000", "side": "SELL", "hash": "15e7bb1c4e28bfb144cce35acc51f08cb7f91cea", "best_bid": "0.48", "best_ask": "0.481"}], "timestamp": "1782707810099", "event_type": "price_change"}}
{"local_timestamp": 1782707808.9336035, "slug": "will-lionel-messi-be-the-top-goalscorer-at-the-2026-fifa-world-cup", "data": {"market": "0xd2a8caba5559bc21e14f6b2aa504cb14a1782751658b71409e25b82e432c0a97", "price_changes": [{"asset_id": "36586667785814641857008731622413716797407337292495614620493145114086484487337", "price": "0.35", "size": "3200", "side": "BUY", "hash": "3389edebc2738e6c39138c25935f08c30a2b73ec", "best_bid": "0.48", "best_ask": "0.481"}, {"asset_id": "19214394437683566921750936876376421489271269944393354497977881791256347396217", "price": "0.65", "size": "3200", "side": "SELL", "hash": "c86bc662f6e97725d9104588781b10537e8cec80", "best_bid": "0.519", "best_ask": "0.52"}], "timestamp": "1782707810100", "event_type": "price_change"}}
{"local_timestamp": 1782707809.04664, "slug": "will-lionel-messi-be-the-top-goalscorer-at-the-2026-fifa-world-cup", "data": {"market": "0xd2a8caba5559bc21e14f6b2aa504cb14a1782751658b71409e25b82e432c0a97", "price_changes": [{"asset_id": "19214394437683566921750936876376421489271269944393354497977881791256347396217", "price": "0.487", "size": "0", "side": "BUY", "hash": "2d41af6a3f3d03c7221382a7762b80897b601005", "best_bid": "0.519", "best_ask": "0.52"}, {"asset_id": "36586667785814641857008731622413716797407337292495614620493145114086484487337", "price": "0.513", "size": "0", "side": "SELL", "hash": "fe90eecf6c654755492ead1fc4dc2bd97dfb63bc", "best_bid": "0.48", "best_ask": "0.481"}], "timestamp": "1782707810273", "event_type": "price_change"}}
{"local_timestamp": 1782707809.6767902, "slug": "will-lionel-messi-be-the-top-goalscorer-at-the-2026-fifa-world-cup", "data": {"market": "0xd2a8caba5559bc21e14f6b2aa504cb14a1782751658b71409e25b82e432c0a97", "price_changes": [{"asset_id": "19214394437683566921750936876376421489271269944393354497977881791256347396217", "price": "0.521", "size": "4584.59", "side": "SELL", "hash": "eee3ec56e07810c83649369f01cf0843307150f1", "best_bid": "0.519", "best_ask": "0.52"}, {"asset_id": "36586667785814641857008731622413716797407337292495614620493145114086484487337", "price": "0.479", "size": "4584.59", "side": "BUY", "hash": "8260ea2a18c889936275baa9a06dc261e6c4a5b6", "best_bid": "0.48", "best_ask": "0.481"}], "timestamp": "1782707810904", "event_type": "price_change"}}
{"local_timestamp": 1782707810.30713, "slug": "will-lionel-messi-be-the-top-goalscorer-at-the-2026-fifa-world-cup", "data": {"market": "0xd2a8caba5559bc21e14f6b2aa504cb14a1782751658b71409e25b82e432c0a97", "price_changes": [{"asset_id": "19214394437683566921750936876376421489271269944393354497977881791256347396217", "price": "0.518", "size": "19190.13", "side": "BUY", "hash": "018b823f50e1ed16d6b80b4c6733ad4508155385", "best_bid": "0.519", "best_ask": "0.52"}, {"asset_id": "36586667785814641857008731622413716797407337292495614620493145114086484487337", "price": "0.482", "size": "19190.13", "side": "SELL", "hash": "b39018dbd2c240a53ff83cb3ba7053c7f6ce30ab", "best_bid": "0.48", "best_ask": "0.481"}], "timestamp": "1782707811536", "event_type": "price_change"}}
{"local_timestamp": 1782707810.3378649, "slug": "will-lionel-messi-be-the-top-goalscorer-at-the-2026-fifa-world-cup", "data": {"market": "0xd2a8caba5559bc21e14f6b2aa504cb14a1782751658b71409e25b82e432c0a97", "price_changes": [{"asset_id": "36586667785814641857008731622413716797407337292495614620493145114086484487337", "price": "0.479", "size": "5016.43", "side": "BUY", "hash": "a50853358e898da4b8972ed7991b96f088cbfaa9", "best_bid": "0.48", "best_ask": "0.481"}, {"asset_id": "19214394437683566921750936876376421489271269944393354497977881791256347396217", "price": "0.521", "size": "5016.43", "side": "SELL", "hash": "d7d7517d44e17bfd30b9a1a1fb62205cb639b758", "best_bid": "0.519", "best_ask": "0.52"}], "timestamp": "1782707811567", "event_type": "price_change"}}
{"local_timestamp": 1782707810.3911877, "slug": "will-lionel-messi-be-the-top-goalscorer-at-the-2026-fifa-world-cup", "data": {"market": "0xd2a8caba5559bc21e14f6b2aa504cb14a1782751658b71409e25b82e432c0a97", "price_changes": [{"asset_id": "19214394437683566921750936876376421489271269944393354497977881791256347396217", "price": "0.26", "size": "0", "side": "BUY", "hash": "f58b439df22ba72eab64159f79f56e877da3abd0", "best_bid": "0.519", "best_ask": "0.52"}, {"asset_id": "36586667785814641857008731622413716797407337292495614620493145114086484487337", "price": "0.74", "size": "0", "side": "SELL", "hash": "ad92fd0d9ae8febd782b0e6844032907a01fae49", "best_bid": "0.48", "best_ask": "0.481"}], "timestamp": "1782707811622", "event_type": "price_change"}}
{"local_timestamp": 1782707810.3933208, "slug": "will-lionel-messi-be-the-top-goalscorer-at-the-2026-fifa-world-cup", "data": {"market": "0xd2a8caba5559bc21e14f6b2aa504cb14a1782751658b71409e25b82e432c0a97", "price_changes": [{"asset_id": "36586667785814641857008731622413716797407337292495614620493145114086484487337", "price": "0.35", "size": "200", "side": "BUY", "hash": "90475b7009825fe8f253992dc81cea701d21e05a", "best_bid": "0.48", "best_ask": "0.481"}, {"asset_id": "19214394437683566921750936876376421489271269944393354497977881791256347396217", "price": "0.65", "size": "200", "side": "SELL", "hash": "bcc95d05c0e46fa7097e9d737f30e15e654509a1", "best_bid": "0.519", "best_ask": "0.52"}], "timestamp": "1782707811622", "event_type": "price_change"}}
{"local_timestamp": 1782707811.8271332, "slug": "will-lionel-messi-be-the-top-goalscorer-at-the-2026-fifa-world-cup", "data": {"market": "0xd2a8caba5559bc21e14f6b2aa504cb14a1782751658b71409e25b82e432c0a97", "price_changes": [{"asset_id": "19214394437683566921750936876376421489271269944393354497977881791256347396217", "price": "0.514", "size": "0", "side": "BUY", "hash": "6065cd9894c9771424afd61da43c52d6bf523968", "best_bid": "0.519", "best_ask": "0.52"}, {"asset_id": "36586667785814641857008731622413716797407337292495614620493145114086484487337", "price": "0.486", "size": "0", "side": "SELL", "hash": "f36079ed685c17f01e6943ff1f1209956c9cb00f", "best_bid": "0.48", "best_ask": "0.481"}], "timestamp": "1782707813059", "event_type": "price_change"}}
{"local_timestamp": 1782707811.8279915, "slug": "will-lionel-messi-be-the-top-goalscorer-at-the-2026-fifa-world-cup", "data": {"market": "0xd2a8caba5559bc21e14f6b2aa504cb14a1782751658b71409e25b82e432c0a97", "price_changes": [{"asset_id": "36586667785814641857008731622413716797407337292495614620493145114086484487337", "price": "0.475", "size": "6937.77", "side": "BUY", "hash": "58315595de1e9a9fe4ca17d5e15ce38a73950f89", "best_bid": "0.48", "best_ask": "0.481"}, {"asset_id": "19214394437683566921750936876376421489271269944393354497977881791256347396217", "price": "0.525", "size": "6937.77", "side": "SELL", "hash": "d81fd28a184b4fa62768a9f1139376b773e2d1bf", "best_bid": "0.519", "best_ask": "0.52"}], "timestamp": "1782707813059", "event_type": "price_change"}}
{"local_timestamp": 1782707811.8976843, "slug": "will-lionel-messi-be-the-top-goalscorer-at-the-2026-fifa-world-cup", "data": {"market": "0xd2a8caba5559bc21e14f6b2aa504cb14a1782751658b71409e25b82e432c0a97", "price_changes": [{"asset_id": "36586667785814641857008731622413716797407337292495614620493145114086484487337", "price": "0.477", "size": "250", "side": "BUY", "hash": "3e8f1b4645ff1c117255f62c844ff9d4a01294a1", "best_bid": "0.48", "best_ask": "0.481"}, {"asset_id": "19214394437683566921750936876376421489271269944393354497977881791256347396217", "price": "0.523", "size": "250", "side": "SELL", "hash": "6fa14b88d9a4448643b4d8ebd428be2c9c93ba0d", "best_bid": "0.519", "best_ask": "0.52"}], "timestamp": "1782707813131", "event_type": "price_change"}}
{"local_timestamp": 1782707811.898892, "slug": "will-lionel-messi-be-the-top-goalscorer-at-the-2026-fifa-world-cup", "data": {"market": "0xd2a8caba5559bc21e14f6b2aa504cb14a1782751658b71409e25b82e432c0a97", "price_changes": [{"asset_id": "19214394437683566921750936876376421489271269944393354497977881791256347396217", "price": "0.516", "size": "1218", "side": "BUY", "hash": "ba53fa91be6e23833409cc71e1e8a27568cf6393", "best_bid": "0.519", "best_ask": "0.52"}, {"asset_id": "36586667785814641857008731622413716797407337292495614620493145114086484487337", "price": "0.484", "size": "1218", "side": "SELL", "hash": "2a4e054cb153fb80e6e99e9a4349d3ad6e1b166c", "best_bid": "0.48", "best_ask": "0.481"}], "timestamp": "1782707813132", "event_type": "price_change"}}
{"local_timestamp": 1782707811.900405, "slug": "will-lionel-messi-be-the-top-goalscorer-at-the-2026-fifa-world-cup", "data": {"market": "0xd2a8caba5559bc21e14f6b2aa504cb14a1782751658b71409e25b82e432c0a97", "price_changes": [{"asset_id": "36586667785814641857008731622413716797407337292495614620493145114086484487337", "price": "0.35", "size": "3200", "side": "BUY", "hash": "083aa231f6c2f0147e8bd003c880b634ecb4077d", "best_bid": "0.48", "best_ask": "0.481"}, {"asset_id": "19214394437683566921750936876376421489271269944393354497977881791256347396217", "price": "0.65", "size": "3200", "side": "SELL", "hash": "ed2cfba28f7279caaef23cc7261dc72b85654e5e", "best_bid": "0.519", "best_ask": "0.52"}], "timestamp": "1782707813134", "event_type": "price_change"}}
{"local_timestamp": 1782707811.9039133, "slug": "will-lionel-messi-be-the-top-goalscorer-at-the-2026-fifa-world-cup", "data": {"market": "0xd2a8caba5559bc21e14f6b2aa504cb14a1782751658b71409e25b82e432c0a97", "price_changes": [{"asset_id": "19214394437683566921750936876376421489271269944393354497977881791256347396217", "price": "0.26", "size": "3000", "side": "BUY", "hash": "5f138720275e84bbf15771bd528e4b46d9676592", "best_bid": "0.519", "best_ask": "0.52"}, {"asset_id": "36586667785814641857008731622413716797407337292495614620493145114086484487337", "price": "0.74", "size": "3000", "side": "SELL", "hash": "4c5891bd321757e6747cf56e722cbb7fd85fa516", "best_bid": "0.48", "best_ask": "0.481"}], "timestamp": "1782707813138", "event_type": "price_change"}}
{"local_timestamp": 1782707812.0504136, "slug": "will-lionel-messi-be-the-top-goalscorer-at-the-2026-fifa-world-cup", "data": {"market": "0xd2a8caba5559bc21e14f6b2aa504cb14a1782751658b71409e25b82e432c0a97", "price_changes": [{"asset_id": "19214394437683566921750936876376421489271269944393354497977881791256347396217", "price": "0.511", "size": "3261.5", "side": "BUY", "hash": "e84225ee18a5d6d3d4b571cf8df675ac860dbc86", "best_bid": "0.519", "best_ask": "0.52"}, {"asset_id": "36586667785814641857008731622413716797407337292495614620493145114086484487337", "price": "0.489", "size": "3261.5", "side": "SELL", "hash": "e0c60f1a4371fe248252ede9ca681798e8e1c27b", "best_bid": "0.48", "best_ask": "0.481"}], "timestamp": "1782707813284", "event_type": "price_change"}}
{"local_timestamp": 1782707812.2219527, "slug": "will-lionel-messi-be-the-top-goalscorer-at-the-2026-fifa-world-cup", "data": {"market": "0xd2a8caba5559bc21e14f6b2aa504cb14a1782751658b71409e25b82e432c0a97", "price_changes": [{"asset_id": "19214394437683566921750936876376421489271269944393354497977881791256347396217", "price": "0.511", "size": "2961.5", "side": "BUY", "hash": "8767c89929990d3ff7e67c6d64f1820fe69c8eea", "best_bid": "0.519", "best_ask": "0.52"}, {"asset_id": "36586667785814641857008731622413716797407337292495614620493145114086484487337", "price": "0.489", "size": "2961.5", "side": "SELL", "hash": "dbac183d5247fcda44a0a0802b3d9988c58b2c3b", "best_bid": "0.48", "best_ask": "0.481"}], "timestamp": "1782707813286", "event_type": "price_change"}}
{"local_timestamp": 1782707812.2225912, "slug": "will-lionel-messi-be-the-top-goalscorer-at-the-2026-fifa-world-cup", "data": {"market": "0xd2a8caba5559bc21e14f6b2aa504cb14a1782751658b71409e25b82e432c0a97", "price_changes": [{"asset_id": "19214394437683566921750936876376421489271269944393354497977881791256347396217", "price": "0.521", "size": "4919.34", "side": "SELL", "hash": "f7860a12be967ac1b0796b0b4845527096128e70", "best_bid": "0.519", "best_ask": "0.52"}, {"asset_id": "36586667785814641857008731622413716797407337292495614620493145114086484487337", "price": "0.479", "size": "4919.34", "side": "BUY", "hash": "2b9b4e5e4d35729f532079ec5b77caa26e39f5ff", "best_bid": "0.48", "best_ask": "0.481"}], "timestamp": "1782707813450", "event_type": "price_change"}}
{"local_timestamp": 1782707813.3668313, "slug": "will-lionel-messi-be-the-top-goalscorer-at-the-2026-fifa-world-cup", "data": {"market": "0xd2a8caba5559bc21e14f6b2aa504cb14a1782751658b71409e25b82e432c0a97", "price_changes": [{"asset_id": "36586667785814641857008731622413716797407337292495614620493145114086484487337", "price": "0.35", "size": "200", "side": "BUY", "hash": "f51e949678614b1e60690f5b7168fcd80e767eb9", "best_bid": "0.48", "best_ask": "0.481"}, {"asset_id": "19214394437683566921750936876376421489271269944393354497977881791256347396217", "price": "0.65", "size": "200", "side": "SELL", "hash": "5012c625878815c0d04d0773780f9d4653eb4f82", "best_bid": "0.519", "best_ask": "0.52"}], "timestamp": "1782707814600", "event_type": "price_change"}}
{"local_timestamp": 1782707813.368193, "slug": "will-lionel-messi-be-the-top-goalscorer-at-the-2026-fifa-world-cup", "data": {"market": "0xd2a8caba5559bc21e14f6b2aa504cb14a1782751658b71409e25b82e432c0a97", "price_changes": [{"asset_id": "19214394437683566921750936876376421489271269944393354497977881791256347396217", "price": "0.26", "size": "0", "side": "BUY", "hash": "790a18cb8566414278b65bdd93dff5e73ee3fef8", "best_bid": "0.519", "best_ask": "0.52"}, {"asset_id": "36586667785814641857008731622413716797407337292495614620493145114086484487337", "price": "0.74", "size": "0", "side": "SELL", "hash": "a8f1c7deef97d07e1d72155319fe7d8deeafcd18", "best_bid": "0.48", "best_ask": "0.481"}], "timestamp": "1782707814600", "event_type": "price_change"}}
{"local_timestamp": 1782707814.174699, "slug": "will-lionel-messi-be-the-top-goalscorer-at-the-2026-fifa-world-cup", "data": {"market": "0xd2a8caba5559bc21e14f6b2aa504cb14a1782751658b71409e25b82e432c0a97", "price_changes": [{"asset_id": "19214394437683566921750936876376421489271269944393354497977881791256347396217", "price": "0.487", "size": "9883", "side": "BUY", "hash": "b35c6b7d8dddeaacbc05052ba27599b33ed44ee9", "best_bid": "0.519", "best_ask": "0.52"}, {"asset_id": "36586667785814641857008731622413716797407337292495614620493145114086484487337", "price": "0.513", "size": "9883", "side": "SELL", "hash": "e29dc862b099065a9335ab5997e2067af1b19b52", "best_bid": "0.48", "best_ask": "0.481"}], "timestamp": "1782707815408", "event_type": "price_change"}}
{"local_timestamp": 1782707814.2309577, "slug": "will-lionel-messi-be-the-top-goalscorer-at-the-2026-fifa-world-cup", "data": {"market": "0xd2a8caba5559bc21e14f6b2aa504cb14a1782751658b71409e25b82e432c0a97", "price_changes": [{"asset_id": "19214394437683566921750936876376421489271269944393354497977881791256347396217", "price": "0.5", "size": "29562", "side": "BUY", "hash": "a1b6e47a289cc32dda57b3edb7a8440d228d79c7", "best_bid": "0.519", "best_ask": "0.52"}, {"asset_id": "36586667785814641857008731622413716797407337292495614620493145114086484487337", "price": "0.5", "size": "29562", "side": "SELL", "hash": "7d9ed62b4c50b059a478c986f4d7853bc295f70d", "best_bid": "0.48", "best_ask": "0.481"}], "timestamp": "1782707815465", "event_type": "price_change"}}
{"local_timestamp": 1782707814.5516558, "slug": "will-lionel-messi-be-the-top-goalscorer-at-the-2026-fifa-world-cup", "data": {"market": "0xd2a8caba5559bc21e14f6b2aa504cb14a1782751658b71409e25b82e432c0a97", "price_changes": [{"asset_id": "19214394437683566921750936876376421489271269944393354497977881791256347396217", "price": "0.521", "size": "5016.43", "side": "SELL", "hash": "10b4dc5b8f1cbe354d504c4a885654ee1653229f", "best_bid": "0.519", "best_ask": "0.52"}, {"asset_id": "36586667785814641857008731622413716797407337292495614620493145114086484487337", "price": "0.479", "size": "5016.43", "side": "BUY", "hash": "b528c24740158e00fc243b612cfb7ff1a0baaf80", "best_bid": "0.48", "best_ask": "0.481"}], "timestamp": "1782707815785", "event_type": "price_change"}}
{"local_timestamp": 1782707814.8356986, "slug": "will-lionel-messi-be-the-top-goalscorer-at-the-2026-fifa-world-cup", "data": {"market": "0xd2a8caba5559bc21e14f6b2aa504cb14a1782751658b71409e25b82e432c0a97", "price_changes": [{"asset_id": "19214394437683566921750936876376421489271269944393354497977881791256347396217", "price": "0.26", "size": "3000", "side": "BUY", "hash": "a279b9421c5c3804df4e95f79daf43ed1ec4094a", "best_bid": "0.519", "best_ask": "0.52"}, {"asset_id": "36586667785814641857008731622413716797407337292495614620493145114086484487337", "price": "0.74", "size": "3000", "side": "SELL", "hash": "36e9bb6c09d04f35da27dcac3d8915922f7a74c2", "best_bid": "0.48", "best_ask": "0.481"}], "timestamp": "1782707816069", "event_type": "price_change"}}
{"local_timestamp": 1782707814.8396327, "slug": "will-lionel-messi-be-the-top-goalscorer-at-the-2026-fifa-world-cup", "data": {"market": "0xd2a8caba5559bc21e14f6b2aa504cb14a1782751658b71409e25b82e432c0a97", "price_changes": [{"asset_id": "36586667785814641857008731622413716797407337292495614620493145114086484487337", "price": "0.35", "size": "3200", "side": "BUY", "hash": "bb6ce3d59c74903c26d8e257853a3ebc61aeabd5", "best_bid": "0.48", "best_ask": "0.481"}, {"asset_id": "19214394437683566921750936876376421489271269944393354497977881791256347396217", "price": "0.65", "size": "3200", "side": "SELL", "hash": "15672b3390dd8fe016bc12ead212cbb5c1568fdf", "best_bid": "0.519", "best_ask": "0.52"}], "timestamp": "1782707816073", "event_type": "price_change"}}
{"local_timestamp": 1782707816.3343759, "slug": "will-lionel-messi-be-the-top-goalscorer-at-the-2026-fifa-world-cup", "data": {"market": "0xd2a8caba5559bc21e14f6b2aa504cb14a1782751658b71409e25b82e432c0a97", "price_changes": [{"asset_id": "36586667785814641857008731622413716797407337292495614620493145114086484487337", "price": "0.35", "size": "200", "side": "BUY", "hash": "5af0d78b52ea5d6dccc3d4b519dd3153fc8dcb20", "best_bid": "0.48", "best_ask": "0.481"}, {"asset_id": "19214394437683566921750936876376421489271269944393354497977881791256347396217", "price": "0.65", "size": "200", "side": "SELL", "hash": "2578745d9e791ae11858a396ece9ee1fa73b0eb9", "best_bid": "0.519", "best_ask": "0.52"}], "timestamp": "1782707817566", "event_type": "price_change"}}
{"local_timestamp": 1782707816.3354013, "slug": "will-lionel-messi-be-the-top-goalscorer-at-the-2026-fifa-world-cup", "data": {"market": "0xd2a8caba5559bc21e14f6b2aa504cb14a1782751658b71409e25b82e432c0a97", "price_changes": [{"asset_id": "19214394437683566921750936876376421489271269944393354497977881791256347396217", "price": "0.26", "size": "0", "side": "BUY", "hash": "a1cb755dc6f3670a8e0d19ce2e4777c767059dee", "best_bid": "0.519", "best_ask": "0.52"}, {"asset_id": "36586667785814641857008731622413716797407337292495614620493145114086484487337", "price": "0.74", "size": "0", "side": "SELL", "hash": "5b58b1216ca805eadce7a7c422f8b18947f744a5", "best_bid": "0.48", "best_ask": "0.481"}], "timestamp": "1782707817567", "event_type": "price_change"}}
{"local_timestamp": 1782707816.7729259, "slug": "will-lionel-messi-be-the-top-goalscorer-at-the-2026-fifa-world-cup", "data": {"market": "0xd2a8caba5559bc21e14f6b2aa504cb14a1782751658b71409e25b82e432c0a97", "price_changes": [{"asset_id": "19214394437683566921750936876376421489271269944393354497977881791256347396217", "price": "0.5", "size": "29162", "side": "BUY", "hash": "bb27a6016ad369fd850c185ec2d19022c7afbf50", "best_bid": "0.519", "best_ask": "0.52"}, {"asset_id": "36586667785814641857008731622413716797407337292495614620493145114086484487337", "price": "0.5", "size": "29162", "side": "SELL", "hash": "be28381fc24bb21b0ddd0718a157ef89ea9e8c8f", "best_bid": "0.48", "best_ask": "0.481"}], "timestamp": "1782707818007", "event_type": "price_change"}}
{"local_timestamp": 1782707816.7735956, "slug": "will-lionel-messi-be-the-top-goalscorer-at-the-2026-fifa-world-cup", "data": {"market": "0xd2a8caba5559bc21e14f6b2aa504cb14a1782751658b71409e25b82e432c0a97", "price_changes": [{"asset_id": "19214394437683566921750936876376421489271269944393354497977881791256347396217", "price": "0.5", "size": "29162", "side": "BUY", "hash": "bb27a6016ad369fd850c185ec2d19022c7afbf50", "best_bid": "0.519", "best_ask": "0.52"}, {"asset_id": "36586667785814641857008731622413716797407337292495614620493145114086484487337", "price": "0.5", "size": "29162", "side": "SELL", "hash": "be28381fc24bb21b0ddd0718a157ef89ea9e8c8f", "best_bid": "0.48", "best_ask": "0.481"}], "timestamp": "1782707818007", "event_type": "price_change"}}
{"local_timestamp": 1782707817.8898318, "slug": "will-lionel-messi-be-the-top-goalscorer-at-the-2026-fifa-world-cup", "data": {"market": "0xd2a8caba5559bc21e14f6b2aa504cb14a1782751658b71409e25b82e432c0a97", "price_changes": [{"asset_id": "36586667785814641857008731622413716797407337292495614620493145114086484487337", "price": "0.35", "size": "3200", "side": "BUY", "hash": "ea31be6f86967837d58cac92be1ff66efb0ce422", "best_bid": "0.48", "best_ask": "0.481"}, {"asset_id": "19214394437683566921750936876376421489271269944393354497977881791256347396217", "price": "0.65", "size": "3200", "side": "SELL", "hash": "86ddd640ac7ec15a101e10228e19eb382a593a69", "best_bid": "0.519", "best_ask": "0.52"}], "timestamp": "1782707819124", "event_type": "price_change"}}
{"local_timestamp": 1782707817.8991313, "slug": "will-lionel-messi-be-the-top-goalscorer-at-the-2026-fifa-world-cup", "data": {"market": "0xd2a8caba5559bc21e14f6b2aa504cb14a1782751658b71409e25b82e432c0a97", "price_changes": [{"asset_id": "19214394437683566921750936876376421489271269944393354497977881791256347396217", "price": "0.26", "size": "3000", "side": "BUY", "hash": "eb0730b0ddbab4a46c61a62bb09803cef98f95cf", "best_bid": "0.519", "best_ask": "0.52"}, {"asset_id": "36586667785814641857008731622413716797407337292495614620493145114086484487337", "price": "0.74", "size": "3000", "side": "SELL", "hash": "4dc3f3797be530e41df4efd9932e6f0353d7cf7f", "best_bid": "0.48", "best_ask": "0.481"}], "timestamp": "1782707819132", "event_type": "price_change"}}
{"local_timestamp": 1782707818.1077967, "slug": "will-lionel-messi-be-the-top-goalscorer-at-the-2026-fifa-world-cup", "data": {"market": "0xd2a8caba5559bc21e14f6b2aa504cb14a1782751658b71409e25b82e432c0a97", "price_changes": [{"asset_id": "19214394437683566921750936876376421489271269944393354497977881791256347396217", "price": "0.521", "size": "4919.34", "side": "SELL", "hash": "dbfd562b6612397cf072ab8d1b8f65185cf78095", "best_bid": "0.519", "best_ask": "0.52"}, {"asset_id": "36586667785814641857008731622413716797407337292495614620493145114086484487337", "price": "0.479", "size": "4919.34", "side": "BUY", "hash": "4dd92d2c31bab0b54f797e51f21738a618c8e7f0", "best_bid": "0.48", "best_ask": "0.481"}], "timestamp": "1782707819299", "event_type": "price_change"}}
{"local_timestamp": 1782707818.1093345, "slug": "will-lionel-messi-be-the-top-goalscorer-at-the-2026-fifa-world-cup", "data": {"market": "0xd2a8caba5559bc21e14f6b2aa504cb14a1782751658b71409e25b82e432c0a97", "price_changes": [{"asset_id": "36586667785814641857008731622413716797407337292495614620493145114086484487337", "price": "0.312", "size": "2000", "side": "BUY", "hash": "f87f25650948ed5668ee9486e114e152eea2b502", "best_bid": "0.48", "best_ask": "0.481"}, {"asset_id": "19214394437683566921750936876376421489271269944393354497977881791256347396217", "price": "0.688", "size": "2000", "side": "SELL", "hash": "26228420be2db994fc2648581e2042226cfc2288", "best_bid": "0.519", "best_ask": "0.52"}], "timestamp": "1782707819334", "event_type": "price_change"}}
{"local_timestamp": 1782707819.3774788, "slug": "will-lionel-messi-be-the-top-goalscorer-at-the-2026-fifa-world-cup", "data": {"market": "0xd2a8caba5559bc21e14f6b2aa504cb14a1782751658b71409e25b82e432c0a97", "price_changes": [{"asset_id": "36586667785814641857008731622413716797407337292495614620493145114086484487337", "price": "0.35", "size": "200", "side": "BUY", "hash": "a850b981ca10aa415e05e96afc9244bb131562f0", "best_bid": "0.48", "best_ask": "0.481"}, {"asset_id": "19214394437683566921750936876376421489271269944393354497977881791256347396217", "price": "0.65", "size": "200", "side": "SELL", "hash": "8ae82a40006267a5341938d917b337626260be63", "best_bid": "0.519", "best_ask": "0.52"}], "timestamp": "1782707820591", "event_type": "price_change"}}
{"local_timestamp": 1782707819.3781846, "slug": "will-lionel-messi-be-the-top-goalscorer-at-the-2026-fifa-world-cup", "data": {"market": "0xd2a8caba5559bc21e14f6b2aa504cb14a1782751658b71409e25b82e432c0a97", "price_changes": [{"asset_id": "19214394437683566921750936876376421489271269944393354497977881791256347396217", "price": "0.26", "size": "0", "side": "BUY", "hash": "790b616ff026e3c929a8f9e72d991d46e8e83136", "best_bid": "0.519", "best_ask": "0.52"}, {"asset_id": "36586667785814641857008731622413716797407337292495614620493145114086484487337", "price": "0.74", "size": "0", "side": "SELL", "hash": "2cd08be1a266002b1deb7674471a546e04a85f10", "best_bid": "0.48", "best_ask": "0.481"}], "timestamp": "1782707820592", "event_type": "price_change"}}
{"local_timestamp": 1782707820.7731764, "slug": "will-lionel-messi-be-the-top-goalscorer-at-the-2026-fifa-world-cup", "data": {"market": "0xd2a8caba5559bc21e14f6b2aa504cb14a1782751658b71409e25b82e432c0a97", "price_changes": [{"asset_id": "36586667785814641857008731622413716797407337292495614620493145114086484487337", "price": "0.46", "size": "42877", "side": "BUY", "hash": "1af9e4e50c68a052c7504bceb7d67f6d7510fbb4", "best_bid": "0.48", "best_ask": "0.481"}, {"asset_id": "19214394437683566921750936876376421489271269944393354497977881791256347396217", "price": "0.54", "size": "42877", "side": "SELL", "hash": "61c7dd2951c2d6769c30447cea5771d5941178a3", "best_bid": "0.519", "best_ask": "0.52"}], "timestamp": "1782707822006", "event_type": "price_change"}}
{"local_timestamp": 1782707820.774508, "slug": "will-lionel-messi-be-the-top-goalscorer-at-the-2026-fifa-world-cup", "data": {"market": "0xd2a8caba5559bc21e14f6b2aa504cb14a1782751658b71409e25b82e432c0a97", "price_changes": [{"asset_id": "36586667785814641857008731622413716797407337292495614620493145114086484487337", "price": "0.46", "size": "42877", "side": "BUY", "hash": "1af9e4e50c68a052c7504bceb7d67f6d7510fbb4", "best_bid": "0.48", "best_ask": "0.481"}, {"asset_id": "19214394437683566921750936876376421489271269944393354497977881791256347396217", "price": "0.54", "size": "42877", "side": "SELL", "hash": "61c7dd2951c2d6769c30447cea5771d5941178a3", "best_bid": "0.519", "best_ask": "0.52"}], "timestamp": "1782707822006", "event_type": "price_change"}}
{"local_timestamp": 1782707820.775373, "slug": "will-lionel-messi-be-the-top-goalscorer-at-the-2026-fifa-world-cup", "data": {"market": "0xd2a8caba5559bc21e14f6b2aa504cb14a1782751658b71409e25b82e432c0a97", "price_changes": [{"asset_id": "36586667785814641857008731622413716797407337292495614620493145114086484487337", "price": "0.45", "size": "1903", "side": "BUY", "hash": "af7294965f288199e9217e06d125cd3226c67a8c", "best_bid": "0.48", "best_ask": "0.481"}, {"asset_id": "19214394437683566921750936876376421489271269944393354497977881791256347396217", "price": "0.55", "size": "1903", "side": "SELL", "hash": "c08e6b6c1f2edae7d1cf9525d6e3d79cd734d96b", "best_bid": "0.519", "best_ask": "0.52"}], "timestamp": "1782707822007", "event_type": "price_change"}}
{"local_timestamp": 1782707820.8653126, "slug": "will-lionel-messi-be-the-top-goalscorer-at-the-2026-fifa-world-cup", "data": {"market": "0xd2a8caba5559bc21e14f6b2aa504cb14a1782751658b71409e25b82e432c0a97", "price_changes": [{"asset_id": "19214394437683566921750936876376421489271269944393354497977881791256347396217", "price": "0.26", "size": "3000", "side": "BUY", "hash": "c7d66f186db023dd1bae6fa74c5d1598007cdbdc", "best_bid": "0.519", "best_ask": "0.52"}, {"asset_id": "36586667785814641857008731622413716797407337292495614620493145114086484487337", "price": "0.74", "size": "3000", "side": "SELL", "hash": "19e8643e415bfe27799c4ed9d9fba2b8d78a2d63", "best_bid": "0.48", "best_ask": "0.481"}], "timestamp": "1782707822096", "event_type": "price_change"}}
{"local_timestamp": 1782707820.866384, "slug": "will-lionel-messi-be-the-top-goalscorer-at-the-2026-fifa-world-cup", "data": {"market": "0xd2a8caba5559bc21e14f6b2aa504cb14a1782751658b71409e25b82e432c0a97", "price_changes": [{"asset_id": "36586667785814641857008731622413716797407337292495614620493145114086484487337", "price": "0.35", "size": "3200", "side": "BUY", "hash": "6984d9d1846567686488f74bc717fb27c3d14ba8", "best_bid": "0.48", "best_ask": "0.481"}, {"asset_id": "19214394437683566921750936876376421489271269944393354497977881791256347396217", "price": "0.65", "size": "3200", "side": "SELL", "hash": "bb15570bffa6fdcc06e433961f80f1ff7995ad1c", "best_bid": "0.519", "best_ask": "0.52"}], "timestamp": "1782707822100", "event_type": "price_change"}}
{"local_timestamp": 1782707821.7739897, "slug": "will-lionel-messi-be-the-top-goalscorer-at-the-2026-fifa-world-cup", "data": {"market": "0xd2a8caba5559bc21e14f6b2aa504cb14a1782751658b71409e25b82e432c0a97", "price_changes": [{"asset_id": "36586667785814641857008731622413716797407337292495614620493145114086484487337", "price": "0.46", "size": "42620", "side": "BUY", "hash": "54baac9dc86b8c5ac88e65a248dd3675ae1f5f05", "best_bid": "0.48", "best_ask": "0.481"}, {"asset_id": "19214394437683566921750936876376421489271269944393354497977881791256347396217", "price": "0.54", "size": "42620", "side": "SELL", "hash": "8cea83455ac85443b62e32ccbefc6a01c67c0d11", "best_bid": "0.519", "best_ask": "0.52"}], "timestamp": "1782707823000", "event_type": "price_change"}}
{"local_timestamp": 1782707821.9783247, "slug": "will-lionel-messi-be-the-top-goalscorer-at-the-2026-fifa-world-cup", "data": {"market": "0xd2a8caba5559bc21e14f6b2aa504cb14a1782751658b71409e25b82e432c0a97", "price_changes": [{"asset_id": "36586667785814641857008731622413716797407337292495614620493145114086484487337", "price": "0.361", "size": "0", "side": "BUY", "hash": "075819ef684f0f749523da47da520a38db695107", "best_bid": "0.48", "best_ask": "0.481"}, {"asset_id": "19214394437683566921750936876376421489271269944393354497977881791256347396217", "price": "0.639", "size": "0", "side": "SELL", "hash": "a646b4b33b5572584707967b8d5d824a11a9e751", "best_bid": "0.519", "best_ask": "0.52"}], "timestamp": "1782707823211", "event_type": "price_change"}}
{"local_timestamp": 1782707822.372295, "slug": "will-lionel-messi-be-the-top-goalscorer-at-the-2026-fifa-world-cup", "data": {"market": "0xd2a8caba5559bc21e14f6b2aa504cb14a1782751658b71409e25b82e432c0a97", "price_changes": [{"asset_id": "19214394437683566921750936876376421489271269944393354497977881791256347396217", "price": "0.26", "size": "0", "side": "BUY", "hash": "8ab31812105227d7c676391dfe8899946af47d96", "best_bid": "0.519", "best_ask": "0.52"}, {"asset_id": "36586667785814641857008731622413716797407337292495614620493145114086484487337", "price": "0.74", "size": "0", "side": "SELL", "hash": "987226279a2d55018f01f32692f9c98411e40231", "best_bid": "0.48", "best_ask": "0.481"}], "timestamp": "1782707823592", "event_type": "price_change"}}
{"local_timestamp": 1782707822.3728106, "slug": "will-lionel-messi-be-the-top-goalscorer-at-the-2026-fifa-world-cup", "data": {"market": "0xd2a8caba5559bc21e14f6b2aa504cb14a1782751658b71409e25b82e432c0a97", "price_changes": [{"asset_id": "36586667785814641857008731622413716797407337292495614620493145114086484487337", "price": "0.35", "size": "200", "side": "BUY", "hash": "e497ab3d30409e9f1ae645b661adee4f3dc59c1e", "best_bid": "0.48", "best_ask": "0.481"}, {"asset_id": "19214394437683566921750936876376421489271269944393354497977881791256347396217", "price": "0.65", "size": "200", "side": "SELL", "hash": "15f28cb211d10c59d0fdc5cc1ee2b84237beb477", "best_bid": "0.519", "best_ask": "0.52"}], "timestamp": "1782707823592", "event_type": "price_change"}}
{"local_timestamp": 1782707823.4685311, "slug": "will-lionel-messi-be-the-top-goalscorer-at-the-2026-fifa-world-cup", "data": {"market": "0xd2a8caba5559bc21e14f6b2aa504cb14a1782751658b71409e25b82e432c0a97", "price_changes": [{"asset_id": "36586667785814641857008731622413716797407337292495614620493145114086484487337", "price": "0.46", "size": "43533", "side": "BUY", "hash": "ed5d9c437c7222f2e49116fe2ceef93e079fe1d1", "best_bid": "0.48", "best_ask": "0.481"}, {"asset_id": "19214394437683566921750936876376421489271269944393354497977881791256347396217", "price": "0.54", "size": "43533", "side": "SELL", "hash": "6026f408beb22e2cf47e3f82d4ee462e14a796bf", "best_bid": "0.519", "best_ask": "0.52"}], "timestamp": "1782707824703", "event_type": "price_change"}}
{"local_timestamp": 1782707823.4900806, "slug": "will-lionel-messi-be-the-top-goalscorer-at-the-2026-fifa-world-cup", "data": {"market": "0xd2a8caba5559bc21e14f6b2aa504cb14a1782751658b71409e25b82e432c0a97", "price_changes": [{"asset_id": "36586667785814641857008731622413716797407337292495614620493145114086484487337", "price": "0.45", "size": "2816", "side": "BUY", "hash": "c974ea5d846a32a4582403057a3129fc49c2ef86", "best_bid": "0.48", "best_ask": "0.481"}, {"asset_id": "19214394437683566921750936876376421489271269944393354497977881791256347396217", "price": "0.55", "size": "2816", "side": "SELL", "hash": "9f17840a92e0b8d86b51dad841648ac2c2ad2bcf", "best_bid": "0.519", "best_ask": "0.52"}], "timestamp": "1782707824724", "event_type": "price_change"}}
{"local_timestamp": 1782707823.8782628, "slug": "will-lionel-messi-be-the-top-goalscorer-at-the-2026-fifa-world-cup", "data": {"market": "0xd2a8caba5559bc21e14f6b2aa504cb14a1782751658b71409e25b82e432c0a97", "price_changes": [{"asset_id": "36586667785814641857008731622413716797407337292495614620493145114086484487337", "price": "0.35", "size": "3200", "side": "BUY", "hash": "ff78f701454df3210f5b76cc7224691714bc1cd9", "best_bid": "0.48", "best_ask": "0.481"}, {"asset_id": "19214394437683566921750936876376421489271269944393354497977881791256347396217", "price": "0.65", "size": "3200", "side": "SELL", "hash": "8bfb19d9a544ed0a4b55d03b6cf470c97a453895", "best_bid": "0.519", "best_ask": "0.52"}], "timestamp": "1782707825113", "event_type": "price_change"}}
{"local_timestamp": 1782707823.90625, "slug": "will-lionel-messi-be-the-top-goalscorer-at-the-2026-fifa-world-cup", "data": {"market": "0xd2a8caba5559bc21e14f6b2aa504cb14a1782751658b71409e25b82e432c0a97", "price_changes": [{"asset_id": "19214394437683566921750936876376421489271269944393354497977881791256347396217", "price": "0.26", "size": "3000", "side": "BUY", "hash": "32006965d8d30effcf02a5c82ad4a32dccf77155", "best_bid": "0.519", "best_ask": "0.52"}, {"asset_id": "36586667785814641857008731622413716797407337292495614620493145114086484487337", "price": "0.74", "size": "3000", "side": "SELL", "hash": "3e52fde722404fc50e3c1fc5178667a02e81b1fc", "best_bid": "0.48", "best_ask": "0.481"}], "timestamp": "1782707825137", "event_type": "price_change"}}
{"local_timestamp": 1782707825.3575456, "slug": "will-lionel-messi-be-the-top-goalscorer-at-the-2026-fifa-world-cup", "data": {"market": "0xd2a8caba5559bc21e14f6b2aa504cb14a1782751658b71409e25b82e432c0a97", "price_changes": [{"asset_id": "19214394437683566921750936876376421489271269944393354497977881791256347396217", "price": "0.26", "size": "0", "side": "BUY", "hash": "60ec4e4b07957ff5f5c191c83c432ea7f7af8057", "best_bid": "0.519", "best_ask": "0.52"}, {"asset_id": "36586667785814641857008731622413716797407337292495614620493145114086484487337", "price": "0.74", "size": "0", "side": "SELL", "hash": "a00cce85de6db9f63c6b3097c5d71e33458804eb", "best_bid": "0.48", "best_ask": "0.481"}], "timestamp": "1782707826591", "event_type": "price_change"}}
{"local_timestamp": 1782707825.3587492, "slug": "will-lionel-messi-be-the-top-goalscorer-at-the-2026-fifa-world-cup", "data": {"market": "0xd2a8caba5559bc21e14f6b2aa504cb14a1782751658b71409e25b82e432c0a97", "price_changes": [{"asset_id": "36586667785814641857008731622413716797407337292495614620493145114086484487337", "price": "0.35", "size": "200", "side": "BUY", "hash": "5b3b4a5fdb5a7be410790abb70408e2f999f1af0", "best_bid": "0.48", "best_ask": "0.481"}, {"asset_id": "19214394437683566921750936876376421489271269944393354497977881791256347396217", "price": "0.65", "size": "200", "side": "SELL", "hash": "f613834de046d58da09d9260e64d04688f11ef5c", "best_bid": "0.519", "best_ask": "0.52"}], "timestamp": "1782707826591", "event_type": "price_change"}}
{"local_timestamp": 1782707826.4734523, "slug": "will-lionel-messi-be-the-top-goalscorer-at-the-2026-fifa-world-cup", "data": {"market": "0xd2a8caba5559bc21e14f6b2aa504cb14a1782751658b71409e25b82e432c0a97", "price_changes": [{"asset_id": "36586667785814641857008731622413716797407337292495614620493145114086484487337", "price": "0.312", "size": "2100", "side": "BUY", "hash": "f932fcffa2f70f012daf46c1ffa79b170956db90", "best_bid": "0.48", "best_ask": "0.481"}, {"asset_id": "19214394437683566921750936876376421489271269944393354497977881791256347396217", "price": "0.688", "size": "2100", "side": "SELL", "hash": "4e5cb891c5924db53556bb80132aad382d004a60", "best_bid": "0.519", "best_ask": "0.52"}], "timestamp": "1782707827705", "event_type": "price_change"}}
{"local_timestamp": 1782707826.7772288, "slug": "will-lionel-messi-be-the-top-goalscorer-at-the-2026-fifa-world-cup", "data": {"market": "0xd2a8caba5559bc21e14f6b2aa504cb14a1782751658b71409e25b82e432c0a97", "price_changes": [{"asset_id": "36586667785814641857008731622413716797407337292495614620493145114086484487337", "price": "0.46", "size": "43333", "side": "BUY", "hash": "a8c6dd4f788a670de57fbe2c243aca9d35cca7a7", "best_bid": "0.48", "best_ask": "0.481"}, {"asset_id": "19214394437683566921750936876376421489271269944393354497977881791256347396217", "price": "0.54", "size": "43333", "side": "SELL", "hash": "4ee61840159489d0ab90147433cae95789974826", "best_bid": "0.519", "best_ask": "0.52"}], "timestamp": "1782707828002", "event_type": "price_change"}}
{"local_timestamp": 1782707826.8540902, "slug": "will-lionel-messi-be-the-top-goalscorer-at-the-2026-fifa-world-cup", "data": {"market": "0xd2a8caba5559bc21e14f6b2aa504cb14a1782751658b71409e25b82e432c0a97", "price_changes": [{"asset_id": "19214394437683566921750936876376421489271269944393354497977881791256347396217", "price": "0.26", "size": "3000", "side": "BUY", "hash": "f4532b6bb70c19d636b5edc45dca8c4dd3083450", "best_bid": "0.519", "best_ask": "0.52"}, {"asset_id": "36586667785814641857008731622413716797407337292495614620493145114086484487337", "price": "0.74", "size": "3000", "side": "SELL", "hash": "2db4c6ed4662900f5648d2ac27075d5ad0c866fe", "best_bid": "0.48", "best_ask": "0.481"}], "timestamp": "1782707828088", "event_type": "price_change"}}
{"local_timestamp": 1782707826.872081, "slug": "will-lionel-messi-be-the-top-goalscorer-at-the-2026-fifa-world-cup", "data": {"market": "0xd2a8caba5559bc21e14f6b2aa504cb14a1782751658b71409e25b82e432c0a97", "price_changes": [{"asset_id": "36586667785814641857008731622413716797407337292495614620493145114086484487337", "price": "0.35", "size": "3200", "side": "BUY", "hash": "8aa318e04f0bf44f5cea13eb6e2fecc1eddd5e9f", "best_bid": "0.48", "best_ask": "0.481"}, {"asset_id": "19214394437683566921750936876376421489271269944393354497977881791256347396217", "price": "0.65", "size": "3200", "side": "SELL", "hash": "10e79eba2a73d2ebd953e620e2fb328007be214c", "best_bid": "0.519", "best_ask": "0.52"}], "timestamp": "1782707828106", "event_type": "price_change"}}
