{"local_timestamp": 1782707599.4678588, "slug": "will-lionel-messi-be-the-top-goalscorer-at-the-2026-fifa-world-cup", "data": [{"market": "0xd2a8caba5559bc21e14f6b2aa504cb14a1782751658b71409e25b82e432c0a97", "asset_id": "19214394437683566921750936876376421489271269944393354497977881791256347396217", "timestamp": "1782707599974", "hash": "a8a7511ea172b0cdf4ea1bc87261a59e232af2ff", "bids": [{"price": "0.001", "size": "1012937"}, {"price": "0.002", "size": "28250"}, {"price": "0.003", "size": "5149.96"}, {"price": "0.004", "size": "3000"}, {"price": "0.005", "size": "2400"}, {"price": "0.006", "size": "1999.93"}, {"price": "0.007", "size": "3142.81"}, {"price": "0.008", "size": "2750"}, {"price": "0.009", "size": "2444.41"}, {"price": "0.01", "size": "22219.34"}, {"price": "0.011", "size": "181.81"}, {"price": "0.012", "size": "1666.66"}, {"price": "0.013", "size": "1122.81"}, {"price": "0.014", "size": "142.85"}, {"price": "0.015", "size": "133.33"}, {"price": "0.016", "size": "125"}, {"price": "0.017", "size": "117.64"}, {"price": "0.018", "size": "111.11"}, {"price": "0.019", "size": "105.26"}, {"price": "0.02", "size": "100"}, {"price": "0.021", "size": "95.23"}, {"price": "0.022", "size": "90.9"}, {"price": "0.023", "size": "86.95"}, {"price": "0.024", "size": "83.33"}, {"price": "0.025", "size": "80"}, {"price": "0.026", "size": "76.92"}, {"price": "0.027", "size": "74.07"}, {"price": "0.028", "size": "71.42"}, {"price": "0.029", "size": "68.96"}, {"price": "0.03", "size": "66.66"}, {"price": "0.031", "size": "64.51"}, {"price": "0.032", "size": "62.5"}, {"price": "0.033", "size": "60.6"}, {"price": "0.04", "size": "350"}, {"price": "0.041", "size": "102"}, {"price": "0.042", "size": "136.15"}, {"price": "0.043", "size": "191.99"}, {"price": "0.05", "size": "1250"}, {"price": "0.051", "size": "450"}, {"price": "0.052", "size": "45.26"}, {"price": "0.054", "size": "15"}, {"price": "0.055", "size": "1119.42"}, {"price": "0.057", "size": "91.58"}, {"price": "0.058", "size": "1000"}, {"price": "0.059", "size": "97"}, {"price": "0.06", "size": "292"}, {"price": "0.111", "size": "250"}, {"price": "0.132", "size": "2499.97"}, {"price": "0.182", "size": "2500"}, {"price": "0.19", "size": "86.63"}, {"price": "0.2", "size": "12.29"}, {"price": "0.201", "size": "200"}, {"price": "0.202", "size": "5.11"}, {"price": "0.206", "size": "5"}, {"price": "0.241", "size": "621"}, {"price": "0.242", "size": "455.43"}, {"price": "0.27", "size": "291.16"}, {"price": "0.281", "size": "10000"}, {"price": "0.282", "size": "2000"}, {"price": "0.298", "size": "3000"}, {"price": "0.3", "size": "146.72"}, {"price": "0.317", "size": "1000"}, {"price": "0.318", "size": "200"}, {"price": "0.33", "size": "200"}, {"price": "0.334", "size": "5.09"}, {"price": "0.337", "size": "699.99"}, {"price": "0.341", "size": "209.99"}, {"price": "0.346", "size": "500"}, {"price": "0.35", "size": "1000"}, {"price": "0.358", "size": "32.52"}, {"price": "0.361", "size": "900"}, {"price": "0.366", "size": "100"}, {"price": "0.373", "size": "100"}, {"price": "0.377", "size": "434.96"}, {"price": "0.378", "size": "40"}, {"price": "0.379", "size": "5"}, {"price": "0.381", "size": "100"}, {"price": "0.382", "size": "40.49"}, {"price": "0.389", "size": "333.19"}, {"price": "0.391", "size": "17"}, {"price": "0.4", "size": "230"}, {"price": "0.402", "size": "100"}, {"price": "0.41", "size": "5"}, {"price": "0.425", "size": "220"}, {"price": "0.445", "size": "10"}, {"price": "0.447", "size": "50"}, {"price": "0.46", "size": "700"}, {"price": "0.47", "size": "1975"}, {"price": "0.478", "size": "500"}, {"price": "0.48", "size": "2475"}, {"price": "0.481", "size": "1445"}, {"price": "0.486", "size": "2234.64"}, {"price": "0.487", "size": "9883"}, {"price": "0.488", "size": "6921"}, {"price": "0.49", "size": "8848"}, {"price": "0.491", "size": "10833.34"}, {"price": "0.492", "size": "1500"}, {"price": "0.495", "size": "250"}, {"price": "0.498", "size": "5646.52"}, {"price": "0.499", "size": "58223"}, {"price": "0.5", "size": "27275"}, {"price": "0.501", "size": "2700"}, {"price": "0.502", "size": "441.38"}, {"price": "0.505", "size": "445.68"}, {"price": "0.506", "size": "258.04"}, {"price": "0.508", "size": "400"}, {"price": "0.509", "size": "1700"}, {"price": "0.51", "size": "11"}, {"price": "0.511", "size": "1967.5"}, {"price": "0.514", "size": "250"}, {"price": "0.516", "size": "968"}, {"price": "0.517", "size": "400"}, {"price": "0.518", "size": "18594.71"}, {"price": "0.519", "size": "699.93"}], "asks": [{"price": "0.999", "size": "21003050.58"}, {"price": "0.998", "size": "13507.31"}, {"price": "0.997", "size": "90666.66"}, {"price": "0.996", "size": "506.67"}, {"price": "0.995", "size": "400"}, {"price": "0.994", "size": "333.33"}, {"price": "0.993", "size": "290.94"}, {"price": "0.992", "size": "250"}, {"price": "0.991", "size": "222.22"}, {"price": "0.99", "size": "10800.65"}, {"price": "0.989", "size": "60181.81"}, {"price": "0.988", "size": "966.66"}, {"price": "0.987", "size": "158.91"}, {"price": "0.986", "size": "142.85"}, {"price": "0.985", "size": "133.33"}, {"price": "0.984", "size": "125"}, {"price": "0.983", "size": "117.64"}, {"price": "0.982", "size": "111.11"}, {"price": "0.981", "size": "155.26"}, {"price": "0.98", "size": "1100"}, {"price": "0.979", "size": "3095.23"}, {"price": "0.978", "size": "90.9"}, {"price": "0.977", "size": "86.95"}, {"price": "0.976", "size": "83.33"}, {"price": "0.975", "size": "85.08"}, {"price": "0.974", "size": "76.92"}, {"price": "0.973", "size": "74.07"}, {"price": "0.972", "size": "71.42"}, {"price": "0.971", "size": "68.96"}, {"price": "0.97", "size": "66.66"}, {"price": "0.969", "size": "64.51"}, {"price": "0.968", "size": "62.5"}, {"price": "0.967", "size": "60.6"}, {"price": "0.95", "size": "20"}, {"price": "0.949", "size": "8.83"}, {"price": "0.92", "size": "1000"}, {"price": "0.904", "size": "50"}, {"price": "0.9", "size": "5"}, {"price": "0.89", "size": "700"}, {"price": "0.88", "size": "500"}, {"price": "0.87", "size": "500"}, {"price": "0.86", "size": "499.99"}, {"price": "0.85", "size": "410.99"}, {"price": "0.84", "size": "300"}, {"price": "0.839", "size": "10.21"}, {"price": "0.834", "size": "50"}, {"price": "0.83", "size": "300"}, {"price": "0.82", "size": "300"}, {"price": "0.81", "size": "16"}, {"price": "0.808", "size": "2000"}, {"price": "0.8", "size": "1005"}, {"price": "0.778", "size": "2000"}, {"price": "0.772", "size": "50"}, {"price": "0.77", "size": "300"}, {"price": "0.768", "size": "200"}, {"price": "0.765", "size": "1241"}, {"price": "0.763", "size": "400"}, {"price": "0.75", "size": "145.44"}, {"price": "0.748", "size": "2000"}, {"price": "0.74", "size": "300"}, {"price": "0.73", "size": "300"}, {"price": "0.729", "size": "100"}, {"price": "0.72", "size": "5"}, {"price": "0.718", "size": "2000"}, {"price": "0.717", "size": "50"}, {"price": "0.716", "size": "462.07"}, {"price": "0.69", "size": "300"}, {"price": "0.688", "size": "2100"}, {"price": "0.68", "size": "200"}, {"price": "0.67", "size": "200"}, {"price": "0.669", "size": "50"}, {"price": "0.66", "size": "199.99"}, {"price": "0.658", "size": "2000"}, {"price": "0.65", "size": "200"}, {"price": "0.64", "size": "200"}, {"price": "0.639", "size": "50"}, {"price": "0.637", "size": "2000"}, {"price": "0.63", "size": "200"}, {"price": "0.629", "size": "50"}, {"price": "0.628", "size": "186.76"}, {"price": "0.626", "size": "2000"}, {"price": "0.62", "size": "1000"}, {"price": "0.619", "size": "100"}, {"price": "0.616", "size": "1537"}, {"price": "0.61", "size": "2075"}, {"price": "0.606", "size": "1537"}, {"price": "0.6", "size": "2696.3"}, {"price": "0.598", "size": "350"}, {"price": "0.596", "size": "1287"}, {"price": "0.595", "size": "50"}, {"price": "0.59", "size": "2396.3"}, {"price": "0.589", "size": "150"}, {"price": "0.588", "size": "50"}, {"price": "0.586", "size": "1010"}, {"price": "0.58", "size": "1996.3"}, {"price": "0.579", "size": "25"}, {"price": "0.578", "size": "45"}, {"price": "0.573", "size": "31"}, {"price": "0.57", "size": "150"}, {"price": "0.569", "size": "11.3"}, {"price": "0.568", "size": "30"}, {"price": "0.567", "size": "30"}, {"price": "0.558", "size": "2019.99"}, {"price": "0.554", "size": "1604"}, {"price": "0.553", "size": "3029.72"}, {"price": "0.552", "size": "1000"}, {"price": "0.551", "size": "754"}, {"price": "0.55", "size": "1777"}, {"price": "0.546", "size": "2000"}, {"price": "0.545", "size": "1976"}, {"price": "0.543", "size": "40000"}, {"price": "0.542", "size": "205200"}, {"price": "0.541", "size": "604"}, {"price": "0.54", "size": "43024"}, {"price": "0.539", "size": "20"}, {"price": "0.535", "size": "1294.7"}, {"price": "0.531", "size": "804"}, {"price": "0.53", "size": "18406"}, {"price": "0.529", "size": "200"}, {"price": "0.527", "size": "600"}, {"price": "0.526", "size": "295.35"}, {"price": "0.525", "size": "7187.77"}, {"price": "0.524", "size": "861.94"}, {"price": "0.522", "size": "409.99"}, {"price": "0.521", "size": "4481.61"}, {"price": "0.52", "size": "244.35"}], "tick_size": "0.001", "event_type": "book", "last_trade_price": "0.481"}]}
{"local_timestamp": 1782707601.0324419, "slug": "will-lionel-messi-be-the-top-goalscorer-at-the-2026-fifa-world-cup", "data": {"market": "0xd2a8caba5559bc21e14f6b2aa504cb14a1782751658b71409e25b82e432c0a97", "price_changes": [{"asset_id": "19214394437683566921750936876376421489271269944393354497977881791256347396217", "price": "0.521", "size": "4578.7", "side": "SELL", "hash": "535ba2f8c1d02c8620ba93979dbbdb2f865ed507", "best_bid": "0.519", "best_ask": "0.52"}, {"asset_id": "36586667785814641857008731622413716797407337292495614620493145114086484487337", "price": "0.479", "size": "4578.7", "side": "BUY", "hash": "62a9077341aebba9942a304c48cdaefb757370bc", "best_bid": "0.48", "best_ask": "0.481"}], "timestamp": "1782707602253", "event_type": "price_change"}}
{"local_timestamp": 1782707601.2338269, "slug": "will-lionel-messi-be-the-top-goalscorer-at-the-2026-fifa-world-cup", "data": {"market": "0xd2a8caba5559bc21e14f6b2aa504cb14a1782751658b71409e25b82e432c0a97", "price_changes": [{"asset_id": "19214394437683566921750936876376421489271269944393354497977881791256347396217", "price": "0.48", "size": "3079", "side": "BUY", "hash": "5b7b3621d233faa5e2850bb6037d1003e590d8aa", "best_bid": "0.519", "best_ask": "0.52"}, {"asset_id": "36586667785814641857008731622413716797407337292495614620493145114086484487337", "price": "0.52", "size": "3079", "side": "SELL", "hash": "a9f5fd7c4888a2c524b7148bdcfbfac89b9cb7ed", "best_bid": "0.48", "best_ask": "0.481"}], "timestamp": "1782707602460", "event_type": "price_change"}}
{"local_timestamp": 1782707602.7640035, "slug": "will-lionel-messi-be-the-top-goalscorer-at-the-2026-fifa-world-cup", "data": {"market": "0xd2a8caba5559bc21e14f6b2aa504cb14a1782751658b71409e25b82e432c0a97", "price_changes": [{"asset_id": "19214394437683566921750936876376421489271269944393354497977881791256347396217", "price": "0.521", "size": "4481.61", "side": "SELL", "hash": "71b0dbbf9119ae2d395d527625834821c7b55a0f", "best_bid": "0.519", "best_ask": "0.52"}, {"asset_id": "36586667785814641857008731622413716797407337292495614620493145114086484487337", "price": "0.479", "size": "4481.61", "side": "BUY", "hash": "cb0dd7d37d19e6a5e8ad570e3c43b1b54b0e6d9f", "best_bid": "0.48", "best_ask": "0.481"}], "timestamp": "1782707603991", "event_type": "price_change"}}
{"local_timestamp": 1782707602.7776666, "slug": "will-lionel-messi-be-the-top-goalscorer-at-the-2026-fifa-world-cup", "data": {"market": "0xd2a8caba5559bc21e14f6b2aa504cb14a1782751658b71409e25b82e432c0a97", "price_changes": [{"asset_id": "36586667785814641857008731622413716797407337292495614620493145114086484487337", "price": "0.46", "size": "42746", "side": "BUY", "hash": "37c6011f8b7540c649fa988f48c4cd68c9c207e0", "best_bid": "0.48", "best_ask": "0.481"}, {"asset_id": "19214394437683566921750936876376421489271269944393354497977881791256347396217", "price": "0.54", "size": "42746", "side": "SELL", "hash": "41169af2a38013afb20bda3763de3a21d17b765c", "best_bid": "0.519", "best_ask": "0.52"}], "timestamp": "1782707604001", "event_type": "price_change"}}
{"local_timestamp": 1782707603.614877, "slug": "will-lionel-messi-be-the-top-goalscorer-at-the-2026-fifa-world-cup", "data": {"market": "0xd2a8caba5559bc21e14f6b2aa504cb14a1782751658b71409e25b82e432c0a97", "price_changes": [{"asset_id": "36586667785814641857008731622413716797407337292495614620493145114086484487337", "price": "0.473", "size": "300", "side": "BUY", "hash": "cb7e1d91bd32e45b0aed4a86571b01daeac51526", "best_bid": "0.48", "best_ask": "0.481"}, {"asset_id": "19214394437683566921750936876376421489271269944393354497977881791256347396217", "price": "0.527", "size": "300", "side": "SELL", "hash": "e004404013cd7e04a252215ef4e3c36c72160a55", "best_bid": "0.519", "best_ask": "0.52"}], "timestamp": "1782707604839", "event_type": "price_change"}}
{"local_timestamp": 1782707603.8022614, "slug": "will-lionel-messi-be-the-top-goalscorer-at-the-2026-fifa-world-cup", "data": {"market": "0xd2a8caba5559bc21e14f6b2aa504cb14a1782751658b71409e25b82e432c0a97", "price_changes": [{"asset_id": "36586667785814641857008731622413716797407337292495614620493145114086484487337", "price": "0.473", "size": "0", "side": "BUY", "hash": "41a7676ea0b5b1f6a24b0349b0874229c82420fa", "best_bid": "0.48", "best_ask": "0.481"}, {"asset_id": "19214394437683566921750936876376421489271269944393354497977881791256347396217", "price": "0.527", "size": "0", "side": "SELL", "hash": "00cb2a9c939e6c554f59893d376cc703f9581b63", "best_bid": "0.519", "best_ask": "0.52"}], "timestamp": "1782707605030", "event_type": "price_change"}}
{"local_timestamp": 1782707603.8646622, "slug": "will-lionel-messi-be-the-top-goalscorer-at-the-2026-fifa-world-cup", "data": {"market": "0xd2a8caba5559bc21e14f6b2aa504cb14a1782751658b71409e25b82e432c0a97", "price_changes": [{"asset_id": "19214394437683566921750936876376421489271269944393354497977881791256347396217", "price": "0.518", "size": "19210.48", "side": "BUY", "hash": "c5b1a52424e1bf99ddb8709e8fe52cc2a0c3044c", "best_bid": "0.519", "best_ask": "0.52"}, {"asset_id": "36586667785814641857008731622413716797407337292495614620493145114086484487337", "price": "0.482", "size": "19210.48", "side": "SELL", "hash": "4f816da07b2ebd08066d31b038f8add17b64d8ec", "best_bid": "0.48", "best_ask": "0.481"}], "timestamp": "1782707605092", "event_type": "price_change"}}
{"local_timestamp": 1782707603.8924625, "slug": "will-lionel-messi-be-the-top-goalscorer-at-the-2026-fifa-world-cup", "data": {"market": "0xd2a8caba5559bc21e14f6b2aa504cb14a1782751658b71409e25b82e432c0a97", "price_changes": [{"asset_id": "36586667785814641857008731622413716797407337292495614620493145114086484487337", "price": "0.479", "size": "4897.34", "side": "BUY", "hash": "1c492d913ea6f26cd1cdda3ae6fc886ca3b36467", "best_bid": "0.48", "best_ask": "0.481"}, {"asset_id": "19214394437683566921750936876376421489271269944393354497977881791256347396217", "price": "0.521", "size": "4897.34", "side": "SELL", "hash": "32ef3eb1f6a47a781b9cf535403d75281cead571", "best_bid": "0.519", "best_ask": "0.52"}], "timestamp": "1782707605120", "event_type": "price_change"}}
{"local_timestamp": 1782707605.3748972, "slug": "will-lionel-messi-be-the-top-goalscorer-at-the-2026-fifa-world-cup", "data": {"market": "0xd2a8caba5559bc21e14f6b2aa504cb14a1782751658b71409e25b82e432c0a97", "price_changes": [{"asset_id": "36586667785814641857008731622413716797407337292495614620493145114086484487337", "price": "0.469", "size": "200", "side": "BUY", "hash": "6a266b9c3cbcf0bbb2105d6e82f8c05e32f1ae12", "best_bid": "0.48", "best_ask": "0.481"}, {"asset_id": "19214394437683566921750936876376421489271269944393354497977881791256347396217", "price": "0.531", "size": "200", "side": "SELL", "hash": "673b157e0b96a0046fda12a3602e140a7358a336", "best_bid": "0.519", "best_ask": "0.52"}], "timestamp": "1782707606602", "event_type": "price_change"}}
{"local_timestamp": 1782707605.376391, "slug": "will-lionel-messi-be-the-top-goalscorer-at-the-2026-fifa-world-cup", "data": {"market": "0xd2a8caba5559bc21e14f6b2aa504cb14a1782751658b71409e25b82e432c0a97", "price_changes": [{"asset_id": "36586667785814641857008731622413716797407337292495614620493145114086484487337", "price": "0.459", "size": "0", "side": "BUY", "hash": "6a266b9c3cbcf0bbb2105d6e82f8c05e32f1ae12", "best_bid": "0.48", "best_ask": "0.481"}, {"asset_id": "19214394437683566921750936876376421489271269944393354497977881791256347396217", "price": "0.541", "size": "0", "side": "SELL", "hash": "673b157e0b96a0046fda12a3602e140a7358a336", "best_bid": "0.519", "best_ask": "0.52"}], "timestamp": "1782707606602", "event_type": "price_change"}}
{"local_timestamp": 1782707605.3771205, "slug": "will-lionel-messi-be-the-top-goalscorer-at-the-2026-fifa-world-cup", "data": {"market": "0xd2a8caba5559bc21e14f6b2aa504cb14a1782751658b71409e25b82e432c0a97", "price_changes": [{"asset_id": "36586667785814641857008731622413716797407337292495614620493145114086484487337", "price": "0.449", "size": "150", "side": "BUY", "hash": "6a266b9c3cbcf0bbb2105d6e82f8c05e32f1ae12", "best_bid": "0.48", "best_ask": "0.481"}, {"asset_id": "19214394437683566921750936876376421489271269944393354497977881791256347396217", "price": "0.551", "size": "150", "side": "SELL", "hash": "673b157e0b96a0046fda12a3602e140a7358a336", "best_bid": "0.519", "best_ask": "0.52"}], "timestamp": "1782707606602", "event_type": "price_change"}}
{"local_timestamp": 1782707605.3776526, "slug": "will-lionel-messi-be-the-top-goalscorer-at-the-2026-fifa-world-cup", "data": {"market": "0xd2a8caba5559bc21e14f6b2aa504cb14a1782751658b71409e25b82e432c0a97", "price_changes": [{"asset_id": "19214394437683566921750936876376421489271269944393354497977881791256347396217", "price": "0.5", "size": "26671", "side": "BUY", "hash": "6a1df942246adc57bcc07e92cad549507a9fc554", "best_bid": "0.519", "best_ask": "0.52"}, {"asset_id": "36586667785814641857008731622413716797407337292495614620493145114086484487337", "price": "0.5", "size": "26671", "side": "SELL", "hash": "982b2280cfba5810537109b34d09f1157ed711e6", "best_bid": "0.48", "best_ask": "0.481"}], "timestamp": "1782707606602", "event_type": "price_change"}}
{"local_timestamp": 1782707605.3783329, "slug": "will-lionel-messi-be-the-top-goalscorer-at-the-2026-fifa-world-cup", "data": {"market": "0xd2a8caba5559bc21e14f6b2aa504cb14a1782751658b71409e25b82e432c0a97", "price_changes": [{"asset_id": "19214394437683566921750936876376421489271269944393354497977881791256347396217", "price": "0.49", "size": "8244", "side": "BUY", "hash": "6a1df942246adc57bcc07e92cad549507a9fc554", "best_bid": "0.519", "best_ask": "0.52"}, {"asset_id": "36586667785814641857008731622413716797407337292495614620493145114086484487337", "price": "0.51", "size": "8244", "side": "SELL", "hash": "982b2280cfba5810537109b34d09f1157ed711e6", "best_bid": "0.48", "best_ask": "0.481"}], "timestamp": "1782707606602", "event_type": "price_change"}}
{"local_timestamp": 1782707605.3789032, "slug": "will-lionel-messi-be-the-top-goalscorer-at-the-2026-fifa-world-cup", "data": {"market": "0xd2a8caba5559bc21e14f6b2aa504cb14a1782751658b71409e25b82e432c0a97", "price_changes": [{"asset_id": "19214394437683566921750936876376421489271269944393354497977881791256347396217", "price": "0.48", "size": "2475", "side": "BUY", "hash": "6a1df942246adc57bcc07e92cad549507a9fc554", "best_bid": "0.519", "best_ask": "0.52"}, {"asset_id": "36586667785814641857008731622413716797407337292495614620493145114086484487337", "price": "0.52", "size": "2475", "side": "SELL", "hash": "982b2280cfba5810537109b34d09f1157ed711e6", "best_bid": "0.48", "best_ask": "0.481"}], "timestamp": "1782707606602", "event_type": "price_change"}}
{"local_timestamp": 1782707605.6752057, "slug": "will-lionel-messi-be-the-top-goalscorer-at-the-2026-fifa-world-cup", "data": {"market": "0xd2a8caba5559bc21e14f6b2aa504cb14a1782751658b71409e25b82e432c0a97", "price_changes": [{"asset_id": "19214394437683566921750936876376421489271269944393354497977881791256347396217", "price": "0.521", "size": "4994.43", "side": "SELL", "hash": "77e3eb285db35cc7d68bd3534c77f58e1957dd78", "best_bid": "0.519", "best_ask": "0.52"}, {"asset_id": "36586667785814641857008731622413716797407337292495614620493145114086484487337", "price": "0.479", "size": "4994.43", "side": "BUY", "hash": "a2bce668a92923bcde50ea3b5dad5baa9427fff0", "best_bid": "0.48", "best_ask": "0.481"}], "timestamp": "1782707606903", "event_type": "price_change"}}
{"local_timestamp": 1782707606.0229862, "slug": "will-lionel-messi-be-the-top-goalscorer-at-the-2026-fifa-world-cup", "data": {"market": "0xd2a8caba5559bc21e14f6b2aa504cb14a1782751658b71409e25b82e432c0a97", "price_changes": [{"asset_id": "36586667785814641857008731622413716797407337292495614620493145114086484487337", "price": "0.475", "size": "6937.77", "side": "BUY", "hash": "43381b53b24219cf06089b6fef58f47660c526f1", "best_bid": "0.48", "best_ask": "0.481"}, {"asset_id": "19214394437683566921750936876376421489271269944393354497977881791256347396217", "price": "0.525", "size": "6937.77", "side": "SELL", "hash": "8aadd99943eea4730714e3f38fcb36383fc2db28", "best_bid": "0.519", "best_ask": "0.52"}], "timestamp": "1782707607249", "event_type": "price_change"}}
{"local_timestamp": 1782707606.02352, "slug": "will-lionel-messi-be-the-top-goalscorer-at-the-2026-fifa-world-cup", "data": {"market": "0xd2a8caba5559bc21e14f6b2aa504cb14a1782751658b71409e25b82e432c0a97", "price_changes": [{"asset_id": "19214394437683566921750936876376421489271269944393354497977881791256347396217", "price": "0.514", "size": "0", "side": "BUY", "hash": "d048bc2e562febf7df6185265f4e300530e8e881", "best_bid": "0.519", "best_ask": "0.52"}, {"asset_id": "36586667785814641857008731622413716797407337292495614620493145114086484487337", "price": "0.486", "size": "0", "side": "SELL", "hash": "622b938bfcfde8c4a76f9f597d65f08255c9d407", "best_bid": "0.48", "best_ask": "0.481"}], "timestamp": "1782707607249", "event_type": "price_change"}}
{"local_timestamp": 1782707606.0878437, "slug": "will-lionel-messi-be-the-top-goalscorer-at-the-2026-fifa-world-cup", "data": {"market": "0xd2a8caba5559bc21e14f6b2aa504cb14a1782751658b71409e25b82e432c0a97", "price_changes": [{"asset_id": "19214394437683566921750936876376421489271269944393354497977881791256347396217", "price": "0.516", "size": "1218", "side": "BUY", "hash": "0d20cf22fdc13dca77ca045869f69610a84029d5", "best_bid": "0.519", "best_ask": "0.52"}, {"asset_id": "36586667785814641857008731622413716797407337292495614620493145114086484487337", "price": "0.484", "size": "1218", "side": "SELL", "hash": "14fade0ca8c3e819c451e6e3db90eb93a3b2f144", "best_bid": "0.48", "best_ask": "0.481"}], "timestamp": "1782707607316", "event_type": "price_change"}}
{"local_timestamp": 1782707606.091409, "slug": "will-lionel-messi-be-the-top-goalscorer-at-the-2026-fifa-world-cup", "data": {"market": "0xd2a8caba5559bc21e14f6b2aa504cb14a1782751658b71409e25b82e432c0a97", "price_changes": [{"asset_id": "36586667785814641857008731622413716797407337292495614620493145114086484487337", "price": "0.477", "size": "250", "side": "BUY", "hash": "fe07fdeb49cf29cdef7646bc53a1667613f06e60", "best_bid": "0.48", "best_ask": "0.481"}, {"asset_id": "19214394437683566921750936876376421489271269944393354497977881791256347396217", "price": "0.523", "size": "250", "side": "SELL", "hash": "b860324dc505aff4b4c9eb587e16bf7ebdd21057", "best_bid": "0.519", "best_ask": "0.52"}], "timestamp": "1782707607320", "event_type": "price_change"}}
{"local_timestamp": 1782707606.1356645, "slug": "will-lionel-messi-be-the-top-goalscorer-at-the-2026-fifa-world-cup", "data": {"market": "0xd2a8caba5559bc21e14f6b2aa504cb14a1782751658b71409e25b82e432c0a97", "price_changes": [{"asset_id": "36586667785814641857008731622413716797407337292495614620493145114086484487337", "price": "0.34", "size": "3199.99", "side": "BUY", "hash": "f912fb7f0e64489fc81b6b43c75eec6c2427924f", "best_bid": "0.48", "best_ask": "0.481"}, {"asset_id": "19214394437683566921750936876376421489271269944393354497977881791256347396217", "price": "0.66", "size": "3199.99", "side": "SELL", "hash": "a00b3b24458fe4307c7d2ecb950c20799fe67d1a", "best_bid": "0.519", "best_ask": "0.52"}], "timestamp": "1782707607364", "event_type": "price_change"}}
{"local_timestamp": 1782707606.150411, "slug": "will-lionel-messi-be-the-top-goalscorer-at-the-2026-fifa-world-cup", "data": {"market": "0xd2a8caba5559bc21e14f6b2aa504cb14a1782751658b71409e25b82e432c0a97", "price_changes": [{"asset_id": "19214394437683566921750936876376421489271269944393354497977881791256347396217", "price": "0.26", "size": "3000", "side": "BUY", "hash": "a131dc27578bfc8d2717185cf38bdc85f28bf8d8", "best_bid": "0.519", "best_ask": "0.52"}, {"asset_id": "36586667785814641857008731622413716797407337292495614620493145114086484487337", "price": "0.74", "size": "3000", "side": "SELL", "hash": "b2a0931b51521a6100e57f6d59735878a66b5fe4", "best_bid": "0.48", "best_ask": "0.481"}], "timestamp": "1782707607377", "event_type": "price_change"}}
{"local_timestamp": 1782707607.5216024, "slug": "will-lionel-messi-be-the-top-goalscorer-at-the-2026-fifa-world-cup", "data": {"market": "0xd2a8caba5559bc21e14f6b2aa504cb14a1782751658b71409e25b82e432c0a97", "price_changes": [{"asset_id": "36586667785814641857008731622413716797407337292495614620493145114086484487337", "price": "0.34", "size": "199.99", "side": "BUY", "hash": "9c994f534ae79e9f6c1a3dbe9b51d53f13f3f0f4", "best_bid": "0.48", "best_ask": "0.481"}, {"asset_id": "19214394437683566921750936876376421489271269944393354497977881791256347396217", "price": "0.66", "size": "199.99", "side": "SELL", "hash": "9f933a0c5e5f2c14a7f568a1ec7068f477b890f6", "best_bid": "0.519", "best_ask": "0.52"}], "timestamp": "1782707608750", "event_type": "price_change"}}
{"local_timestamp": 1782707607.5227835, "slug": "will-lionel-messi-be-the-top-goalscorer-at-the-2026-fifa-world-cup", "data": {"market": "0xd2a8caba5559bc21e14f6b2aa504cb14a1782751658b71409e25b82e432c0a97", "price_changes": [{"asset_id": "19214394437683566921750936876376421489271269944393354497977881791256347396217", "price": "0.26", "size": "0", "side": "BUY", "hash": "b2d958ad3bc891e4a6ffad70aefa1d08ace5c3a6", "best_bid": "0.519", "best_ask": "0.52"}, {"asset_id": "36586667785814641857008731622413716797407337292495614620493145114086484487337", "price": "0.74", "size": "0", "side": "SELL", "hash": "a0ad2c6d8a0724c591ab3443595d50f11a530f1c", "best_bid": "0.48", "best_ask": "0.481"}], "timestamp": "1782707608750", "event_type": "price_change"}}
{"local_timestamp": 1782707608.1183403, "slug": "will-lionel-messi-be-the-top-goalscorer-at-the-2026-fifa-world-cup", "data": {"market": "0xd2a8caba5559bc21e14f6b2aa504cb14a1782751658b71409e25b82e432c0a97", "price_changes": [{"asset_id": "19214394437683566921750936876376421489271269944393354497977881791256347396217", "price": "0.521", "size": "4897.34", "side": "SELL", "hash": "552bed0208fa15f5b666c9fcc65a76b0b1648861", "best_bid": "0.519", "best_ask": "0.52"}, {"asset_id": "36586667785814641857008731622413716797407337292495614620493145114086484487337", "price": "0.479", "size": "4897.34", "side": "BUY", "hash": "daae13952f5273e75b51b62c6c4590b6903ee523", "best_bid": "0.48", "best_ask": "0.481"}], "timestamp": "1782707609347", "event_type": "price_change"}}
{"local_timestamp": 1782707609.7757857, "slug": "will-lionel-messi-be-the-top-goalscorer-at-the-2026-fifa-world-cup", "data": {"market": "0xd2a8caba5559bc21e14f6b2aa504cb14a1782751658b71409e25b82e432c0a97", "price_changes": [{"asset_id": "36586667785814641857008731622413716797407337292495614620493145114086484487337", "price": "0.447", "size": "1456.49", "side": "BUY", "hash": "71a8a02734a9d0b73a1a94f8b2fb59c0ce6f86a1", "best_bid": "0.48", "best_ask": "0.481"}, {"asset_id": "19214394437683566921750936876376421489271269944393354497977881791256347396217", "price": "0.553", "size": "1456.49", "side": "SELL", "hash": "cda2a53823b62994910b70e77fac91abb61c9ad5", "best_bid": "0.519", "best_ask": "0.52"}], "timestamp": "1782707611005", "event_type": "price_change"}}
{"local_timestamp": 1782707609.7765949, "slug": "will-lionel-messi-be-the-top-goalscorer-at-the-2026-fifa-world-cup", "data": {"market": "0xd2a8caba5559bc21e14f6b2aa504cb14a1782751658b71409e25b82e432c0a97", "price_changes": [{"asset_id": "19214394437683566921750936876376421489271269944393354497977881791256347396217", "price": "0.486", "size": "787.72", "side": "BUY", "hash": "cda2a53823b62994910b70e77fac91abb61c9ad5", "best_bid": "0.519", "best_ask": "0.52"}, {"asset_id": "36586667785814641857008731622413716797407337292495614620493145114086484487337", "price": "0.514", "size": "787.72", "side": "SELL", "hash": "71a8a02734a9d0b73a1a94f8b2fb59c0ce6f86a1", "best_bid": "0.48", "best_ask": "0.481"}], "timestamp": "1782707611005", "event_type": "price_change"}}
{"local_timestamp": 1782707610.64862, "slug": "will-lionel-messi-be-the-top-goalscorer-at-the-2026-fifa-world-cup", "data": {"market": "0xd2a8caba5559bc21e14f6b2aa504cb14a1782751658b71409e25b82e432c0a97", "price_changes": [{"asset_id": "19214394437683566921750936876376421489271269944393354497977881791256347396217", "price": "0.521", "size": "4994.43", "side": "SELL", "hash": "f0ed8a6195a2e6bdfb5c908b3c3931eef9d71cb3", "best_bid": "0.519", "best_ask": "0.52"}, {"asset_id": "36586667785814641857008731622413716797407337292495614620493145114086484487337", "price": "0.479", "size": "4994.43", "side": "BUY", "hash": "9a6aa4d6835d290bc0ec89e85a35f7841e9bd50e", "best_bid": "0.48", "best_ask": "0.481"}], "timestamp": "1782707611877", "event_type": "price_change"}}
{"local_timestamp": 1782707611.9140306, "slug": "will-lionel-messi-be-the-top-goalscorer-at-the-2026-fifa-world-cup", "data": {"market": "0xd2a8caba5559bc21e14f6b2aa504cb14a1782751658b71409e25b82e432c0a97", "price_changes": [{"asset_id": "36586667785814641857008731622413716797407337292495614620493145114086484487337", "price": "0.34", "size": "3199.99", "side": "BUY", "hash": "a861da34bf5f59f6d399762d9a1044adfd563565", "best_bid": "0.48", "best_ask": "0.481"}, {"asset_id": "19214394437683566921750936876376421489271269944393354497977881791256347396217", "price": "0.66", "size": "3199.99", "side": "SELL", "hash": "92c2dd62de6b3b35af81dd3d666f4366b5b4b574", "best_bid": "0.519", "best_ask": "0.52"}], "timestamp": "1782707613141", "event_type": "price_change"}}
{"local_timestamp": 1782707611.9167113, "slug": "will-lionel-messi-be-the-top-goalscorer-at-the-2026-fifa-world-cup", "data": {"market": "0xd2a8caba5559bc21e14f6b2aa504cb14a1782751658b71409e25b82e432c0a97", "price_changes": [{"asset_id": "19214394437683566921750936876376421489271269944393354497977881791256347396217", "price": "0.26", "size": "3000", "side": "BUY", "hash": "225a74442e00f2725e266a84ca9a9011fa6c6bde", "best_bid": "0.519", "best_ask": "0.52"}, {"asset_id": "36586667785814641857008731622413716797407337292495614620493145114086484487337", "price": "0.74", "size": "3000", "side": "SELL", "hash": "f76ff937b897eeb78e1020a666de15c21e336ed9", "best_bid": "0.48", "best_ask": "0.481"}], "timestamp": "1782707613143", "event_type": "price_change"}}
{"local_timestamp": 1782707612.0130024, "slug": "will-lionel-messi-be-the-top-goalscorer-at-the-2026-fifa-world-cup", "data": {"market": "0xd2a8caba5559bc21e14f6b2aa504cb14a1782751658b71409e25b82e432c0a97", "price_changes": [{"asset_id": "36586667785814641857008731622413716797407337292495614620493145114086484487337", "price": "0.48", "size": "454.35", "side": "BUY", "hash": "27db861fcc08630dba647a1ea6469a374b8c4d69", "best_bid": "0.48", "best_ask": "0.481"}, {"asset_id": "19214394437683566921750936876376421489271269944393354497977881791256347396217", "price": "0.52", "size": "454.35", "side": "SELL", "hash": "633ba97a92dc1d3393a44dbcf0b40e8df416db90", "best_bid": "0.519", "best_ask": "0.52"}], "timestamp": "1782707613240", "event_type": "price_change"}}
{"local_timestamp": 1782707612.0211844, "slug": "will-lionel-messi-be-the-top-goalscorer-at-the-2026-fifa-world-cup", "data": {"market": "0xd2a8caba5559bc21e14f6b2aa504cb14a1782751658b71409e25b82e432c0a97", "price_changes": [{"asset_id": "19214394437683566921750936876376421489271269944393354497977881791256347396217", "price": "0.519", "size": "909.93", "side": "BUY", "hash": "f89f3e944ab2c31a5ffebea0c58e12dd1631756f", "best_bid": "0.519", "best_ask": "0.52"}, {"asset_id": "36586667785814641857008731622413716797407337292495614620493145114086484487337", "price": "0.481", "size": "909.93", "side": "SELL", "hash": "46db6019d2292a9460c8db4b57c04cde2595d1b8", "best_bid": "0.48", "best_ask": "0.481"}], "timestamp": "1782707613246", "event_type": "price_change"}}
{"local_timestamp": 1782707612.2773364, "slug": "will-lionel-messi-be-the-top-goalscorer-at-the-2026-fifa-world-cup", "data": {"market": "0xd2a8caba5559bc21e14f6b2aa504cb14a1782751658b71409e25b82e432c0a97", "price_changes": [{"asset_id": "19214394437683566921750936876376421489271269944393354497977881791256347396217", "price": "0.521", "size": "4897.34", "side": "SELL", "hash": "fefaa68afb2d47167085f48a25d545cddd4d17aa", "best_bid": "0.519", "best_ask": "0.52"}, {"asset_id": "36586667785814641857008731622413716797407337292495614620493145114086484487337", "price": "0.479", "size": "4897.34", "side": "BUY", "hash": "a13647b19a5336e10cf8cf2f5829fe8308c13216", "best_bid": "0.48", "best_ask": "0.481"}], "timestamp": "1782707613505", "event_type": "price_change"}}
{"local_timestamp": 1782707612.7714295, "slug": "will-lionel-messi-be-the-top-goalscorer-at-the-2026-fifa-world-cup", "data": {"market": "0xd2a8caba5559bc21e14f6b2aa504cb14a1782751658b71409e25b82e432c0a97", "price_changes": [{"asset_id": "19214394437683566921750936876376421489271269944393354497977881791256347396217", "price": "0.5", "size": "26393", "side": "BUY", "hash": "449876753253da674523cca07f100a6a78eedc86", "best_bid": "0.519", "best_ask": "0.52"}, {"asset_id": "36586667785814641857008731622413716797407337292495614620493145114086484487337", "price": "0.5", "size": "26393", "side": "SELL", "hash": "586f3eb41efd0784772eb13dec7ac17f03d46e3e", "best_bid": "0.48", "best_ask": "0.481"}], "timestamp": "1782707614000", "event_type": "price_change"}}
{"local_timestamp": 1782707612.8667817, "slug": "will-lionel-messi-be-the-top-goalscorer-at-the-2026-fifa-world-cup", "data": {"market": "0xd2a8caba5559bc21e14f6b2aa504cb14a1782751658b71409e25b82e432c0a97", "price_changes": [{"asset_id": "36586667785814641857008731622413716797407337292495614620493145114086484487337", "price": "0.34", "size": "199.99", "side": "BUY", "hash": "eedaa4c8deb7e6d63a572d5de7ec853bafb185b0", "best_bid": "0.48", "best_ask": "0.481"}, {"asset_id": "19214394437683566921750936876376421489271269944393354497977881791256347396217", "price": "0.66", "size": "199.99", "side": "SELL", "hash": "bc2240b4cd9b3b942b2ed47bf318c3bb7145369a", "best_bid": "0.519", "best_ask": "0.52"}], "timestamp": "1782707614095", "event_type": "price_change"}}
{"local_timestamp": 1782707612.8689046, "slug": "will-lionel-messi-be-the-top-goalscorer-at-the-2026-fifa-world-cup", "data": {"market": "0xd2a8caba5559bc21e14f6b2aa504cb14a1782751658b71409e25b82e432c0a97", "price_changes": [{"asset_id": "19214394437683566921750936876376421489271269944393354497977881791256347396217", "price": "0.26", "size": "0", "side": "BUY", "hash": "d677d2004e31312be186bcd3dfb3671981893198", "best_bid": "0.519", "best_ask": "0.52"}, {"asset_id": "36586667785814641857008731622413716797407337292495614620493145114086484487337", "price": "0.74", "size": "0", "side": "SELL", "hash": "dfaf638cb37e675c5ecab19adfb91b81d184de94", "best_bid": "0.48", "best_ask": "0.481"}], "timestamp": "1782707614095", "event_type": "price_change"}}
{"local_timestamp": 1782707613.645557, "slug": "will-lionel-messi-be-the-top-goalscorer-at-the-2026-fifa-world-cup", "data": {"market": "0xd2a8caba5559bc21e14f6b2aa504cb14a1782751658b71409e25b82e432c0a97", "price_changes": [{"asset_id": "36586667785814641857008731622413716797407337292495614620493145114086484487337", "price": "0.447", "size": "3029.72", "side": "BUY", "hash": "fe78d5ebeeb6f1619b27596c344cb27b1f110912", "best_bid": "0.48", "best_ask": "0.481"}, {"asset_id": "19214394437683566921750936876376421489271269944393354497977881791256347396217", "price": "0.553", "size": "3029.72", "side": "SELL", "hash": "2cb61f38aad18f646ef0fff5d5115fb30f9a08df", "best_bid": "0.519", "best_ask": "0.52"}], "timestamp": "1782707614872", "event_type": "price_change"}}
{"local_timestamp": 1782707613.7907045, "slug": "will-lionel-messi-be-the-top-goalscorer-at-the-2026-fifa-world-cup", "data": {"market": "0xd2a8caba5559bc21e14f6b2aa504cb14a1782751658b71409e25b82e432c0a97", "price_changes": [{"asset_id": "19214394437683566921750936876376421489271269944393354497977881791256347396217", "price": "0.486", "size": "2234.64", "side": "BUY", "hash": "ad38df05caeab0359a69f599fb867c0ff225d453", "best_bid": "0.519", "best_ask": "0.52"}, {"asset_id": "36586667785814641857008731622413716797407337292495614620493145114086484487337", "price": "0.514", "size": "2234.64", "side": "SELL", "hash": "14f14fac08747eca9f8fa2ddd8414c3b8b58a775", "best_bid": "0.48", "best_ask": "0.481"}], "timestamp": "1782707615019", "event_type": "price_change"}}
{"local_timestamp": 1782707614.4526193, "slug": "will-lionel-messi-be-the-top-goalscorer-at-the-2026-fifa-world-cup", "data": {"market": "0xd2a8caba5559bc21e14f6b2aa504cb14a1782751658b71409e25b82e432c0a97", "price_changes": [{"asset_id": "36586667785814641857008731622413716797407337292495614620493145114086484487337", "price": "0.34", "size": "3199.99", "side": "BUY", "hash": "cdc9b0c29cd8ebff905b49aaffb983c04ca8cae8", "best_bid": "0.48", "best_ask": "0.481"}, {"asset_id": "19214394437683566921750936876376421489271269944393354497977881791256347396217", "price": "0.66", "size": "3199.99", "side": "SELL", "hash": "b4e884c279b701816813ceaddc97d7ed47f229de", "best_bid": "0.519", "best_ask": "0.52"}], "timestamp": "1782707615681", "event_type": "price_change"}}
{"local_timestamp": 1782707614.456352, "slug": "will-lionel-messi-be-the-top-goalscorer-at-the-2026-fifa-world-cup", "data": {"market": "0xd2a8caba5559bc21e14f6b2aa504cb14a1782751658b71409e25b82e432c0a97", "price_changes": [{"asset_id": "19214394437683566921750936876376421489271269944393354497977881791256347396217", "price": "0.26", "size": "3000", "side": "BUY", "hash": "913aefa06cc40325e1e02709d98a85c23c5806d1", "best_bid": "0.519", "best_ask": "0.52"}, {"asset_id": "36586667785814641857008731622413716797407337292495614620493145114086484487337", "price": "0.74", "size": "3000", "side": "SELL", "hash": "0af9b020c782f22fbeec95782b61e45614003135", "best_bid": "0.48", "best_ask": "0.481"}], "timestamp": "1782707615685", "event_type": "price_change"}}
{"local_timestamp": 1782707615.5515082, "slug": "will-lionel-messi-be-the-top-goalscorer-at-the-2026-fifa-world-cup", "data": {"market": "0xd2a8caba5559bc21e14f6b2aa504cb14a1782751658b71409e25b82e432c0a97", "price_changes": [{"asset_id": "19214394437683566921750936876376421489271269944393354497977881791256347396217", "price": "0.521", "size": "4994.43", "side": "SELL", "hash": "0ecaeacc02370a0de5d01e5bf824e9dc4b3d0aa2", "best_bid": "0.519", "best_ask": "0.52"}, {"asset_id": "36586667785814641857008731622413716797407337292495614620493145114086484487337", "price": "0.479", "size": "4994.43", "side": "BUY", "hash": "35032f627a55e47d479048a6167a31aaaf5eae63", "best_bid": "0.48", "best_ask": "0.481"}], "timestamp": "1782707616774", "event_type": "price_change"}}
{"local_timestamp": 1782707615.8712835, "slug": "will-lionel-messi-be-the-top-goalscorer-at-the-2026-fifa-world-cup", "data": {"market": "0xd2a8caba5559bc21e14f6b2aa504cb14a1782751658b71409e25b82e432c0a97", "price_changes": [{"asset_id": "36586667785814641857008731622413716797407337292495614620493145114086484487337", "price": "0.34", "size": "199.99", "side": "BUY", "hash": "1394b770c4532b7cab69482d9490e79daec0b0e1", "best_bid": "0.48", "best_ask": "0.481"}, {"asset_id": "19214394437683566921750936876376421489271269944393354497977881791256347396217", "price": "0.66", "size": "199.99", "side": "SELL", "hash": "ecee6a70a777de2e7af1a6e18917fda7a7df8d48", "best_bid": "0.519", "best_ask": "0.52"}], "timestamp": "1782707617098", "event_type": "price_change"}}
{"local_timestamp": 1782707615.8734195, "slug": "will-lionel-messi-be-the-top-goalscorer-at-the-2026-fifa-world-cup", "data": {"market": "0xd2a8caba5559bc21e14f6b2aa504cb14a1782751658b71409e25b82e432c0a97", "price_changes": [{"asset_id": "19214394437683566921750936876376421489271269944393354497977881791256347396217", "price": "0.26", "size": "0", "side": "BUY", "hash": "4dd2a052a1d4fefe0d76c6cb49128bb9a80c31a4", "best_bid": "0.519", "best_ask": "0.52"}, {"asset_id": "36586667785814641857008731622413716797407337292495614620493145114086484487337", "price": "0.74", "size": "0", "side": "SELL", "hash": "3ad266cc50847a48271aaff3d2258b1adf4262c4", "best_bid": "0.48", "best_ask": "0.481"}], "timestamp": "1782707617098", "event_type": "price_change"}}
{"local_timestamp": 1782707617.385632, "slug": "will-lionel-messi-be-the-top-goalscorer-at-the-2026-fifa-world-cup", "data": {"market": "0xd2a8caba5559bc21e14f6b2aa504cb14a1782751658b71409e25b82e432c0a97", "price_changes": [{"asset_id": "36586667785814641857008731622413716797407337292495614620493145114086484487337", "price": "0.34", "size": "3199.99", "side": "BUY", "hash": "81b707e570c48d3d8224447891177a946f04985e", "best_bid": "0.48", "best_ask": "0.481"}, {"asset_id": "19214394437683566921750936876376421489271269944393354497977881791256347396217", "price": "0.66", "size": "3199.99", "side": "SELL", "hash": "2fcb964cbab28ced01bffc887220391e4311b0ac", "best_bid": "0.519", "best_ask": "0.52"}], "timestamp": "1782707618614", "event_type": "price_change"}}
{"local_timestamp": 1782707617.4026175, "slug": "will-lionel-messi-be-the-top-goalscorer-at-the-2026-fifa-world-cup", "data": {"market": "0xd2a8caba5559bc21e14f6b2aa504cb14a1782751658b71409e25b82e432c0a97", "price_changes": [{"asset_id": "19214394437683566921750936876376421489271269944393354497977881791256347396217", "price": "0.26", "size": "3000", "side": "BUY", "hash": "54621d4bdcc913556259ee51894a99869a537e89", "best_bid": "0.519", "best_ask": "0.52"}, {"asset_id": "36586667785814641857008731622413716797407337292495614620493145114086484487337", "price": "0.74", "size": "3000", "side": "SELL", "hash": "5740b073a09637c7057c5e98e7ed34fb7323be65", "best_bid": "0.48", "best_ask": "0.481"}], "timestamp": "1782707618626", "event_type": "price_change"}}
{"local_timestamp": 1782707617.5425205, "slug": "will-lionel-messi-be-the-top-goalscorer-at-the-2026-fifa-world-cup", "data": {"market": "0xd2a8caba5559bc21e14f6b2aa504cb14a1782751658b71409e25b82e432c0a97", "price_changes": [{"asset_id": "19214394437683566921750936876376421489271269944393354497977881791256347396217", "price": "0.521", "size": "4897.34", "side": "SELL", "hash": "955a5914f94727d9b38dfd6ebe09df4f41d9415d", "best_bid": "0.519", "best_ask": "0.52"}, {"asset_id": "36586667785814641857008731622413716797407337292495614620493145114086484487337", "price": "0.479", "size": "4897.34", "side": "BUY", "hash": "f3b6a012d89b35f5d3f49927748da6c7431655b0", "best_bid": "0.48", "best_ask": "0.481"}], "timestamp": "1782707618771", "event_type": "price_change"}}
{"local_timestamp": 1782707618.8537145, "slug": "will-lionel-messi-be-the-top-goalscorer-at-the-2026-fifa-world-cup", "data": {"market": "0xd2a8caba5559bc21e14f6b2aa504cb14a1782751658b71409e25b82e432c0a97", "price_changes": [{"asset_id": "36586667785814641857008731622413716797407337292495614620493145114086484487337", "price": "0.34", "size": "199.99", "side": "BUY", "hash": "c5c480bf412284fc33453df3148217ddabddbf35", "best_bid": "0.48", "best_ask": "0.481"}, {"asset_id": "19214394437683566921750936876376421489271269944393354497977881791256347396217", "price": "0.66", "size": "199.99", "side": "SELL", "hash": "b5c2a2d17b1e851f2fbad56fa804454eb61fd951", "best_bid": "0.519", "best_ask": "0.52"}], "timestamp": "1782707620061", "event_type": "price_change"}}
{"local_timestamp": 1782707618.8558981, "slug": "will-lionel-messi-be-the-top-goalscorer-at-the-2026-fifa-world-cup", "data": {"market": "0xd2a8caba5559bc21e14f6b2aa504cb14a1782751658b71409e25b82e432c0a97", "price_changes": [{"asset_id": "19214394437683566921750936876376421489271269944393354497977881791256347396217", "price": "0.26", "size": "0", "side": "BUY", "hash": "b6cd59411293673201e731ca4d457e0486dda13d", "best_bid": "0.519", "best_ask": "0.52"}, {"asset_id": "36586667785814641857008731622413716797407337292495614620493145114086484487337", "price": "0.74", "size": "0", "side": "SELL", "hash": "de34d698b90af67c0577a9e1abc88f95fd9f4418", "best_bid": "0.48", "best_ask": "0.481"}], "timestamp": "1782707620062", "event_type": "price_change"}}
{"local_timestamp": 1782707618.977795, "slug": "will-lionel-messi-be-the-top-goalscorer-at-the-2026-fifa-world-cup", "data": {"market": "0xd2a8caba5559bc21e14f6b2aa504cb14a1782751658b71409e25b82e432c0a97", "price_changes": [{"asset_id": "36586667785814641857008731622413716797407337292495614620493145114086484487337", "price": "0.312", "size": "2000", "side": "BUY", "hash": "3bfe9675acdf600daf4016d301a7b696db6f12f7", "best_bid": "0.48", "best_ask": "0.481"}, {"asset_id": "19214394437683566921750936876376421489271269944393354497977881791256347396217", "price": "0.688", "size": "2000", "side": "SELL", "hash": "496dfb06e31a894d2438b9a25a22024f9656b174", "best_bid": "0.519", "best_ask": "0.52"}], "timestamp": "1782707620205", "event_type": "price_change"}}
{"local_timestamp": 1782707620.367583, "slug": "will-lionel-messi-be-the-top-goalscorer-at-the-2026-fifa-world-cup", "data": {"market": "0xd2a8caba5559bc21e14f6b2aa504cb14a1782751658b71409e25b82e432c0a97", "price_changes": [{"asset_id": "19214394437683566921750936876376421489271269944393354497977881791256347396217", "price": "0.26", "size": "3000", "side": "BUY", "hash": "60403231fb708a440b0c67fa1d776b837b9b3d26", "best_bid": "0.519", "best_ask": "0.52"}, {"asset_id": "36586667785814641857008731622413716797407337292495614620493145114086484487337", "price": "0.74", "size": "3000", "side": "SELL", "hash": "d3d1059d78ca1909992d0253083bda189b5b2a2e", "best_bid": "0.48", "best_ask": "0.481"}], "timestamp": "1782707621596", "event_type": "price_change"}}
{"local_timestamp": 1782707620.383508, "slug": "will-lionel-messi-be-the-top-goalscorer-at-the-2026-fifa-world-cup", "data": {"market": "0xd2a8caba5559bc21e14f6b2aa504cb14a1782751658b71409e25b82e432c0a97", "price_changes": [{"asset_id": "36586667785814641857008731622413716797407337292495614620493145114086484487337", "price": "0.34", "size": "3199.99", "side": "BUY", "hash": "da5230f106c4746dbf0169d442a1a49f3ddf9197", "best_bid": "0.48", "best_ask": "0.481"}, {"asset_id": "19214394437683566921750936876376421489271269944393354497977881791256347396217", "price": "0.66", "size": "3199.99", "side": "SELL", "hash": "17cd7d3c0de3fd37e67a6c0ebaec84accd7b6bde", "best_bid": "0.519", "best_ask": "0.52"}], "timestamp": "1782707621612", "event_type": "price_change"}}
{"local_timestamp": 1782707620.9339218, "slug": "will-lionel-messi-be-the-top-goalscorer-at-the-2026-fifa-world-cup", "data": {"market": "0xd2a8caba5559bc21e14f6b2aa504cb14a1782751658b71409e25b82e432c0a97", "price_changes": [{"asset_id": "19214394437683566921750936876376421489271269944393354497977881791256347396217", "price": "0.521", "size": "4994.43", "side": "SELL", "hash": "415ff705dec7a43015a84d29f98058d6b3fad90d", "best_bid": "0.519", "best_ask": "0.52"}, {"asset_id": "36586667785814641857008731622413716797407337292495614620493145114086484487337", "price": "0.479", "size": "4994.43", "side": "BUY", "hash": "2706636af8e3374bd382e0bac73380be25d697da", "best_bid": "0.48", "best_ask": "0.481"}], "timestamp": "1782707622138", "event_type": "price_change"}}
{"local_timestamp": 1782707621.5539284, "slug": "will-lionel-messi-be-the-top-goalscorer-at-the-2026-fifa-world-cup", "data": {"market": "0xd2a8caba5559bc21e14f6b2aa504cb14a1782751658b71409e25b82e432c0a97", "price_changes": [{"asset_id": "36586667785814641857008731622413716797407337292495614620493145114086484487337", "price": "0.361", "size": "0", "side": "BUY", "hash": "c4fa909056022650bef725a354b7d5685dae5357", "best_bid": "0.48", "best_ask": "0.481"}, {"asset_id": "19214394437683566921750936876376421489271269944393354497977881791256347396217", "price": "0.639", "size": "0", "side": "SELL", "hash": "048e79ba08a6387dd6986bded9598586e67d44a9", "best_bid": "0.519", "best_ask": "0.52"}], "timestamp": "1782707622781", "event_type": "price_change"}}
{"local_timestamp": 1782707621.890931, "slug": "will-lionel-messi-be-the-top-goalscorer-at-the-2026-fifa-world-cup", "data": {"market": "0xd2a8caba5559bc21e14f6b2aa504cb14a1782751658b71409e25b82e432c0a97", "price_changes": [{"asset_id": "36586667785814641857008731622413716797407337292495614620493145114086484487337", "price": "0.34", "size": "199.99", "side": "BUY", "hash": "0c802f88d5ef6b1ce71e5baa012b33dd7f99f5d2", "best_bid": "0.48", "best_ask": "0.481"}, {"asset_id": "19214394437683566921750936876376421489271269944393354497977881791256347396217", "price": "0.66", "size": "199.99", "side": "SELL", "hash": "c6e9474e03076b9e30c82d59e72592fdc4ae51aa", "best_bid": "0.519", "best_ask": "0.52"}], "timestamp": "1782707623117", "event_type": "price_change"}}
{"local_timestamp": 1782707621.8930895, "slug": "will-lionel-messi-be-the-top-goalscorer-at-the-2026-fifa-world-cup", "data": {"market": "0xd2a8caba5559bc21e14f6b2aa504cb14a1782751658b71409e25b82e432c0a97", "price_changes": [{"asset_id": "19214394437683566921750936876376421489271269944393354497977881791256347396217", "price": "0.26", "size": "0", "side": "BUY", "hash": "dd659a14bd039e673c9018f8f51c0c8952ad3ded", "best_bid": "0.519", "best_ask": "0.52"}, {"asset_id": "36586667785814641857008731622413716797407337292495614620493145114086484487337", "price": "0.74", "size": "0", "side": "SELL", "hash": "976df0fc9e207e8ec420ee1fbd5dbc3df2c31adb", "best_bid": "0.48", "best_ask": "0.481"}], "timestamp": "1782707623118", "event_type": "price_change"}}
{"local_timestamp": 1782707622.6599689, "slug": "will-lionel-messi-be-the-top-goalscorer-at-the-2026-fifa-world-cup", "data": {"market": "0xd2a8caba5559bc21e14f6b2aa504cb14a1782751658b71409e25b82e432c0a97", "price_changes": [{"asset_id": "19214394437683566921750936876376421489271269944393354497977881791256347396217", "price": "0.521", "size": "4897.34", "side": "SELL", "hash": "42203513acb5d6aeb7df50f8c5119b6b80a44e98", "best_bid": "0.519", "best_ask": "0.52"}, {"asset_id": "36586667785814641857008731622413716797407337292495614620493145114086484487337", "price": "0.479", "size": "4897.34", "side": "BUY", "hash": "4745eb0432869eda4c6dd0edbeb69696401349d1", "best_bid": "0.48", "best_ask": "0.481"}], "timestamp": "1782707623888", "event_type": "price_change"}}
{"local_timestamp": 1782707623.4641879, "slug": "will-lionel-messi-be-the-top-goalscorer-at-the-2026-fifa-world-cup", "data": {"market": "0xd2a8caba5559bc21e14f6b2aa504cb14a1782751658b71409e25b82e432c0a97", "price_changes": [{"asset_id": "36586667785814641857008731622413716797407337292495614620493145114086484487337", "price": "0.34", "size": "3199.99", "side": "BUY", "hash": "4cc0b0117f1567bfa4a65a7a56997de021794da1", "best_bid": "0.48", "best_ask": "0.481"}, {"asset_id": "19214394437683566921750936876376421489271269944393354497977881791256347396217", "price": "0.66", "size": "3199.99", "side": "SELL", "hash": "346289e22f734eac11dff0d5aaf82ae9b18855f7", "best_bid": "0.519", "best_ask": "0.52"}], "timestamp": "1782707624692", "event_type": "price_change"}}
{"local_timestamp": 1782707623.4736273, "slug": "will-lionel-messi-be-the-top-goalscorer-at-the-2026-fifa-world-cup", "data": {"market": "0xd2a8caba5559bc21e14f6b2aa504cb14a1782751658b71409e25b82e432c0a97", "price_changes": [{"asset_id": "19214394437683566921750936876376421489271269944393354497977881791256347396217", "price": "0.26", "size": "3000", "side": "BUY", "hash": "940dea77dd5f3b99150706df3f4bedb06e6545a2", "best_bid": "0.519", "best_ask": "0.52"}, {"asset_id": "36586667785814641857008731622413716797407337292495614620493145114086484487337", "price": "0.74", "size": "3000", "side": "SELL", "hash": "44d26488fdac29c3ca942d8c0747405a48ce6a62", "best_bid": "0.48", "best_ask": "0.481"}], "timestamp": "1782707624698", "event_type": "price_change"}}
{"local_timestamp": 1782707623.7256587, "slug": "will-lionel-messi-be-the-top-goalscorer-at-the-2026-fifa-world-cup", "data": {"market": "0xd2a8caba5559bc21e14f6b2aa504cb14a1782751658b71409e25b82e432c0a97", "price_changes": [{"asset_id": "19214394437683566921750936876376421489271269944393354497977881791256347396217", "price": "0.518", "size": "18863.48", "side": "BUY", "hash": "70bf391a7fec7dbcfa21a426de91c47a8e34bfd2", "best_bid": "0.519", "best_ask": "0.52"}, {"asset_id": "36586667785814641857008731622413716797407337292495614620493145114086484487337", "price": "0.482", "size": "18863.48", "side": "SELL", "hash": "6323b4da7e7b0a03a7d6e9ab5b9703113aa1e74b", "best_bid": "0.48", "best_ask": "0.481"}], "timestamp": "1782707624952", "event_type": "price_change"}}
{"local_timestamp": 1782707623.7676637, "slug": "will-lionel-messi-be-the-top-goalscorer-at-the-2026-fifa-world-cup", "data": {"market": "0xd2a8caba5559bc21e14f6b2aa504cb14a1782751658b71409e25b82e432c0a97", "price_changes": [{"asset_id": "19214394437683566921750936876376421489271269944393354497977881791256347396217", "price": "0.518", "size": "19210.48", "side": "BUY", "hash": "70e5a605fdba753310c3b02f5597b7485b3a43f0", "best_bid": "0.519", "best_ask": "0.52"}, {"asset_id": "36586667785814641857008731622413716797407337292495614620493145114086484487337", "price": "0.482", "size": "19210.48", "side": "SELL", "hash": "88ce5bf7bb9d3fdb5efb4e115f984a209a8a7135", "best_bid": "0.48", "best_ask": "0.481"}], "timestamp": "1782707624994", "event_type": "price_change"}}
{"local_timestamp": 1782707623.7781146, "slug": "will-lionel-messi-be-the-top-goalscorer-at-the-2026-fifa-world-cup", "data": {"market": "0xd2a8caba5559bc21e14f6b2aa504cb14a1782751658b71409e25b82e432c0a97", "price_changes": [{"asset_id": "19214394437683566921750936876376421489271269944393354497977881791256347396217", "price": "0.5", "size": "26171", "side": "BUY", "hash": "26f5e035b9ed07b482f585191a9cdeb4f6b98b40", "best_bid": "0.519", "best_ask": "0.52"}, {"asset_id": "36586667785814641857008731622413716797407337292495614620493145114086484487337", "price": "0.5", "size": "26171", "side": "SELL", "hash": "835e0ceb84345794230b20143a68eafe87bd6232", "best_bid": "0.48", "best_ask": "0.481"}], "timestamp": "1782707625003", "event_type": "price_change"}}
{"local_timestamp": 1782707623.7786088, "slug": "will-lionel-messi-be-the-top-goalscorer-at-the-2026-fifa-world-cup", "data": {"market": "0xd2a8caba5559bc21e14f6b2aa504cb14a1782751658b71409e25b82e432c0a97", "price_changes": [{"asset_id": "36586667785814641857008731622413716797407337292495614620493145114086484487337", "price": "0.46", "size": "42525", "side": "BUY", "hash": "b13593db0a6a1ef9cd3fe00baa01cc5adb3e336a", "best_bid": "0.48", "best_ask": "0.481"}, {"asset_id": "19214394437683566921750936876376421489271269944393354497977881791256347396217", "price": "0.54", "size": "42525", "side": "SELL", "hash": "9d4c011f9d8be73eb5fe80ad88bf5bdc646c06dc", "best_bid": "0.519", "best_ask": "0.52"}], "timestamp": "1782707625004", "event_type": "price_change"}}
{"local_timestamp": 1782707623.784003, "slug": "will-lionel-messi-be-the-top-goalscorer-at-the-2026-fifa-world-cup", "data": {"market": "0xd2a8caba5559bc21e14f6b2aa504cb14a1782751658b71409e25b82e432c0a97", "price_changes": [{"asset_id": "36586667785814641857008731622413716797407337292495614620493145114086484487337", "price": "0.45", "size": "2660", "side": "BUY", "hash": "2e6293c0b19aca167ce419439f0b67acff62273a", "best_bid": "0.48", "best_ask": "0.481"}, {"asset_id": "19214394437683566921750936876376421489271269944393354497977881791256347396217", "price": "0.55", "size": "2660", "side": "SELL", "hash": "84d8c13201234ecb66f3449ea237fbcb2ea4f38d", "best_bid": "0.519", "best_ask": "0.52"}], "timestamp": "1782707625012", "event_type": "price_change"}}
{"local_timestamp": 1782707623.8150811, "slug": "will-lionel-messi-be-the-top-goalscorer-at-the-2026-fifa-world-cup", "data": {"market": "0xd2a8caba5559bc21e14f6b2aa504cb14a1782751658b71409e25b82e432c0a97", "price_changes": [{"asset_id": "36586667785814641857008731622413716797407337292495614620493145114086484487337", "price": "0.46", "size": "43408", "side": "BUY", "hash": "76e44e0fad6c2986e48a5664999cfa9ab4fbb15a", "best_bid": "0.48", "best_ask": "0.481"}, {"asset_id": "19214394437683566921750936876376421489271269944393354497977881791256347396217", "price": "0.54", "size": "43408", "side": "SELL", "hash": "64b606ba7aa128407bb6d44380762528a3eab262", "best_bid": "0.519", "best_ask": "0.52"}], "timestamp": "1782707625035", "event_type": "price_change"}}
{"local_timestamp": 1782707624.1616404, "slug": "will-lionel-messi-be-the-top-goalscorer-at-the-2026-fifa-world-cup", "data": {"market": "0xd2a8caba5559bc21e14f6b2aa504cb14a1782751658b71409e25b82e432c0a97", "price_changes": [{"asset_id": "19214394437683566921750936876376421489271269944393354497977881791256347396217", "price": "0.509", "size": "2000", "side": "BUY", "hash": "4b9e11a5447e962f5fc5c22922193cdf5a01ed9f", "best_bid": "0.519", "best_ask": "0.52"}, {"asset_id": "36586667785814641857008731622413716797407337292495614620493145114086484487337", "price": "0.491", "size": "2000", "side": "SELL", "hash": "97ef797013605e32a6ff521059602c2ccf580078", "best_bid": "0.48", "best_ask": "0.481"}], "timestamp": "1782707625389", "event_type": "price_change"}}
{"local_timestamp": 1782707624.2273464, "slug": "will-lionel-messi-be-the-top-goalscorer-at-the-2026-fifa-world-cup", "data": {"market": "0xd2a8caba5559bc21e14f6b2aa504cb14a1782751658b71409e25b82e432c0a97", "price_changes": [{"asset_id": "19214394437683566921750936876376421489271269944393354497977881791256347396217", "price": "0.509", "size": "2300", "side": "BUY", "hash": "ae210d39efaf9e126ebb4a10e809bd109d80011e", "best_bid": "0.519", "best_ask": "0.52"}, {"asset_id": "36586667785814641857008731622413716797407337292495614620493145114086484487337", "price": "0.491", "size": "2300", "side": "SELL", "hash": "7c046a1d495f4ecb057e56757e4041ec17fd4f6d", "best_bid": "0.48", "best_ask": "0.481"}], "timestamp": "1782707625456", "event_type": "price_change"}}
{"local_timestamp": 1782707624.3772256, "slug": "will-lionel-messi-be-the-top-goalscorer-at-the-2026-fifa-world-cup", "data": {"market": "0xd2a8caba5559bc21e14f6b2aa504cb14a1782751658b71409e25b82e432c0a97", "price_changes": [{"asset_id": "36586667785814641857008731622413716797407337292495614620493145114086484487337", "price": "0.474", "size": "595.35", "side": "BUY", "hash": "65006b83cc13893cebbd835b1e6e1fe9f89b1721", "best_bid": "0.48", "best_ask": "0.481"}, {"asset_id": "19214394437683566921750936876376421489271269944393354497977881791256347396217", "price": "0.526", "size": "595.35", "side": "SELL", "hash": "26c30d2afc0450e7419c8e758ac34fc15559a3a7", "best_bid": "0.519", "best_ask": "0.52"}], "timestamp": "1782707625606", "event_type": "price_change"}}
{"local_timestamp": 1782707624.3965554, "slug": "will-lionel-messi-be-the-top-goalscorer-at-the-2026-fifa-world-cup", "data": {"market": "0xd2a8caba5559bc21e14f6b2aa504cb14a1782751658b71409e25b82e432c0a97", "price_changes": [{"asset_id": "36586667785814641857008731622413716797407337292495614620493145114086484487337", "price": "0.47", "size": "19178", "side": "BUY", "hash": "2b7692aad038cdcd4d8eff4c9c7d3a5a14daf150", "best_bid": "0.48", "best_ask": "0.481"}, {"asset_id": "19214394437683566921750936876376421489271269944393354497977881791256347396217", "price": "0.53", "size": "19178", "side": "SELL", "hash": "fa43fb90b3f309d4e5d1d3e91832cd2f7f69c5e3", "best_bid": "0.519", "best_ask": "0.52"}], "timestamp": "1782707625624", "event_type": "price_change"}}
{"local_timestamp": 1782707624.4914463, "slug": "will-lionel-messi-be-the-top-goalscorer-at-the-2026-fifa-world-cup", "data": {"market": "0xd2a8caba5559bc21e14f6b2aa504cb14a1782751658b71409e25b82e432c0a97", "price_changes": [{"asset_id": "36586667785814641857008731622413716797407337292495614620493145114086484487337", "price": "0.474", "size": "895.35", "side": "BUY", "hash": "a16ccbc5882c41285b2f86713cb064fbc51caa92", "best_bid": "0.48", "best_ask": "0.481"}, {"asset_id": "19214394437683566921750936876376421489271269944393354497977881791256347396217", "price": "0.526", "size": "895.35", "side": "SELL", "hash": "3e2879c5018b49002ea21be005bda59234eed7cb", "best_bid": "0.519", "best_ask": "0.52"}], "timestamp": "1782707625683", "event_type": "price_change"}}
{"local_timestamp": 1782707624.869195, "slug": "will-lionel-messi-be-the-top-goalscorer-at-the-2026-fifa-world-cup", "data": {"market": "0xd2a8caba5559bc21e14f6b2aa504cb14a1782751658b71409e25b82e432c0a97", "price_changes": [{"asset_id": "19214394437683566921750936876376421489271269944393354497977881791256347396217", "price": "0.26", "size": "0", "side": "BUY", "hash": "5e3408c417f305d3c597f772358e9cace2973659", "best_bid": "0.519", "best_ask": "0.52"}, {"asset_id": "36586667785814641857008731622413716797407337292495614620493145114086484487337", "price": "0.74", "size": "0", "side": "SELL", "hash": "d9140c5f33ae9ef3c4fb649244d573b6f0e5973c", "best_bid": "0.48", "best_ask": "0.481"}], "timestamp": "1782707626074", "event_type": "price_change"}}
{"local_timestamp": 1782707624.869705, "slug": "will-lionel-messi-be-the-top-goalscorer-at-the-2026-fifa-world-cup", "data": {"market": "0xd2a8caba5559bc21e14f6b2aa504cb14a1782751658b71409e25b82e432c0a97", "price_changes": [{"asset_id": "36586667785814641857008731622413716797407337292495614620493145114086484487337", "price": "0.34", "size": "199.99", "side": "BUY", "hash": "a38705430c6c20b696e7675bbe1832f0b0795f98", "best_bid": "0.48", "best_ask": "0.481"}, {"asset_id": "19214394437683566921750936876376421489271269944393354497977881791256347396217", "price": "0.66", "size": "199.99", "side": "SELL", "hash": "a3037a02e61c31c46a7065262a1d08eb58f1f26d", "best_bid": "0.519", "best_ask": "0.52"}], "timestamp": "1782707626075", "event_type": "price_change"}}
{"local_timestamp": 1782707624.9808774, "slug": "will-lionel-messi-be-the-top-goalscorer-at-the-2026-fifa-world-cup", "data": {"market": "0xd2a8caba5559bc21e14f6b2aa504cb14a1782751658b71409e25b82e432c0a97", "price_changes": [{"asset_id": "19214394437683566921750936876376421489271269944393354497977881791256347396217", "price": "0.521", "size": "4994.43", "side": "SELL", "hash": "9291d21d5809c5c36cdc46957db32e9727295420", "best_bid": "0.519", "best_ask": "0.52"}, {"asset_id": "36586667785814641857008731622413716797407337292495614620493145114086484487337", "price": "0.479", "size": "4994.43", "side": "BUY", "hash": "329cecf407f8e73a7d4cb533f89bda206f096aaa", "best_bid": "0.48", "best_ask": "0.481"}], "timestamp": "1782707626209", "event_type": "price_change"}}
{"local_timestamp": 1782707625.2077317, "slug": "will-lionel-messi-be-the-top-goalscorer-at-the-2026-fifa-world-cup", "data": {"market": "0xd2a8caba5559bc21e14f6b2aa504cb14a1782751658b71409e25b82e432c0a97", "price_changes": [{"asset_id": "36586667785814641857008731622413716797407337292495614620493145114086484487337", "price": "0.312", "size": "2100", "side": "BUY", "hash": "b7e387b7e1702e757fcc52295577c2c2e39b7b5b", "best_bid": "0.48", "best_ask": "0.481"}, {"asset_id": "19214394437683566921750936876376421489271269944393354497977881791256347396217", "price": "0.688", "size": "2100", "side": "SELL", "hash": "b8fb105149029beed6263b2abda3fc45649a5149", "best_bid": "0.519", "best_ask": "0.52"}], "timestamp": "1782707626434", "event_type": "price_change"}}
{"local_timestamp": 1782707625.8606539, "slug": "will-lionel-messi-be-the-top-goalscorer-at-the-2026-fifa-world-cup", "data": {"market": "0xd2a8caba5559bc21e14f6b2aa504cb14a1782751658b71409e25b82e432c0a97", "price_changes": [{"asset_id": "19214394437683566921750936876376421489271269944393354497977881791256347396217", "price": "0.5", "size": "26378", "side": "BUY", "hash": "35b784eaf15d144750c43b78e6cb34dd91d13ad9", "best_bid": "0.519", "best_ask": "0.52"}, {"asset_id": "36586667785814641857008731622413716797407337292495614620493145114086484487337", "price": "0.5", "size": "26378", "side": "SELL", "hash": "8d8fb7d2c364cf5bbb8e63041deee6d8f38d0f2f", "best_bid": "0.48", "best_ask": "0.481"}], "timestamp": "1782707627090", "event_type": "price_change"}}
{"local_timestamp": 1782707625.867828, "slug": "will-lionel-messi-be-the-top-goalscorer-at-the-2026-fifa-world-cup", "data": {"market": "0xd2a8caba5559bc21e14f6b2aa504cb14a1782751658b71409e25b82e432c0a97", "price_changes": [{"asset_id": "19214394437683566921750936876376421489271269944393354497977881791256347396217", "price": "0.49", "size": "8451", "side": "BUY", "hash": "823c005cf6093502d35ac5eb8697745fde9fafaf", "best_bid": "0.519", "best_ask": "0.52"}, {"asset_id": "36586667785814641857008731622413716797407337292495614620493145114086484487337", "price": "0.51", "size": "8451", "side": "SELL", "hash": "adac9e7af4193fb3fb53b1af04f03fa9a6eed47e", "best_bid": "0.48", "best_ask": "0.481"}], "timestamp": "1782707627096", "event_type": "price_change"}}
{"local_timestamp": 1782707626.447881, "slug": "will-lionel-messi-be-the-top-goalscorer-at-the-2026-fifa-world-cup", "data": {"market": "0xd2a8caba5559bc21e14f6b2aa504cb14a1782751658b71409e25b82e432c0a97", "price_changes": [{"asset_id": "19214394437683566921750936876376421489271269944393354497977881791256347396217", "price": "0.26", "size": "3000", "side": "BUY", "hash": "5deee2a0b01400feddb60bc1395b022620fa4033", "best_bid": "0.519", "best_ask": "0.52"}, {"asset_id": "36586667785814641857008731622413716797407337292495614620493145114086484487337", "price": "0.74", "size": "3000", "side": "SELL", "hash": "421ae3ac673d92183761ff26e119b8a3a59b22f4", "best_bid": "0.48", "best_ask": "0.481"}], "timestamp": "1782707627676", "event_type": "price_change"}}
{"local_timestamp": 1782707626.473777, "slug": "will-lionel-messi-be-the-top-goalscorer-at-the-2026-fifa-world-cup", "data": {"market": "0xd2a8caba5559bc21e14f6b2aa504cb14a1782751658b71409e25b82e432c0a97", "price_changes": [{"asset_id": "36586667785814641857008731622413716797407337292495614620493145114086484487337", "price": "0.34", "size": "3199.99", "side": "BUY", "hash": "35d1007bcb4b1837dda21811fb6b1c38f56f8a77", "best_bid": "0.48", "best_ask": "0.481"}, {"asset_id": "19214394437683566921750936876376421489271269944393354497977881791256347396217", "price": "0.66", "size": "3199.99", "side": "SELL", "hash": "6408b9d46ce6d7af5659ac061698e1eb12f1c964", "best_bid": "0.519", "best_ask": "0.52"}], "timestamp": "1782707627685", "event_type": "price_change"}}
{"local_timestamp": 1782707627.170631, "slug": "will-lionel-messi-be-the-top-goalscorer-at-the-2026-fifa-world-cup", "data": {"market": "0xd2a8caba5559bc21e14f6b2aa504cb14a1782751658b71409e25b82e432c0a97", "price_changes": [{"asset_id": "19214394437683566921750936876376421489271269944393354497977881791256347396217", "price": "0.521", "size": "4897.34", "side": "SELL", "hash": "5a09c8e53badb1816916457273511b3e9394f236", "best_bid": "0.519", "best_ask": "0.52"}, {"asset_id": "36586667785814641857008731622413716797407337292495614620493145114086484487337", "price": "0.479", "size": "4897.34", "side": "BUY", "hash": "2bdef590f7cebdc0b9569c7e94ba279ccabaf76e", "best_bid": "0.48", "best_ask": "0.481"}], "timestamp": "1782707628398", "event_type": "price_change"}}
{"local_timestamp": 1782707627.346615, "slug": "will-lionel-messi-be-the-top-goalscorer-at-the-2026-fifa-world-cup", "data": {"market": "0xd2a8caba5559bc21e14f6b2aa504cb14a1782751658b71409e25b82e432c0a97", "price_changes": [{"asset_id": "19214394437683566921750936876376421489271269944393354497977881791256347396217", "price": "0.5", "size": "26578", "side": "BUY", "hash": "94fc459f8785319cefb6fe7cc569c625024692a0", "best_bid": "0.519", "best_ask": "0.52"}, {"asset_id": "36586667785814641857008731622413716797407337292495614620493145114086484487337", "price": "0.5", "size": "26578", "side": "SELL", "hash": "12136df92ec1150348301e860d2561a9fdd0f10a", "best_bid": "0.48", "best_ask": "0.481"}], "timestamp": "1782707628574", "event_type": "price_change"}}
{"local_timestamp": 1782707627.82959, "slug": "will-lionel-messi-be-the-top-goalscorer-at-the-2026-fifa-world-cup", "data": {"market": "0xd2a8caba5559bc21e14f6b2aa504cb14a1782751658b71409e25b82e432c0a97", "price_changes": [{"asset_id": "19214394437683566921750936876376421489271269944393354497977881791256347396217", "price": "0.26", "size": "0", "side": "BUY", "hash": "f8f959045dbd177cd86f89cb760f830564cd9dfe", "best_bid": "0.519", "best_ask": "0.52"}, {"asset_id": "36586667785814641857008731622413716797407337292495614620493145114086484487337", "price": "0.74", "size": "0", "side": "SELL", "hash": "4b6ed49803344404a361200224ee8b5cc43144c1", "best_bid": "0.48", "best_ask": "0.481"}], "timestamp": "1782707629058", "event_type": "price_change"}}
{"local_timestamp": 1782707627.8305037, "slug": "will-lionel-messi-be-the-top-goalscorer-at-the-2026-fifa-world-cup", "data": {"market": "0xd2a8caba5559bc21e14f6b2aa504cb14a1782751658b71409e25b82e432c0a97", "price_changes": [{"asset_id": "36586667785814641857008731622413716797407337292495614620493145114086484487337", "price": "0.34", "size": "199.99", "side": "BUY", "hash": "1d529c5c26da205135ddd26c3ffd5de7d486ab69", "best_bid": "0.48", "best_ask": "0.481"}, {"asset_id": "19214394437683566921750936876376421489271269944393354497977881791256347396217", "price": "0.66", "size": "199.99", "side": "SELL", "hash": "df9bc79cf24b8944ca79716efca78b373c45eac6", "best_bid": "0.519", "best_ask": "0.52"}], "timestamp": "1782707629058", "event_type": "price_change"}}
{"local_timestamp": 1782707628.0951548, "slug": "will-lionel-messi-be-the-top-goalscorer-at-the-2026-fifa-world-cup", "data": {"market": "0xd2a8caba5559bc21e14f6b2aa504cb14a1782751658b71409e25b82e432c0a97", "price_changes": [{"asset_id": "19214394437683566921750936876376421489271269944393354497977881791256347396217", "price": "0.5", "size": "26778", "side": "BUY", "hash": "80a48a86656c421383778a4e264b66dad5c6aad3", "best_bid": "0.519", "best_ask": "0.52"}, {"asset_id": "36586667785814641857008731622413716797407337292495614620493145114086484487337", "price": "0.5", "size": "26778", "side": "SELL", "hash": "02d13d7acd670ac5ae393c051179001073999792", "best_bid": "0.48", "best_ask": "0.481"}], "timestamp": "1782707629324", "event_type": "price_change"}}
{"local_timestamp": 1782707628.1182463, "slug": "will-lionel-messi-be-the-top-goalscorer-at-the-2026-fifa-world-cup", "data": {"market": "0xd2a8caba5559bc21e14f6b2aa504cb14a1782751658b71409e25b82e432c0a97", "price_changes": [{"asset_id": "36586667785814641857008731622413716797407337292495614620493145114086484487337", "price": "0.361", "size": "50", "side": "BUY", "hash": "9ea2683bf931aeda4def1d3bedf567d0f023fb0b", "best_bid": "0.48", "best_ask": "0.481"}, {"asset_id": "19214394437683566921750936876376421489271269944393354497977881791256347396217", "price": "0.639", "size": "50", "side": "SELL", "hash": "027f213c1f45710bd8a97ebefac85996dc756471", "best_bid": "0.519", "best_ask": "0.52"}], "timestamp": "1782707629348", "event_type": "price_change"}}
{"local_timestamp": 1782707629.418955, "slug": "will-lionel-messi-be-the-top-goalscorer-at-the-2026-fifa-world-cup", "data": {"market": "0xd2a8caba5559bc21e14f6b2aa504cb14a1782751658b71409e25b82e432c0a97", "price_changes": [{"asset_id": "36586667785814641857008731622413716797407337292495614620493145114086484487337", "price": "0.34", "size": "3199.99", "side": "BUY", "hash": "ddf873769179ab189ef548c5360af90079745fb8", "best_bid": "0.48", "best_ask": "0.481"}, {"asset_id": "19214394437683566921750936876376421489271269944393354497977881791256347396217", "price": "0.66", "size": "3199.99", "side": "SELL", "hash": "7b36d8abfad486e8347a6b95bec60dc51b9000df", "best_bid": "0.519", "best_ask": "0.52"}], "timestamp": "1782707630645", "event_type": "price_change"}}
{"local_timestamp": 1782707629.453319, "slug": "will-lionel-messi-be-the-top-goalscorer-at-the-2026-fifa-world-cup", "data": {"market": "0xd2a8caba5559bc21e14f6b2aa504cb14a1782751658b71409e25b82e432c0a97", "price_changes": [{"asset_id": "19214394437683566921750936876376421489271269944393354497977881791256347396217", "price": "0.26", "size": "3000", "side": "BUY", "hash": "228de70d1beae8a6684115e52e6d930423e0f8dd", "best_bid": "0.519", "best_ask": "0.52"}, {"asset_id": "36586667785814641857008731622413716797407337292495614620493145114086484487337", "price": "0.74", "size": "3000", "side": "SELL", "hash": "4a8d497a08c2fad809146212defc480ae3738432", "best_bid": "0.48", "best_ask": "0.481"}], "timestamp": "1782707630682", "event_type": "price_change"}}
{"local_timestamp": 1782707629.692117, "slug": "will-lionel-messi-be-the-top-goalscorer-at-the-2026-fifa-world-cup", "data": {"market": "0xd2a8caba5559bc21e14f6b2aa504cb14a1782751658b71409e25b82e432c0a97", "price_changes": [{"asset_id": "19214394437683566921750936876376421489271269944393354497977881791256347396217", "price": "0.521", "size": "4994.43", "side": "SELL", "hash": "f381b661e5be5b515d874b9a83f21872d0415dad", "best_bid": "0.519", "best_ask": "0.52"}, {"asset_id": "36586667785814641857008731622413716797407337292495614620493145114086484487337", "price": "0.479", "size": "4994.43", "side": "BUY", "hash": "e6b8c39dbfc62d1491330af086b930da48836d56", "best_bid": "0.48", "best_ask": "0.481"}], "timestamp": "1782707630920", "event_type": "price_change"}}
{"local_timestamp": 1782707630.3318994, "slug": "will-lionel-messi-be-the-top-goalscorer-at-the-2026-fifa-world-cup", "data": {"market": "0xd2a8caba5559bc21e14f6b2aa504cb14a1782751658b71409e25b82e432c0a97", "price_changes": [{"asset_id": "36586667785814641857008731622413716797407337292495614620493145114086484487337", "price": "0.46", "size": "43608", "side": "BUY", "hash": "9acacdd4ed3256b653e2ea896265a6f3a49df671", "best_bid": "0.48", "best_ask": "0.481"}, {"asset_id": "19214394437683566921750936876376421489271269944393354497977881791256347396217", "price": "0.54", "size": "43608", "side": "SELL", "hash": "0d04249d751e978b27581dcdd3e105d173fa0666", "best_bid": "0.519", "best_ask": "0.52"}], "timestamp": "1782707631560", "event_type": "price_change"}}
{"local_timestamp": 1782707630.8441198, "slug": "will-lionel-messi-be-the-top-goalscorer-at-the-2026-fifa-world-cup", "data": {"market": "0xd2a8caba5559bc21e14f6b2aa504cb14a1782751658b71409e25b82e432c0a97", "price_changes": [{"asset_id": "19214394437683566921750936876376421489271269944393354497977881791256347396217", "price": "0.26", "size": "0", "side": "BUY", "hash": "ef3a1ababef48b4c72dd367249a8adde9a4a2806", "best_bid": "0.519", "best_ask": "0.52"}, {"asset_id": "36586667785814641857008731622413716797407337292495614620493145114086484487337", "price": "0.74", "size": "0", "side": "SELL", "hash": "39f1329b42f12a5a1aa995024372b089228c036b", "best_bid": "0.48", "best_ask": "0.481"}], "timestamp": "1782707632061", "event_type": "price_change"}}
{"local_timestamp": 1782707630.8455527, "slug": "will-lionel-messi-be-the-top-goalscorer-at-the-2026-fifa-world-cup", "data": {"market": "0xd2a8caba5559bc21e14f6b2aa504cb14a1782751658b71409e25b82e432c0a97", "price_changes": [{"asset_id": "36586667785814641857008731622413716797407337292495614620493145114086484487337", "price": "0.34", "size": "199.99", "side": "BUY", "hash": "354fec54b3dd8ecd29e8f976fe567b148a0e9453", "best_bid": "0.48", "best_ask": "0.481"}, {"asset_id": "19214394437683566921750936876376421489271269944393354497977881791256347396217", "price": "0.66", "size": "199.99", "side": "SELL", "hash": "550e6e04a4a4b6b60896c85f81f5c4ac45913117", "best_bid": "0.519", "best_ask": "0.52"}], "timestamp": "1782707632061", "event_type": "price_change"}}
{"local_timestamp": 1782707631.562147, "slug": "will-lionel-messi-be-the-top-goalscorer-at-the-2026-fifa-world-cup", "data": {"market": "0xd2a8caba5559bc21e14f6b2aa504cb14a1782751658b71409e25b82e432c0a97", "price_changes": [{"asset_id": "36586667785814641857008731622413716797407337292495614620493145114086484487337", "price": "0.46", "size": "43808", "side": "BUY", "hash": "45abdb57cf21b1ccb759e2291ae410e96b56d266", "best_bid": "0.48", "best_ask": "0.481"}, {"asset_id": "19214394437683566921750936876376421489271269944393354497977881791256347396217", "price": "0.54", "size": "43808", "side": "SELL", "hash": "cb13a51a90dfa593b8cb76e8b05f13d459b37295", "best_bid": "0.519", "best_ask": "0.52"}], "timestamp": "1782707632791", "event_type": "price_change"}}
{"local_timestamp": 1782707631.5766082, "slug": "will-lionel-messi-be-the-top-goalscorer-at-the-2026-fifa-world-cup", "data": {"market": "0xd2a8caba5559bc21e14f6b2aa504cb14a1782751658b71409e25b82e432c0a97", "price_changes": [{"asset_id": "19214394437683566921750936876376421489271269944393354497977881791256347396217", "price": "0.5", "size": "26978", "side": "BUY", "hash": "7fbdeff40386cc1191cb191e7672b71bb27ad6d8", "best_bid": "0.519", "best_ask": "0.52"}, {"asset_id": "36586667785814641857008731622413716797407337292495614620493145114086484487337", "price": "0.5", "size": "26978", "side": "SELL", "hash": "0066ca2467c6b7ffa358f7f5998116796c9e103d", "best_bid": "0.48", "best_ask": "0.481"}], "timestamp": "1782707632806", "event_type": "price_change"}}
{"local_timestamp": 1782707632.0341988, "slug": "will-lionel-messi-be-the-top-goalscorer-at-the-2026-fifa-world-cup", "data": {"market": "0xd2a8caba5559bc21e14f6b2aa504cb14a1782751658b71409e25b82e432c0a97", "price_changes": [{"asset_id": "19214394437683566921750936876376421489271269944393354497977881791256347396217", "price": "0.5", "size": "27178", "side": "BUY", "hash": "fa93718573da4252a349dce1eeb73389e4ab66c2", "best_bid": "0.519", "best_ask": "0.52"}, {"asset_id": "36586667785814641857008731622413716797407337292495614620493145114086484487337", "price": "0.5", "size": "27178", "side": "SELL", "hash": "e78dbaf2b96ce24d9390818790125bd8b129fe59", "best_bid": "0.48", "best_ask": "0.481"}], "timestamp": "1782707633262", "event_type": "price_change"}}
{"local_timestamp": 1782707632.0430882, "slug": "will-lionel-messi-be-the-top-goalscorer-at-the-2026-fifa-world-cup", "data": {"market": "0xd2a8caba5559bc21e14f6b2aa504cb14a1782751658b71409e25b82e432c0a97", "price_changes": [{"asset_id": "36586667785814641857008731622413716797407337292495614620493145114086484487337", "price": "0.46", "size": "44008", "side": "BUY", "hash": "13a4b915e9a4c1b685127f0b071020612b8226d1", "best_bid": "0.48", "best_ask": "0.481"}, {"asset_id": "19214394437683566921750936876376421489271269944393354497977881791256347396217", "price": "0.54", "size": "44008", "side": "SELL", "hash": "aad9c10e71e8e8d51114163564ab65a398b6106d", "best_bid": "0.519", "best_ask": "0.52"}], "timestamp": "1782707633270", "event_type": "price_change"}}
{"local_timestamp": 1782707632.257182, "slug": "will-lionel-messi-be-the-top-goalscorer-at-the-2026-fifa-world-cup", "data": {"market": "0xd2a8caba5559bc21e14f6b2aa504cb14a1782751658b71409e25b82e432c0a97", "price_changes": [{"asset_id": "36586667785814641857008731622413716797407337292495614620493145114086484487337", "price": "0.232", "size": "400", "side": "BUY", "hash": "2ecd504dcb9b4f3bb602afa19691dafb9f2d0fb5", "best_bid": "0.48", "best_ask": "0.481"}, {"asset_id": "19214394437683566921750936876376421489271269944393354497977881791256347396217", "price": "0.768", "size": "400", "side": "SELL", "hash": "7f894ba605c179d0d54d9b9ff51b75ae6f7ae799", "best_bid": "0.519", "best_ask": "0.52"}], "timestamp": "1782707633486", "event_type": "price_change"}}
{"local_timestamp": 1782707632.38447, "slug": "will-lionel-messi-be-the-top-goalscorer-at-the-2026-fifa-world-cup", "data": {"market": "0xd2a8caba5559bc21e14f6b2aa504cb14a1782751658b71409e25b82e432c0a97", "price_changes": [{"asset_id": "36586667785814641857008731622413716797407337292495614620493145114086484487337", "price": "0.232", "size": "200", "side": "BUY", "hash": "b55ed9ac64f4992e54a24e6cf9aa0da70643cecf", "best_bid": "0.48", "best_ask": "0.481"}, {"asset_id": "19214394437683566921750936876376421489271269944393354497977881791256347396217", "price": "0.768", "size": "200", "side": "SELL", "hash": "f13b1721068b4a5b2a4e5f645db89bef444bcd91", "best_bid": "0.519", "best_ask": "0.52"}], "timestamp": "1782707633613", "event_type": "price_change"}}
{"local_timestamp": 1782707632.3982427, "slug": "will-lionel-messi-be-the-top-goalscorer-at-the-2026-fifa-world-cup", "data": {"market": "0xd2a8caba5559bc21e14f6b2aa504cb14a1782751658b71409e25b82e432c0a97", "price_changes": [{"asset_id": "19214394437683566921750936876376421489271269944393354497977881791256347396217", "price": "0.26", "size": "3000", "side": "BUY", "hash": "1823896a26d68cdd8265bc6f7eef0d4a8283b1e3", "best_bid": "0.519", "best_ask": "0.52"}, {"asset_id": "36586667785814641857008731622413716797407337292495614620493145114086484487337", "price": "0.74", "size": "3000", "side": "SELL", "hash": "a5aa2845b11497b5d79d3408386fa76a5ac5077b", "best_bid": "0.48", "best_ask": "0.481"}], "timestamp": "1782707633626", "event_type": "price_change"}}
{"local_timestamp": 1782707632.4008446, "slug": "will-lionel-messi-be-the-top-goalscorer-at-the-2026-fifa-world-cup", "data": {"market": "0xd2a8caba5559bc21e14f6b2aa504cb14a1782751658b71409e25b82e432c0a97", "price_changes": [{"asset_id": "36586667785814641857008731622413716797407337292495614620493145114086484487337", "price": "0.34", "size": "3199.99", "side": "BUY", "hash": "ceceb930a4488d3b40136bb0ca02bf0387af8bfa", "best_bid": "0.48", "best_ask": "0.481"}, {"asset_id": "19214394437683566921750936876376421489271269944393354497977881791256347396217", "price": "0.66", "size": "3199.99", "side": "SELL", "hash": "3727b94fa36076616ff08bb8a8189c9b9c0cee85", "best_bid": "0.519", "best_ask": "0.52"}], "timestamp": "1782707633630", "event_type": "price_change"}}
{"local_timestamp": 1782707632.9257033, "slug": "will-lionel-messi-be-the-top-goalscorer-at-the-2026-fifa-world-cup", "data": {"market": "0xd2a8caba5559bc21e14f6b2aa504cb14a1782751658b71409e25b82e432c0a97", "price_changes": [{"asset_id": "19214394437683566921750936876376421489271269944393354497977881791256347396217", "price": "0.5", "size": "27378", "side": "BUY", "hash": "4aed88ec74cd0a8627a4089532da9b0ecc997ffb", "best_bid": "0.519", "best_ask": "0.52"}, {"asset_id": "36586667785814641857008731622413716797407337292495614620493145114086484487337", "price": "0.5", "size": "27378", "side": "SELL", "hash": "03a6f7ca3b46f00417c2494ad5020d2cfd9fcc85", "best_bid": "0.48", "best_ask": "0.481"}], "timestamp": "1782707634154", "event_type": "price_change"}}
{"local_timestamp": 1782707633.097073, "slug": "will-lionel-messi-be-the-top-goalscorer-at-the-2026-fifa-world-cup", "data": {"market": "0xd2a8caba5559bc21e14f6b2aa504cb14a1782751658b71409e25b82e432c0a97", "price_changes": [{"asset_id": "19214394437683566921750936876376421489271269944393354497977881791256347396217", "price": "0.521", "size": "4897.34", "side": "SELL", "hash": "df63aff882bef4ef1c584a6d1447281cb64ee040", "best_bid": "0.519", "best_ask": "0.52"}, {"asset_id": "36586667785814641857008731622413716797407337292495614620493145114086484487337", "price": "0.479", "size": "4897.34", "side": "BUY", "hash": "13c97aaf7237679387bfb576b8a7d0fafc686abd", "best_bid": "0.48", "best_ask": "0.481"}], "timestamp": "1782707634326", "event_type": "price_change"}}
{"local_timestamp": 1782707633.8331559, "slug": "will-lionel-messi-be-the-top-goalscorer-at-the-2026-fifa-world-cup", "data": {"market": "0xd2a8caba5559bc21e14f6b2aa504cb14a1782751658b71409e25b82e432c0a97", "price_changes": [{"asset_id": "19214394437683566921750936876376421489271269944393354497977881791256347396217", "price": "0.26", "size": "0", "side": "BUY", "hash": "6025e455974bdf305cb326e4f32257d3bc50371f", "best_bid": "0.519", "best_ask": "0.52"}, {"asset_id": "36586667785814641857008731622413716797407337292495614620493145114086484487337", "price": "0.74", "size": "0", "side": "SELL", "hash": "68d5e784df4ac9a1172cc4571c5767b62b8fd13d", "best_bid": "0.48", "best_ask": "0.481"}], "timestamp": "1782707635062", "event_type": "price_change"}}
{"local_timestamp": 1782707633.8337395, "slug": "will-lionel-messi-be-the-top-goalscorer-at-the-2026-fifa-world-cup", "data": {"market": "0xd2a8caba5559bc21e14f6b2aa504cb14a1782751658b71409e25b82e432c0a97", "price_changes": [{"asset_id": "36586667785814641857008731622413716797407337292495614620493145114086484487337", "price": "0.34", "size": "199.99", "side": "BUY", "hash": "8350000f4a4907d78b73f4cc03380c3b78f32906", "best_bid": "0.48", "best_ask": "0.481"}, {"asset_id": "19214394437683566921750936876376421489271269944393354497977881791256347396217", "price": "0.66", "size": "199.99", "side": "SELL", "hash": "b7b2edfcc173a3342c7dcd21db60000ac44b33d4", "best_bid": "0.519", "best_ask": "0.52"}], "timestamp": "1782707635062", "event_type": "price_change"}}
{"local_timestamp": 1782707634.7714715, "slug": "will-lionel-messi-be-the-top-goalscorer-at-the-2026-fifa-world-cup", "data": {"market": "0xd2a8caba5559bc21e14f6b2aa504cb14a1782751658b71409e25b82e432c0a97", "price_changes": [{"asset_id": "36586667785814641857008731622413716797407337292495614620493145114086484487337", "price": "0.623", "size": "0", "side": "SELL", "hash": "c5a4dce82557fd51f34be42554425f0bb2bf2607", "best_bid": "0.48", "best_ask": "0.481"}, {"asset_id": "19214394437683566921750936876376421489271269944393354497977881791256347396217", "price": "0.377", "size": "0", "side": "BUY", "hash": "26b8240e9662888b5b2006fd00bc3a17a8d59816", "best_bid": "0.519", "best_ask": "0.52"}], "timestamp": "1782707636000", "event_type": "price_change"}}
{"local_timestamp": 1782707635.0886903, "slug": "will-lionel-messi-be-the-top-goalscorer-at-the-2026-fifa-world-cup", "data": {"market": "0xd2a8caba5559bc21e14f6b2aa504cb14a1782751658b71409e25b82e432c0a97", "price_changes": [{"asset_id": "36586667785814641857008731622413716797407337292495614620493145114086484487337", "price": "0.46", "size": "44208", "side": "BUY", "hash": "c2acd32d711d59e5fc78a0eb12fda775b18ea7d1", "best_bid": "0.48", "best_ask": "0.481"}, {"asset_id": "19214394437683566921750936876376421489271269944393354497977881791256347396217", "price": "0.54", "size": "44208", "side": "SELL", "hash": "833abcb7e551f76af688a2f7802d53faaf955b03", "best_bid": "0.519", "best_ask": "0.52"}], "timestamp": "1782707636308", "event_type": "price_change"}}
{"local_timestamp": 1782707635.3767154, "slug": "will-lionel-messi-be-the-top-goalscorer-at-the-2026-fifa-world-cup", "data": {"market": "0xd2a8caba5559bc21e14f6b2aa504cb14a1782751658b71409e25b82e432c0a97", "price_changes": [{"asset_id": "19214394437683566921750936876376421489271269944393354497977881791256347396217", "price": "0.26", "size": "3000", "side": "BUY", "hash": "44cbaa4f6867d8a718d36786033afe8679f149bc", "best_bid": "0.519", "best_ask": "0.52"}, {"asset_id": "36586667785814641857008731622413716797407337292495614620493145114086484487337", "price": "0.74", "size": "3000", "side": "SELL", "hash": "55918432fc877e798c78060cbeb273603fbc6e9d", "best_bid": "0.48", "best_ask": "0.481"}], "timestamp": "1782707636605", "event_type": "price_change"}}
{"local_timestamp": 1782707635.383519, "slug": "will-lionel-messi-be-the-top-goalscorer-at-the-2026-fifa-world-cup", "data": {"market": "0xd2a8caba5559bc21e14f6b2aa504cb14a1782751658b71409e25b82e432c0a97", "price_changes": [{"asset_id": "36586667785814641857008731622413716797407337292495614620493145114086484487337", "price": "0.34", "size": "3199.99", "side": "BUY", "hash": "b4c6b47392162d9d3a9dff69184fdc04c5bf417f", "best_bid": "0.48", "best_ask": "0.481"}, {"asset_id": "19214394437683566921750936876376421489271269944393354497977881791256347396217", "price": "0.66", "size": "3199.99", "side": "SELL", "hash": "8664a6232e3a16496957a1574c484acf43c9ffa3", "best_bid": "0.519", "best_ask": "0.52"}], "timestamp": "1782707636607", "event_type": "price_change"}}
{"local_timestamp": 1782707635.5478733, "slug": "will-lionel-messi-be-the-top-goalscorer-at-the-2026-fifa-world-cup", "data": {"market": "0xd2a8caba5559bc21e14f6b2aa504cb14a1782751658b71409e25b82e432c0a97", "price_changes": [{"asset_id": "19214394437683566921750936876376421489271269944393354497977881791256347396217", "price": "0.521", "size": "4994.43", "side": "SELL", "hash": "f0f8bcd4de23747e86cd3c49664b652a0d325794", "best_bid": "0.519", "best_ask": "0.52"}, {"asset_id": "36586667785814641857008731622413716797407337292495614620493145114086484487337", "price": "0.479", "size": "4994.43", "side": "BUY", "hash": "f718eb3723b06dae71bb7aeb58db54b319bc563d", "best_bid": "0.48", "best_ask": "0.481"}], "timestamp": "1782707636767", "event_type": "price_change"}}
{"local_timestamp": 1782707635.8510432, "slug": "will-lionel-messi-be-the-top-goalscorer-at-the-2026-fifa-world-cup", "data": {"market": "0xd2a8caba5559bc21e14f6b2aa504cb14a1782751658b71409e25b82e432c0a97", "price_changes": [{"asset_id": "36586667785814641857008731622413716797407337292495614620493145114086484487337", "price": "0.479", "size": "4780.82", "side": "BUY", "hash": "485e8860b8dc5d6fe6292ca0ce1a4763f0ba5af2", "best_bid": "0.48", "best_ask": "0.481"}, {"asset_id": "19214394437683566921750936876376421489271269944393354497977881791256347396217", "price": "0.521", "size": "4780.82", "side": "SELL", "hash": "c5aa6978173cfe9c63749892fd4ac44103672bd5", "best_bid": "0.519", "best_ask": "0.52"}], "timestamp": "1782707637005", "event_type": "price_change"}}
{"local_timestamp": 1782707635.8530862, "slug": "will-lionel-messi-be-the-top-goalscorer-at-the-2026-fifa-world-cup", "data": {"market": "0xd2a8caba5559bc21e14f6b2aa504cb14a1782751658b71409e25b82e432c0a97", "price_changes": [{"asset_id": "19214394437683566921750936876376421489271269944393354497977881791256347396217", "price": "0.518", "size": "18879.1", "side": "BUY", "hash": "5d23b04c7556db79c64bad705006ab4a5d582989", "best_bid": "0.519", "best_ask": "0.52"}, {"asset_id": "36586667785814641857008731622413716797407337292495614620493145114086484487337", "price": "0.482", "size": "18879.1", "side": "SELL", "hash": "485e8860b8dc5d6fe6292ca0ce1a4763f0ba5af2", "best_bid": "0.48", "best_ask": "0.481"}], "timestamp": "1782707637006", "event_type": "price_change"}}
{"local_timestamp": 1782707635.9310894, "slug": "will-lionel-messi-be-the-top-goalscorer-at-the-2026-fifa-world-cup", "data": {"market": "0xd2a8caba5559bc21e14f6b2aa504cb14a1782751658b71409e25b82e432c0a97", "price_changes": [{"asset_id": "19214394437683566921750936876376421489271269944393354497977881791256347396217", "price": "0.5", "size": "27578", "side": "BUY", "hash": "f25d41d7f574f106a723c8f1f97d411759a0fb4d", "best_bid": "0.519", "best_ask": "0.52"}, {"asset_id": "36586667785814641857008731622413716797407337292495614620493145114086484487337", "price": "0.5", "size": "27578", "side": "SELL", "hash": "03ccbada8a4de1c5c1b9e6803b4bd240ecc340b9", "best_bid": "0.48", "best_ask": "0.481"}], "timestamp": "1782707637160", "event_type": "price_change"}}
{"local_timestamp": 1782707636.8671498, "slug": "will-lionel-messi-be-the-top-goalscorer-at-the-2026-fifa-world-cup", "data": {"market": "0xd2a8caba5559bc21e14f6b2aa504cb14a1782751658b71409e25b82e432c0a97", "price_changes": [{"asset_id": "19214394437683566921750936876376421489271269944393354497977881791256347396217", "price": "0.26", "size": "0", "side": "BUY", "hash": "328b39546371cf8d9a311db6a1adcb83b950c85f", "best_bid": "0.519", "best_ask": "0.52"}, {"asset_id": "36586667785814641857008731622413716797407337292495614620493145114086484487337", "price": "0.74", "size": "0", "side": "SELL", "hash": "9d71c06e15c75110a0b571d03791a8753dc00b35", "best_bid": "0.48", "best_ask": "0.481"}], "timestamp": "1782707638095", "event_type": "price_change"}}
{"local_timestamp": 1782707636.8693056, "slug": "will-lionel-messi-be-the-top-goalscorer-at-the-2026-fifa-world-cup", "data": {"market": "0xd2a8caba5559bc21e14f6b2aa504cb14a1782751658b71409e25b82e432c0a97", "price_changes": [{"asset_id": "36586667785814641857008731622413716797407337292495614620493145114086484487337", "price": "0.34", "size": "199.99", "side": "BUY", "hash": "59cd0a77203530747929fd60dcced548c5a00130", "best_bid": "0.48", "best_ask": "0.481"}, {"asset_id": "19214394437683566921750936876376421489271269944393354497977881791256347396217", "price": "0.66", "size": "199.99", "side": "SELL", "hash": "584e26c539a52b2f82ad1041e69576970cebe50b", "best_bid": "0.519", "best_ask": "0.52"}], "timestamp": "1782707638095", "event_type": "price_change"}}
{"local_timestamp": 1782707637.3369105, "slug": "will-lionel-messi-be-the-top-goalscorer-at-the-2026-fifa-world-cup", "data": {"market": "0xd2a8caba5559bc21e14f6b2aa504cb14a1782751658b71409e25b82e432c0a97", "price_changes": [{"asset_id": "19214394437683566921750936876376421489271269944393354497977881791256347396217", "price": "0.521", "size": "4683.73", "side": "SELL", "hash": "608b968149ed39b13a685abe94fb0c675716efee", "best_bid": "0.519", "best_ask": "0.52"}, {"asset_id": "36586667785814641857008731622413716797407337292495614620493145114086484487337", "price": "0.479", "size": "4683.73", "side": "BUY", "hash": "177916f4c85d125c306e0fc46491d7bee87fb7cf", "best_bid": "0.48", "best_ask": "0.481"}], "timestamp": "1782707638566", "event_type": "price_change"}}
{"local_timestamp": 1782707638.4309924, "slug": "will-lionel-messi-be-the-top-goalscorer-at-the-2026-fifa-world-cup", "data": {"market": "0xd2a8caba5559bc21e14f6b2aa504cb14a1782751658b71409e25b82e432c0a97", "price_changes": [{"asset_id": "19214394437683566921750936876376421489271269944393354497977881791256347396217", "price": "0.26", "size": "3000", "side": "BUY", "hash": "720785b95533ba0da854370fc1c94ea463c527cd", "best_bid": "0.519", "best_ask": "0.52"}, {"asset_id": "36586667785814641857008731622413716797407337292495614620493145114086484487337", "price": "0.74", "size": "3000", "side": "SELL", "hash": "9c981bfe59304513b61b7b79710a01f244365285", "best_bid": "0.48", "best_ask": "0.481"}], "timestamp": "1782707639661", "event_type": "price_change"}}
{"local_timestamp": 1782707638.4345987, "slug": "will-lionel-messi-be-the-top-goalscorer-at-the-2026-fifa-world-cup", "data": {"market": "0xd2a8caba5559bc21e14f6b2aa504cb14a1782751658b71409e25b82e432c0a97", "price_changes": [{"asset_id": "36586667785814641857008731622413716797407337292495614620493145114086484487337", "price": "0.34", "size": "3199.99", "side": "BUY", "hash": "9ef70ad8bcdae0e41f1db00cfe55d0a6db768ba7", "best_bid": "0.48", "best_ask": "0.481"}, {"asset_id": "19214394437683566921750936876376421489271269944393354497977881791256347396217", "price": "0.66", "size": "3199.99", "side": "SELL", "hash": "a3f9ffe95ecf41740d4016945c064034bee237ff", "best_bid": "0.519", "best_ask": "0.52"}], "timestamp": "1782707639664", "event_type": "price_change"}}
{"local_timestamp": 1782707639.4748185, "slug": "will-lionel-messi-be-the-top-goalscorer-at-the-2026-fifa-world-cup", "data": {"market": "0xd2a8caba5559bc21e14f6b2aa504cb14a1782751658b71409e25b82e432c0a97", "price_changes": [{"asset_id": "36586667785814641857008731622413716797407337292495614620493145114086484487337", "price": "0.232", "size": "400", "side": "BUY", "hash": "ef1491c4217c045b89d7c1c3deb4b002093c0c8f", "best_bid": "0.48", "best_ask": "0.481"}, {"asset_id": "19214394437683566921750936876376421489271269944393354497977881791256347396217", "price": "0.768", "size": "400", "side": "SELL", "hash": "bca4fc7c796bc094bc327c15e5f17492b3069d9e", "best_bid": "0.519", "best_ask": "0.52"}], "timestamp": "1782707640699", "event_type": "price_change"}}
{"local_timestamp": 1782707639.7232318, "slug": "will-lionel-messi-be-the-top-goalscorer-at-the-2026-fifa-world-cup", "data": {"market": "0xd2a8caba5559bc21e14f6b2aa504cb14a1782751658b71409e25b82e432c0a97", "price_changes": [{"asset_id": "19214394437683566921750936876376421489271269944393354497977881791256347396217", "price": "0.521", "size": "4780.82", "side": "SELL", "hash": "d73a8fb2a84f23a8f9e8e75222627eb8cb5cbd7d", "best_bid": "0.519", "best_ask": "0.52"}, {"asset_id": "36586667785814641857008731622413716797407337292495614620493145114086484487337", "price": "0.479", "size": "4780.82", "side": "BUY", "hash": "6ff47ad776e0953b2113ec59a0d8de5e1038c0c8", "best_bid": "0.48", "best_ask": "0.481"}], "timestamp": "1782707640952", "event_type": "price_change"}}
{"local_timestamp": 1782707639.841962, "slug": "will-lionel-messi-be-the-top-goalscorer-at-the-2026-fifa-world-cup", "data": {"market": "0xd2a8caba5559bc21e14f6b2aa504cb14a1782751658b71409e25b82e432c0a97", "price_changes": [{"asset_id": "36586667785814641857008731622413716797407337292495614620493145114086484487337", "price": "0.34", "size": "199.99", "side": "BUY", "hash": "bdcd4e271a6135544ea58c19a2d8a940dbb1b156", "best_bid": "0.48", "best_ask": "0.481"}, {"asset_id": "19214394437683566921750936876376421489271269944393354497977881791256347396217", "price": "0.66", "size": "199.99", "side": "SELL", "hash": "5d05f70069a5ca2ee28bef57caac5b2ed348731b", "best_bid": "0.519", "best_ask": "0.52"}], "timestamp": "1782707641068", "event_type": "price_change"}}
{"local_timestamp": 1782707639.8439639, "slug": "will-lionel-messi-be-the-top-goalscorer-at-the-2026-fifa-world-cup", "data": {"market": "0xd2a8caba5559bc21e14f6b2aa504cb14a1782751658b71409e25b82e432c0a97", "price_changes": [{"asset_id": "19214394437683566921750936876376421489271269944393354497977881791256347396217", "price": "0.26", "size": "0", "side": "BUY", "hash": "476a52b390d60474684f3908ae1ce7d064ab0027", "best_bid": "0.519", "best_ask": "0.52"}, {"asset_id": "36586667785814641857008731622413716797407337292495614620493145114086484487337", "price": "0.74", "size": "0", "side": "SELL", "hash": "f72a774d1384c4988928fddeae5e52fa6422b6ad", "best_bid": "0.48", "best_ask": "0.481"}], "timestamp": "1782707641069", "event_type": "price_change"}}
{"local_timestamp": 1782707640.0588908, "slug": "will-lionel-messi-be-the-top-goalscorer-at-the-2026-fifa-world-cup", "data": {"market": "0xd2a8caba5559bc21e14f6b2aa504cb14a1782751658b71409e25b82e432c0a97", "price_changes": [{"asset_id": "36586667785814641857008731622413716797407337292495614620493145114086484487337", "price": "0.232", "size": "200", "side": "BUY", "hash": "6e4dd7b3ca1a5ec18f62337881b1d78b870e29b4", "best_bid": "0.48", "best_ask": "0.481"}, {"asset_id": "19214394437683566921750936876376421489271269944393354497977881791256347396217", "price": "0.768", "size": "200", "side": "SELL", "hash": "9ad769afd3adbd723e02d4a3ab3ba44772637fcb", "best_bid": "0.519", "best_ask": "0.52"}], "timestamp": "1782707641287", "event_type": "price_change"}}
{"local_timestamp": 1782707641.3448412, "slug": "will-lionel-messi-be-the-top-goalscorer-at-the-2026-fifa-world-cup", "data": {"market": "0xd2a8caba5559bc21e14f6b2aa504cb14a1782751658b71409e25b82e432c0a97", "price_changes": [{"asset_id": "36586667785814641857008731622413716797407337292495614620493145114086484487337", "price": "0.34", "size": "3199.99", "side": "BUY", "hash": "fd7733b4a2615baf431eb6752f106e58b722e914", "best_bid": "0.48", "best_ask": "0.481"}, {"asset_id": "19214394437683566921750936876376421489271269944393354497977881791256347396217", "price": "0.66", "size": "3199.99", "side": "SELL", "hash": "9be09cc8b34286a61a2ff6e05aeaee4020875da3", "best_bid": "0.519", "best_ask": "0.52"}], "timestamp": "1782707642574", "event_type": "price_change"}}
{"local_timestamp": 1782707641.3527815, "slug": "will-lionel-messi-be-the-top-goalscorer-at-the-2026-fifa-world-cup", "data": {"market": "0xd2a8caba5559bc21e14f6b2aa504cb14a1782751658b71409e25b82e432c0a97", "price_changes": [{"asset_id": "19214394437683566921750936876376421489271269944393354497977881791256347396217", "price": "0.26", "size": "3000", "side": "BUY", "hash": "cb4011735e7cc61619733b02ac7bab6b5211ae1d", "best_bid": "0.519", "best_ask": "0.52"}, {"asset_id": "36586667785814641857008731622413716797407337292495614620493145114086484487337", "price": "0.74", "size": "3000", "side": "SELL", "hash": "40c08b00cad353ea4a1ee47872a95fb8316ec204", "best_bid": "0.48", "best_ask": "0.481"}], "timestamp": "1782707642579", "event_type": "price_change"}}
{"local_timestamp": 1782707641.4189966, "slug": "will-lionel-messi-be-the-top-goalscorer-at-the-2026-fifa-world-cup", "data": {"market": "0xd2a8caba5559bc21e14f6b2aa504cb14a1782751658b71409e25b82e432c0a97", "price_changes": [{"asset_id": "19214394437683566921750936876376421489271269944393354497977881791256347396217", "price": "0.5", "size": "27778", "side": "BUY", "hash": "322180865889ec165b11d87b52069a96135191fb", "best_bid": "0.519", "best_ask": "0.52"}, {"asset_id": "36586667785814641857008731622413716797407337292495614620493145114086484487337", "price": "0.5", "size": "27778", "side": "SELL", "hash": "d915b8c4ecef2e47e8fbad9f3824289156b8c6f5", "best_bid": "0.48", "best_ask": "0.481"}], "timestamp": "1782707642648", "event_type": "price_change"}}
{"local_timestamp": 1782707641.4575164, "slug": "will-lionel-messi-be-the-top-goalscorer-at-the-2026-fifa-world-cup", "data": {"market": "0xd2a8caba5559bc21e14f6b2aa504cb14a1782751658b71409e25b82e432c0a97", "price_changes": [{"asset_id": "36586667785814641857008731622413716797407337292495614620493145114086484487337", "price": "0.46", "size": "44408", "side": "BUY", "hash": "781ffb19a5dc03f24fb4e25083c8c89298d53f29", "best_bid": "0.48", "best_ask": "0.481"}, {"asset_id": "19214394437683566921750936876376421489271269944393354497977881791256347396217", "price": "0.54", "size": "44408", "side": "SELL", "hash": "88d92957290f7d34c23694ae754efb4e96a6ba80", "best_bid": "0.519", "best_ask": "0.52"}], "timestamp": "1782707642686", "event_type": "price_change"}}
{"local_timestamp": 1782707642.1698258, "slug": "will-lionel-messi-be-the-top-goalscorer-at-the-2026-fifa-world-cup", "data": {"market": "0xd2a8caba5559bc21e14f6b2aa504cb14a1782751658b71409e25b82e432c0a97", "price_changes": [{"asset_id": "19214394437683566921750936876376421489271269944393354497977881791256347396217", "price": "0.521", "size": "4683.73", "side": "SELL", "hash": "a8c6a902b58b4834aaec29d91cd50adad0d0cd3b", "best_bid": "0.519", "best_ask": "0.52"}, {"asset_id": "36586667785814641857008731622413716797407337292495614620493145114086484487337", "price": "0.479", "size": "4683.73", "side": "BUY", "hash": "469a9714ed37d8dbc7bd771985701a0253058479", "best_bid": "0.48", "best_ask": "0.481"}], "timestamp": "1782707643397", "event_type": "price_change"}}
{"local_timestamp": 1782707642.7768917, "slug": "will-lionel-messi-be-the-top-goalscorer-at-the-2026-fifa-world-cup", "data": {"market": "0xd2a8caba5559bc21e14f6b2aa504cb14a1782751658b71409e25b82e432c0a97", "price_changes": [{"asset_id": "19214394437683566921750936876376421489271269944393354497977881791256347396217", "price": "0.002", "size": "3250", "side": "BUY", "hash": "ac087ee6572ec2b9f68cddd66c8d5b5e8f55d9dd", "best_bid": "0.519", "best_ask": "0.52"}, {"asset_id": "36586667785814641857008731622413716797407337292495614620493145114086484487337", "price": "0.998", "size": "3250", "side": "SELL", "hash": "e61e98d2a47216052cf8d97c722c3244a272a75f", "best_bid": "0.48", "best_ask": "0.481"}], "timestamp": "1782707644004", "event_type": "price_change"}}
{"local_timestamp": 1782707642.7799165, "slug": "will-lionel-messi-be-the-top-goalscorer-at-the-2026-fifa-world-cup", "data": {"market": "0xd2a8caba5559bc21e14f6b2aa504cb14a1782751658b71409e25b82e432c0a97", "price_changes": [{"asset_id": "36586667785814641857008731622413716797407337292495614620493145114086484487337", "price": "0.002", "size": "1007.31", "side": "BUY", "hash": "1807d8f824cc05faeec7c13e058152278419caa5", "best_bid": "0.48", "best_ask": "0.481"}, {"asset_id": "19214394437683566921750936876376421489271269944393354497977881791256347396217", "price": "0.998", "size": "1007.31", "side": "SELL", "hash": "d48cd70aed28eaadc2d5a6e499e04fb9e83e9cc3", "best_bid": "0.519", "best_ask": "0.52"}], "timestamp": "1782707644005", "event_type": "price_change"}}
{"local_timestamp": 1782707642.8702717, "slug": "will-lionel-messi-be-the-top-goalscorer-at-the-2026-fifa-world-cup", "data": {"market": "0xd2a8caba5559bc21e14f6b2aa504cb14a1782751658b71409e25b82e432c0a97", "price_changes": [{"asset_id": "36586667785814641857008731622413716797407337292495614620493145114086484487337", "price": "0.34", "size": "199.99", "side": "BUY", "hash": "f08c458a12d45327bcdb4eef5c21c95e23d5fdef", "best_bid": "0.48", "best_ask": "0.481"}, {"asset_id": "19214394437683566921750936876376421489271269944393354497977881791256347396217", "price": "0.66", "size": "199.99", "side": "SELL", "hash": "376e0a5acc3430ff2379bce4466f19a0dfc8a93a", "best_bid": "0.519", "best_ask": "0.52"}], "timestamp": "1782707644097", "event_type": "price_change"}}
{"local_timestamp": 1782707642.8724043, "slug": "will-lionel-messi-be-the-top-goalscorer-at-the-2026-fifa-world-cup", "data": {"market": "0xd2a8caba5559bc21e14f6b2aa504cb14a1782751658b71409e25b82e432c0a97", "price_changes": [{"asset_id": "19214394437683566921750936876376421489271269944393354497977881791256347396217", "price": "0.26", "size": "0", "side": "BUY", "hash": "42070c9cb4e63d00f9c258a93ca37460756053e0", "best_bid": "0.519", "best_ask": "0.52"}, {"asset_id": "36586667785814641857008731622413716797407337292495614620493145114086484487337", "price": "0.74", "size": "0", "side": "SELL", "hash": "75c2cba843ebbc0d52dab93433d58ada6b2f2613", "best_bid": "0.48", "best_ask": "0.481"}], "timestamp": "1782707644098", "event_type": "price_change"}}
{"local_timestamp": 1782707643.1099105, "slug": "will-lionel-messi-be-the-top-goalscorer-at-the-2026-fifa-world-cup", "data": {"market": "0xd2a8caba5559bc21e14f6b2aa504cb14a1782751658b71409e25b82e432c0a97", "price_changes": [{"asset_id": "36586667785814641857008731622413716797407337292495614620493145114086484487337", "price": "0.46", "size": "44608", "side": "BUY", "hash": "c6b70a838579841e4dd8a9eccbeb4711d5be7317", "best_bid": "0.48", "best_ask": "0.481"}, {"asset_id": "19214394437683566921750936876376421489271269944393354497977881791256347396217", "price": "0.54", "size": "44608", "side": "SELL", "hash": "b2c166163376ced59fd5f9c457db57e860ee5cf4", "best_bid": "0.519", "best_ask": "0.52"}], "timestamp": "1782707644338", "event_type": "price_change"}}
{"local_timestamp": 1782707643.1306875, "slug": "will-lionel-messi-be-the-top-goalscorer-at-the-2026-fifa-world-cup", "data": {"market": "0xd2a8caba5559bc21e14f6b2aa504cb14a1782751658b71409e25b82e432c0a97", "price_changes": [{"asset_id": "19214394437683566921750936876376421489271269944393354497977881791256347396217", "price": "0.5", "size": "27978", "side": "BUY", "hash": "ebe0a3062cdd1895b5a5b89548367954dc784df7", "best_bid": "0.519", "best_ask": "0.52"}, {"asset_id": "36586667785814641857008731622413716797407337292495614620493145114086484487337", "price": "0.5", "size": "27978", "side": "SELL", "hash": "bafb77bda5cb7e1cc01925ba7620a50e27bfb509", "best_bid": "0.48", "best_ask": "0.481"}], "timestamp": "1782707644345", "event_type": "price_change"}}
{"local_timestamp": 1782707644.3775127, "slug": "will-lionel-messi-be-the-top-goalscorer-at-the-2026-fifa-world-cup", "data": {"market": "0xd2a8caba5559bc21e14f6b2aa504cb14a1782751658b71409e25b82e432c0a97", "price_changes": [{"asset_id": "19214394437683566921750936876376421489271269944393354497977881791256347396217", "price": "0.26", "size": "3000", "side": "BUY", "hash": "fe43994cebb31e7c825fd34cdd36f50a9f474111", "best_bid": "0.519", "best_ask": "0.52"}, {"asset_id": "36586667785814641857008731622413716797407337292495614620493145114086484487337", "price": "0.74", "size": "3000", "side": "SELL", "hash": "84ed27f6650779e3828dc72e9c3b003ad3b9866d", "best_bid": "0.48", "best_ask": "0.481"}], "timestamp": "1782707645607", "event_type": "price_change"}}
{"local_timestamp": 1782707644.381783, "slug": "will-lionel-messi-be-the-top-goalscorer-at-the-2026-fifa-world-cup", "data": {"market": "0xd2a8caba5559bc21e14f6b2aa504cb14a1782751658b71409e25b82e432c0a97", "price_changes": [{"asset_id": "36586667785814641857008731622413716797407337292495614620493145114086484487337", "price": "0.34", "size": "3199.99", "side": "BUY", "hash": "0e7eb0298e58281f468bd675bac29972d015e20f", "best_bid": "0.48", "best_ask": "0.481"}, {"asset_id": "19214394437683566921750936876376421489271269944393354497977881791256347396217", "price": "0.66", "size": "3199.99", "side": "SELL", "hash": "4a375a13958afb2bd2c680bd93bb84a66f31363c", "best_bid": "0.519", "best_ask": "0.52"}], "timestamp": "1782707645611", "event_type": "price_change"}}
{"local_timestamp": 1782707645.6418738, "slug": "will-lionel-messi-be-the-top-goalscorer-at-the-2026-fifa-world-cup", "data": {"market": "0xd2a8caba5559bc21e14f6b2aa504cb14a1782751658b71409e25b82e432c0a97", "price_changes": [{"asset_id": "19214394437683566921750936876376421489271269944393354497977881791256347396217", "price": "0.521", "size": "4780.82", "side": "SELL", "hash": "d5fbf8f515b4c7f1a4afb0d23b8dba397b119ca6", "best_bid": "0.519", "best_ask": "0.52"}, {"asset_id": "36586667785814641857008731622413716797407337292495614620493145114086484487337", "price": "0.479", "size": "4780.82", "side": "BUY", "hash": "e72022b944c61be4c0f56a259e6d5258fc471b88", "best_bid": "0.48", "best_ask": "0.481"}], "timestamp": "1782707646869", "event_type": "price_change"}}
{"local_timestamp": 1782707645.8405013, "slug": "will-lionel-messi-be-the-top-goalscorer-at-the-2026-fifa-world-cup", "data": {"market": "0xd2a8caba5559bc21e14f6b2aa504cb14a1782751658b71409e25b82e432c0a97", "price_changes": [{"asset_id": "19214394437683566921750936876376421489271269944393354497977881791256347396217", "price": "0.26", "size": "0", "side": "BUY", "hash": "dedeeef03193e3ddf2ce8d21f5f07d5be7e95781", "best_bid": "0.519", "best_ask": "0.52"}, {"asset_id": "36586667785814641857008731622413716797407337292495614620493145114086484487337", "price": "0.74", "size": "0", "side": "SELL", "hash": "80435d4537b3cd953ce2c36812a295ed0a1794ce", "best_bid": "0.48", "best_ask": "0.481"}], "timestamp": "1782707647068", "event_type": "price_change"}}
{"local_timestamp": 1782707645.842782, "slug": "will-lionel-messi-be-the-top-goalscorer-at-the-2026-fifa-world-cup", "data": {"market": "0xd2a8caba5559bc21e14f6b2aa504cb14a1782751658b71409e25b82e432c0a97", "price_changes": [{"asset_id": "36586667785814641857008731622413716797407337292495614620493145114086484487337", "price": "0.34", "size": "199.99", "side": "BUY", "hash": "41bfbb0e38e59e51d94693a76d69514053cacfd4", "best_bid": "0.48", "best_ask": "0.481"}, {"asset_id": "19214394437683566921750936876376421489271269944393354497977881791256347396217", "price": "0.66", "size": "199.99", "side": "SELL", "hash": "46222a5bf9ae838b18faf126fc44a443373dc5d0", "best_bid": "0.519", "best_ask": "0.52"}], "timestamp": "1782707647068", "event_type": "price_change"}}
{"local_timestamp": 1782707647.303339, "slug": "will-lionel-messi-be-the-top-goalscorer-at-the-2026-fifa-world-cup", "data": {"market": "0xd2a8caba5559bc21e14f6b2aa504cb14a1782751658b71409e25b82e432c0a97", "price_changes": [{"asset_id": "19214394437683566921750936876376421489271269944393354497977881791256347396217", "price": "0.521", "size": "4683.73", "side": "SELL", "hash": "1b343b4cb49c69fb621eb4f3986273c642fcfd72", "best_bid": "0.519", "best_ask": "0.52"}, {"asset_id": "36586667785814641857008731622413716797407337292495614620493145114086484487337", "price": "0.479", "size": "4683.73", "side": "BUY", "hash": "11da40008694284a9682a5d8741e837c8c4e0be4", "best_bid": "0.48", "best_ask": "0.481"}], "timestamp": "1782707648532", "event_type": "price_change"}}
{"local_timestamp": 1782707647.3970163, "slug": "will-lionel-messi-be-the-top-goalscorer-at-the-2026-fifa-world-cup", "data": {"market": "0xd2a8caba5559bc21e14f6b2aa504cb14a1782751658b71409e25b82e432c0a97", "price_changes": [{"asset_id": "19214394437683566921750936876376421489271269944393354497977881791256347396217", "price": "0.26", "size": "3000", "side": "BUY", "hash": "09b0c90aaf3adf4e5f9c807ebeb92c8a8f6be064", "best_bid": "0.519", "best_ask": "0.52"}, {"asset_id": "36586667785814641857008731622413716797407337292495614620493145114086484487337", "price": "0.74", "size": "3000", "side": "SELL", "hash": "1bab1eab9caa09eebc828bb60caa2d049dcca91b", "best_bid": "0.48", "best_ask": "0.481"}], "timestamp": "1782707648625", "event_type": "price_change"}}
{"local_timestamp": 1782707647.49662, "slug": "will-lionel-messi-be-the-top-goalscorer-at-the-2026-fifa-world-cup", "data": {"market": "0xd2a8caba5559bc21e14f6b2aa504cb14a1782751658b71409e25b82e432c0a97", "price_changes": [{"asset_id": "19214394437683566921750936876376421489271269944393354497977881791256347396217", "price": "0.5", "size": "28178", "side": "BUY", "hash": "101e56a28fda7edc5905a330e9e690c01d93a760", "best_bid": "0.519", "best_ask": "0.52"}, {"asset_id": "36586667785814641857008731622413716797407337292495614620493145114086484487337", "price": "0.5", "size": "28178", "side": "SELL", "hash": "cb842f6606afcf39f3023120d1fc305144415d22", "best_bid": "0.48", "best_ask": "0.481"}], "timestamp": "1782707648724", "event_type": "price_change"}}
{"local_timestamp": 1782707647.5105817, "slug": "will-lionel-messi-be-the-top-goalscorer-at-the-2026-fifa-world-cup", "data": {"market": "0xd2a8caba5559bc21e14f6b2aa504cb14a1782751658b71409e25b82e432c0a97", "price_changes": [{"asset_id": "36586667785814641857008731622413716797407337292495614620493145114086484487337", "price": "0.34", "size": "3199.99", "side": "BUY", "hash": "9c3d9397d8d114bb0057a59b1a5543c54a70c10b", "best_bid": "0.48", "best_ask": "0.481"}, {"asset_id": "19214394437683566921750936876376421489271269944393354497977881791256347396217", "price": "0.66", "size": "3199.99", "side": "SELL", "hash": "6ed700704ed391dcd22dbf7f84bb4a5b3ec2ebc5", "best_bid": "0.519", "best_ask": "0.52"}], "timestamp": "1782707648739", "event_type": "price_change"}}
{"local_timestamp": 1782707648.870813, "slug": "will-lionel-messi-be-the-top-goalscorer-at-the-2026-fifa-world-cup", "data": {"market": "0xd2a8caba5559bc21e14f6b2aa504cb14a1782751658b71409e25b82e432c0a97", "price_changes": [{"asset_id": "19214394437683566921750936876376421489271269944393354497977881791256347396217", "price": "0.26", "size": "0", "side": "BUY", "hash": "a291ebcaddf647562242a0f42eecadefbb1f6420", "best_bid": "0.519", "best_ask": "0.52"}, {"asset_id": "36586667785814641857008731622413716797407337292495614620493145114086484487337", "price": "0.74", "size": "0", "side": "SELL", "hash": "aaf5765dafe825696393d25cf640f302871fa854", "best_bid": "0.48", "best_ask": "0.481"}], "timestamp": "1782707650098", "event_type": "price_change"}}
{"local_timestamp": 1782707648.873153, "slug": "will-lionel-messi-be-the-top-goalscorer-at-the-2026-fifa-world-cup", "data": {"market": "0xd2a8caba5559bc21e14f6b2aa504cb14a1782751658b71409e25b82e432c0a97", "price_changes": [{"asset_id": "36586667785814641857008731622413716797407337292495614620493145114086484487337", "price": "0.34", "size": "199.99", "side": "BUY", "hash": "e66b51bf295d4d9a18d25c2d78a0586598fca201", "best_bid": "0.48", "best_ask": "0.481"}, {"asset_id": "19214394437683566921750936876376421489271269944393354497977881791256347396217", "price": "0.66", "size": "199.99", "side": "SELL", "hash": "c51c8a9ff4d05a0d1aba81e5b926536c449f3dd9", "best_bid": "0.519", "best_ask": "0.52"}], "timestamp": "1782707650098", "event_type": "price_change"}}
{"local_timestamp": 1782707649.7397804, "slug": "will-lionel-messi-be-the-top-goalscorer-at-the-2026-fifa-world-cup", "data": {"market": "0xd2a8caba5559bc21e14f6b2aa504cb14a1782751658b71409e25b82e432c0a97", "price_changes": [{"asset_id": "19214394437683566921750936876376421489271269944393354497977881791256347396217", "price": "0.521", "size": "4780.82", "side": "SELL", "hash": "0afabfd588b97eae413f9871a84d2ff4f236c72d", "best_bid": "0.519", "best_ask": "0.52"}, {"asset_id": "36586667785814641857008731622413716797407337292495614620493145114086484487337", "price": "0.479", "size": "4780.82", "side": "BUY", "hash": "8c52e670c922d3c302d4fd5a6de6df5a8c5ba419", "best_bid": "0.48", "best_ask": "0.481"}], "timestamp": "1782707650966", "event_type": "price_change"}}
{"local_timestamp": 1782707650.3730626, "slug": "will-lionel-messi-be-the-top-goalscorer-at-the-2026-fifa-world-cup", "data": {"market": "0xd2a8caba5559bc21e14f6b2aa504cb14a1782751658b71409e25b82e432c0a97", "price_changes": [{"asset_id": "36586667785814641857008731622413716797407337292495614620493145114086484487337", "price": "0.232", "size": "0", "side": "BUY", "hash": "c65f086f6f16a120fccc99a78d81e329f126df21", "best_bid": "0.48", "best_ask": "0.481"}, {"asset_id": "19214394437683566921750936876376421489271269944393354497977881791256347396217", "price": "0.768", "size": "0", "side": "SELL", "hash": "b3ec9adbdc56c10d5b8a6990c552641b59d89a00", "best_bid": "0.519", "best_ask": "0.52"}], "timestamp": "1782707651601", "event_type": "price_change"}}
{"local_timestamp": 1782707650.4017203, "slug": "will-lionel-messi-be-the-top-goalscorer-at-the-2026-fifa-world-cup", "data": {"market": "0xd2a8caba5559bc21e14f6b2aa504cb14a1782751658b71409e25b82e432c0a97", "price_changes": [{"asset_id": "36586667785814641857008731622413716797407337292495614620493145114086484487337", "price": "0.34", "size": "3199.99", "side": "BUY", "hash": "360f6a4157de233a6d5653b3d21913a0d6b7d91e", "best_bid": "0.48", "best_ask": "0.481"}, {"asset_id": "19214394437683566921750936876376421489271269944393354497977881791256347396217", "price": "0.66", "size": "3199.99", "side": "SELL", "hash": "534df50aafcbb0f4edb829668855c8397e845991", "best_bid": "0.519", "best_ask": "0.52"}], "timestamp": "1782707651630", "event_type": "price_change"}}
{"local_timestamp": 1782707650.4049504, "slug": "will-lionel-messi-be-the-top-goalscorer-at-the-2026-fifa-world-cup", "data": {"market": "0xd2a8caba5559bc21e14f6b2aa504cb14a1782751658b71409e25b82e432c0a97", "price_changes": [{"asset_id": "19214394437683566921750936876376421489271269944393354497977881791256347396217", "price": "0.26", "size": "3000", "side": "BUY", "hash": "20e50f0ca23fb4265ba8e2c58314f6dc0ba20998", "best_bid": "0.519", "best_ask": "0.52"}, {"asset_id": "36586667785814641857008731622413716797407337292495614620493145114086484487337", "price": "0.74", "size": "3000", "side": "SELL", "hash": "49085bbd26237111a19c29f8d60854b98dfb49f1", "best_bid": "0.48", "best_ask": "0.481"}], "timestamp": "1782707651634", "event_type": "price_change"}}
{"local_timestamp": 1782707651.8505197, "slug": "will-lionel-messi-be-the-top-goalscorer-at-the-2026-fifa-world-cup", "data": {"market": "0xd2a8caba5559bc21e14f6b2aa504cb14a1782751658b71409e25b82e432c0a97", "price_changes": [{"asset_id": "36586667785814641857008731622413716797407337292495614620493145114086484487337", "price": "0.34", "size": "199.99", "side": "BUY", "hash": "a1f778f1ab640f0742fb920835bd3d24d485bc30", "best_bid": "0.48", "best_ask": "0.481"}, {"asset_id": "19214394437683566921750936876376421489271269944393354497977881791256347396217", "price": "0.66", "size": "199.99", "side": "SELL", "hash": "11b33f467a3e05c38bd1eccab2b9835e861d3617", "best_bid": "0.519", "best_ask": "0.52"}], "timestamp": "1782707653076", "event_type": "price_change"}}
{"local_timestamp": 1782707651.8514411, "slug": "will-lionel-messi-be-the-top-goalscorer-at-the-2026-fifa-world-cup", "data": {"market": "0xd2a8caba5559bc21e14f6b2aa504cb14a1782751658b71409e25b82e432c0a97", "price_changes": [{"asset_id": "19214394437683566921750936876376421489271269944393354497977881791256347396217", "price": "0.26", "size": "0", "side": "BUY", "hash": "6422eb745ac4dc014d2a67766772612201eaf0f9", "best_bid": "0.519", "best_ask": "0.52"}, {"asset_id": "36586667785814641857008731622413716797407337292495614620493145114086484487337", "price": "0.74", "size": "0", "side": "SELL", "hash": "cde8ec55761d7122949c201951c995566989e69e", "best_bid": "0.48", "best_ask": "0.481"}], "timestamp": "1782707653076", "event_type": "price_change"}}
{"local_timestamp": 1782707652.1804256, "slug": "will-lionel-messi-be-the-top-goalscorer-at-the-2026-fifa-world-cup", "data": {"market": "0xd2a8caba5559bc21e14f6b2aa504cb14a1782751658b71409e25b82e432c0a97", "price_changes": [{"asset_id": "19214394437683566921750936876376421489271269944393354497977881791256347396217", "price": "0.521", "size": "4683.73", "side": "SELL", "hash": "9bbb18718dd631d37bf5327501f83d5ca311d7e4", "best_bid": "0.519", "best_ask": "0.52"}, {"asset_id": "36586667785814641857008731622413716797407337292495614620493145114086484487337", "price": "0.479", "size": "4683.73", "side": "BUY", "hash": "d09eb5da0ec74b472deb36a96073dfda765f35d8", "best_bid": "0.48", "best_ask": "0.481"}], "timestamp": "1782707653407", "event_type": "price_change"}}
{"local_timestamp": 1782707652.7563505, "slug": "will-lionel-messi-be-the-top-goalscorer-at-the-2026-fifa-world-cup", "data": {"market": "0xd2a8caba5559bc21e14f6b2aa504cb14a1782751658b71409e25b82e432c0a97", "price_changes": [{"asset_id": "36586667785814641857008731622413716797407337292495614620493145114086484487337", "price": "0.454", "size": "1500", "side": "BUY", "hash": "0fca5dba56b8338f24fd8f9e2d5a858d2d66bb2c", "best_bid": "0.48", "best_ask": "0.481"}, {"asset_id": "19214394437683566921750936876376421489271269944393354497977881791256347396217", "price": "0.546", "size": "1500", "side": "SELL", "hash": "1526d1e2dcac09157081a7ff28e8718fda7dceb3", "best_bid": "0.519", "best_ask": "0.52"}], "timestamp": "1782707653985", "event_type": "price_change"}}
{"local_timestamp": 1782707652.7588675, "slug": "will-lionel-messi-be-the-top-goalscorer-at-the-2026-fifa-world-cup", "data": {"market": "0xd2a8caba5559bc21e14f6b2aa504cb14a1782751658b71409e25b82e432c0a97", "price_changes": [{"asset_id": "19214394437683566921750936876376421489271269944393354497977881791256347396217", "price": "0.478", "size": "0", "side": "BUY", "hash": "d2f10b43210c9abda573366190241e15ad96721a", "best_bid": "0.519", "best_ask": "0.52"}, {"asset_id": "36586667785814641857008731622413716797407337292495614620493145114086484487337", "price": "0.522", "size": "0", "side": "SELL", "hash": "32ff48fb32c8512aa7a3a2b66e1ebfe134151112", "best_bid": "0.48", "best_ask": "0.481"}], "timestamp": "1782707653986", "event_type": "price_change"}}
{"local_timestamp": 1782707653.346196, "slug": "will-lionel-messi-be-the-top-goalscorer-at-the-2026-fifa-world-cup", "data": {"market": "0xd2a8caba5559bc21e14f6b2aa504cb14a1782751658b71409e25b82e432c0a97", "price_changes": [{"asset_id": "36586667785814641857008731622413716797407337292495614620493145114086484487337", "price": "0.34", "size": "3199.99", "side": "BUY", "hash": "00a0a49062495da85e38d62e4745f2f427ada1af", "best_bid": "0.48", "best_ask": "0.481"}, {"asset_id": "19214394437683566921750936876376421489271269944393354497977881791256347396217", "price": "0.66", "size": "3199.99", "side": "SELL", "hash": "7a41ade48eaa5c05f5371b875c412c5b91d84e85", "best_bid": "0.519", "best_ask": "0.52"}], "timestamp": "1782707654574", "event_type": "price_change"}}
{"local_timestamp": 1782707653.3498223, "slug": "will-lionel-messi-be-the-top-goalscorer-at-the-2026-fifa-world-cup", "data": {"market": "0xd2a8caba5559bc21e14f6b2aa504cb14a1782751658b71409e25b82e432c0a97", "price_changes": [{"asset_id": "19214394437683566921750936876376421489271269944393354497977881791256347396217", "price": "0.26", "size": "3000", "side": "BUY", "hash": "8520c04c67c60878e6a9d0dd1c447fe530453070", "best_bid": "0.519", "best_ask": "0.52"}, {"asset_id": "36586667785814641857008731622413716797407337292495614620493145114086484487337", "price": "0.74", "size": "3000", "side": "SELL", "hash": "71245e229f4b6db0e7969f7a2672e11ae81c2e66", "best_bid": "0.48", "best_ask": "0.481"}], "timestamp": "1782707654578", "event_type": "price_change"}}
{"local_timestamp": 1782707654.8363574, "slug": "will-lionel-messi-be-the-top-goalscorer-at-the-2026-fifa-world-cup", "data": {"market": "0xd2a8caba5559bc21e14f6b2aa504cb14a1782751658b71409e25b82e432c0a97", "price_changes": [{"asset_id": "19214394437683566921750936876376421489271269944393354497977881791256347396217", "price": "0.521", "size": "4780.82", "side": "SELL", "hash": "0d31f6ee55622f78467bff14784680cd33f75e12", "best_bid": "0.519", "best_ask": "0.52"}, {"asset_id": "36586667785814641857008731622413716797407337292495614620493145114086484487337", "price": "0.479", "size": "4780.82", "side": "BUY", "hash": "13542081da0117d7fcbd46bbe5cd63e2a2c61d2f", "best_bid": "0.48", "best_ask": "0.481"}], "timestamp": "1782707656066", "event_type": "price_change"}}
{"local_timestamp": 1782707654.8828783, "slug": "will-lionel-messi-be-the-top-goalscorer-at-the-2026-fifa-world-cup", "data": {"market": "0xd2a8caba5559bc21e14f6b2aa504cb14a1782751658b71409e25b82e432c0a97", "price_changes": [{"asset_id": "36586667785814641857008731622413716797407337292495614620493145114086484487337", "price": "0.34", "size": "199.99", "side": "BUY", "hash": "e62fdcc567cbf540cb1d3c92d68dc3c55987dac6", "best_bid": "0.48", "best_ask": "0.481"}, {"asset_id": "19214394437683566921750936876376421489271269944393354497977881791256347396217", "price": "0.66", "size": "199.99", "side": "SELL", "hash": "2c4268859c81b08dbb7f852fd76cd17114add0a8", "best_bid": "0.519", "best_ask": "0.52"}], "timestamp": "1782707656112", "event_type": "price_change"}}
{"local_timestamp": 1782707654.88345, "slug": "will-lionel-messi-be-the-top-goalscorer-at-the-2026-fifa-world-cup", "data": {"market": "0xd2a8caba5559bc21e14f6b2aa504cb14a1782751658b71409e25b82e432c0a97", "price_changes": [{"asset_id": "19214394437683566921750936876376421489271269944393354497977881791256347396217", "price": "0.26", "size": "0", "side": "BUY", "hash": "a8db6d2bc5031781689b0380fac346e482a89535", "best_bid": "0.519", "best_ask": "0.52"}, {"asset_id": "36586667785814641857008731622413716797407337292495614620493145114086484487337", "price": "0.74", "size": "0", "side": "SELL", "hash": "d112181414fb7d9e5ebf6b9f6412b555df1fcd51", "best_bid": "0.48", "best_ask": "0.481"}], "timestamp": "1782707656113", "event_type": "price_change"}}
{"local_timestamp": 1782707656.392965, "slug": "will-lionel-messi-be-the-top-goalscorer-at-the-2026-fifa-world-cup", "data": {"market": "0xd2a8caba5559bc21e14f6b2aa504cb14a1782751658b71409e25b82e432c0a97", "price_changes": [{"asset_id": "19214394437683566921750936876376421489271269944393354497977881791256347396217", "price": "0.26", "size": "3000", "side": "BUY", "hash": "690bda8e47a05dd85398a7b3566ca0ed5024bafd", "best_bid": "0.519", "best_ask": "0.52"}, {"asset_id": "36586667785814641857008731622413716797407337292495614620493145114086484487337", "price": "0.74", "size": "3000", "side": "SELL", "hash": "7111e5046b37d576d174a8af39e683c84ef0a730", "best_bid": "0.48", "best_ask": "0.481"}], "timestamp": "1782707657621", "event_type": "price_change"}}
{"local_timestamp": 1782707656.3966784, "slug": "will-lionel-messi-be-the-top-goalscorer-at-the-2026-fifa-world-cup", "data": {"market": "0xd2a8caba5559bc21e14f6b2aa504cb14a1782751658b71409e25b82e432c0a97", "price_changes": [{"asset_id": "36586667785814641857008731622413716797407337292495614620493145114086484487337", "price": "0.34", "size": "3199.99", "side": "BUY", "hash": "f0f541f3486cbf5eb20b121f27213fa25ca254b1", "best_bid": "0.48", "best_ask": "0.481"}, {"asset_id": "19214394437683566921750936876376421489271269944393354497977881791256347396217", "price": "0.66", "size": "3199.99", "side": "SELL", "hash": "318c679ab635bfd479ab6b376879dbeaa685cf32", "best_bid": "0.519", "best_ask": "0.52"}], "timestamp": "1782707657624", "event_type": "price_change"}}
{"local_timestamp": 1782707657.872067, "slug": "will-lionel-messi-be-the-top-goalscorer-at-the-2026-fifa-world-cup", "data": {"market": "0xd2a8caba5559bc21e14f6b2aa504cb14a1782751658b71409e25b82e432c0a97", "price_changes": [{"asset_id": "19214394437683566921750936876376421489271269944393354497977881791256347396217", "price": "0.26", "size": "0", "side": "BUY", "hash": "3e7155100661a423a62ad1b833948b8b5c1d182e", "best_bid": "0.519", "best_ask": "0.52"}, {"asset_id": "36586667785814641857008731622413716797407337292495614620493145114086484487337", "price": "0.74", "size": "0", "side": "SELL", "hash": "b998160ba5aa07542cbc3cba325c7e658f9ad3c7", "best_bid": "0.48", "best_ask": "0.481"}], "timestamp": "1782707659101", "event_type": "price_change"}}
{"local_timestamp": 1782707657.873031, "slug": "will-lionel-messi-be-the-top-goalscorer-at-the-2026-fifa-world-cup", "data": {"market": "0xd2a8caba5559bc21e14f6b2aa504cb14a1782751658b71409e25b82e432c0a97", "price_changes": [{"asset_id": "36586667785814641857008731622413716797407337292495614620493145114086484487337", "price": "0.34", "size": "199.99", "side": "BUY", "hash": "97c11ad521da6844135d51ce6e90354cfd913ff8", "best_bid": "0.48", "best_ask": "0.481"}, {"asset_id": "19214394437683566921750936876376421489271269944393354497977881791256347396217", "price": "0.66", "size": "199.99", "side": "SELL", "hash": "11d59369c3c5b7ec996702aadd2ad0b00d218a82", "best_bid": "0.519", "best_ask": "0.52"}], "timestamp": "1782707659102", "event_type": "price_change"}}
{"local_timestamp": 1782707658.0897334, "slug": "will-lionel-messi-be-the-top-goalscorer-at-the-2026-fifa-world-cup", "data": {"market": "0xd2a8caba5559bc21e14f6b2aa504cb14a1782751658b71409e25b82e432c0a97", "price_changes": [{"asset_id": "19214394437683566921750936876376421489271269944393354497977881791256347396217", "price": "0.521", "size": "4683.73", "side": "SELL", "hash": "c939e0c15c26b09ad311419beeee8f2d385550cc", "best_bid": "0.519", "best_ask": "0.52"}, {"asset_id": "36586667785814641857008731622413716797407337292495614620493145114086484487337", "price": "0.479", "size": "4683.73", "side": "BUY", "hash": "cc10b4c75337584439c6f25a51310c0b0c58e3fa", "best_bid": "0.48", "best_ask": "0.481"}], "timestamp": "1782707659320", "event_type": "price_change"}}
{"local_timestamp": 1782707658.6580071, "slug": "will-lionel-messi-be-the-top-goalscorer-at-the-2026-fifa-world-cup", "data": {"market": "0xd2a8caba5559bc21e14f6b2aa504cb14a1782751658b71409e25b82e432c0a97", "price_changes": [{"asset_id": "36586667785814641857008731622413716797407337292495614620493145114086484487337", "price": "0.231", "size": "200", "side": "BUY", "hash": "ebcbdd9c1003d2547c75ac22e41ee4104eea0912", "best_bid": "0.48", "best_ask": "0.481"}, {"asset_id": "19214394437683566921750936876376421489271269944393354497977881791256347396217", "price": "0.769", "size": "200", "side": "SELL", "hash": "3aa5e0715e80ce8b7e6adb1f3637648bbdd30d0a", "best_bid": "0.519", "best_ask": "0.52"}], "timestamp": "1782707659887", "event_type": "price_change"}}
{"local_timestamp": 1782707658.9125037, "slug": "will-lionel-messi-be-the-top-goalscorer-at-the-2026-fifa-world-cup", "data": {"market": "0xd2a8caba5559bc21e14f6b2aa504cb14a1782751658b71409e25b82e432c0a97", "price_changes": [{"asset_id": "36586667785814641857008731622413716797407337292495614620493145114086484487337", "price": "0.623", "size": "434.96", "side": "SELL", "hash": "d46c7b7aa0485522bc08eca87bc43ea9572a913c", "best_bid": "0.48", "best_ask": "0.481"}, {"asset_id": "19214394437683566921750936876376421489271269944393354497977881791256347396217", "price": "0.377", "size": "434.96", "side": "BUY", "hash": "432af8596a74a553163942bad5eca607a2eaac70", "best_bid": "0.519", "best_ask": "0.52"}], "timestamp": "1782707660141", "event_type": "price_change"}}
{"local_timestamp": 1782707659.4411283, "slug": "will-lionel-messi-be-the-top-goalscorer-at-the-2026-fifa-world-cup", "data": {"market": "0xd2a8caba5559bc21e14f6b2aa504cb14a1782751658b71409e25b82e432c0a97", "price_changes": [{"asset_id": "36586667785814641857008731622413716797407337292495614620493145114086484487337", "price": "0.34", "size": "3199.99", "side": "BUY", "hash": "8dae3e7504d2fdaa63dabf803bd7c8c869f41e01", "best_bid": "0.48", "best_ask": "0.481"}, {"asset_id": "19214394437683566921750936876376421489271269944393354497977881791256347396217", "price": "0.66", "size": "3199.99", "side": "SELL", "hash": "fc2fd54ae7b1f9dbc585cf633bdc40eace6c8967", "best_bid": "0.519", "best_ask": "0.52"}], "timestamp": "1782707660671", "event_type": "price_change"}}
{"local_timestamp": 1782707659.4607363, "slug": "will-lionel-messi-be-the-top-goalscorer-at-the-2026-fifa-world-cup", "data": {"market": "0xd2a8caba5559bc21e14f6b2aa504cb14a1782751658b71409e25b82e432c0a97", "price_changes": [{"asset_id": "19214394437683566921750936876376421489271269944393354497977881791256347396217", "price": "0.26", "size": "3000", "side": "BUY", "hash": "eaffa4fd34030944a50819e09bcc9b5c6b4b7e86", "best_bid": "0.519", "best_ask": "0.52"}, {"asset_id": "36586667785814641857008731622413716797407337292495614620493145114086484487337", "price": "0.74", "size": "3000", "side": "SELL", "hash": "11bfd48f2508429b5cb40d10a7d46f629fd11666", "best_bid": "0.48", "best_ask": "0.481"}], "timestamp": "1782707660690", "event_type": "price_change"}}
{"local_timestamp": 1782707660.8639755, "slug": "will-lionel-messi-be-the-top-goalscorer-at-the-2026-fifa-world-cup", "data": {"market": "0xd2a8caba5559bc21e14f6b2aa504cb14a1782751658b71409e25b82e432c0a97", "price_changes": [{"asset_id": "19214394437683566921750936876376421489271269944393354497977881791256347396217", "price": "0.26", "size": "0", "side": "BUY", "hash": "5c59ca4672d33b73a2d21ad3f9cacde7a1cf9c91", "best_bid": "0.519", "best_ask": "0.52"}, {"asset_id": "36586667785814641857008731622413716797407337292495614620493145114086484487337", "price": "0.74", "size": "0", "side": "SELL", "hash": "ee3268188dcf39dfaa4e738ecccff5a8cac30a16", "best_bid": "0.48", "best_ask": "0.481"}], "timestamp": "1782707662093", "event_type": "price_change"}}
{"local_timestamp": 1782707660.8661993, "slug": "will-lionel-messi-be-the-top-goalscorer-at-the-2026-fifa-world-cup", "data": {"market": "0xd2a8caba5559bc21e14f6b2aa504cb14a1782751658b71409e25b82e432c0a97", "price_changes": [{"asset_id": "36586667785814641857008731622413716797407337292495614620493145114086484487337", "price": "0.34", "size": "199.99", "side": "BUY", "hash": "55ac261847b4b00362d51b43203183b15bd0c59a", "best_bid": "0.48", "best_ask": "0.481"}, {"asset_id": "19214394437683566921750936876376421489271269944393354497977881791256347396217", "price": "0.66", "size": "199.99", "side": "SELL", "hash": "e4c31982143cdba61dc829c86ff4a37a03525050", "best_bid": "0.519", "best_ask": "0.52"}], "timestamp": "1782707662093", "event_type": "price_change"}}
{"local_timestamp": 1782707660.9094105, "slug": "will-lionel-messi-be-the-top-goalscorer-at-the-2026-fifa-world-cup", "data": {"market": "0xd2a8caba5559bc21e14f6b2aa504cb14a1782751658b71409e25b82e432c0a97", "price_changes": [{"asset_id": "19214394437683566921750936876376421489271269944393354497977881791256347396217", "price": "0.521", "size": "4780.82", "side": "SELL", "hash": "8942e6210b18cf05e2d0079009110f32a8ba12a4", "best_bid": "0.519", "best_ask": "0.52"}, {"asset_id": "36586667785814641857008731622413716797407337292495614620493145114086484487337", "price": "0.479", "size": "4780.82", "side": "BUY", "hash": "609bcd74b32706e62e381073a5807cd8e63b2692", "best_bid": "0.48", "best_ask": "0.481"}], "timestamp": "1782707662139", "event_type": "price_change"}}
{"local_timestamp": 1782707661.2626293, "slug": "will-lionel-messi-be-the-top-goalscorer-at-the-2026-fifa-world-cup", "data": {"market": "0xd2a8caba5559bc21e14f6b2aa504cb14a1782751658b71409e25b82e432c0a97", "price_changes": [{"asset_id": "36586667785814641857008731622413716797407337292495614620493145114086484487337", "price": "0.002", "size": "13507.31", "side": "BUY", "hash": "abf7f301ede6dd6de1405595b2d357a1747e6b29", "best_bid": "0.48", "best_ask": "0.481"}, {"asset_id": "19214394437683566921750936876376421489271269944393354497977881791256347396217", "price": "0.998", "size": "13507.31", "side": "SELL", "hash": "130021a76079876185dc2b973bfe7fcb8b38d52a", "best_bid": "0.519", "best_ask": "0.52"}], "timestamp": "1782707662491", "event_type": "price_change"}}
{"local_timestamp": 1782707661.2765086, "slug": "will-lionel-messi-be-the-top-goalscorer-at-the-2026-fifa-world-cup", "data": {"market": "0xd2a8caba5559bc21e14f6b2aa504cb14a1782751658b71409e25b82e432c0a97", "price_changes": [{"asset_id": "19214394437683566921750936876376421489271269944393354497977881791256347396217", "price": "0.002", "size": "28250", "side": "BUY", "hash": "1d730438299cbc9b4e6b30b0cc8c8ed3d1f49eb0", "best_bid": "0.519", "best_ask": "0.52"}, {"asset_id": "36586667785814641857008731622413716797407337292495614620493145114086484487337", "price": "0.998", "size": "28250", "side": "SELL", "hash": "89e62b76f9ba0c816de162fc678b8c07b431eda1", "best_bid": "0.48", "best_ask": "0.481"}], "timestamp": "1782707662506", "event_type": "price_change"}}
{"local_timestamp": 1782707662.3448982, "slug": "will-lionel-messi-be-the-top-goalscorer-at-the-2026-fifa-world-cup", "data": {"market": "0xd2a8caba5559bc21e14f6b2aa504cb14a1782751658b71409e25b82e432c0a97", "price_changes": [{"asset_id": "19214394437683566921750936876376421489271269944393354497977881791256347396217", "price": "0.26", "size": "3000", "side": "BUY", "hash": "18142acb411adb9a80699558c91cd890459b01c8", "best_bid": "0.519", "best_ask": "0.52"}, {"asset_id": "36586667785814641857008731622413716797407337292495614620493145114086484487337", "price": "0.74", "size": "3000", "side": "SELL", "hash": "12cdfe789beb6a212f1c040a86c01823468a7da1", "best_bid": "0.48", "best_ask": "0.481"}], "timestamp": "1782707663575", "event_type": "price_change"}}
{"local_timestamp": 1782707662.3514266, "slug": "will-lionel-messi-be-the-top-goalscorer-at-the-2026-fifa-world-cup", "data": {"market": "0xd2a8caba5559bc21e14f6b2aa504cb14a1782751658b71409e25b82e432c0a97", "price_changes": [{"asset_id": "36586667785814641857008731622413716797407337292495614620493145114086484487337", "price": "0.34", "size": "3199.99", "side": "BUY", "hash": "89ffa3f651540e20a95d84a5c9f656670436619b", "best_bid": "0.48", "best_ask": "0.481"}, {"asset_id": "19214394437683566921750936876376421489271269944393354497977881791256347396217", "price": "0.66", "size": "3199.99", "side": "SELL", "hash": "ea8ac4c1d1ae21cef0a760b5c28719ebbf30548b", "best_bid": "0.519", "best_ask": "0.52"}], "timestamp": "1782707663581", "event_type": "price_change"}}
{"local_timestamp": 1782707663.7858477, "slug": "will-lionel-messi-be-the-top-goalscorer-at-the-2026-fifa-world-cup", "data": {"market": "0xd2a8caba5559bc21e14f6b2aa504cb14a1782751658b71409e25b82e432c0a97", "price_changes": [{"asset_id": "19214394437683566921750936876376421489271269944393354497977881791256347396217", "price": "0.318", "size": "0", "side": "BUY", "hash": "01541ba0980531ae1f7d19e696f5776cab30ebc5", "best_bid": "0.519", "best_ask": "0.52"}, {"asset_id": "36586667785814641857008731622413716797407337292495614620493145114086484487337", "price": "0.682", "size": "0", "side": "SELL", "hash": "55bdd75354a9ee1a2f91eb125f427199aaa8da86", "best_bid": "0.48", "best_ask": "0.481"}], "timestamp": "1782707665000", "event_type": "price_change"}}
{"local_timestamp": 1782707663.8801217, "slug": "will-lionel-messi-be-the-top-goalscorer-at-the-2026-fifa-world-cup", "data": {"market": "0xd2a8caba5559bc21e14f6b2aa504cb14a1782751658b71409e25b82e432c0a97", "price_changes": [{"asset_id": "36586667785814641857008731622413716797407337292495614620493145114086484487337", "price": "0.34", "size": "199.99", "side": "BUY", "hash": "1a5b316771197c7291ed772e582b004b6f795beb", "best_bid": "0.48", "best_ask": "0.481"}, {"asset_id": "19214394437683566921750936876376421489271269944393354497977881791256347396217", "price": "0.66", "size": "199.99", "side": "SELL", "hash": "60ab8d1da7d2bbb706bbe8bd3fa1ac8120604a3e", "best_bid": "0.519", "best_ask": "0.52"}], "timestamp": "1782707665110", "event_type": "price_change"}}
{"local_timestamp": 1782707663.881402, "slug": "will-lionel-messi-be-the-top-goalscorer-at-the-2026-fifa-world-cup", "data": {"market": "0xd2a8caba5559bc21e14f6b2aa504cb14a1782751658b71409e25b82e432c0a97", "price_changes": [{"asset_id": "19214394437683566921750936876376421489271269944393354497977881791256347396217", "price": "0.26", "size": "0", "side": "BUY", "hash": "356fce9758fb719636dfa102ef924c6656e28648", "best_bid": "0.519", "best_ask": "0.52"}, {"asset_id": "36586667785814641857008731622413716797407337292495614620493145114086484487337", "price": "0.74", "size": "0", "side": "SELL", "hash": "086f85a291279a70389dee4d8faaa9d90a445eab", "best_bid": "0.48", "best_ask": "0.481"}], "timestamp": "1782707665110", "event_type": "price_change"}}
{"local_timestamp": 1782707664.5750113, "slug": "will-lionel-messi-be-the-top-goalscorer-at-the-2026-fifa-world-cup", "data": {"market": "0xd2a8caba5559bc21e14f6b2aa504cb14a1782751658b71409e25b82e432c0a97", "price_changes": [{"asset_id": "19214394437683566921750936876376421489271269944393354497977881791256347396217", "price": "0.521", "size": "4683.73", "side": "SELL", "hash": "6c5c0a3b848be10d1ebf95c70e2ae5a0af464102", "best_bid": "0.519", "best_ask": "0.52"}, {"asset_id": "36586667785814641857008731622413716797407337292495614620493145114086484487337", "price": "0.479", "size": "4683.73", "side": "BUY", "hash": "c403f0427e4b8c203cebf0f0cef6885fc1cba453", "best_bid": "0.48", "best_ask": "0.481"}], "timestamp": "1782707665800", "event_type": "price_change"}}
{"local_timestamp": 1782707665.3341906, "slug": "will-lionel-messi-be-the-top-goalscorer-at-the-2026-fifa-world-cup", "data": {"market": "0xd2a8caba5559bc21e14f6b2aa504cb14a1782751658b71409e25b82e432c0a97", "price_changes": [{"asset_id": "36586667785814641857008731622413716797407337292495614620493145114086484487337", "price": "0.34", "size": "3199.99", "side": "BUY", "hash": "1cfdc4c8bfc49dbf5abb1675d9391853e63608e5", "best_bid": "0.48", "best_ask": "0.481"}, {"asset_id": "19214394437683566921750936876376421489271269944393354497977881791256347396217", "price": "0.66", "size": "3199.99", "side": "SELL", "hash": "8bfe4aa8d8084b38904d9e738c80607519e657fb", "best_bid": "0.519", "best_ask": "0.52"}], "timestamp": "1782707666564", "event_type": "price_change"}}
{"local_timestamp": 1782707665.3360677, "slug": "will-lionel-messi-be-the-top-goalscorer-at-the-2026-fifa-world-cup", "data": {"market": "0xd2a8caba5559bc21e14f6b2aa504cb14a1782751658b71409e25b82e432c0a97", "price_changes": [{"asset_id": "19214394437683566921750936876376421489271269944393354497977881791256347396217", "price": "0.26", "size": "3000", "side": "BUY", "hash": "3722fd93a9f386ec55a0acfc05128277879d6437", "best_bid": "0.519", "best_ask": "0.52"}, {"asset_id": "36586667785814641857008731622413716797407337292495614620493145114086484487337", "price": "0.74", "size": "3000", "side": "SELL", "hash": "a3413b9a6e9f0bd1f60efd8c92dad557598b50aa", "best_bid": "0.48", "best_ask": "0.481"}], "timestamp": "1782707666566", "event_type": "price_change"}}
{"local_timestamp": 1782707666.5032365, "slug": "will-lionel-messi-be-the-top-goalscorer-at-the-2026-fifa-world-cup", "data": {"market": "0xd2a8caba5559bc21e14f6b2aa504cb14a1782751658b71409e25b82e432c0a97", "price_changes": [{"asset_id": "36586667785814641857008731622413716797407337292495614620493145114086484487337", "price": "0.232", "size": "200", "side": "BUY", "hash": "445a9c43d1d380a73bb4d3a713df7bd25df1d65f", "best_bid": "0.48", "best_ask": "0.481"}, {"asset_id": "19214394437683566921750936876376421489271269944393354497977881791256347396217", "price": "0.768", "size": "200", "side": "SELL", "hash": "f161f4736ae8e8a2513dfa7482b840ebc81c3530", "best_bid": "0.519", "best_ask": "0.52"}], "timestamp": "1782707667733", "event_type": "price_change"}}
{"local_timestamp": 1782707666.6149986, "slug": "will-lionel-messi-be-the-top-goalscorer-at-the-2026-fifa-world-cup", "data": {"market": "0xd2a8caba5559bc21e14f6b2aa504cb14a1782751658b71409e25b82e432c0a97", "price_changes": [{"asset_id": "36586667785814641857008731622413716797407337292495614620493145114086484487337", "price": "0.231", "size": "0", "side": "BUY", "hash": "e950f9714dd82123e0181be879c0bd6ae8d3b388", "best_bid": "0.48", "best_ask": "0.481"}, {"asset_id": "19214394437683566921750936876376421489271269944393354497977881791256347396217", "price": "0.769", "size": "0", "side": "SELL", "hash": "0e7c8050f0950e1687d291c5cc8f0bc80966841e", "best_bid": "0.519", "best_ask": "0.52"}], "timestamp": "1782707667844", "event_type": "price_change"}}
{"local_timestamp": 1782707666.8689504, "slug": "will-lionel-messi-be-the-top-goalscorer-at-the-2026-fifa-world-cup", "data": {"market": "0xd2a8caba5559bc21e14f6b2aa504cb14a1782751658b71409e25b82e432c0a97", "price_changes": [{"asset_id": "19214394437683566921750936876376421489271269944393354497977881791256347396217", "price": "0.26", "size": "0", "side": "BUY", "hash": "1d81ac8b2d262f5a94765ae0c695724adf4384b5", "best_bid": "0.519", "best_ask": "0.52"}, {"asset_id": "36586667785814641857008731622413716797407337292495614620493145114086484487337", "price": "0.74", "size": "0", "side": "SELL", "hash": "ef95ebcc19437dc3ad2c10548725e936706aa71f", "best_bid": "0.48", "best_ask": "0.481"}], "timestamp": "1782707668099", "event_type": "price_change"}}
{"local_timestamp": 1782707666.8695164, "slug": "will-lionel-messi-be-the-top-goalscorer-at-the-2026-fifa-world-cup", "data": {"market": "0xd2a8caba5559bc21e14f6b2aa504cb14a1782751658b71409e25b82e432c0a97", "price_changes": [{"asset_id": "36586667785814641857008731622413716797407337292495614620493145114086484487337", "price": "0.34", "size": "199.99", "side": "BUY", "hash": "b57291a66b707f73663af447f9f710b876228f03", "best_bid": "0.48", "best_ask": "0.481"}, {"asset_id": "19214394437683566921750936876376421489271269944393354497977881791256347396217", "price": "0.66", "size": "199.99", "side": "SELL", "hash": "c9596f9801525e64a2d24fac1a03cf2d13d9297f", "best_bid": "0.519", "best_ask": "0.52"}], "timestamp": "1782707668099", "event_type": "price_change"}}
{"local_timestamp": 1782707666.9229934, "slug": "will-lionel-messi-be-the-top-goalscorer-at-the-2026-fifa-world-cup", "data": {"market": "0xd2a8caba5559bc21e14f6b2aa504cb14a1782751658b71409e25b82e432c0a97", "price_changes": [{"asset_id": "19214394437683566921750936876376421489271269944393354497977881791256347396217", "price": "0.521", "size": "4780.82", "side": "SELL", "hash": "3d10797a6e3fa1aee1ef74e14c2da3ce700339cb", "best_bid": "0.519", "best_ask": "0.52"}, {"asset_id": "36586667785814641857008731622413716797407337292495614620493145114086484487337", "price": "0.479", "size": "4780.82", "side": "BUY", "hash": "a1ad1901732df5f951b2a2539523ea809cfecc0d", "best_bid": "0.48", "best_ask": "0.481"}], "timestamp": "1782707668153", "event_type": "price_change"}}
{"local_timestamp": 1782707667.6606066, "slug": "will-lionel-messi-be-the-top-goalscorer-at-the-2026-fifa-world-cup", "data": {"market": "0xd2a8caba5559bc21e14f6b2aa504cb14a1782751658b71409e25b82e432c0a97", "price_changes": [{"asset_id": "36586667785814641857008731622413716797407337292495614620493145114086484487337", "price": "0.494", "size": "220", "side": "SELL", "hash": "61a02ddcb8e46835e7ac1092b4d6825b08b8789b", "best_bid": "0.48", "best_ask": "0.481"}, {"asset_id": "19214394437683566921750936876376421489271269944393354497977881791256347396217", "price": "0.506", "size": "220", "side": "BUY", "hash": "14432c9699b9eb9ed29d5b2583ab46f4de31898f", "best_bid": "0.519", "best_ask": "0.52"}], "timestamp": "1782707668889", "event_type": "price_change"}}
{"local_timestamp": 1782707668.377147, "slug": "will-lionel-messi-be-the-top-goalscorer-at-the-2026-fifa-world-cup", "data": {"market": "0xd2a8caba5559bc21e14f6b2aa504cb14a1782751658b71409e25b82e432c0a97", "price_changes": [{"asset_id": "19214394437683566921750936876376421489271269944393354497977881791256347396217", "price": "0.26", "size": "3000", "side": "BUY", "hash": "087983f8ff33ef6983987542a96226f6f761f125", "best_bid": "0.519", "best_ask": "0.52"}, {"asset_id": "36586667785814641857008731622413716797407337292495614620493145114086484487337", "price": "0.74", "size": "3000", "side": "SELL", "hash": "4e860683dfbe6623a256a27a36d06ebe9e1885fb", "best_bid": "0.48", "best_ask": "0.481"}], "timestamp": "1782707669607", "event_type": "price_change"}}
{"local_timestamp": 1782707668.3830738, "slug": "will-lionel-messi-be-the-top-goalscorer-at-the-2026-fifa-world-cup", "data": {"market": "0xd2a8caba5559bc21e14f6b2aa504cb14a1782751658b71409e25b82e432c0a97", "price_changes": [{"asset_id": "36586667785814641857008731622413716797407337292495614620493145114086484487337", "price": "0.34", "size": "3199.99", "side": "BUY", "hash": "b4a55d4b05df468a55c15ff8ae17b33c1a3346f4", "best_bid": "0.48", "best_ask": "0.481"}, {"asset_id": "19214394437683566921750936876376421489271269944393354497977881791256347396217", "price": "0.66", "size": "3199.99", "side": "SELL", "hash": "6bf3719c99f171184c3e24343c4521b9d423774e", "best_bid": "0.519", "best_ask": "0.52"}], "timestamp": "1782707669612", "event_type": "price_change"}}
{"local_timestamp": 1782707668.5330641, "slug": "will-lionel-messi-be-the-top-goalscorer-at-the-2026-fifa-world-cup", "data": {"market": "0xd2a8caba5559bc21e14f6b2aa504cb14a1782751658b71409e25b82e432c0a97", "price_changes": [{"asset_id": "36586667785814641857008731622413716797407337292495614620493145114086484487337", "price": "0.46", "size": "44808", "side": "BUY", "hash": "670ecb21d83fda8c86a78e3c6aeaa0be1e94f02b", "best_bid": "0.48", "best_ask": "0.481"}, {"asset_id": "19214394437683566921750936876376421489271269944393354497977881791256347396217", "price": "0.54", "size": "44808", "side": "SELL", "hash": "9a258128a238760b8d0703c69413a2f5b084ed2a", "best_bid": "0.519", "best_ask": "0.52"}], "timestamp": "1782707669763", "event_type": "price_change"}}
{"local_timestamp": 1782707668.570092, "slug": "will-lionel-messi-be-the-top-goalscorer-at-the-2026-fifa-world-cup", "data": {"market": "0xd2a8caba5559bc21e14f6b2aa504cb14a1782751658b71409e25b82e432c0a97", "price_changes": [{"asset_id": "19214394437683566921750936876376421489271269944393354497977881791256347396217", "price": "0.512", "size": "250", "side": "BUY", "hash": "8eec06d5ad8c40112cae841dcdeda13140172750", "best_bid": "0.519", "best_ask": "0.52"}, {"asset_id": "36586667785814641857008731622413716797407337292495614620493145114086484487337", "price": "0.488", "size": "250", "side": "SELL", "hash": "a416c9805dbc50e3d2d5fa9f9d26e7e5175b9f08", "best_bid": "0.48", "best_ask": "0.481"}], "timestamp": "1782707669800", "event_type": "price_change"}}
{"local_timestamp": 1782707668.7720125, "slug": "will-lionel-messi-be-the-top-goalscorer-at-the-2026-fifa-world-cup", "data": {"market": "0xd2a8caba5559bc21e14f6b2aa504cb14a1782751658b71409e25b82e432c0a97", "price_changes": [{"asset_id": "36586667785814641857008731622413716797407337292495614620493145114086484487337", "price": "0.46", "size": "44608", "side": "BUY", "hash": "0ffef47e89b8a03de6a4f35c953cb6c4ec2ff2ff", "best_bid": "0.48", "best_ask": "0.481"}, {"asset_id": "19214394437683566921750936876376421489271269944393354497977881791256347396217", "price": "0.54", "size": "44608", "side": "SELL", "hash": "c6eb2ae31591f796dbe944c523502f9557126296", "best_bid": "0.519", "best_ask": "0.52"}], "timestamp": "1782707670002", "event_type": "price_change"}}
{"local_timestamp": 1782707669.447575, "slug": "will-lionel-messi-be-the-top-goalscorer-at-the-2026-fifa-world-cup", "data": {"market": "0xd2a8caba5559bc21e14f6b2aa504cb14a1782751658b71409e25b82e432c0a97", "price_changes": [{"asset_id": "36586667785814641857008731622413716797407337292495614620493145114086484487337", "price": "0.473", "size": "250", "side": "BUY", "hash": "2dca588e7c9517ff887bd0a7f4a0769178277599", "best_bid": "0.48", "best_ask": "0.481"}, {"asset_id": "19214394437683566921750936876376421489271269944393354497977881791256347396217", "price": "0.527", "size": "250", "side": "SELL", "hash": "46f80624dbcac41324d804a2d95e9016edfd4e5f", "best_bid": "0.519", "best_ask": "0.52"}], "timestamp": "1782707670677", "event_type": "price_change"}}
{"local_timestamp": 1782707669.5758116, "slug": "will-lionel-messi-be-the-top-goalscorer-at-the-2026-fifa-world-cup", "data": {"market": "0xd2a8caba5559bc21e14f6b2aa504cb14a1782751658b71409e25b82e432c0a97", "price_changes": [{"asset_id": "19214394437683566921750936876376421489271269944393354497977881791256347396217", "price": "0.521", "size": "4683.73", "side": "SELL", "hash": "ca1ae70a1961e7b4bf33078fc5b49d20bfe7ed22", "best_bid": "0.519", "best_ask": "0.52"}, {"asset_id": "36586667785814641857008731622413716797407337292495614620493145114086484487337", "price": "0.479", "size": "4683.73", "side": "BUY", "hash": "125f6c867763918ba54e3faad1e0063ef31c41da", "best_bid": "0.48", "best_ask": "0.481"}], "timestamp": "1782707670805", "event_type": "price_change"}}
{"local_timestamp": 1782707669.8219354, "slug": "will-lionel-messi-be-the-top-goalscorer-at-the-2026-fifa-world-cup", "data": {"market": "0xd2a8caba5559bc21e14f6b2aa504cb14a1782751658b71409e25b82e432c0a97", "price_changes": [{"asset_id": "19214394437683566921750936876376421489271269944393354497977881791256347396217", "price": "0.26", "size": "0", "side": "BUY", "hash": "875a5fcd4aa783cffa6286369a16df9dccfb3824", "best_bid": "0.519", "best_ask": "0.52"}, {"asset_id": "36586667785814641857008731622413716797407337292495614620493145114086484487337", "price": "0.74", "size": "0", "side": "SELL", "hash": "881964596472eeffc5b1fbf2310215756d2048c0", "best_bid": "0.48", "best_ask": "0.481"}], "timestamp": "1782707671052", "event_type": "price_change"}}
{"local_timestamp": 1782707669.824443, "slug": "will-lionel-messi-be-the-top-goalscorer-at-the-2026-fifa-world-cup", "data": {"market": "0xd2a8caba5559bc21e14f6b2aa504cb14a1782751658b71409e25b82e432c0a97", "price_changes": [{"asset_id": "36586667785814641857008731622413716797407337292495614620493145114086484487337", "price": "0.34", "size": "199.99", "side": "BUY", "hash": "b3cedbceaf7b4b4375f670051ab08c680cba7c82", "best_bid": "0.48", "best_ask": "0.481"}, {"asset_id": "19214394437683566921750936876376421489271269944393354497977881791256347396217", "price": "0.66", "size": "199.99", "side": "SELL", "hash": "56c21b30cf018ab03ec74e3a3bf5b81ccd61cabb", "best_bid": "0.519", "best_ask": "0.52"}], "timestamp": "1782707671052", "event_type": "price_change"}}
{"local_timestamp": 1782707669.9814773, "slug": "will-lionel-messi-be-the-top-goalscorer-at-the-2026-fifa-world-cup", "data": {"market": "0xd2a8caba5559bc21e14f6b2aa504cb14a1782751658b71409e25b82e432c0a97", "price_changes": [{"asset_id": "36586667785814641857008731622413716797407337292495614620493145114086484487337", "price": "0.494", "size": "258.04", "side": "SELL", "hash": "809928e09f9db1b8355f474c85197f5acd555d6e", "best_bid": "0.48", "best_ask": "0.481"}, {"asset_id": "19214394437683566921750936876376421489271269944393354497977881791256347396217", "price": "0.506", "size": "258.04", "side": "BUY", "hash": "ebefce331bb365bd5951fad3029285f231db85e4", "best_bid": "0.519", "best_ask": "0.52"}], "timestamp": "1782707671212", "event_type": "price_change"}}
{"local_timestamp": 1782707670.4468222, "slug": "will-lionel-messi-be-the-top-goalscorer-at-the-2026-fifa-world-cup", "data": {"market": "0xd2a8caba5559bc21e14f6b2aa504cb14a1782751658b71409e25b82e432c0a97", "price_changes": [{"asset_id": "19214394437683566921750936876376421489271269944393354497977881791256347396217", "price": "0.5", "size": "28432", "side": "BUY", "hash": "df55507f06b47aad34cc1dc4ea486d6936a56223", "best_bid": "0.519", "best_ask": "0.52"}, {"asset_id": "36586667785814641857008731622413716797407337292495614620493145114086484487337", "price": "0.5", "size": "28432", "side": "SELL", "hash": "aea4664a0953a43cdb47a4d4b11cae7517f87160", "best_bid": "0.48", "best_ask": "0.481"}], "timestamp": "1782707671676", "event_type": "price_change"}}
{"local_timestamp": 1782707671.3924766, "slug": "will-lionel-messi-be-the-top-goalscorer-at-the-2026-fifa-world-cup", "data": {"market": "0xd2a8caba5559bc21e14f6b2aa504cb14a1782751658b71409e25b82e432c0a97", "price_changes": [{"asset_id": "19214394437683566921750936876376421489271269944393354497977881791256347396217", "price": "0.26", "size": "3000", "side": "BUY", "hash": "e75b65d3c005f5b84832111f1fd62a1101db31bc", "best_bid": "0.519", "best_ask": "0.52"}, {"asset_id": "36586667785814641857008731622413716797407337292495614620493145114086484487337", "price": "0.74", "size": "3000", "side": "SELL", "hash": "ea1610c6ba83eaf2e344d04af658ccc406b4a197", "best_bid": "0.48", "best_ask": "0.481"}], "timestamp": "1782707672622", "event_type": "price_change"}}
{"local_timestamp": 1782707671.400881, "slug": "will-lionel-messi-be-the-top-goalscorer-at-the-2026-fifa-world-cup", "data": {"market": "0xd2a8caba5559bc21e14f6b2aa504cb14a1782751658b71409e25b82e432c0a97", "price_changes": [{"asset_id": "36586667785814641857008731622413716797407337292495614620493145114086484487337", "price": "0.34", "size": "3199.99", "side": "BUY", "hash": "f06b4e6ed76ff6a0986e72767c7cb52d655597cb", "best_bid": "0.48", "best_ask": "0.481"}, {"asset_id": "19214394437683566921750936876376421489271269944393354497977881791256347396217", "price": "0.66", "size": "3199.99", "side": "SELL", "hash": "2de43dd5eaaacfbcd7f76eea3f8e7397c34a5ed7", "best_bid": "0.519", "best_ask": "0.52"}], "timestamp": "1782707672630", "event_type": "price_change"}}
{"local_timestamp": 1782707671.4446113, "slug": "will-lionel-messi-be-the-top-goalscorer-at-the-2026-fifa-world-cup", "data": {"market": "0xd2a8caba5559bc21e14f6b2aa504cb14a1782751658b71409e25b82e432c0a97", "price_changes": [{"asset_id": "19214394437683566921750936876376421489271269944393354497977881791256347396217", "price": "0.318", "size": "200", "side": "BUY", "hash": "254a74ccff8886f1385ce8443752bde66a81a35b", "best_bid": "0.519", "best_ask": "0.52"}, {"asset_id": "36586667785814641857008731622413716797407337292495614620493145114086484487337", "price": "0.682", "size": "200", "side": "SELL", "hash": "48b314e1c287d3e91a0efcc96f27f9d3f75884cf", "best_bid": "0.48", "best_ask": "0.481"}], "timestamp": "1782707672674", "event_type": "price_change"}}
{"local_timestamp": 1782707672.1972883, "slug": "will-lionel-messi-be-the-top-goalscorer-at-the-2026-fifa-world-cup", "data": {"market": "0xd2a8caba5559bc21e14f6b2aa504cb14a1782751658b71409e25b82e432c0a97", "price_changes": [{"asset_id": "19214394437683566921750936876376421489271269944393354497977881791256347396217", "price": "0.521", "size": "4780.82", "side": "SELL", "hash": "eb05377090f63c6c2917cc5bc5985b5289d43b6b", "best_bid": "0.519", "best_ask": "0.52"}, {"asset_id": "36586667785814641857008731622413716797407337292495614620493145114086484487337", "price": "0.479", "size": "4780.82", "side": "BUY", "hash": "c5373dfae7e4ccbcf3ae9a0d16a3d88775287d0d", "best_bid": "0.48", "best_ask": "0.481"}], "timestamp": "1782707673428", "event_type": "price_change"}}
{"local_timestamp": 1782707672.8346152, "slug": "will-lionel-messi-be-the-top-goalscorer-at-the-2026-fifa-world-cup", "data": {"market": "0xd2a8caba5559bc21e14f6b2aa504cb14a1782751658b71409e25b82e432c0a97", "price_changes": [{"asset_id": "19214394437683566921750936876376421489271269944393354497977881791256347396217", "price": "0.26", "size": "0", "side": "BUY", "hash": "7f286993df91cf7619de6f6d8943b07ec0b42ea8", "best_bid": "0.519", "best_ask": "0.52"}, {"asset_id": "36586667785814641857008731622413716797407337292495614620493145114086484487337", "price": "0.74", "size": "0", "side": "SELL", "hash": "64e8f5ef76132e5ed1f867ad4388497d61a136b4", "best_bid": "0.48", "best_ask": "0.481"}], "timestamp": "1782707674065", "event_type": "price_change"}}
{"local_timestamp": 1782707672.837679, "slug": "will-lionel-messi-be-the-top-goalscorer-at-the-2026-fifa-world-cup", "data": {"market": "0xd2a8caba5559bc21e14f6b2aa504cb14a1782751658b71409e25b82e432c0a97", "price_changes": [{"asset_id": "36586667785814641857008731622413716797407337292495614620493145114086484487337", "price": "0.34", "size": "199.99", "side": "BUY", "hash": "001ca8e4131cb3f2bfb0a028d90dc77dd06d9e3e", "best_bid": "0.48", "best_ask": "0.481"}, {"asset_id": "19214394437683566921750936876376421489271269944393354497977881791256347396217", "price": "0.66", "size": "199.99", "side": "SELL", "hash": "9deaf5886f3324f71ce4a16d2d3da0d1ccd84ccd", "best_bid": "0.519", "best_ask": "0.52"}], "timestamp": "1782707674065", "event_type": "price_change"}}
{"local_timestamp": 1782707673.826013, "slug": "will-lionel-messi-be-the-top-goalscorer-at-the-2026-fifa-world-cup", "data": {"market": "0xd2a8caba5559bc21e14f6b2aa504cb14a1782751658b71409e25b82e432c0a97", "price_changes": [{"asset_id": "19214394437683566921750936876376421489271269944393354497977881791256347396217", "price": "0.521", "size": "4683.73", "side": "SELL", "hash": "348d51a8566af279594f80887fcee9888f19562b", "best_bid": "0.519", "best_ask": "0.52"}, {"asset_id": "36586667785814641857008731622413716797407337292495614620493145114086484487337", "price": "0.479", "size": "4683.73", "side": "BUY", "hash": "d8cf26e3fdb392102848f50b6f642263e13841f5", "best_bid": "0.48", "best_ask": "0.481"}], "timestamp": "1782707675024", "event_type": "price_change"}}
{"local_timestamp": 1782707674.378174, "slug": "will-lionel-messi-be-the-top-goalscorer-at-the-2026-fifa-world-cup", "data": {"market": "0xd2a8caba5559bc21e14f6b2aa504cb14a1782751658b71409e25b82e432c0a97", "price_changes": [{"asset_id": "36586667785814641857008731622413716797407337292495614620493145114086484487337", "price": "0.34", "size": "3199.99", "side": "BUY", "hash": "766ae6f02ea8d19c4bdfa690cff22c15ccc8673b", "best_bid": "0.48", "best_ask": "0.481"}, {"asset_id": "19214394437683566921750936876376421489271269944393354497977881791256347396217", "price": "0.66", "size": "3199.99", "side": "SELL", "hash": "872ecb73f7a06c2ed935d4e0961ef44323825c24", "best_bid": "0.519", "best_ask": "0.52"}], "timestamp": "1782707675604", "event_type": "price_change"}}
{"local_timestamp": 1782707674.3817918, "slug": "will-lionel-messi-be-the-top-goalscorer-at-the-2026-fifa-world-cup", "data": {"market": "0xd2a8caba5559bc21e14f6b2aa504cb14a1782751658b71409e25b82e432c0a97", "price_changes": [{"asset_id": "19214394437683566921750936876376421489271269944393354497977881791256347396217", "price": "0.26", "size": "3000", "side": "BUY", "hash": "d42bd12e19f83184af431039cdf19a44fe3f5de0", "best_bid": "0.519", "best_ask": "0.52"}, {"asset_id": "36586667785814641857008731622413716797407337292495614620493145114086484487337", "price": "0.74", "size": "3000", "side": "SELL", "hash": "0f6f94da631d58c31af5fcb44b44d44571fb82be", "best_bid": "0.48", "best_ask": "0.481"}], "timestamp": "1782707675611", "event_type": "price_change"}}
{"local_timestamp": 1782707674.7997468, "slug": "will-lionel-messi-be-the-top-goalscorer-at-the-2026-fifa-world-cup", "data": {"market": "0xd2a8caba5559bc21e14f6b2aa504cb14a1782751658b71409e25b82e432c0a97", "price_changes": [{"asset_id": "36586667785814641857008731622413716797407337292495614620493145114086484487337", "price": "0.46", "size": "44808", "side": "BUY", "hash": "95a6b9f24175a2934d2dc66b588d213d7755d20b", "best_bid": "0.48", "best_ask": "0.481"}, {"asset_id": "19214394437683566921750936876376421489271269944393354497977881791256347396217", "price": "0.54", "size": "44808", "side": "SELL", "hash": "4eb3667f536a9b9b93ebc207efb7b1b6667baad5", "best_bid": "0.519", "best_ask": "0.52"}], "timestamp": "1782707676029", "event_type": "price_change"}}
{"local_timestamp": 1782707675.035801, "slug": "will-lionel-messi-be-the-top-goalscorer-at-the-2026-fifa-world-cup", "data": {"market": "0xd2a8caba5559bc21e14f6b2aa504cb14a1782751658b71409e25b82e432c0a97", "price_changes": [{"asset_id": "36586667785814641857008731622413716797407337292495614620493145114086484487337", "price": "0.232", "size": "400", "side": "BUY", "hash": "b6f8ea67211c6305402d373f6167228a4f0dc949", "best_bid": "0.48", "best_ask": "0.481"}, {"asset_id": "19214394437683566921750936876376421489271269944393354497977881791256347396217", "price": "0.768", "size": "400", "side": "SELL", "hash": "9c7ce837b59f94b8dfb552927a26176af5b012ab", "best_bid": "0.519", "best_ask": "0.52"}], "timestamp": "1782707676266", "event_type": "price_change"}}
{"local_timestamp": 1782707675.1549718, "slug": "will-lionel-messi-be-the-top-goalscorer-at-the-2026-fifa-world-cup", "data": {"market": "0xd2a8caba5559bc21e14f6b2aa504cb14a1782751658b71409e25b82e432c0a97", "price_changes": [{"asset_id": "36586667785814641857008731622413716797407337292495614620493145114086484487337", "price": "0.232", "size": "200", "side": "BUY", "hash": "060c667f41ef99e243ce5d400fc2e8c102cb5666", "best_bid": "0.48", "best_ask": "0.481"}, {"asset_id": "19214394437683566921750936876376421489271269944393354497977881791256347396217", "price": "0.768", "size": "200", "side": "SELL", "hash": "54066519eae0da1db42b6e26868858057e67e308", "best_bid": "0.519", "best_ask": "0.52"}], "timestamp": "1782707676385", "event_type": "price_change"}}
{"local_timestamp": 1782707675.7691317, "slug": "will-lionel-messi-be-the-top-goalscorer-at-the-2026-fifa-world-cup", "data": {"market": "0xd2a8caba5559bc21e14f6b2aa504cb14a1782751658b71409e25b82e432c0a97", "price_changes": [{"asset_id": "19214394437683566921750936876376421489271269944393354497977881791256347396217", "price": "0.26", "size": "0", "side": "BUY", "hash": "7d7eb8471bf54e3a070fa89948d00aa83ca94ee4", "best_bid": "0.519", "best_ask": "0.52"}, {"asset_id": "36586667785814641857008731622413716797407337292495614620493145114086484487337", "price": "0.74", "size": "0", "side": "SELL", "hash": "40b94f938825f68ce8136e8b8454d46fe4bbef4f", "best_bid": "0.48", "best_ask": "0.481"}], "timestamp": "1782707676999", "event_type": "price_change"}}
{"local_timestamp": 1782707675.7758827, "slug": "will-lionel-messi-be-the-top-goalscorer-at-the-2026-fifa-world-cup", "data": {"market": "0xd2a8caba5559bc21e14f6b2aa504cb14a1782751658b71409e25b82e432c0a97", "price_changes": [{"asset_id": "36586667785814641857008731622413716797407337292495614620493145114086484487337", "price": "0.34", "size": "199.99", "side": "BUY", "hash": "875e3b96ffb9ffcbe35edffe7b2563603b25461b", "best_bid": "0.48", "best_ask": "0.481"}, {"asset_id": "19214394437683566921750936876376421489271269944393354497977881791256347396217", "price": "0.66", "size": "199.99", "side": "SELL", "hash": "299894c1b173b5f1df5d8edff00b2dc75c35b633", "best_bid": "0.519", "best_ask": "0.52"}], "timestamp": "1782707677000", "event_type": "price_change"}}
{"local_timestamp": 1782707676.101664, "slug": "will-lionel-messi-be-the-top-goalscorer-at-the-2026-fifa-world-cup", "data": {"market": "0xd2a8caba5559bc21e14f6b2aa504cb14a1782751658b71409e25b82e432c0a97", "price_changes": [{"asset_id": "19214394437683566921750936876376421489271269944393354497977881791256347396217", "price": "0.521", "size": "4780.82", "side": "SELL", "hash": "ee461d3045674e8d87895246403b941a107f1d99", "best_bid": "0.519", "best_ask": "0.52"}, {"asset_id": "36586667785814641857008731622413716797407337292495614620493145114086484487337", "price": "0.479", "size": "4780.82", "side": "BUY", "hash": "d189175321bc3462863809e95dde4e7c6a749c6c", "best_bid": "0.48", "best_ask": "0.481"}], "timestamp": "1782707677331", "event_type": "price_change"}}
{"local_timestamp": 1782707676.7745667, "slug": "will-lionel-messi-be-the-top-goalscorer-at-the-2026-fifa-world-cup", "data": {"market": "0xd2a8caba5559bc21e14f6b2aa504cb14a1782751658b71409e25b82e432c0a97", "price_changes": [{"asset_id": "36586667785814641857008731622413716797407337292495614620493145114086484487337", "price": "0.479", "size": "4530.82", "side": "BUY", "hash": "f5a65445ffb66b209705444a8ef4f1435bbc435f", "best_bid": "0.48", "best_ask": "0.481"}, {"asset_id": "19214394437683566921750936876376421489271269944393354497977881791256347396217", "price": "0.521", "size": "4530.82", "side": "SELL", "hash": "2b4f79050910924a43802ad1f389712ce0853dac", "best_bid": "0.519", "best_ask": "0.52"}], "timestamp": "1782707678004", "event_type": "price_change"}}
{"local_timestamp": 1782707676.7762465, "slug": "will-lionel-messi-be-the-top-goalscorer-at-the-2026-fifa-world-cup", "data": {"market": "0xd2a8caba5559bc21e14f6b2aa504cb14a1782751658b71409e25b82e432c0a97", "price_changes": [{"asset_id": "19214394437683566921750936876376421489271269944393354497977881791256347396217", "price": "0.518", "size": "18629.1", "side": "BUY", "hash": "a52497f3a18d666731a5f7cad9e3e7f748d50f8e", "best_bid": "0.519", "best_ask": "0.52"}, {"asset_id": "36586667785814641857008731622413716797407337292495614620493145114086484487337", "price": "0.482", "size": "18629.1", "side": "SELL", "hash": "f5a65445ffb66b209705444a8ef4f1435bbc435f", "best_bid": "0.48", "best_ask": "0.481"}], "timestamp": "1782707678005", "event_type": "price_change"}}
{"local_timestamp": 1782707676.8963828, "slug": "will-lionel-messi-be-the-top-goalscorer-at-the-2026-fifa-world-cup", "data": {"market": "0xd2a8caba5559bc21e14f6b2aa504cb14a1782751658b71409e25b82e432c0a97", "price_changes": [{"asset_id": "36586667785814641857008731622413716797407337292495614620493145114086484487337", "price": "0.34", "size": "3199.99", "side": "BUY", "hash": "e8a2ea1e2fcca52c9fa749a3a2222faa200f87d6", "best_bid": "0.48", "best_ask": "0.481"}, {"asset_id": "19214394437683566921750936876376421489271269944393354497977881791256347396217", "price": "0.66", "size": "3199.99", "side": "SELL", "hash": "9ebdd611d6ae89f7f07cbeee993a79c331cbee19", "best_bid": "0.519", "best_ask": "0.52"}], "timestamp": "1782707678124", "event_type": "price_change"}}
{"local_timestamp": 1782707676.900548, "slug": "will-lionel-messi-be-the-top-goalscorer-at-the-2026-fifa-world-cup", "data": {"market": "0xd2a8caba5559bc21e14f6b2aa504cb14a1782751658b71409e25b82e432c0a97", "price_changes": [{"asset_id": "19214394437683566921750936876376421489271269944393354497977881791256347396217", "price": "0.26", "size": "3000", "side": "BUY", "hash": "a7b15415768d1b2d8e3896cdd8c6e92691acf0e7", "best_bid": "0.519", "best_ask": "0.52"}, {"asset_id": "36586667785814641857008731622413716797407337292495614620493145114086484487337", "price": "0.74", "size": "3000", "side": "SELL", "hash": "91891e17bc19d10c1aa0414a25667b0ae2e4135f", "best_bid": "0.48", "best_ask": "0.481"}], "timestamp": "1782707678129", "event_type": "price_change"}}
{"local_timestamp": 1782707677.7473607, "slug": "will-lionel-messi-be-the-top-goalscorer-at-the-2026-fifa-world-cup", "data": {"market": "0xd2a8caba5559bc21e14f6b2aa504cb14a1782751658b71409e25b82e432c0a97", "price_changes": [{"asset_id": "19214394437683566921750936876376421489271269944393354497977881791256347396217", "price": "0.319", "size": "200", "side": "BUY", "hash": "30d23acf71badd453681a0f05c5e75f3c802b5dc", "best_bid": "0.519", "best_ask": "0.52"}, {"asset_id": "36586667785814641857008731622413716797407337292495614620493145114086484487337", "price": "0.681", "size": "200", "side": "SELL", "hash": "8ccbab02306beacc22bc66777c1009ddf84fa69d", "best_bid": "0.48", "best_ask": "0.481"}], "timestamp": "1782707678977", "event_type": "price_change"}}
{"local_timestamp": 1782707677.777051, "slug": "will-lionel-messi-be-the-top-goalscorer-at-the-2026-fifa-world-cup", "data": {"market": "0xd2a8caba5559bc21e14f6b2aa504cb14a1782751658b71409e25b82e432c0a97", "price_changes": [{"asset_id": "19214394437683566921750936876376421489271269944393354497977881791256347396217", "price": "0.521", "size": "4433.73", "side": "SELL", "hash": "4dd730d1db3ed7565c9b1409fbb06fa713d60fdf", "best_bid": "0.519", "best_ask": "0.52"}, {"asset_id": "36586667785814641857008731622413716797407337292495614620493145114086484487337", "price": "0.479", "size": "4433.73", "side": "BUY", "hash": "ac8732592cd78094db3ce424036e9ab0b50f71fa", "best_bid": "0.48", "best_ask": "0.481"}], "timestamp": "1782707679004", "event_type": "price_change"}}
{"local_timestamp": 1782707677.8434925, "slug": "will-lionel-messi-be-the-top-goalscorer-at-the-2026-fifa-world-cup", "data": {"market": "0xd2a8caba5559bc21e14f6b2aa504cb14a1782751658b71409e25b82e432c0a97", "price_changes": [{"asset_id": "19214394437683566921750936876376421489271269944393354497977881791256347396217", "price": "0.318", "size": "0", "side": "BUY", "hash": "7061e18b21807bf9f9317d3f2d385bba1338da0d", "best_bid": "0.519", "best_ask": "0.52"}, {"asset_id": "36586667785814641857008731622413716797407337292495614620493145114086484487337", "price": "0.682", "size": "0", "side": "SELL", "hash": "91e34552bf8a75335e10ab975b8c2311dd792532", "best_bid": "0.48", "best_ask": "0.481"}], "timestamp": "1782707679072", "event_type": "price_change"}}
{"local_timestamp": 1782707678.2530599, "slug": "will-lionel-messi-be-the-top-goalscorer-at-the-2026-fifa-world-cup", "data": {"market": "0xd2a8caba5559bc21e14f6b2aa504cb14a1782751658b71409e25b82e432c0a97", "price_changes": [{"asset_id": "36586667785814641857008731622413716797407337292495614620493145114086484487337", "price": "0.477", "size": "0", "side": "BUY", "hash": "250dff87300a4a6282b5e013586aa184eaea5c74", "best_bid": "0.48", "best_ask": "0.481"}, {"asset_id": "19214394437683566921750936876376421489271269944393354497977881791256347396217", "price": "0.523", "size": "0", "side": "SELL", "hash": "ac581957e610cd74c2846b2fab75137c16b4f52b", "best_bid": "0.519", "best_ask": "0.52"}], "timestamp": "1782707679481", "event_type": "price_change"}}
{"local_timestamp": 1782707678.254026, "slug": "will-lionel-messi-be-the-top-goalscorer-at-the-2026-fifa-world-cup", "data": {"market": "0xd2a8caba5559bc21e14f6b2aa504cb14a1782751658b71409e25b82e432c0a97", "price_changes": [{"asset_id": "19214394437683566921750936876376421489271269944393354497977881791256347396217", "price": "0.516", "size": "968", "side": "BUY", "hash": "b920959d2e6542a7e75d97ef12348c864fbbb98b", "best_bid": "0.519", "best_ask": "0.52"}, {"asset_id": "36586667785814641857008731622413716797407337292495614620493145114086484487337", "price": "0.484", "size": "968", "side": "SELL", "hash": "a7ade442bcab13d5fdb224991013b18c90bd7d23", "best_bid": "0.48", "best_ask": "0.481"}], "timestamp": "1782707679482", "event_type": "price_change"}}
{"local_timestamp": 1782707678.3209674, "slug": "will-lionel-messi-be-the-top-goalscorer-at-the-2026-fifa-world-cup", "data": {"market": "0xd2a8caba5559bc21e14f6b2aa504cb14a1782751658b71409e25b82e432c0a97", "price_changes": [{"asset_id": "19214394437683566921750936876376421489271269944393354497977881791256347396217", "price": "0.515", "size": "250", "side": "BUY", "hash": "ecaf18299d57ea7dbdf025ac2cfe648fac1d9c35", "best_bid": "0.519", "best_ask": "0.52"}, {"asset_id": "36586667785814641857008731622413716797407337292495614620493145114086484487337", "price": "0.485", "size": "250", "side": "SELL", "hash": "865a398952849ca3f832f346b5a954afe58b8175", "best_bid": "0.48", "best_ask": "0.481"}], "timestamp": "1782707679548", "event_type": "price_change"}}
{"local_timestamp": 1782707678.3238971, "slug": "will-lionel-messi-be-the-top-goalscorer-at-the-2026-fifa-world-cup", "data": {"market": "0xd2a8caba5559bc21e14f6b2aa504cb14a1782751658b71409e25b82e432c0a97", "price_changes": [{"asset_id": "36586667785814641857008731622413716797407337292495614620493145114086484487337", "price": "0.476", "size": "1111.94", "side": "BUY", "hash": "72bb1fb1a157291d7bd7a04479c17e7712620f9d", "best_bid": "0.48", "best_ask": "0.481"}, {"asset_id": "19214394437683566921750936876376421489271269944393354497977881791256347396217", "price": "0.524", "size": "1111.94", "side": "SELL", "hash": "070aee97593eb07e8aa4aae4252618b1e4f595d1", "best_bid": "0.519", "best_ask": "0.52"}], "timestamp": "1782707679552", "event_type": "price_change"}}
{"local_timestamp": 1782707678.4119394, "slug": "will-lionel-messi-be-the-top-goalscorer-at-the-2026-fifa-world-cup", "data": {"market": "0xd2a8caba5559bc21e14f6b2aa504cb14a1782751658b71409e25b82e432c0a97", "price_changes": [{"asset_id": "19214394437683566921750936876376421489271269944393354497977881791256347396217", "price": "0.26", "size": "0", "side": "BUY", "hash": "a74f5ea08cfcb3559bf51516b5ddd209f1658112", "best_bid": "0.519", "best_ask": "0.52"}, {"asset_id": "36586667785814641857008731622413716797407337292495614620493145114086484487337", "price": "0.74", "size": "0", "side": "SELL", "hash": "8f8b55da15f7caa43271602b0ac6acafefda0abb", "best_bid": "0.48", "best_ask": "0.481"}], "timestamp": "1782707679639", "event_type": "price_change"}}
{"local_timestamp": 1782707678.4128802, "slug": "will-lionel-messi-be-the-top-goalscorer-at-the-2026-fifa-world-cup", "data": {"market": "0xd2a8caba5559bc21e14f6b2aa504cb14a1782751658b71409e25b82e432c0a97", "price_changes": [{"asset_id": "36586667785814641857008731622413716797407337292495614620493145114086484487337", "price": "0.34", "size": "199.99", "side": "BUY", "hash": "2a013f8f2c4078ffa710cb0f064b5c9a9e6cd038", "best_bid": "0.48", "best_ask": "0.481"}, {"asset_id": "19214394437683566921750936876376421489271269944393354497977881791256347396217", "price": "0.66", "size": "199.99", "side": "SELL", "hash": "579b625716f69515139734fff182e482768ab10a", "best_bid": "0.519", "best_ask": "0.52"}], "timestamp": "1782707679639", "event_type": "price_change"}}
{"local_timestamp": 1782707678.4761343, "slug": "will-lionel-messi-be-the-top-goalscorer-at-the-2026-fifa-world-cup", "data": {"market": "0xd2a8caba5559bc21e14f6b2aa504cb14a1782751658b71409e25b82e432c0a97", "price_changes": [{"asset_id": "36586667785814641857008731622413716797407337292495614620493145114086484487337", "price": "0.474", "size": "595.35", "side": "BUY", "hash": "f23f44139c86ba7f8507383724a10ec814df0f52", "best_bid": "0.48", "best_ask": "0.481"}, {"asset_id": "19214394437683566921750936876376421489271269944393354497977881791256347396217", "price": "0.526", "size": "595.35", "side": "SELL", "hash": "eaa1106e8365dbf15fb392cf5927d56c8dea0329", "best_bid": "0.519", "best_ask": "0.52"}], "timestamp": "1782707679706", "event_type": "price_change"}}
{"local_timestamp": 1782707678.4947298, "slug": "will-lionel-messi-be-the-top-goalscorer-at-the-2026-fifa-world-cup", "data": {"market": "0xd2a8caba5559bc21e14f6b2aa504cb14a1782751658b71409e25b82e432c0a97", "price_changes": [{"asset_id": "36586667785814641857008731622413716797407337292495614620493145114086484487337", "price": "0.474", "size": "295.35", "side": "BUY", "hash": "2f7a9355bbc8b610793b1c1a3e0d92682d2dc4ab", "best_bid": "0.48", "best_ask": "0.481"}, {"asset_id": "19214394437683566921750936876376421489271269944393354497977881791256347396217", "price": "0.526", "size": "295.35", "side": "SELL", "hash": "2c31c6ebd9eecfe605918fa66ed1900699fd83dc", "best_bid": "0.519", "best_ask": "0.52"}], "timestamp": "1782707679725", "event_type": "price_change"}}
{"local_timestamp": 1782707679.9295917, "slug": "will-lionel-messi-be-the-top-goalscorer-at-the-2026-fifa-world-cup", "data": {"market": "0xd2a8caba5559bc21e14f6b2aa504cb14a1782751658b71409e25b82e432c0a97", "price_changes": [{"asset_id": "36586667785814641857008731622413716797407337292495614620493145114086484487337", "price": "0.34", "size": "3199.99", "side": "BUY", "hash": "10a21c6af771ae04f82a6ef92bd6811232469d6e", "best_bid": "0.48", "best_ask": "0.481"}, {"asset_id": "19214394437683566921750936876376421489271269944393354497977881791256347396217", "price": "0.66", "size": "3199.99", "side": "SELL", "hash": "01c4c50d7e36db273eee8dcd5e081021a36f5d4d", "best_bid": "0.519", "best_ask": "0.52"}], "timestamp": "1782707681160", "event_type": "price_change"}}
{"local_timestamp": 1782707679.9337273, "slug": "will-lionel-messi-be-the-top-goalscorer-at-the-2026-fifa-world-cup", "data": {"market": "0xd2a8caba5559bc21e14f6b2aa504cb14a1782751658b71409e25b82e432c0a97", "price_changes": [{"asset_id": "19214394437683566921750936876376421489271269944393354497977881791256347396217", "price": "0.26", "size": "3000", "side": "BUY", "hash": "e2c1274f087dd96b1b1db9ed5779880f36b19539", "best_bid": "0.519", "best_ask": "0.52"}, {"asset_id": "36586667785814641857008731622413716797407337292495614620493145114086484487337", "price": "0.74", "size": "3000", "side": "SELL", "hash": "c871c74f699bd718e1386f390db5013297a72771", "best_bid": "0.48", "best_ask": "0.481"}], "timestamp": "1782707681164", "event_type": "price_change"}}
{"local_timestamp": 1782707680.1032367, "slug": "will-lionel-messi-be-the-top-goalscorer-at-the-2026-fifa-world-cup", "data": {"market": "0xd2a8caba5559bc21e14f6b2aa504cb14a1782751658b71409e25b82e432c0a97", "price_changes": [{"asset_id": "36586667785814641857008731622413716797407337292495614620493145114086484487337", "price": "0.34", "size": "199.99", "side": "BUY", "hash": "b39a0a2377467cc70120649b6e6d0214c5f4e473", "best_bid": "0.48", "best_ask": "0.481"}, {"asset_id": "19214394437683566921750936876376421489271269944393354497977881791256347396217", "price": "0.66", "size": "199.99", "side": "SELL", "hash": "f989feb996564cd42638a979a7f63c701653b914", "best_bid": "0.519", "best_ask": "0.52"}], "timestamp": "1782707681331", "event_type": "price_change"}}
{"local_timestamp": 1782707680.1053135, "slug": "will-lionel-messi-be-the-top-goalscorer-at-the-2026-fifa-world-cup", "data": {"market": "0xd2a8caba5559bc21e14f6b2aa504cb14a1782751658b71409e25b82e432c0a97", "price_changes": [{"asset_id": "19214394437683566921750936876376421489271269944393354497977881791256347396217", "price": "0.26", "size": "0", "side": "BUY", "hash": "522683fa0b66b3647d9fb845c2fed8ba8633e2f2", "best_bid": "0.519", "best_ask": "0.52"}, {"asset_id": "36586667785814641857008731622413716797407337292495614620493145114086484487337", "price": "0.74", "size": "0", "side": "SELL", "hash": "d90f6e8d28b5c267616eaca6eb25ae852c6fce5f", "best_bid": "0.48", "best_ask": "0.481"}], "timestamp": "1782707681331", "event_type": "price_change"}}
{"local_timestamp": 1782707680.4864523, "slug": "will-lionel-messi-be-the-top-goalscorer-at-the-2026-fifa-world-cup", "data": {"market": "0xd2a8caba5559bc21e14f6b2aa504cb14a1782751658b71409e25b82e432c0a97", "price_changes": [{"asset_id": "19214394437683566921750936876376421489271269944393354497977881791256347396217", "price": "0.52", "size": "446.3", "side": "SELL", "hash": "f300e4a2435f2fd1fd25da9a4582584c53f33f54", "best_bid": "0.519", "best_ask": "0.52"}, {"asset_id": "36586667785814641857008731622413716797407337292495614620493145114086484487337", "price": "0.48", "size": "446.3", "side": "BUY", "hash": "4575b2449418917adb7d56c260c17cdae4993bcd", "best_bid": "0.48", "best_ask": "0.481"}], "timestamp": "1782707681717", "event_type": "price_change"}}
