{"local_timestamp": 1782707680.4943073, "slug": "will-lionel-messi-be-the-top-goalscorer-at-the-2026-fifa-world-cup", "data": {"market": "0xd2a8caba5559bc21e14f6b2aa504cb14a1782751658b71409e25b82e432c0a97", "asset_id": "19214394437683566921750936876376421489271269944393354497977881791256347396217", "bids": [{"price": "0.001", "size": "1012937"}, {"price": "0.002", "size": "28250"}, {"price": "0.003", "size": "5149.96"}, {"price": "0.004", "size": "3000"}, {"price": "0.005", "size": "2400"}, {"price": "0.006", "size": "1999.93"}, {"price": "0.007", "size": "3142.81"}, {"price": "0.008", "size": "2750"}, {"price": "0.009", "size": "2444.41"}, {"price": "0.01", "size": "22219.34"}, {"price": "0.011", "size": "181.81"}, {"price": "0.012", "size": "1666.66"}, {"price": "0.013", "size": "1122.81"}, {"price": "0.014", "size": "142.85"}, {"price": "0.015", "size": "133.33"}, {"price": "0.016", "size": "125"}, {"price": "0.017", "size": "117.64"}, {"price": "0.018", "size": "111.11"}, {"price": "0.019", "size": "105.26"}, {"price": "0.02", "size": "100"}, {"price": "0.021", "size": "95.23"}, {"price": "0.022", "size": "90.9"}, {"price": "0.023", "size": "86.95"}, {"price": "0.024", "size": "83.33"}, {"price": "0.025", "size": "80"}, {"price": "0.026", "size": "76.92"}, {"price": "0.027", "size": "74.07"}, {"price": "0.028", "size": "71.42"}, {"price": "0.029", "size": "68.96"}, {"price": "0.03", "size": "66.66"}, {"price": "0.031", "size": "64.51"}, {"price": "0.032", "size": "62.5"}, {"price": "0.033", "size": "60.6"}, {"price": "0.04", "size": "350"}, {"price": "0.041", "size": "102"}, {"price": "0.042", "size": "136.15"}, {"price": "0.043", "size": "191.99"}, {"price": "0.05", "size": "1250"}, {"price": "0.051", "size": "450"}, {"price": "0.052", "size": "45.26"}, {"price": "0.054", "size": "15"}, {"price": "0.055", "size": "1119.42"}, {"price": "0.057", "size": "91.58"}, {"price": "0.058", "size": "1000"}, {"price": "0.059", "size": "97"}, {"price": "0.06", "size": "292"}, {"price": "0.111", "size": "250"}, {"price": "0.132", "size": "2499.97"}, {"price": "0.182", "size": "2500"}, {"price": "0.19", "size": "86.63"}, {"price": "0.2", "size": "12.29"}, {"price": "0.201", "size": "200"}, {"price": "0.202", "size": "5.11"}, {"price": "0.206", "size": "5"}, {"price": "0.241", "size": "621"}, {"price": "0.242", "size": "455.43"}, {"price": "0.27", "size": "291.16"}, {"price": "0.281", "size": "10000"}, {"price": "0.282", "size": "2000"}, {"price": "0.298", "size": "3000"}, {"price": "0.3", "size": "146.72"}, {"price": "0.317", "size": "1000"}, {"price": "0.319", "size": "200"}, {"price": "0.33", "size": "200"}, {"price": "0.334", "size": "5.09"}, {"price": "0.337", "size": "699.99"}, {"price": "0.341", "size": "209.99"}, {"price": "0.346", "size": "500"}, {"price": "0.35", "size": "1000"}, {"price": "0.358", "size": "32.52"}, {"price": "0.361", "size": "900"}, {"price": "0.366", "size": "100"}, {"price": "0.373", "size": "100"}, {"price": "0.377", "size": "434.96"}, {"price": "0.378", "size": "40"}, {"price": "0.379", "size": "5"}, {"price": "0.381", "size": "100"}, {"price": "0.382", "size": "40.49"}, {"price": "0.389", "size": "333.19"}, {"price": "0.391", "size": "17"}, {"price": "0.4", "size": "230"}, {"price": "0.402", "size": "100"}, {"price": "0.41", "size": "5"}, {"price": "0.425", "size": "220"}, {"price": "0.445", "size": "10"}, {"price": "0.447", "size": "50"}, {"price": "0.46", "size": "700"}, {"price": "0.47", "size": "1975"}, {"price": "0.48", "size": "2475"}, {"price": "0.481", "size": "1445"}, {"price": "0.486", "size": "2234.64"}, {"price": "0.487", "size": "9883"}, {"price": "0.488", "size": "6921"}, {"price": "0.49", "size": "8451"}, {"price": "0.491", "size": "10833.34"}, {"price": "0.492", "size": "1500"}, {"price": "0.495", "size": "250"}, {"price": "0.498", "size": "5646.52"}, {"price": "0.499", "size": "58223"}, {"price": "0.5", "size": "28432"}, {"price": "0.501", "size": "2700"}, {"price": "0.502", "size": "441.38"}, {"price": "0.505", "size": "445.68"}, {"price": "0.506", "size": "258.04"}, {"price": "0.508", "size": "400"}, {"price": "0.509", "size": "2300"}, {"price": "0.51", "size": "11"}, {"price": "0.511", "size": "1967.5"}, {"price": "0.512", "size": "250"}, {"price": "0.515", "size": "250"}, {"price": "0.516", "size": "968"}, {"price": "0.517", "size": "400"}, {"price": "0.518", "size": "18629.1"}, {"price": "0.519", "size": "909.93"}], "asks": [{"price": "0.999", "size": "21003050.58"}, {"price": "0.998", "size": "13507.31"}, {"price": "0.997", "size": "90666.66"}, {"price": "0.996", "size": "506.67"}, {"price": "0.995", "size": "400"}, {"price": "0.994", "size": "333.33"}, {"price": "0.993", "size": "290.94"}, {"price": "0.992", "size": "250"}, {"price": "0.991", "size": "222.22"}, {"price": "0.99", "size": "10800.65"}, {"price": "0.989", "size": "60181.81"}, {"price": "0.988", "size": "966.66"}, {"price": "0.987", "size": "158.91"}, {"price": "0.986", "size": "142.85"}, {"price": "0.985", "size": "133.33"}, {"price": "0.984", "size": "125"}, {"price": "0.983", "size": "117.64"}, {"price": "0.982", "size": "111.11"}, {"price": "0.981", "size": "155.26"}, {"price": "0.98", "size": "1100"}, {"price": "0.979", "size": "3095.23"}, {"price": "0.978", "size": "90.9"}, {"price": "0.977", "size": "86.95"}, {"price": "0.976", "size": "83.33"}, {"price": "0.975", "size": "85.08"}, {"price": "0.974", "size": "76.92"}, {"price": "0.973", "size": "74.07"}, {"price": "0.972", "size": "71.42"}, {"price": "0.971", "size": "68.96"}, {"price": "0.97", "size": "66.66"}, {"price": "0.969", "size": "64.51"}, {"price": "0.968", "size": "62.5"}, {"price": "0.967", "size": "60.6"}, {"price": "0.95", "size": "20"}, {"price": "0.949", "size": "8.83"}, {"price": "0.92", "size": "1000"}, {"price": "0.904", "size": "50"}, {"price": "0.9", "size": "5"}, {"price": "0.89", "size": "700"}, {"price": "0.88", "size": "500"}, {"price": "0.87", "size": "500"}, {"price": "0.86", "size": "499.99"}, {"price": "0.85", "size": "410.99"}, {"price": "0.84", "size": "300"}, {"price": "0.839", "size": "10.21"}, {"price": "0.834", "size": "50"}, {"price": "0.83", "size": "300"}, {"price": "0.82", "size": "300"}, {"price": "0.81", "size": "16"}, {"price": "0.808", "size": "2000"}, {"price": "0.8", "size": "1005"}, {"price": "0.778", "size": "2000"}, {"price": "0.772", "size": "50"}, {"price": "0.77", "size": "300"}, {"price": "0.768", "size": "200"}, {"price": "0.765", "size": "1241"}, {"price": "0.763", "size": "400"}, {"price": "0.75", "size": "145.44"}, {"price": "0.748", "size": "2000"}, {"price": "0.74", "size": "300"}, {"price": "0.73", "size": "300"}, {"price": "0.729", "size": "100"}, {"price": "0.72", "size": "5"}, {"price": "0.718", "size": "2000"}, {"price": "0.717", "size": "50"}, {"price": "0.716", "size": "462.07"}, {"price": "0.69", "size": "300"}, {"price": "0.688", "size": "2100"}, {"price": "0.68", "size": "200"}, {"price": "0.67", "size": "200"}, {"price": "0.669", "size": "50"}, {"price": "0.66", "size": "199.99"}, {"price": "0.658", "size": "2000"}, {"price": "0.65", "size": "200"}, {"price": "0.64", "size": "200"}, {"price": "0.639", "size": "50"}, {"price": "0.637", "size": "2000"}, {"price": "0.63", "size": "200"}, {"price": "0.629", "size": "50"}, {"price": "0.628", "size": "186.76"}, {"price": "0.626", "size": "2000"}, {"price": "0.62", "size": "1000"}, {"price": "0.619", "size": "100"}, {"price": "0.616", "size": "1537"}, {"price": "0.61", "size": "2075"}, {"price": "0.606", "size": "1537"}, {"price": "0.6", "size": "2696.3"}, {"price": "0.598", "size": "350"}, {"price": "0.596", "size": "1287"}, {"price": "0.595", "size": "50"}, {"price": "0.59", "size": "2396.3"}, {"price": "0.589", "size": "150"}, {"price": "0.588", "size": "50"}, {"price": "0.586", "size": "1010"}, {"price": "0.58", "size": "1996.3"}, {"price": "0.579", "size": "25"}, {"price": "0.578", "size": "45"}, {"price": "0.573", "size": "31"}, {"price": "0.57", "size": "150"}, {"price": "0.569", "size": "11.3"}, {"price": "0.568", "size": "30"}, {"price": "0.567", "size": "30"}, {"price": "0.558", "size": "2019.99"}, {"price": "0.554", "size": "1604"}, {"price": "0.553", "size": "3029.72"}, {"price": "0.552", "size": "1000"}, {"price": "0.551", "size": "150"}, {"price": "0.55", "size": "2660"}, {"price": "0.546", "size": "1500"}, {"price": "0.545", "size": "1976"}, {"price": "0.543", "size": "40000"}, {"price": "0.542", "size": "205200"}, {"price": "0.54", "size": "44808"}, {"price": "0.539", "size": "20"}, {"price": "0.535", "size": "1294.7"}, {"price": "0.531", "size": "200"}, {"price": "0.53", "size": "19178"}, {"price": "0.529", "size": "200"}, {"price": "0.527", "size": "250"}, {"price": "0.526", "size": "295.35"}, {"price": "0.525", "size": "6937.77"}, {"price": "0.524", "size": "1111.94"}, {"price": "0.522", "size": "409.99"}, {"price": "0.521", "size": "4433.73"}, {"price": "0.52", "size": "446.3"}], "hash": "f300e4a2435f2fd1fd25da9a4582584c53f33f54", "timestamp": "1782707681717", "event_type": "book"}}
{"local_timestamp": 1782707680.5094237, "slug": "will-lionel-messi-be-the-top-goalscorer-at-the-2026-fifa-world-cup", "data": {"market": "0xd2a8caba5559bc21e14f6b2aa504cb14a1782751658b71409e25b82e432c0a97", "asset_id": "19214394437683566921750936876376421489271269944393354497977881791256347396217", "price": "0.52", "size": "8.05", "fee_rate_bps": "0", "side": "BUY", "timestamp": "1782707681737", "event_type": "last_trade_price", "transaction_hash": "0x2e2fc13e7414ef3b95b550e65cecee896d77e7ec772c8601d8cc2f6a57871f1f"}}
{"local_timestamp": 1782707680.578437, "slug": "will-lionel-messi-be-the-top-goalscorer-at-the-2026-fifa-world-cup", "data": {"market": "0xd2a8caba5559bc21e14f6b2aa504cb14a1782751658b71409e25b82e432c0a97", "price_changes": [{"asset_id": "19214394437683566921750936876376421489271269944393354497977881791256347396217", "price": "0.519", "size": "699.93", "side": "BUY", "hash": "6d8a60b734b3e0d8335b70bc858c9258ce7252ff", "best_bid": "0.519", "best_ask": "0.52"}, {"asset_id": "36586667785814641857008731622413716797407337292495614620493145114086484487337", "price": "0.481", "size": "699.93", "side": "SELL", "hash": "dea42ddb31d163672010389e5cf2b88e85947d28", "best_bid": "0.48", "best_ask": "0.481"}], "timestamp": "1782707681809", "event_type": "price_change"}}
{"local_timestamp": 1782707680.7204144, "slug": "will-lionel-messi-be-the-top-goalscorer-at-the-2026-fifa-world-cup", "data": {"market": "0xd2a8caba5559bc21e14f6b2aa504cb14a1782751658b71409e25b82e432c0a97", "price_changes": [{"asset_id": "36586667785814641857008731622413716797407337292495614620493145114086484487337", "price": "0.476", "size": "861.94", "side": "BUY", "hash": "d072e0b89e93c2e15bbf569b13e3c55d85f37648", "best_bid": "0.48", "best_ask": "0.481"}, {"asset_id": "19214394437683566921750936876376421489271269944393354497977881791256347396217", "price": "0.524", "size": "861.94", "side": "SELL", "hash": "934d411feff3cf3199da3a0b521fc31fae97c099", "best_bid": "0.519", "best_ask": "0.52"}], "timestamp": "1782707681826", "event_type": "price_change"}}
{"local_timestamp": 1782707680.7223647, "slug": "will-lionel-messi-be-the-top-goalscorer-at-the-2026-fifa-world-cup", "data": {"market": "0xd2a8caba5559bc21e14f6b2aa504cb14a1782751658b71409e25b82e432c0a97", "price_changes": [{"asset_id": "19214394437683566921750936876376421489271269944393354497977881791256347396217", "price": "0.515", "size": "0", "side": "BUY", "hash": "5a66763782c701198d198a98c3a29a09eb7e43da", "best_bid": "0.519", "best_ask": "0.52"}, {"asset_id": "36586667785814641857008731622413716797407337292495614620493145114086484487337", "price": "0.485", "size": "0", "side": "SELL", "hash": "be28d778572cb18a79aa7d878b4486573b44d5d5", "best_bid": "0.48", "best_ask": "0.481"}], "timestamp": "1782707681826", "event_type": "price_change"}}
{"local_timestamp": 1782707680.723983, "slug": "will-lionel-messi-be-the-top-goalscorer-at-the-2026-fifa-world-cup", "data": {"market": "0xd2a8caba5559bc21e14f6b2aa504cb14a1782751658b71409e25b82e432c0a97", "price_changes": [{"asset_id": "36586667785814641857008731622413716797407337292495614620493145114086484487337", "price": "0.48", "size": "236.3", "side": "BUY", "hash": "53ed8006dda6b032eb3bf4da85152682f35b805c", "best_bid": "0.48", "best_ask": "0.481"}, {"asset_id": "19214394437683566921750936876376421489271269944393354497977881791256347396217", "price": "0.52", "size": "236.3", "side": "SELL", "hash": "c173fbf37b78d4f7295c4b08579794221404e689", "best_bid": "0.519", "best_ask": "0.52"}], "timestamp": "1782707681874", "event_type": "price_change"}}
{"local_timestamp": 1782707680.7255418, "slug": "will-lionel-messi-be-the-top-goalscorer-at-the-2026-fifa-world-cup", "data": {"market": "0xd2a8caba5559bc21e14f6b2aa504cb14a1782751658b71409e25b82e432c0a97", "price_changes": [{"asset_id": "19214394437683566921750936876376421489271269944393354497977881791256347396217", "price": "0.514", "size": "250", "side": "BUY", "hash": "8acdcf0d7aefa80e1512180939074c05a324d16b", "best_bid": "0.519", "best_ask": "0.52"}, {"asset_id": "36586667785814641857008731622413716797407337292495614620493145114086484487337", "price": "0.486", "size": "250", "side": "SELL", "hash": "39530c0c2486b03fa3eac7268e9e590911d93b06", "best_bid": "0.48", "best_ask": "0.481"}], "timestamp": "1782707681904", "event_type": "price_change"}}
{"local_timestamp": 1782707680.7275648, "slug": "will-lionel-messi-be-the-top-goalscorer-at-the-2026-fifa-world-cup", "data": {"market": "0xd2a8caba5559bc21e14f6b2aa504cb14a1782751658b71409e25b82e432c0a97", "price_changes": [{"asset_id": "36586667785814641857008731622413716797407337292495614620493145114086484487337", "price": "0.475", "size": "7187.77", "side": "BUY", "hash": "7d6f777973ad210344f91f4696cdde1e5799a42a", "best_bid": "0.48", "best_ask": "0.481"}, {"asset_id": "19214394437683566921750936876376421489271269944393354497977881791256347396217", "price": "0.525", "size": "7187.77", "side": "SELL", "hash": "bea4bae5944a244762acb45073c218fedeb6b6af", "best_bid": "0.519", "best_ask": "0.52"}], "timestamp": "1782707681906", "event_type": "price_change"}}
{"local_timestamp": 1782707681.2538655, "slug": "will-lionel-messi-be-the-top-goalscorer-at-the-2026-fifa-world-cup", "data": {"market": "0xd2a8caba5559bc21e14f6b2aa504cb14a1782751658b71409e25b82e432c0a97", "price_changes": [{"asset_id": "19214394437683566921750936876376421489271269944393354497977881791256347396217", "price": "0.521", "size": "4530.82", "side": "SELL", "hash": "b1afcfb54f9edb204d1a67f7fe6d350af37b4f41", "best_bid": "0.519", "best_ask": "0.52"}, {"asset_id": "36586667785814641857008731622413716797407337292495614620493145114086484487337", "price": "0.479", "size": "4530.82", "side": "BUY", "hash": "8ada4188dbe5bec0730e98c2c343e15e45207973", "best_bid": "0.48", "best_ask": "0.481"}], "timestamp": "1782707682479", "event_type": "price_change"}}
{"local_timestamp": 1782707681.409387, "slug": "will-lionel-messi-be-the-top-goalscorer-at-the-2026-fifa-world-cup", "data": {"market": "0xd2a8caba5559bc21e14f6b2aa504cb14a1782751658b71409e25b82e432c0a97", "price_changes": [{"asset_id": "36586667785814641857008731622413716797407337292495614620493145114086484487337", "price": "0.35", "size": "3200", "side": "BUY", "hash": "8a14594b453cf954a68b7f525532b4f7feab1881", "best_bid": "0.48", "best_ask": "0.481"}, {"asset_id": "19214394437683566921750936876376421489271269944393354497977881791256347396217", "price": "0.65", "size": "3200", "side": "SELL", "hash": "286a4529dd4db82eac6d0142edc8544137f24509", "best_bid": "0.519", "best_ask": "0.52"}], "timestamp": "1782707682638", "event_type": "price_change"}}
{"local_timestamp": 1782707681.4131575, "slug": "will-lionel-messi-be-the-top-goalscorer-at-the-2026-fifa-world-cup", "data": {"market": "0xd2a8caba5559bc21e14f6b2aa504cb14a1782751658b71409e25b82e432c0a97", "price_changes": [{"asset_id": "19214394437683566921750936876376421489271269944393354497977881791256347396217", "price": "0.26", "size": "3000", "side": "BUY", "hash": "cb551a247a88ecd42098ae78b2ec371be30da76c", "best_bid": "0.519", "best_ask": "0.52"}, {"asset_id": "36586667785814641857008731622413716797407337292495614620493145114086484487337", "price": "0.74", "size": "3000", "side": "SELL", "hash": "8db52b0f6d2619e3dfa0a09ff6488c5f2e2afd4e", "best_bid": "0.48", "best_ask": "0.481"}], "timestamp": "1782707682643", "event_type": "price_change"}}
{"local_timestamp": 1782707681.780619, "slug": "will-lionel-messi-be-the-top-goalscorer-at-the-2026-fifa-world-cup", "data": {"market": "0xd2a8caba5559bc21e14f6b2aa504cb14a1782751658b71409e25b82e432c0a97", "price_changes": [{"asset_id": "19214394437683566921750936876376421489271269944393354497977881791256347396217", "price": "0.5", "size": "28232", "side": "BUY", "hash": "fcf22de454fb5bbbb717d4fe42453df503cc85ef", "best_bid": "0.519", "best_ask": "0.52"}, {"asset_id": "36586667785814641857008731622413716797407337292495614620493145114086484487337", "price": "0.5", "size": "28232", "side": "SELL", "hash": "7c82419d3bcbff30c97825e6d8fd3ab438eb2926", "best_bid": "0.48", "best_ask": "0.481"}], "timestamp": "1782707683010", "event_type": "price_change"}}
{"local_timestamp": 1782707681.7828138, "slug": "will-lionel-messi-be-the-top-goalscorer-at-the-2026-fifa-world-cup", "data": {"market": "0xd2a8caba5559bc21e14f6b2aa504cb14a1782751658b71409e25b82e432c0a97", "price_changes": [{"asset_id": "36586667785814641857008731622413716797407337292495614620493145114086484487337", "price": "0.46", "size": "44608", "side": "BUY", "hash": "4252a6c167af906430961fc63e8237e1ccb00049", "best_bid": "0.48", "best_ask": "0.481"}, {"asset_id": "19214394437683566921750936876376421489271269944393354497977881791256347396217", "price": "0.54", "size": "44608", "side": "SELL", "hash": "e69e2f023c20378369735d5a92d22eb8100895a3", "best_bid": "0.519", "best_ask": "0.52"}], "timestamp": "1782707683011", "event_type": "price_change"}}
{"local_timestamp": 1782707681.822946, "slug": "will-lionel-messi-be-the-top-goalscorer-at-the-2026-fifa-world-cup", "data": {"market": "0xd2a8caba5559bc21e14f6b2aa504cb14a1782751658b71409e25b82e432c0a97", "price_changes": [{"asset_id": "36586667785814641857008731622413716797407337292495614620493145114086484487337", "price": "0.46", "size": "44808", "side": "BUY", "hash": "5abeff835fa1c06382b5c50c16404c668d8e437c", "best_bid": "0.48", "best_ask": "0.481"}, {"asset_id": "19214394437683566921750936876376421489271269944393354497977881791256347396217", "price": "0.54", "size": "44808", "side": "SELL", "hash": "555b18129a802edd61fdffb784e3256a95a57a37", "best_bid": "0.519", "best_ask": "0.52"}], "timestamp": "1782707683053", "event_type": "price_change"}}
{"local_timestamp": 1782707681.8371403, "slug": "will-lionel-messi-be-the-top-goalscorer-at-the-2026-fifa-world-cup", "data": {"market": "0xd2a8caba5559bc21e14f6b2aa504cb14a1782751658b71409e25b82e432c0a97", "price_changes": [{"asset_id": "19214394437683566921750936876376421489271269944393354497977881791256347396217", "price": "0.5", "size": "28432", "side": "BUY", "hash": "f6e64a6673e4f7429129affa22e58a8bd90d41f2", "best_bid": "0.519", "best_ask": "0.52"}, {"asset_id": "36586667785814641857008731622413716797407337292495614620493145114086484487337", "price": "0.5", "size": "28432", "side": "SELL", "hash": "e902bb7a8b045758abcdf67d6d700b5ccddbbf6e", "best_bid": "0.48", "best_ask": "0.481"}], "timestamp": "1782707683068", "event_type": "price_change"}}
{"local_timestamp": 1782707682.8170166, "slug": "will-lionel-messi-be-the-top-goalscorer-at-the-2026-fifa-world-cup", "data": {"market": "0xd2a8caba5559bc21e14f6b2aa504cb14a1782751658b71409e25b82e432c0a97", "price_changes": [{"asset_id": "19214394437683566921750936876376421489271269944393354497977881791256347396217", "price": "0.521", "size": "4433.73", "side": "SELL", "hash": "69282167b3097edc00c18b3015d26a79536bb441", "best_bid": "0.519", "best_ask": "0.52"}, {"asset_id": "36586667785814641857008731622413716797407337292495614620493145114086484487337", "price": "0.479", "size": "4433.73", "side": "BUY", "hash": "1fcfd5e0ff2db10281de5c31549a9bf6f5892079", "best_bid": "0.48", "best_ask": "0.481"}], "timestamp": "1782707684047", "event_type": "price_change"}}
{"local_timestamp": 1782707682.8358505, "slug": "will-lionel-messi-be-the-top-goalscorer-at-the-2026-fifa-world-cup", "data": {"market": "0xd2a8caba5559bc21e14f6b2aa504cb14a1782751658b71409e25b82e432c0a97", "price_changes": [{"asset_id": "36586667785814641857008731622413716797407337292495614620493145114086484487337", "price": "0.35", "size": "200", "side": "BUY", "hash": "4bd4cece173382934307dbf315b2a192fea7d15f", "best_bid": "0.48", "best_ask": "0.481"}, {"asset_id": "19214394437683566921750936876376421489271269944393354497977881791256347396217", "price": "0.65", "size": "200", "side": "SELL", "hash": "e7169b3a9a3e313a3653fb3af1ddf810decd1169", "best_bid": "0.519", "best_ask": "0.52"}], "timestamp": "1782707684066", "event_type": "price_change"}}
{"local_timestamp": 1782707682.8382556, "slug": "will-lionel-messi-be-the-top-goalscorer-at-the-2026-fifa-world-cup", "data": {"market": "0xd2a8caba5559bc21e14f6b2aa504cb14a1782751658b71409e25b82e432c0a97", "price_changes": [{"asset_id": "19214394437683566921750936876376421489271269944393354497977881791256347396217", "price": "0.26", "size": "0", "side": "BUY", "hash": "05307d2b1985cbe9d9a0dfd92115a4b2b6e4bfa4", "best_bid": "0.519", "best_ask": "0.52"}, {"asset_id": "36586667785814641857008731622413716797407337292495614620493145114086484487337", "price": "0.74", "size": "0", "side": "SELL", "hash": "197c212e41f5d345d87c0cf3a17db049925c4319", "best_bid": "0.48", "best_ask": "0.481"}], "timestamp": "1782707684066", "event_type": "price_change"}}
{"local_timestamp": 1782707683.619463, "slug": "will-lionel-messi-be-the-top-goalscorer-at-the-2026-fifa-world-cup", "data": {"market": "0xd2a8caba5559bc21e14f6b2aa504cb14a1782751658b71409e25b82e432c0a97", "price_changes": [{"asset_id": "19214394437683566921750936876376421489271269944393354497977881791256347396217", "price": "0.32", "size": "200", "side": "BUY", "hash": "1bd3e2989ae9a4e7af93fffe99d2de1c8c45be4d", "best_bid": "0.519", "best_ask": "0.52"}, {"asset_id": "36586667785814641857008731622413716797407337292495614620493145114086484487337", "price": "0.68", "size": "200", "side": "SELL", "hash": "1b10fdba94b4ac95d4a4ffa7f08bf9126d16d961", "best_bid": "0.48", "best_ask": "0.481"}], "timestamp": "1782707684849", "event_type": "price_change"}}
{"local_timestamp": 1782707683.7184875, "slug": "will-lionel-messi-be-the-top-goalscorer-at-the-2026-fifa-world-cup", "data": {"market": "0xd2a8caba5559bc21e14f6b2aa504cb14a1782751658b71409e25b82e432c0a97", "price_changes": [{"asset_id": "19214394437683566921750936876376421489271269944393354497977881791256347396217", "price": "0.319", "size": "0", "side": "BUY", "hash": "b2418ac0a10fb279ccc23386e7c6cbda1815f215", "best_bid": "0.519", "best_ask": "0.52"}, {"asset_id": "36586667785814641857008731622413716797407337292495614620493145114086484487337", "price": "0.681", "size": "0", "side": "SELL", "hash": "4c751563d49ff8eaf8560efeb6ce3bc9f4d0455a", "best_bid": "0.48", "best_ask": "0.481"}], "timestamp": "1782707684948", "event_type": "price_change"}}
{"local_timestamp": 1782707684.4052527, "slug": "will-lionel-messi-be-the-top-goalscorer-at-the-2026-fifa-world-cup", "data": {"market": "0xd2a8caba5559bc21e14f6b2aa504cb14a1782751658b71409e25b82e432c0a97", "price_changes": [{"asset_id": "36586667785814641857008731622413716797407337292495614620493145114086484487337", "price": "0.35", "size": "3200", "side": "BUY", "hash": "0477fa48ca7e32dbe3a34db0280e9451a91fc6e0", "best_bid": "0.48", "best_ask": "0.481"}, {"asset_id": "19214394437683566921750936876376421489271269944393354497977881791256347396217", "price": "0.65", "size": "3200", "side": "SELL", "hash": "b024125e6e3b6190c1c9f5d67a93540ca6dc0a50", "best_bid": "0.519", "best_ask": "0.52"}], "timestamp": "1782707685635", "event_type": "price_change"}}
{"local_timestamp": 1782707684.4088917, "slug": "will-lionel-messi-be-the-top-goalscorer-at-the-2026-fifa-world-cup", "data": {"market": "0xd2a8caba5559bc21e14f6b2aa504cb14a1782751658b71409e25b82e432c0a97", "price_changes": [{"asset_id": "19214394437683566921750936876376421489271269944393354497977881791256347396217", "price": "0.26", "size": "3000", "side": "BUY", "hash": "6a37270547067a1d16dab17bb2a8b80dfd62905e", "best_bid": "0.519", "best_ask": "0.52"}, {"asset_id": "36586667785814641857008731622413716797407337292495614620493145114086484487337", "price": "0.74", "size": "3000", "side": "SELL", "hash": "6692234ab31b06f6a47cc141cc7109f74a2e9450", "best_bid": "0.48", "best_ask": "0.481"}], "timestamp": "1782707685639", "event_type": "price_change"}}
{"local_timestamp": 1782707685.1752384, "slug": "will-lionel-messi-be-the-top-goalscorer-at-the-2026-fifa-world-cup", "data": {"market": "0xd2a8caba5559bc21e14f6b2aa504cb14a1782751658b71409e25b82e432c0a97", "price_changes": [{"asset_id": "19214394437683566921750936876376421489271269944393354497977881791256347396217", "price": "0.521", "size": "4530.82", "side": "SELL", "hash": "afba127d543318f3595f3cb9d665383374758f14", "best_bid": "0.519", "best_ask": "0.52"}, {"asset_id": "36586667785814641857008731622413716797407337292495614620493145114086484487337", "price": "0.479", "size": "4530.82", "side": "BUY", "hash": "7fbf529d19b065f6ea7748866d33d695e0e45599", "best_bid": "0.48", "best_ask": "0.481"}], "timestamp": "1782707686405", "event_type": "price_change"}}
{"local_timestamp": 1782707685.8797898, "slug": "will-lionel-messi-be-the-top-goalscorer-at-the-2026-fifa-world-cup", "data": {"market": "0xd2a8caba5559bc21e14f6b2aa504cb14a1782751658b71409e25b82e432c0a97", "price_changes": [{"asset_id": "19214394437683566921750936876376421489271269944393354497977881791256347396217", "price": "0.26", "size": "0", "side": "BUY", "hash": "cf2b3243e370003a16a8f1c55e384eec05748e09", "best_bid": "0.519", "best_ask": "0.52"}, {"asset_id": "36586667785814641857008731622413716797407337292495614620493145114086484487337", "price": "0.74", "size": "0", "side": "SELL", "hash": "c703b5041433286e7e893c9b695ee9e8cfce17b4", "best_bid": "0.48", "best_ask": "0.481"}], "timestamp": "1782707687109", "event_type": "price_change"}}
{"local_timestamp": 1782707685.8803856, "slug": "will-lionel-messi-be-the-top-goalscorer-at-the-2026-fifa-world-cup", "data": {"market": "0xd2a8caba5559bc21e14f6b2aa504cb14a1782751658b71409e25b82e432c0a97", "price_changes": [{"asset_id": "36586667785814641857008731622413716797407337292495614620493145114086484487337", "price": "0.35", "size": "200", "side": "BUY", "hash": "b980c2461d38adbfbe8486d72fc1c6be097f8aa1", "best_bid": "0.48", "best_ask": "0.481"}, {"asset_id": "19214394437683566921750936876376421489271269944393354497977881791256347396217", "price": "0.65", "size": "200", "side": "SELL", "hash": "dae76df427f78062a796a41a7400cc403f25a894", "best_bid": "0.519", "best_ask": "0.52"}], "timestamp": "1782707687109", "event_type": "price_change"}}
{"local_timestamp": 1782707687.2217512, "slug": "will-lionel-messi-be-the-top-goalscorer-at-the-2026-fifa-world-cup", "data": {"market": "0xd2a8caba5559bc21e14f6b2aa504cb14a1782751658b71409e25b82e432c0a97", "price_changes": [{"asset_id": "19214394437683566921750936876376421489271269944393354497977881791256347396217", "price": "0.521", "size": "4433.73", "side": "SELL", "hash": "99e01597c656401753afe52012a67d56eee02355", "best_bid": "0.519", "best_ask": "0.52"}, {"asset_id": "36586667785814641857008731622413716797407337292495614620493145114086484487337", "price": "0.479", "size": "4433.73", "side": "BUY", "hash": "09655da8b8432ec3d8ce9d988022c155b4618656", "best_bid": "0.48", "best_ask": "0.481"}], "timestamp": "1782707688453", "event_type": "price_change"}}
{"local_timestamp": 1782707687.3616571, "slug": "will-lionel-messi-be-the-top-goalscorer-at-the-2026-fifa-world-cup", "data": {"market": "0xd2a8caba5559bc21e14f6b2aa504cb14a1782751658b71409e25b82e432c0a97", "price_changes": [{"asset_id": "19214394437683566921750936876376421489271269944393354497977881791256347396217", "price": "0.26", "size": "3000", "side": "BUY", "hash": "b1deae2f2fb1d8a04aa5ed7bf9945a40144e150e", "best_bid": "0.519", "best_ask": "0.52"}, {"asset_id": "36586667785814641857008731622413716797407337292495614620493145114086484487337", "price": "0.74", "size": "3000", "side": "SELL", "hash": "231ac9e437aabab7b79e9f150ddfab85ffb72745", "best_bid": "0.48", "best_ask": "0.481"}], "timestamp": "1782707688591", "event_type": "price_change"}}
{"local_timestamp": 1782707687.3643043, "slug": "will-lionel-messi-be-the-top-goalscorer-at-the-2026-fifa-world-cup", "data": {"market": "0xd2a8caba5559bc21e14f6b2aa504cb14a1782751658b71409e25b82e432c0a97", "price_changes": [{"asset_id": "36586667785814641857008731622413716797407337292495614620493145114086484487337", "price": "0.35", "size": "3200", "side": "BUY", "hash": "aedf372338b260f6dab93979d8187179db38edad", "best_bid": "0.48", "best_ask": "0.481"}, {"asset_id": "19214394437683566921750936876376421489271269944393354497977881791256347396217", "price": "0.65", "size": "3200", "side": "SELL", "hash": "b1c32fdebd0a3977ac16051c4063d107896c47ca", "best_bid": "0.519", "best_ask": "0.52"}], "timestamp": "1782707688593", "event_type": "price_change"}}
{"local_timestamp": 1782707688.7041783, "slug": "will-lionel-messi-be-the-top-goalscorer-at-the-2026-fifa-world-cup", "data": {"market": "0xd2a8caba5559bc21e14f6b2aa504cb14a1782751658b71409e25b82e432c0a97", "price_changes": [{"asset_id": "36586667785814641857008731622413716797407337292495614620493145114086484487337", "price": "0.402", "size": "550", "side": "BUY", "hash": "dad45720dac3ef520056f46d8b291b7c3bc7ab98", "best_bid": "0.48", "best_ask": "0.481"}, {"asset_id": "19214394437683566921750936876376421489271269944393354497977881791256347396217", "price": "0.598", "size": "550", "side": "SELL", "hash": "a30d975876eeb2e96ce87396b60abdd433222996", "best_bid": "0.519", "best_ask": "0.52"}], "timestamp": "1782707689932", "event_type": "price_change"}}
{"local_timestamp": 1782707688.866703, "slug": "will-lionel-messi-be-the-top-goalscorer-at-the-2026-fifa-world-cup", "data": {"market": "0xd2a8caba5559bc21e14f6b2aa504cb14a1782751658b71409e25b82e432c0a97", "price_changes": [{"asset_id": "19214394437683566921750936876376421489271269944393354497977881791256347396217", "price": "0.26", "size": "0", "side": "BUY", "hash": "835f4ec23ca762b671e68ba7b622e0d535aab23e", "best_bid": "0.519", "best_ask": "0.52"}, {"asset_id": "36586667785814641857008731622413716797407337292495614620493145114086484487337", "price": "0.74", "size": "0", "side": "SELL", "hash": "414c3c775efd37d32168c3b619ba4f5587a74c26", "best_bid": "0.48", "best_ask": "0.481"}], "timestamp": "1782707690096", "event_type": "price_change"}}
{"local_timestamp": 1782707688.8672512, "slug": "will-lionel-messi-be-the-top-goalscorer-at-the-2026-fifa-world-cup", "data": {"market": "0xd2a8caba5559bc21e14f6b2aa504cb14a1782751658b71409e25b82e432c0a97", "price_changes": [{"asset_id": "36586667785814641857008731622413716797407337292495614620493145114086484487337", "price": "0.35", "size": "200", "side": "BUY", "hash": "dcc6a28ccb74565100e09becac65400e2e6b4b93", "best_bid": "0.48", "best_ask": "0.481"}, {"asset_id": "19214394437683566921750936876376421489271269944393354497977881791256347396217", "price": "0.65", "size": "200", "side": "SELL", "hash": "9e61b2645a20a8ecf17dde417c566c32ad3fee3f", "best_bid": "0.519", "best_ask": "0.52"}], "timestamp": "1782707690096", "event_type": "price_change"}}
{"local_timestamp": 1782707689.4665272, "slug": "will-lionel-messi-be-the-top-goalscorer-at-the-2026-fifa-world-cup", "data": {"market": "0xd2a8caba5559bc21e14f6b2aa504cb14a1782751658b71409e25b82e432c0a97", "price_changes": [{"asset_id": "19214394437683566921750936876376421489271269944393354497977881791256347396217", "price": "0.518", "size": "18956.21", "side": "BUY", "hash": "f82f639e8564847ab111f64ac92e6c4867b0b0aa", "best_bid": "0.519", "best_ask": "0.52"}, {"asset_id": "36586667785814641857008731622413716797407337292495614620493145114086484487337", "price": "0.482", "size": "18956.21", "side": "SELL", "hash": "eaed37e22af2de967950bd289c227cce4a3060e5", "best_bid": "0.48", "best_ask": "0.481"}], "timestamp": "1782707690697", "event_type": "price_change"}}
{"local_timestamp": 1782707689.5251231, "slug": "will-lionel-messi-be-the-top-goalscorer-at-the-2026-fifa-world-cup", "data": {"market": "0xd2a8caba5559bc21e14f6b2aa504cb14a1782751658b71409e25b82e432c0a97", "price_changes": [{"asset_id": "36586667785814641857008731622413716797407337292495614620493145114086484487337", "price": "0.479", "size": "4651.96", "side": "BUY", "hash": "972f476a0c5e2c42e8d0fee6259c4f6ff8062ac5", "best_bid": "0.48", "best_ask": "0.481"}, {"asset_id": "19214394437683566921750936876376421489271269944393354497977881791256347396217", "price": "0.521", "size": "4651.96", "side": "SELL", "hash": "643e70fa63f1cbfe1b25ec70344f411848bc5368", "best_bid": "0.519", "best_ask": "0.52"}], "timestamp": "1782707690756", "event_type": "price_change"}}
{"local_timestamp": 1782707689.7488618, "slug": "will-lionel-messi-be-the-top-goalscorer-at-the-2026-fifa-world-cup", "data": {"market": "0xd2a8caba5559bc21e14f6b2aa504cb14a1782751658b71409e25b82e432c0a97", "price_changes": [{"asset_id": "19214394437683566921750936876376421489271269944393354497977881791256347396217", "price": "0.521", "size": "4749.05", "side": "SELL", "hash": "8df7e624c9c790ea9d5d4b806ec543eadd306f28", "best_bid": "0.519", "best_ask": "0.52"}, {"asset_id": "36586667785814641857008731622413716797407337292495614620493145114086484487337", "price": "0.479", "size": "4749.05", "side": "BUY", "hash": "f0e3ee1cd3f8181d300b966167251b70c47f3cf6", "best_bid": "0.48", "best_ask": "0.481"}], "timestamp": "1782707690977", "event_type": "price_change"}}
{"local_timestamp": 1782707690.2455466, "slug": "will-lionel-messi-be-the-top-goalscorer-at-the-2026-fifa-world-cup", "data": {"market": "0xd2a8caba5559bc21e14f6b2aa504cb14a1782751658b71409e25b82e432c0a97", "price_changes": [{"asset_id": "36586667785814641857008731622413716797407337292495614620493145114086484487337", "price": "0.402", "size": "350", "side": "BUY", "hash": "b81eec72e0f56037afcb8dbabd2a0bcfd4e3da13", "best_bid": "0.48", "best_ask": "0.481"}, {"asset_id": "19214394437683566921750936876376421489271269944393354497977881791256347396217", "price": "0.598", "size": "350", "side": "SELL", "hash": "42e46048317bf738070ebd91e06ca41cdb80f698", "best_bid": "0.519", "best_ask": "0.52"}], "timestamp": "1782707691472", "event_type": "price_change"}}
{"local_timestamp": 1782707690.4135225, "slug": "will-lionel-messi-be-the-top-goalscorer-at-the-2026-fifa-world-cup", "data": {"market": "0xd2a8caba5559bc21e14f6b2aa504cb14a1782751658b71409e25b82e432c0a97", "price_changes": [{"asset_id": "19214394437683566921750936876376421489271269944393354497977881791256347396217", "price": "0.26", "size": "3000", "side": "BUY", "hash": "08a33e997f0c1bd84fb9d667b8dd685285948ed6", "best_bid": "0.519", "best_ask": "0.52"}, {"asset_id": "36586667785814641857008731622413716797407337292495614620493145114086484487337", "price": "0.74", "size": "3000", "side": "SELL", "hash": "6e0152f7f9d97483759e66252888a88fddb68945", "best_bid": "0.48", "best_ask": "0.481"}], "timestamp": "1782707691644", "event_type": "price_change"}}
{"local_timestamp": 1782707690.417075, "slug": "will-lionel-messi-be-the-top-goalscorer-at-the-2026-fifa-world-cup", "data": {"market": "0xd2a8caba5559bc21e14f6b2aa504cb14a1782751658b71409e25b82e432c0a97", "price_changes": [{"asset_id": "36586667785814641857008731622413716797407337292495614620493145114086484487337", "price": "0.35", "size": "3200", "side": "BUY", "hash": "29dadc47ecf634f59651055446978b7d53c4d0bb", "best_bid": "0.48", "best_ask": "0.481"}, {"asset_id": "19214394437683566921750936876376421489271269944393354497977881791256347396217", "price": "0.65", "size": "3200", "side": "SELL", "hash": "930fa9c47eee58ad2054378d09fc45d354e4f5ba", "best_bid": "0.519", "best_ask": "0.52"}], "timestamp": "1782707691647", "event_type": "price_change"}}
{"local_timestamp": 1782707691.9116945, "slug": "will-lionel-messi-be-the-top-goalscorer-at-the-2026-fifa-world-cup", "data": {"market": "0xd2a8caba5559bc21e14f6b2aa504cb14a1782751658b71409e25b82e432c0a97", "price_changes": [{"asset_id": "36586667785814641857008731622413716797407337292495614620493145114086484487337", "price": "0.35", "size": "200", "side": "BUY", "hash": "3b2e7144c68b1fbb9dc5f394ad9bb81a1df4fe5d", "best_bid": "0.48", "best_ask": "0.481"}, {"asset_id": "19214394437683566921750936876376421489271269944393354497977881791256347396217", "price": "0.65", "size": "200", "side": "SELL", "hash": "bfdb6f946cb6d25392ef509916c7d7ac4d4fd744", "best_bid": "0.519", "best_ask": "0.52"}], "timestamp": "1782707693141", "event_type": "price_change"}}
{"local_timestamp": 1782707691.9138913, "slug": "will-lionel-messi-be-the-top-goalscorer-at-the-2026-fifa-world-cup", "data": {"market": "0xd2a8caba5559bc21e14f6b2aa504cb14a1782751658b71409e25b82e432c0a97", "price_changes": [{"asset_id": "19214394437683566921750936876376421489271269944393354497977881791256347396217", "price": "0.26", "size": "0", "side": "BUY", "hash": "d98a41eca471d66a1eca0bd8717fc32bebd54406", "best_bid": "0.519", "best_ask": "0.52"}, {"asset_id": "36586667785814641857008731622413716797407337292495614620493145114086484487337", "price": "0.74", "size": "0", "side": "SELL", "hash": "bbc284067c4a40759ca35ce393f85abe27746041", "best_bid": "0.48", "best_ask": "0.481"}], "timestamp": "1782707693142", "event_type": "price_change"}}
{"local_timestamp": 1782707693.395666, "slug": "will-lionel-messi-be-the-top-goalscorer-at-the-2026-fifa-world-cup", "data": {"market": "0xd2a8caba5559bc21e14f6b2aa504cb14a1782751658b71409e25b82e432c0a97", "price_changes": [{"asset_id": "19214394437683566921750936876376421489271269944393354497977881791256347396217", "price": "0.26", "size": "3000", "side": "BUY", "hash": "ba491d2d075018d35747b943ec6852cf49f68c92", "best_bid": "0.519", "best_ask": "0.52"}, {"asset_id": "36586667785814641857008731622413716797407337292495614620493145114086484487337", "price": "0.74", "size": "3000", "side": "SELL", "hash": "bc90b6a1d87c41312d2cd9767b99ffa82794a9f7", "best_bid": "0.48", "best_ask": "0.481"}], "timestamp": "1782707694626", "event_type": "price_change"}}
{"local_timestamp": 1782707693.4006686, "slug": "will-lionel-messi-be-the-top-goalscorer-at-the-2026-fifa-world-cup", "data": {"market": "0xd2a8caba5559bc21e14f6b2aa504cb14a1782751658b71409e25b82e432c0a97", "price_changes": [{"asset_id": "36586667785814641857008731622413716797407337292495614620493145114086484487337", "price": "0.35", "size": "3200", "side": "BUY", "hash": "8e26eb79ed961d099d3d6af1005d548b1209f2e0", "best_bid": "0.48", "best_ask": "0.481"}, {"asset_id": "19214394437683566921750936876376421489271269944393354497977881791256347396217", "price": "0.65", "size": "3200", "side": "SELL", "hash": "0c9ca93913ce0914834e8308a4f38357a6b4481e", "best_bid": "0.519", "best_ask": "0.52"}], "timestamp": "1782707694630", "event_type": "price_change"}}
{"local_timestamp": 1782707693.822977, "slug": "will-lionel-messi-be-the-top-goalscorer-at-the-2026-fifa-world-cup", "data": {"market": "0xd2a8caba5559bc21e14f6b2aa504cb14a1782751658b71409e25b82e432c0a97", "price_changes": [{"asset_id": "36586667785814641857008731622413716797407337292495614620493145114086484487337", "price": "0.469", "size": "822", "side": "BUY", "hash": "35495e7389940b431af8821f988a86babbfe7936", "best_bid": "0.48", "best_ask": "0.481"}, {"asset_id": "19214394437683566921750936876376421489271269944393354497977881791256347396217", "price": "0.531", "size": "822", "side": "SELL", "hash": "17c3314f4f350b917b1ceb759801e28237bf9a37", "best_bid": "0.519", "best_ask": "0.52"}], "timestamp": "1782707695053", "event_type": "price_change"}}
{"local_timestamp": 1782707693.8259573, "slug": "will-lionel-messi-be-the-top-goalscorer-at-the-2026-fifa-world-cup", "data": {"market": "0xd2a8caba5559bc21e14f6b2aa504cb14a1782751658b71409e25b82e432c0a97", "price_changes": [{"asset_id": "19214394437683566921750936876376421489271269944393354497977881791256347396217", "price": "0.5", "size": "29054", "side": "BUY", "hash": "6b0e53639261687a4a9f1f87675279e4e74221c0", "best_bid": "0.519", "best_ask": "0.52"}, {"asset_id": "36586667785814641857008731622413716797407337292495614620493145114086484487337", "price": "0.5", "size": "29054", "side": "SELL", "hash": "6b017e33f9ed125fe90ebc615bd07486d7181501", "best_bid": "0.48", "best_ask": "0.481"}], "timestamp": "1782707695056", "event_type": "price_change"}}
{"local_timestamp": 1782707693.8339374, "slug": "will-lionel-messi-be-the-top-goalscorer-at-the-2026-fifa-world-cup", "data": {"market": "0xd2a8caba5559bc21e14f6b2aa504cb14a1782751658b71409e25b82e432c0a97", "price_changes": [{"asset_id": "36586667785814641857008731622413716797407337292495614620493145114086484487337", "price": "0.459", "size": "622", "side": "BUY", "hash": "ddbedc3dcceb78729b197a18ac59d518b72d0195", "best_bid": "0.48", "best_ask": "0.481"}, {"asset_id": "19214394437683566921750936876376421489271269944393354497977881791256347396217", "price": "0.541", "size": "622", "side": "SELL", "hash": "b6353dff04665d3448ce726e26f47875f36a1125", "best_bid": "0.519", "best_ask": "0.52"}], "timestamp": "1782707695064", "event_type": "price_change"}}
{"local_timestamp": 1782707693.8428905, "slug": "will-lionel-messi-be-the-top-goalscorer-at-the-2026-fifa-world-cup", "data": {"market": "0xd2a8caba5559bc21e14f6b2aa504cb14a1782751658b71409e25b82e432c0a97", "price_changes": [{"asset_id": "36586667785814641857008731622413716797407337292495614620493145114086484487337", "price": "0.449", "size": "772", "side": "BUY", "hash": "9cb681b56c587f7f92a081b46debb5e7b872a49b", "best_bid": "0.48", "best_ask": "0.481"}, {"asset_id": "19214394437683566921750936876376421489271269944393354497977881791256347396217", "price": "0.551", "size": "772", "side": "SELL", "hash": "00e26aeb53faae47edae19f50a96be87265b54c3", "best_bid": "0.519", "best_ask": "0.52"}], "timestamp": "1782707695072", "event_type": "price_change"}}
{"local_timestamp": 1782707694.7791185, "slug": "will-lionel-messi-be-the-top-goalscorer-at-the-2026-fifa-world-cup", "data": {"market": "0xd2a8caba5559bc21e14f6b2aa504cb14a1782751658b71409e25b82e432c0a97", "price_changes": [{"asset_id": "36586667785814641857008731622413716797407337292495614620493145114086484487337", "price": "0.46", "size": "44572", "side": "BUY", "hash": "efaa11a797ec0d21eb1a60e3cf7a4649a4cbe515", "best_bid": "0.48", "best_ask": "0.481"}, {"asset_id": "19214394437683566921750936876376421489271269944393354497977881791256347396217", "price": "0.54", "size": "44572", "side": "SELL", "hash": "305ae94f22c9cfc0b84c5feb7ba9b22581c5f0a2", "best_bid": "0.519", "best_ask": "0.52"}], "timestamp": "1782707696007", "event_type": "price_change"}}
{"local_timestamp": 1782707694.8584952, "slug": "will-lionel-messi-be-the-top-goalscorer-at-the-2026-fifa-world-cup", "data": {"market": "0xd2a8caba5559bc21e14f6b2aa504cb14a1782751658b71409e25b82e432c0a97", "price_changes": [{"asset_id": "19214394437683566921750936876376421489271269944393354497977881791256347396217", "price": "0.26", "size": "0", "side": "BUY", "hash": "3a0732a16f52f86145fd58cb9ef883bb62438bd9", "best_bid": "0.519", "best_ask": "0.52"}, {"asset_id": "36586667785814641857008731622413716797407337292495614620493145114086484487337", "price": "0.74", "size": "0", "side": "SELL", "hash": "1c9b3f13b295e00010a3dd1030e58d31b3f98fc8", "best_bid": "0.48", "best_ask": "0.481"}], "timestamp": "1782707696086", "event_type": "price_change"}}
{"local_timestamp": 1782707694.859029, "slug": "will-lionel-messi-be-the-top-goalscorer-at-the-2026-fifa-world-cup", "data": {"market": "0xd2a8caba5559bc21e14f6b2aa504cb14a1782751658b71409e25b82e432c0a97", "price_changes": [{"asset_id": "36586667785814641857008731622413716797407337292495614620493145114086484487337", "price": "0.35", "size": "200", "side": "BUY", "hash": "3eb4f8930c9bbe26dab62c41e6a7e60d7e1b0e81", "best_bid": "0.48", "best_ask": "0.481"}, {"asset_id": "19214394437683566921750936876376421489271269944393354497977881791256347396217", "price": "0.65", "size": "200", "side": "SELL", "hash": "727489fa6d56aa8fcf06c8a8e502f2ca6bbca491", "best_bid": "0.519", "best_ask": "0.52"}], "timestamp": "1782707696087", "event_type": "price_change"}}
{"local_timestamp": 1782707695.3673332, "slug": "will-lionel-messi-be-the-top-goalscorer-at-the-2026-fifa-world-cup", "data": {"market": "0xd2a8caba5559bc21e14f6b2aa504cb14a1782751658b71409e25b82e432c0a97", "price_changes": [{"asset_id": "19214394437683566921750936876376421489271269944393354497977881791256347396217", "price": "0.26", "size": "3000", "side": "BUY", "hash": "16e9a75647ad1851a76a318b60a1d911d94220cb", "best_bid": "0.519", "best_ask": "0.52"}, {"asset_id": "36586667785814641857008731622413716797407337292495614620493145114086484487337", "price": "0.74", "size": "3000", "side": "SELL", "hash": "cd5134fb2d04aea52487634ee564b38a097053d9", "best_bid": "0.48", "best_ask": "0.481"}], "timestamp": "1782707696597", "event_type": "price_change"}}
{"local_timestamp": 1782707695.3700964, "slug": "will-lionel-messi-be-the-top-goalscorer-at-the-2026-fifa-world-cup", "data": {"market": "0xd2a8caba5559bc21e14f6b2aa504cb14a1782751658b71409e25b82e432c0a97", "price_changes": [{"asset_id": "36586667785814641857008731622413716797407337292495614620493145114086484487337", "price": "0.35", "size": "3200", "side": "BUY", "hash": "f4160c6e34b212a39aa31f9320d62a011e0a7b2f", "best_bid": "0.48", "best_ask": "0.481"}, {"asset_id": "19214394437683566921750936876376421489271269944393354497977881791256347396217", "price": "0.65", "size": "3200", "side": "SELL", "hash": "394b722b1bd4a4e7a95b4a45ea6018e4e3e77d0c", "best_bid": "0.519", "best_ask": "0.52"}], "timestamp": "1782707696600", "event_type": "price_change"}}
{"local_timestamp": 1782707696.353745, "slug": "will-lionel-messi-be-the-top-goalscorer-at-the-2026-fifa-world-cup", "data": {"market": "0xd2a8caba5559bc21e14f6b2aa504cb14a1782751658b71409e25b82e432c0a97", "price_changes": [{"asset_id": "36586667785814641857008731622413716797407337292495614620493145114086484487337", "price": "0.35", "size": "200", "side": "BUY", "hash": "6acc5b3943a68e8c9deee24c0131222c5fcc4e88", "best_bid": "0.48", "best_ask": "0.481"}, {"asset_id": "19214394437683566921750936876376421489271269944393354497977881791256347396217", "price": "0.65", "size": "200", "side": "SELL", "hash": "02c8c2591a66e50bbff353c7cad1c8407b68af05", "best_bid": "0.519", "best_ask": "0.52"}], "timestamp": "1782707697582", "event_type": "price_change"}}
{"local_timestamp": 1782707696.3560076, "slug": "will-lionel-messi-be-the-top-goalscorer-at-the-2026-fifa-world-cup", "data": {"market": "0xd2a8caba5559bc21e14f6b2aa504cb14a1782751658b71409e25b82e432c0a97", "price_changes": [{"asset_id": "19214394437683566921750936876376421489271269944393354497977881791256347396217", "price": "0.26", "size": "0", "side": "BUY", "hash": "9737ed9a9abb7c529795a1aa33a52fc0cc90ffa6", "best_bid": "0.519", "best_ask": "0.52"}, {"asset_id": "36586667785814641857008731622413716797407337292495614620493145114086484487337", "price": "0.74", "size": "0", "side": "SELL", "hash": "58066329cc19cd919aa263f20da1584b86cfe2ad", "best_bid": "0.48", "best_ask": "0.481"}], "timestamp": "1782707697582", "event_type": "price_change"}}
{"local_timestamp": 1782707697.8798745, "slug": "will-lionel-messi-be-the-top-goalscorer-at-the-2026-fifa-world-cup", "data": {"market": "0xd2a8caba5559bc21e14f6b2aa504cb14a1782751658b71409e25b82e432c0a97", "price_changes": [{"asset_id": "36586667785814641857008731622413716797407337292495614620493145114086484487337", "price": "0.35", "size": "3200", "side": "BUY", "hash": "9646c1a3659dca86ef6aad3c9c0e8161b7f28251", "best_bid": "0.48", "best_ask": "0.481"}, {"asset_id": "19214394437683566921750936876376421489271269944393354497977881791256347396217", "price": "0.65", "size": "3200", "side": "SELL", "hash": "d48015198f009b2b348874eddf14068db58990e6", "best_bid": "0.519", "best_ask": "0.52"}], "timestamp": "1782707699108", "event_type": "price_change"}}
{"local_timestamp": 1782707697.8947868, "slug": "will-lionel-messi-be-the-top-goalscorer-at-the-2026-fifa-world-cup", "data": {"market": "0xd2a8caba5559bc21e14f6b2aa504cb14a1782751658b71409e25b82e432c0a97", "price_changes": [{"asset_id": "19214394437683566921750936876376421489271269944393354497977881791256347396217", "price": "0.26", "size": "3000", "side": "BUY", "hash": "dcbd88b59e903698e90daff9c0c124cc53bf328d", "best_bid": "0.519", "best_ask": "0.52"}, {"asset_id": "36586667785814641857008731622413716797407337292495614620493145114086484487337", "price": "0.74", "size": "3000", "side": "SELL", "hash": "ab1e97f2eb29d5fdb5261ce609d0f5a52ce117e5", "best_bid": "0.48", "best_ask": "0.481"}], "timestamp": "1782707699121", "event_type": "price_change"}}
{"local_timestamp": 1782707698.6280336, "slug": "will-lionel-messi-be-the-top-goalscorer-at-the-2026-fifa-world-cup", "data": {"market": "0xd2a8caba5559bc21e14f6b2aa504cb14a1782751658b71409e25b82e432c0a97", "price_changes": [{"asset_id": "19214394437683566921750936876376421489271269944393354497977881791256347396217", "price": "0.509", "size": "2000", "side": "BUY", "hash": "f7d2331098994dd87eba8a6c0a841b03df938ecd", "best_bid": "0.519", "best_ask": "0.52"}, {"asset_id": "36586667785814641857008731622413716797407337292495614620493145114086484487337", "price": "0.491", "size": "2000", "side": "SELL", "hash": "ec674aebaf8bd1e8f655a0a278e435a62d11b7c0", "best_bid": "0.48", "best_ask": "0.481"}], "timestamp": "1782707699857", "event_type": "price_change"}}
{"local_timestamp": 1782707699.0553446, "slug": "will-lionel-messi-be-the-top-goalscorer-at-the-2026-fifa-world-cup", "data": {"market": "0xd2a8caba5559bc21e14f6b2aa504cb14a1782751658b71409e25b82e432c0a97", "price_changes": [{"asset_id": "19214394437683566921750936876376421489271269944393354497977881791256347396217", "price": "0.509", "size": "1700", "side": "BUY", "hash": "0200672b3957e7e753ced85e826098629e82fa37", "best_bid": "0.519", "best_ask": "0.52"}, {"asset_id": "36586667785814641857008731622413716797407337292495614620493145114086484487337", "price": "0.491", "size": "1700", "side": "SELL", "hash": "6b826b7266ddb4833c67313a5d4ee52be260235d", "best_bid": "0.48", "best_ask": "0.481"}], "timestamp": "1782707700286", "event_type": "price_change"}}
{"local_timestamp": 1782707699.3770423, "slug": "will-lionel-messi-be-the-top-goalscorer-at-the-2026-fifa-world-cup", "data": {"market": "0xd2a8caba5559bc21e14f6b2aa504cb14a1782751658b71409e25b82e432c0a97", "price_changes": [{"asset_id": "19214394437683566921750936876376421489271269944393354497977881791256347396217", "price": "0.26", "size": "0", "side": "BUY", "hash": "8866fe434d8bbff22e3852f011ce030c4d709fc8", "best_bid": "0.519", "best_ask": "0.52"}, {"asset_id": "36586667785814641857008731622413716797407337292495614620493145114086484487337", "price": "0.74", "size": "0", "side": "SELL", "hash": "f8c2b68a8d5b9348e0eac4a8a3cc85dda7f7abca", "best_bid": "0.48", "best_ask": "0.481"}], "timestamp": "1782707700598", "event_type": "price_change"}}
{"local_timestamp": 1782707699.3792577, "slug": "will-lionel-messi-be-the-top-goalscorer-at-the-2026-fifa-world-cup", "data": {"market": "0xd2a8caba5559bc21e14f6b2aa504cb14a1782751658b71409e25b82e432c0a97", "price_changes": [{"asset_id": "36586667785814641857008731622413716797407337292495614620493145114086484487337", "price": "0.35", "size": "200", "side": "BUY", "hash": "8471a060bc23a9eeec0d741ad7fc6773a9772fa9", "best_bid": "0.48", "best_ask": "0.481"}, {"asset_id": "19214394437683566921750936876376421489271269944393354497977881791256347396217", "price": "0.65", "size": "200", "side": "SELL", "hash": "e3eccebd1ee4e6722704953f30f9676afb55154c", "best_bid": "0.519", "best_ask": "0.52"}], "timestamp": "1782707700602", "event_type": "price_change"}}
{"local_timestamp": 1782707699.614655, "slug": "will-lionel-messi-be-the-top-goalscorer-at-the-2026-fifa-world-cup", "data": {"market": "0xd2a8caba5559bc21e14f6b2aa504cb14a1782751658b71409e25b82e432c0a97", "price_changes": [{"asset_id": "36586667785814641857008731622413716797407337292495614620493145114086484487337", "price": "0.447", "size": "3364.93", "side": "BUY", "hash": "37819b75fe082ad99ba1a4c233d8d9cf5fcdd3f3", "best_bid": "0.48", "best_ask": "0.481"}, {"asset_id": "19214394437683566921750936876376421489271269944393354497977881791256347396217", "price": "0.553", "size": "3364.93", "side": "SELL", "hash": "17a1b3574da22ed7e97a0c4a541bd3c6de7ac595", "best_bid": "0.519", "best_ask": "0.52"}], "timestamp": "1782707700846", "event_type": "price_change"}}
{"local_timestamp": 1782707700.7110076, "slug": "will-lionel-messi-be-the-top-goalscorer-at-the-2026-fifa-world-cup", "data": {"market": "0xd2a8caba5559bc21e14f6b2aa504cb14a1782751658b71409e25b82e432c0a97", "price_changes": [{"asset_id": "19214394437683566921750936876376421489271269944393354497977881791256347396217", "price": "0.521", "size": "4651.96", "side": "SELL", "hash": "1967ee579088ec7532c386bc50c939d51327990e", "best_bid": "0.519", "best_ask": "0.52"}, {"asset_id": "36586667785814641857008731622413716797407337292495614620493145114086484487337", "price": "0.479", "size": "4651.96", "side": "BUY", "hash": "d64a506d58ba1be8dc54b94ef86333c22af2237a", "best_bid": "0.48", "best_ask": "0.481"}], "timestamp": "1782707701926", "event_type": "price_change"}}
{"local_timestamp": 1782707700.9033594, "slug": "will-lionel-messi-be-the-top-goalscorer-at-the-2026-fifa-world-cup", "data": {"market": "0xd2a8caba5559bc21e14f6b2aa504cb14a1782751658b71409e25b82e432c0a97", "price_changes": [{"asset_id": "36586667785814641857008731622413716797407337292495614620493145114086484487337", "price": "0.35", "size": "3200", "side": "BUY", "hash": "8866fdbe1066510a1f3ffcd6b0540c8b336ca121", "best_bid": "0.48", "best_ask": "0.481"}, {"asset_id": "19214394437683566921750936876376421489271269944393354497977881791256347396217", "price": "0.65", "size": "3200", "side": "SELL", "hash": "9ab1c69aa259f75d88d595dfbac173f1bca819bc", "best_bid": "0.519", "best_ask": "0.52"}], "timestamp": "1782707702132", "event_type": "price_change"}}
{"local_timestamp": 1782707700.9087017, "slug": "will-lionel-messi-be-the-top-goalscorer-at-the-2026-fifa-world-cup", "data": {"market": "0xd2a8caba5559bc21e14f6b2aa504cb14a1782751658b71409e25b82e432c0a97", "price_changes": [{"asset_id": "19214394437683566921750936876376421489271269944393354497977881791256347396217", "price": "0.26", "size": "3000", "side": "BUY", "hash": "9c9f5d987d4bc789b44a361f9e9852fa31a98d2b", "best_bid": "0.519", "best_ask": "0.52"}, {"asset_id": "36586667785814641857008731622413716797407337292495614620493145114086484487337", "price": "0.74", "size": "3000", "side": "SELL", "hash": "deed33c4f35d7ef0e9c50ac1c8f70b3ed1ad51cb", "best_bid": "0.48", "best_ask": "0.481"}], "timestamp": "1782707702140", "event_type": "price_change"}}
{"local_timestamp": 1782707702.3394077, "slug": "will-lionel-messi-be-the-top-goalscorer-at-the-2026-fifa-world-cup", "data": {"market": "0xd2a8caba5559bc21e14f6b2aa504cb14a1782751658b71409e25b82e432c0a97", "price_changes": [{"asset_id": "19214394437683566921750936876376421489271269944393354497977881791256347396217", "price": "0.26", "size": "0", "side": "BUY", "hash": "90242a07b2a2e5b8e38159c9fe916309e24822f8", "best_bid": "0.519", "best_ask": "0.52"}, {"asset_id": "36586667785814641857008731622413716797407337292495614620493145114086484487337", "price": "0.74", "size": "0", "side": "SELL", "hash": "c7030a0c6d1472947bc0c8fb8e8466f587cc32f9", "best_bid": "0.48", "best_ask": "0.481"}], "timestamp": "1782707703570", "event_type": "price_change"}}
{"local_timestamp": 1782707702.3421526, "slug": "will-lionel-messi-be-the-top-goalscorer-at-the-2026-fifa-world-cup", "data": {"market": "0xd2a8caba5559bc21e14f6b2aa504cb14a1782751658b71409e25b82e432c0a97", "price_changes": [{"asset_id": "36586667785814641857008731622413716797407337292495614620493145114086484487337", "price": "0.35", "size": "200", "side": "BUY", "hash": "0327edfb2b6042498e4451e87b6116ff087a21c2", "best_bid": "0.48", "best_ask": "0.481"}, {"asset_id": "19214394437683566921750936876376421489271269944393354497977881791256347396217", "price": "0.65", "size": "200", "side": "SELL", "hash": "72c2630075375817001cc6249c0fc4422286b086", "best_bid": "0.519", "best_ask": "0.52"}], "timestamp": "1782707703570", "event_type": "price_change"}}
{"local_timestamp": 1782707703.086979, "slug": "will-lionel-messi-be-the-top-goalscorer-at-the-2026-fifa-world-cup", "data": {"market": "0xd2a8caba5559bc21e14f6b2aa504cb14a1782751658b71409e25b82e432c0a97", "price_changes": [{"asset_id": "36586667785814641857008731622413716797407337292495614620493145114086484487337", "price": "0.46", "size": "44792", "side": "BUY", "hash": "d7a9e2c283cede3955f51c1309796e875fe85d4f", "best_bid": "0.48", "best_ask": "0.481"}, {"asset_id": "19214394437683566921750936876376421489271269944393354497977881791256347396217", "price": "0.54", "size": "44792", "side": "SELL", "hash": "e55abdc18a250c8769a7ff6d9b90036e3f655dd8", "best_bid": "0.519", "best_ask": "0.52"}], "timestamp": "1782707704316", "event_type": "price_change"}}
{"local_timestamp": 1782707703.0954802, "slug": "will-lionel-messi-be-the-top-goalscorer-at-the-2026-fifa-world-cup", "data": {"market": "0xd2a8caba5559bc21e14f6b2aa504cb14a1782751658b71409e25b82e432c0a97", "price_changes": [{"asset_id": "36586667785814641857008731622413716797407337292495614620493145114086484487337", "price": "0.45", "size": "2880", "side": "BUY", "hash": "0c85270056a2a6a4125018f6dd0b40514b9f41ee", "best_bid": "0.48", "best_ask": "0.481"}, {"asset_id": "19214394437683566921750936876376421489271269944393354497977881791256347396217", "price": "0.55", "size": "2880", "side": "SELL", "hash": "9405e1671fc46b383ad21ea5bde52e6585edfc3f", "best_bid": "0.519", "best_ask": "0.52"}], "timestamp": "1782707704319", "event_type": "price_change"}}
{"local_timestamp": 1782707703.1687727, "slug": "will-lionel-messi-be-the-top-goalscorer-at-the-2026-fifa-world-cup", "data": {"market": "0xd2a8caba5559bc21e14f6b2aa504cb14a1782751658b71409e25b82e432c0a97", "price_changes": [{"asset_id": "36586667785814641857008731622413716797407337292495614620493145114086484487337", "price": "0.232", "size": "0", "side": "BUY", "hash": "6befb54fd8d8d09dfc3dbc8439277d3797c723ff", "best_bid": "0.48", "best_ask": "0.481"}, {"asset_id": "19214394437683566921750936876376421489271269944393354497977881791256347396217", "price": "0.768", "size": "0", "side": "SELL", "hash": "364a24fe9d2ba98cf03a68edd487b438acf181d0", "best_bid": "0.519", "best_ask": "0.52"}], "timestamp": "1782707704399", "event_type": "price_change"}}
{"local_timestamp": 1782707703.893941, "slug": "will-lionel-messi-be-the-top-goalscorer-at-the-2026-fifa-world-cup", "data": {"market": "0xd2a8caba5559bc21e14f6b2aa504cb14a1782751658b71409e25b82e432c0a97", "price_changes": [{"asset_id": "36586667785814641857008731622413716797407337292495614620493145114086484487337", "price": "0.35", "size": "3200", "side": "BUY", "hash": "c82703b181e73f1bd32754d9a04dddffd7a70c36", "best_bid": "0.48", "best_ask": "0.481"}, {"asset_id": "19214394437683566921750936876376421489271269944393354497977881791256347396217", "price": "0.65", "size": "3200", "side": "SELL", "hash": "01d31391666bd6343afa4d16356059067dfb6041", "best_bid": "0.519", "best_ask": "0.52"}], "timestamp": "1782707705125", "event_type": "price_change"}}
{"local_timestamp": 1782707703.90082, "slug": "will-lionel-messi-be-the-top-goalscorer-at-the-2026-fifa-world-cup", "data": {"market": "0xd2a8caba5559bc21e14f6b2aa504cb14a1782751658b71409e25b82e432c0a97", "price_changes": [{"asset_id": "19214394437683566921750936876376421489271269944393354497977881791256347396217", "price": "0.26", "size": "3000", "side": "BUY", "hash": "e151f72bef03b3ff69d536e8f220b3b2be6c3793", "best_bid": "0.519", "best_ask": "0.52"}, {"asset_id": "36586667785814641857008731622413716797407337292495614620493145114086484487337", "price": "0.74", "size": "3000", "side": "SELL", "hash": "69b36a7244ef0fb43d4462aefc592235dfaa22f2", "best_bid": "0.48", "best_ask": "0.481"}], "timestamp": "1782707705131", "event_type": "price_change"}}
{"local_timestamp": 1782707704.6107872, "slug": "will-lionel-messi-be-the-top-goalscorer-at-the-2026-fifa-world-cup", "data": {"market": "0xd2a8caba5559bc21e14f6b2aa504cb14a1782751658b71409e25b82e432c0a97", "price_changes": [{"asset_id": "19214394437683566921750936876376421489271269944393354497977881791256347396217", "price": "0.521", "size": "4749.05", "side": "SELL", "hash": "3f10011abb360c6fbe87c059cad115a480503633", "best_bid": "0.519", "best_ask": "0.52"}, {"asset_id": "36586667785814641857008731622413716797407337292495614620493145114086484487337", "price": "0.479", "size": "4749.05", "side": "BUY", "hash": "5d972fcc28e6520ee95082c53294d73e32eb20be", "best_bid": "0.48", "best_ask": "0.481"}], "timestamp": "1782707705842", "event_type": "price_change"}}
{"local_timestamp": 1782707705.3662813, "slug": "will-lionel-messi-be-the-top-goalscorer-at-the-2026-fifa-world-cup", "data": {"market": "0xd2a8caba5559bc21e14f6b2aa504cb14a1782751658b71409e25b82e432c0a97", "price_changes": [{"asset_id": "19214394437683566921750936876376421489271269944393354497977881791256347396217", "price": "0.26", "size": "0", "side": "BUY", "hash": "c36f4d1bab0378df15c74e6c1a2aa3d7d8f61f62", "best_bid": "0.519", "best_ask": "0.52"}, {"asset_id": "36586667785814641857008731622413716797407337292495614620493145114086484487337", "price": "0.74", "size": "0", "side": "SELL", "hash": "e7790f756bd15a984d4b205c96d531cfc7b74ec9", "best_bid": "0.48", "best_ask": "0.481"}], "timestamp": "1782707706597", "event_type": "price_change"}}
{"local_timestamp": 1782707705.3670666, "slug": "will-lionel-messi-be-the-top-goalscorer-at-the-2026-fifa-world-cup", "data": {"market": "0xd2a8caba5559bc21e14f6b2aa504cb14a1782751658b71409e25b82e432c0a97", "price_changes": [{"asset_id": "36586667785814641857008731622413716797407337292495614620493145114086484487337", "price": "0.35", "size": "200", "side": "BUY", "hash": "8a3f87e5c8bb50047a39df11e15a1102c944b75b", "best_bid": "0.48", "best_ask": "0.481"}, {"asset_id": "19214394437683566921750936876376421489271269944393354497977881791256347396217", "price": "0.65", "size": "200", "side": "SELL", "hash": "1894d1524843ccf2a10d9c3f19337e3527fafeb9", "best_bid": "0.519", "best_ask": "0.52"}], "timestamp": "1782707706597", "event_type": "price_change"}}
{"local_timestamp": 1782707705.74854, "slug": "will-lionel-messi-be-the-top-goalscorer-at-the-2026-fifa-world-cup", "data": {"market": "0xd2a8caba5559bc21e14f6b2aa504cb14a1782751658b71409e25b82e432c0a97", "price_changes": [{"asset_id": "19214394437683566921750936876376421489271269944393354497977881791256347396217", "price": "0.49", "size": "8671", "side": "BUY", "hash": "9ec7b40f22c89cf928ddc52e0c8698bde17db315", "best_bid": "0.519", "best_ask": "0.52"}, {"asset_id": "36586667785814641857008731622413716797407337292495614620493145114086484487337", "price": "0.51", "size": "8671", "side": "SELL", "hash": "cf0b27f256abf65f782ee1401fbc359411237f6f", "best_bid": "0.48", "best_ask": "0.481"}], "timestamp": "1782707706979", "event_type": "price_change"}}
{"local_timestamp": 1782707705.7611916, "slug": "will-lionel-messi-be-the-top-goalscorer-at-the-2026-fifa-world-cup", "data": {"market": "0xd2a8caba5559bc21e14f6b2aa504cb14a1782751658b71409e25b82e432c0a97", "price_changes": [{"asset_id": "19214394437683566921750936876376421489271269944393354497977881791256347396217", "price": "0.5", "size": "29274", "side": "BUY", "hash": "2af842212c06a9eef3859041f7a24767394278c0", "best_bid": "0.519", "best_ask": "0.52"}, {"asset_id": "36586667785814641857008731622413716797407337292495614620493145114086484487337", "price": "0.5", "size": "29274", "side": "SELL", "hash": "2cb55a448b2a3828f71e9048949fb6a00bb9390c", "best_bid": "0.48", "best_ask": "0.481"}], "timestamp": "1782707706991", "event_type": "price_change"}}
{"local_timestamp": 1782707706.9161317, "slug": "will-lionel-messi-be-the-top-goalscorer-at-the-2026-fifa-world-cup", "data": {"market": "0xd2a8caba5559bc21e14f6b2aa504cb14a1782751658b71409e25b82e432c0a97", "price_changes": [{"asset_id": "19214394437683566921750936876376421489271269944393354497977881791256347396217", "price": "0.521", "size": "4651.96", "side": "SELL", "hash": "d5cf0183996e89a97d0ac2accff5879a92550490", "best_bid": "0.519", "best_ask": "0.52"}, {"asset_id": "36586667785814641857008731622413716797407337292495614620493145114086484487337", "price": "0.479", "size": "4651.96", "side": "BUY", "hash": "8a7614c47ad0bdfc69c2c8bdc3b7df8b9e156423", "best_bid": "0.48", "best_ask": "0.481"}], "timestamp": "1782707708148", "event_type": "price_change"}}
{"local_timestamp": 1782707706.9293418, "slug": "will-lionel-messi-be-the-top-goalscorer-at-the-2026-fifa-world-cup", "data": {"market": "0xd2a8caba5559bc21e14f6b2aa504cb14a1782751658b71409e25b82e432c0a97", "price_changes": [{"asset_id": "19214394437683566921750936876376421489271269944393354497977881791256347396217", "price": "0.26", "size": "3000", "side": "BUY", "hash": "032eb5b3ffe3f5ea14c9f583045140b24c4ccfad", "best_bid": "0.519", "best_ask": "0.52"}, {"asset_id": "36586667785814641857008731622413716797407337292495614620493145114086484487337", "price": "0.74", "size": "3000", "side": "SELL", "hash": "55bc778717cfe75ea78038d6e051f11fc2e23bc8", "best_bid": "0.48", "best_ask": "0.481"}], "timestamp": "1782707708160", "event_type": "price_change"}}
{"local_timestamp": 1782707706.9337804, "slug": "will-lionel-messi-be-the-top-goalscorer-at-the-2026-fifa-world-cup", "data": {"market": "0xd2a8caba5559bc21e14f6b2aa504cb14a1782751658b71409e25b82e432c0a97", "price_changes": [{"asset_id": "36586667785814641857008731622413716797407337292495614620493145114086484487337", "price": "0.35", "size": "3200", "side": "BUY", "hash": "fd42f64338898a016f15d6a39d416b2853732413", "best_bid": "0.48", "best_ask": "0.481"}, {"asset_id": "19214394437683566921750936876376421489271269944393354497977881791256347396217", "price": "0.65", "size": "3200", "side": "SELL", "hash": "78195f31cbc35ce6c30f601b7967ef2058995d30", "best_bid": "0.519", "best_ask": "0.52"}], "timestamp": "1782707708165", "event_type": "price_change"}}
{"local_timestamp": 1782707708.3335028, "slug": "will-lionel-messi-be-the-top-goalscorer-at-the-2026-fifa-world-cup", "data": {"market": "0xd2a8caba5559bc21e14f6b2aa504cb14a1782751658b71409e25b82e432c0a97", "price_changes": [{"asset_id": "19214394437683566921750936876376421489271269944393354497977881791256347396217", "price": "0.26", "size": "0", "side": "BUY", "hash": "aac0292c8cacd7ca0c7f3458d5cc922177de00d6", "best_bid": "0.519", "best_ask": "0.52"}, {"asset_id": "36586667785814641857008731622413716797407337292495614620493145114086484487337", "price": "0.74", "size": "0", "side": "SELL", "hash": "d3102929ecc853614254231900e030f28dbf94e7", "best_bid": "0.48", "best_ask": "0.481"}], "timestamp": "1782707709560", "event_type": "price_change"}}
{"local_timestamp": 1782707708.335817, "slug": "will-lionel-messi-be-the-top-goalscorer-at-the-2026-fifa-world-cup", "data": {"market": "0xd2a8caba5559bc21e14f6b2aa504cb14a1782751658b71409e25b82e432c0a97", "price_changes": [{"asset_id": "36586667785814641857008731622413716797407337292495614620493145114086484487337", "price": "0.35", "size": "200", "side": "BUY", "hash": "4eba7b0416324694c2650e27d052fac3ba29958c", "best_bid": "0.48", "best_ask": "0.481"}, {"asset_id": "19214394437683566921750936876376421489271269944393354497977881791256347396217", "price": "0.65", "size": "200", "side": "SELL", "hash": "681638b8d38874ddf4a53ad671e8f33d94efe774", "best_bid": "0.519", "best_ask": "0.52"}], "timestamp": "1782707709560", "event_type": "price_change"}}
{"local_timestamp": 1782707708.5159297, "slug": "will-lionel-messi-be-the-top-goalscorer-at-the-2026-fifa-world-cup", "data": {"market": "0xd2a8caba5559bc21e14f6b2aa504cb14a1782751658b71409e25b82e432c0a97", "price_changes": [{"asset_id": "19214394437683566921750936876376421489271269944393354497977881791256347396217", "price": "0.49", "size": "9073", "side": "BUY", "hash": "3c999ddb998d43b1755098380914507a32cc0531", "best_bid": "0.519", "best_ask": "0.52"}, {"asset_id": "36586667785814641857008731622413716797407337292495614620493145114086484487337", "price": "0.51", "size": "9073", "side": "SELL", "hash": "1d78e5e02b68dd3a7ebfda7d0e0e3b57b37b4bb0", "best_bid": "0.48", "best_ask": "0.481"}], "timestamp": "1782707709747", "event_type": "price_change"}}
{"local_timestamp": 1782707708.5342076, "slug": "will-lionel-messi-be-the-top-goalscorer-at-the-2026-fifa-world-cup", "data": {"market": "0xd2a8caba5559bc21e14f6b2aa504cb14a1782751658b71409e25b82e432c0a97", "price_changes": [{"asset_id": "19214394437683566921750936876376421489271269944393354497977881791256347396217", "price": "0.5", "size": "29676", "side": "BUY", "hash": "b3ec65cc86bd3d773c40de4cea02f86a92e7e8da", "best_bid": "0.519", "best_ask": "0.52"}, {"asset_id": "36586667785814641857008731622413716797407337292495614620493145114086484487337", "price": "0.5", "size": "29676", "side": "SELL", "hash": "cf61bbf832550e7a74f4b5d13be1846246b218fa", "best_bid": "0.48", "best_ask": "0.481"}], "timestamp": "1782707709765", "event_type": "price_change"}}
{"local_timestamp": 1782707709.291261, "slug": "will-lionel-messi-be-the-top-goalscorer-at-the-2026-fifa-world-cup", "data": {"market": "0xd2a8caba5559bc21e14f6b2aa504cb14a1782751658b71409e25b82e432c0a97", "price_changes": [{"asset_id": "19214394437683566921750936876376421489271269944393354497977881791256347396217", "price": "0.521", "size": "4749.05", "side": "SELL", "hash": "d10b69e792c62ca4b8998c4eb1e6f671cc22223d", "best_bid": "0.519", "best_ask": "0.52"}, {"asset_id": "36586667785814641857008731622413716797407337292495614620493145114086484487337", "price": "0.479", "size": "4749.05", "side": "BUY", "hash": "ed274906eb743a70f139fda4b1ef99b85f797ba9", "best_bid": "0.48", "best_ask": "0.481"}], "timestamp": "1782707710521", "event_type": "price_change"}}
{"local_timestamp": 1782707709.791063, "slug": "will-lionel-messi-be-the-top-goalscorer-at-the-2026-fifa-world-cup", "data": {"market": "0xd2a8caba5559bc21e14f6b2aa504cb14a1782751658b71409e25b82e432c0a97", "price_changes": [{"asset_id": "36586667785814641857008731622413716797407337292495614620493145114086484487337", "price": "0.231", "size": "200", "side": "BUY", "hash": "0ade5221c391272ec09e147168309541485fed89", "best_bid": "0.48", "best_ask": "0.481"}, {"asset_id": "19214394437683566921750936876376421489271269944393354497977881791256347396217", "price": "0.769", "size": "200", "side": "SELL", "hash": "80a19eed11e350ed05d8e0184467ee16ba993ee1", "best_bid": "0.519", "best_ask": "0.52"}], "timestamp": "1782707711008", "event_type": "price_change"}}
{"local_timestamp": 1782707709.8978317, "slug": "will-lionel-messi-be-the-top-goalscorer-at-the-2026-fifa-world-cup", "data": {"market": "0xd2a8caba5559bc21e14f6b2aa504cb14a1782751658b71409e25b82e432c0a97", "price_changes": [{"asset_id": "19214394437683566921750936876376421489271269944393354497977881791256347396217", "price": "0.26", "size": "3000", "side": "BUY", "hash": "e36c6821c10175cd2734b443334767bae5bbb461", "best_bid": "0.519", "best_ask": "0.52"}, {"asset_id": "36586667785814641857008731622413716797407337292495614620493145114086484487337", "price": "0.74", "size": "3000", "side": "SELL", "hash": "f830d846d031f88d0ab3c8262253f78b38a2f0c2", "best_bid": "0.48", "best_ask": "0.481"}], "timestamp": "1782707711129", "event_type": "price_change"}}
{"local_timestamp": 1782707709.913502, "slug": "will-lionel-messi-be-the-top-goalscorer-at-the-2026-fifa-world-cup", "data": {"market": "0xd2a8caba5559bc21e14f6b2aa504cb14a1782751658b71409e25b82e432c0a97", "price_changes": [{"asset_id": "36586667785814641857008731622413716797407337292495614620493145114086484487337", "price": "0.35", "size": "3200", "side": "BUY", "hash": "e412c1a3496feaae59d1a5ad72e226c3a0fb942a", "best_bid": "0.48", "best_ask": "0.481"}, {"asset_id": "19214394437683566921750936876376421489271269944393354497977881791256347396217", "price": "0.65", "size": "3200", "side": "SELL", "hash": "3114286d913f443d5efb67d539600c2c42137346", "best_bid": "0.519", "best_ask": "0.52"}], "timestamp": "1782707711143", "event_type": "price_change"}}
{"local_timestamp": 1782707710.0572438, "slug": "will-lionel-messi-be-the-top-goalscorer-at-the-2026-fifa-world-cup", "data": {"market": "0xd2a8caba5559bc21e14f6b2aa504cb14a1782751658b71409e25b82e432c0a97", "price_changes": [{"asset_id": "19214394437683566921750936876376421489271269944393354497977881791256347396217", "price": "0.49", "size": "10002", "side": "BUY", "hash": "e8a2a6b519618002a868dfbddf7353f2a1bcbdee", "best_bid": "0.519", "best_ask": "0.52"}, {"asset_id": "36586667785814641857008731622413716797407337292495614620493145114086484487337", "price": "0.51", "size": "10002", "side": "SELL", "hash": "3759fe5c04a71cc6128411f4ae41ee7376328fc6", "best_bid": "0.48", "best_ask": "0.481"}], "timestamp": "1782707711288", "event_type": "price_change"}}
{"local_timestamp": 1782707710.0731258, "slug": "will-lionel-messi-be-the-top-goalscorer-at-the-2026-fifa-world-cup", "data": {"market": "0xd2a8caba5559bc21e14f6b2aa504cb14a1782751658b71409e25b82e432c0a97", "price_changes": [{"asset_id": "19214394437683566921750936876376421489271269944393354497977881791256347396217", "price": "0.5", "size": "30605", "side": "BUY", "hash": "bf3f5923f6cd148336adb95d10d8c4c8514a2c6d", "best_bid": "0.519", "best_ask": "0.52"}, {"asset_id": "36586667785814641857008731622413716797407337292495614620493145114086484487337", "price": "0.5", "size": "30605", "side": "SELL", "hash": "e1b20426e4842cb343a7514affb7e87e4b498794", "best_bid": "0.48", "best_ask": "0.481"}], "timestamp": "1782707711304", "event_type": "price_change"}}
{"local_timestamp": 1782707710.4124897, "slug": "will-lionel-messi-be-the-top-goalscorer-at-the-2026-fifa-world-cup", "data": {"market": "0xd2a8caba5559bc21e14f6b2aa504cb14a1782751658b71409e25b82e432c0a97", "price_changes": [{"asset_id": "19214394437683566921750936876376421489271269944393354497977881791256347396217", "price": "0.402", "size": "0", "side": "BUY", "hash": "62de9cf9ba057cfed495f7575da5c044234395d1", "best_bid": "0.519", "best_ask": "0.52"}, {"asset_id": "36586667785814641857008731622413716797407337292495614620493145114086484487337", "price": "0.598", "size": "0", "side": "SELL", "hash": "3be584f3f637b5bcfe11ebcac74d63f3597165bc", "best_bid": "0.48", "best_ask": "0.481"}], "timestamp": "1782707711643", "event_type": "price_change"}}
{"local_timestamp": 1782707710.7870295, "slug": "will-lionel-messi-be-the-top-goalscorer-at-the-2026-fifa-world-cup", "data": {"market": "0xd2a8caba5559bc21e14f6b2aa504cb14a1782751658b71409e25b82e432c0a97", "price_changes": [{"asset_id": "19214394437683566921750936876376421489271269944393354497977881791256347396217", "price": "0.5", "size": "30395", "side": "BUY", "hash": "a1a26e438fc65a9afe3b63f9280cabe67a6016cc", "best_bid": "0.519", "best_ask": "0.52"}, {"asset_id": "36586667785814641857008731622413716797407337292495614620493145114086484487337", "price": "0.5", "size": "30395", "side": "SELL", "hash": "17213ade5799a4fa0bcefaa93eee5dc3e0e2ac7e", "best_bid": "0.48", "best_ask": "0.481"}], "timestamp": "1782707712004", "event_type": "price_change"}}
{"local_timestamp": 1782707711.2976935, "slug": "will-lionel-messi-be-the-top-goalscorer-at-the-2026-fifa-world-cup", "data": {"market": "0xd2a8caba5559bc21e14f6b2aa504cb14a1782751658b71409e25b82e432c0a97", "price_changes": [{"asset_id": "19214394437683566921750936876376421489271269944393354497977881791256347396217", "price": "0.48", "size": "2877", "side": "BUY", "hash": "54b2432e47eedd2b94e7cea71fc830801177ad1c", "best_bid": "0.519", "best_ask": "0.52"}, {"asset_id": "36586667785814641857008731622413716797407337292495614620493145114086484487337", "price": "0.52", "size": "2877", "side": "SELL", "hash": "cd64288da6fb4d35d75061c1bb69a11df5ce34f4", "best_bid": "0.48", "best_ask": "0.481"}], "timestamp": "1782707712529", "event_type": "price_change"}}
{"local_timestamp": 1782707711.333767, "slug": "will-lionel-messi-be-the-top-goalscorer-at-the-2026-fifa-world-cup", "data": {"market": "0xd2a8caba5559bc21e14f6b2aa504cb14a1782751658b71409e25b82e432c0a97", "price_changes": [{"asset_id": "36586667785814641857008731622413716797407337292495614620493145114086484487337", "price": "0.35", "size": "200", "side": "BUY", "hash": "4425ecaa5ee3bbe1b066580d741b57591c945758", "best_bid": "0.48", "best_ask": "0.481"}, {"asset_id": "19214394437683566921750936876376421489271269944393354497977881791256347396217", "price": "0.65", "size": "200", "side": "SELL", "hash": "e5ef040f39d104a5198b9259788cbfcac1eb5c76", "best_bid": "0.519", "best_ask": "0.52"}], "timestamp": "1782707712563", "event_type": "price_change"}}
{"local_timestamp": 1782707711.3342881, "slug": "will-lionel-messi-be-the-top-goalscorer-at-the-2026-fifa-world-cup", "data": {"market": "0xd2a8caba5559bc21e14f6b2aa504cb14a1782751658b71409e25b82e432c0a97", "price_changes": [{"asset_id": "19214394437683566921750936876376421489271269944393354497977881791256347396217", "price": "0.26", "size": "0", "side": "BUY", "hash": "cb0ea9cef8a918fa9243b86cd61ea01038ec0410", "best_bid": "0.519", "best_ask": "0.52"}, {"asset_id": "36586667785814641857008731622413716797407337292495614620493145114086484487337", "price": "0.74", "size": "0", "side": "SELL", "hash": "ed10dfa1fbb0747c8fb7ab69886db15feb834d15", "best_bid": "0.48", "best_ask": "0.481"}], "timestamp": "1782707712564", "event_type": "price_change"}}
{"local_timestamp": 1782707711.8955564, "slug": "will-lionel-messi-be-the-top-goalscorer-at-the-2026-fifa-world-cup", "data": {"market": "0xd2a8caba5559bc21e14f6b2aa504cb14a1782751658b71409e25b82e432c0a97", "price_changes": [{"asset_id": "19214394437683566921750936876376421489271269944393354497977881791256347396217", "price": "0.521", "size": "4651.96", "side": "SELL", "hash": "4f212ddd1a6814ee975acd1f1c92c880a2731d5a", "best_bid": "0.519", "best_ask": "0.52"}, {"asset_id": "36586667785814641857008731622413716797407337292495614620493145114086484487337", "price": "0.479", "size": "4651.96", "side": "BUY", "hash": "e33dd5c74cdda92eae4e0bba7771ea92419fcd16", "best_bid": "0.48", "best_ask": "0.481"}], "timestamp": "1782707713122", "event_type": "price_change"}}
{"local_timestamp": 1782707712.8682334, "slug": "will-lionel-messi-be-the-top-goalscorer-at-the-2026-fifa-world-cup", "data": {"market": "0xd2a8caba5559bc21e14f6b2aa504cb14a1782751658b71409e25b82e432c0a97", "price_changes": [{"asset_id": "19214394437683566921750936876376421489271269944393354497977881791256347396217", "price": "0.26", "size": "3000", "side": "BUY", "hash": "54a027430f5ad2fb05281ea1b8bfa339dfa44d4d", "best_bid": "0.519", "best_ask": "0.52"}, {"asset_id": "36586667785814641857008731622413716797407337292495614620493145114086484487337", "price": "0.74", "size": "3000", "side": "SELL", "hash": "39eab70d3df6cee4ea7f29116a718ed755e9e4af", "best_bid": "0.48", "best_ask": "0.481"}], "timestamp": "1782707714098", "event_type": "price_change"}}
{"local_timestamp": 1782707712.8743265, "slug": "will-lionel-messi-be-the-top-goalscorer-at-the-2026-fifa-world-cup", "data": {"market": "0xd2a8caba5559bc21e14f6b2aa504cb14a1782751658b71409e25b82e432c0a97", "price_changes": [{"asset_id": "36586667785814641857008731622413716797407337292495614620493145114086484487337", "price": "0.35", "size": "3200", "side": "BUY", "hash": "770b17c41e913e03a1730140cca4ca506ea30258", "best_bid": "0.48", "best_ask": "0.481"}, {"asset_id": "19214394437683566921750936876376421489271269944393354497977881791256347396217", "price": "0.65", "size": "3200", "side": "SELL", "hash": "68f7f222418620604c4f444d648b80d79fd92a8e", "best_bid": "0.519", "best_ask": "0.52"}], "timestamp": "1782707714104", "event_type": "price_change"}}
{"local_timestamp": 1782707714.3639896, "slug": "will-lionel-messi-be-the-top-goalscorer-at-the-2026-fifa-world-cup", "data": {"market": "0xd2a8caba5559bc21e14f6b2aa504cb14a1782751658b71409e25b82e432c0a97", "price_changes": [{"asset_id": "19214394437683566921750936876376421489271269944393354497977881791256347396217", "price": "0.521", "size": "4749.05", "side": "SELL", "hash": "2292e08254c96161479d3e6c75205b5504ac855d", "best_bid": "0.519", "best_ask": "0.52"}, {"asset_id": "36586667785814641857008731622413716797407337292495614620493145114086484487337", "price": "0.479", "size": "4749.05", "side": "BUY", "hash": "2eaf6b685b2d845c51aea7092918b1c2d52c1e25", "best_bid": "0.48", "best_ask": "0.481"}], "timestamp": "1782707715576", "event_type": "price_change"}}
{"local_timestamp": 1782707714.400395, "slug": "will-lionel-messi-be-the-top-goalscorer-at-the-2026-fifa-world-cup", "data": {"market": "0xd2a8caba5559bc21e14f6b2aa504cb14a1782751658b71409e25b82e432c0a97", "price_changes": [{"asset_id": "36586667785814641857008731622413716797407337292495614620493145114086484487337", "price": "0.35", "size": "200", "side": "BUY", "hash": "4bf016de4f62202281445abda35b8ebcae2451ac", "best_bid": "0.48", "best_ask": "0.481"}, {"asset_id": "19214394437683566921750936876376421489271269944393354497977881791256347396217", "price": "0.65", "size": "200", "side": "SELL", "hash": "15d31f4d1e9eb913303e7ead5c092151f2bf4540", "best_bid": "0.519", "best_ask": "0.52"}], "timestamp": "1782707715630", "event_type": "price_change"}}
{"local_timestamp": 1782707714.402943, "slug": "will-lionel-messi-be-the-top-goalscorer-at-the-2026-fifa-world-cup", "data": {"market": "0xd2a8caba5559bc21e14f6b2aa504cb14a1782751658b71409e25b82e432c0a97", "price_changes": [{"asset_id": "19214394437683566921750936876376421489271269944393354497977881791256347396217", "price": "0.26", "size": "0", "side": "BUY", "hash": "ce2c06981e357b087fcc203fa358153bc684f767", "best_bid": "0.519", "best_ask": "0.52"}, {"asset_id": "36586667785814641857008731622413716797407337292495614620493145114086484487337", "price": "0.74", "size": "0", "side": "SELL", "hash": "c067385e7956b524cde072ca018c470f7bf1469e", "best_bid": "0.48", "best_ask": "0.481"}], "timestamp": "1782707715630", "event_type": "price_change"}}
{"local_timestamp": 1782707715.8830912, "slug": "will-lionel-messi-be-the-top-goalscorer-at-the-2026-fifa-world-cup", "data": {"market": "0xd2a8caba5559bc21e14f6b2aa504cb14a1782751658b71409e25b82e432c0a97", "price_changes": [{"asset_id": "36586667785814641857008731622413716797407337292495614620493145114086484487337", "price": "0.35", "size": "3200", "side": "BUY", "hash": "64b5afa734efc2b4e81f8ed9f6f37882daeb5df9", "best_bid": "0.48", "best_ask": "0.481"}, {"asset_id": "19214394437683566921750936876376421489271269944393354497977881791256347396217", "price": "0.65", "size": "3200", "side": "SELL", "hash": "1fc8de7bfbbbd7b8fa6a863d9f5267baae818971", "best_bid": "0.519", "best_ask": "0.52"}], "timestamp": "1782707717112", "event_type": "price_change"}}
{"local_timestamp": 1782707715.890392, "slug": "will-lionel-messi-be-the-top-goalscorer-at-the-2026-fifa-world-cup", "data": {"market": "0xd2a8caba5559bc21e14f6b2aa504cb14a1782751658b71409e25b82e432c0a97", "price_changes": [{"asset_id": "19214394437683566921750936876376421489271269944393354497977881791256347396217", "price": "0.26", "size": "3000", "side": "BUY", "hash": "a4fb3c4bd3fb80d7e42fae0e998df0fea8c381e6", "best_bid": "0.519", "best_ask": "0.52"}, {"asset_id": "36586667785814641857008731622413716797407337292495614620493145114086484487337", "price": "0.74", "size": "3000", "side": "SELL", "hash": "87d9cfc2d1b69178d92b5a2390159244b553de5c", "best_bid": "0.48", "best_ask": "0.481"}], "timestamp": "1782707717122", "event_type": "price_change"}}
{"local_timestamp": 1782707716.0134058, "slug": "will-lionel-messi-be-the-top-goalscorer-at-the-2026-fifa-world-cup", "data": {"market": "0xd2a8caba5559bc21e14f6b2aa504cb14a1782751658b71409e25b82e432c0a97", "price_changes": [{"asset_id": "19214394437683566921750936876376421489271269944393354497977881791256347396217", "price": "0.521", "size": "4651.96", "side": "SELL", "hash": "964916d287d20b10892bebe66dc12656b5fa58f2", "best_bid": "0.519", "best_ask": "0.52"}, {"asset_id": "36586667785814641857008731622413716797407337292495614620493145114086484487337", "price": "0.479", "size": "4651.96", "side": "BUY", "hash": "d229b3e943ff109815d41483ff5ba29b28c9301f", "best_bid": "0.48", "best_ask": "0.481"}], "timestamp": "1782707717244", "event_type": "price_change"}}
{"local_timestamp": 1782707716.645454, "slug": "will-lionel-messi-be-the-top-goalscorer-at-the-2026-fifa-world-cup", "data": {"market": "0xd2a8caba5559bc21e14f6b2aa504cb14a1782751658b71409e25b82e432c0a97", "price_changes": [{"asset_id": "36586667785814641857008731622413716797407337292495614620493145114086484487337", "price": "0.232", "size": "200", "side": "BUY", "hash": "bfc4f406ed2ce1d988e31db8becc1bd54f74a4b1", "best_bid": "0.48", "best_ask": "0.481"}, {"asset_id": "19214394437683566921750936876376421489271269944393354497977881791256347396217", "price": "0.768", "size": "200", "side": "SELL", "hash": "5014b688c3875465d10ea71d194a5efeb7493721", "best_bid": "0.519", "best_ask": "0.52"}], "timestamp": "1782707717872", "event_type": "price_change"}}
{"local_timestamp": 1782707716.724902, "slug": "will-lionel-messi-be-the-top-goalscorer-at-the-2026-fifa-world-cup", "data": {"market": "0xd2a8caba5559bc21e14f6b2aa504cb14a1782751658b71409e25b82e432c0a97", "price_changes": [{"asset_id": "36586667785814641857008731622413716797407337292495614620493145114086484487337", "price": "0.231", "size": "0", "side": "BUY", "hash": "e1ec8e573210fb55589160d1a96178d946c51653", "best_bid": "0.48", "best_ask": "0.481"}, {"asset_id": "19214394437683566921750936876376421489271269944393354497977881791256347396217", "price": "0.769", "size": "0", "side": "SELL", "hash": "8e194240cd043630af9edf8812ff9d609120879b", "best_bid": "0.519", "best_ask": "0.52"}], "timestamp": "1782707717956", "event_type": "price_change"}}
{"local_timestamp": 1782707717.3988433, "slug": "will-lionel-messi-be-the-top-goalscorer-at-the-2026-fifa-world-cup", "data": {"market": "0xd2a8caba5559bc21e14f6b2aa504cb14a1782751658b71409e25b82e432c0a97", "price_changes": [{"asset_id": "36586667785814641857008731622413716797407337292495614620493145114086484487337", "price": "0.35", "size": "200", "side": "BUY", "hash": "7b8acea46bcbe0fbddc2b83813f72951dfe9877d", "best_bid": "0.48", "best_ask": "0.481"}, {"asset_id": "19214394437683566921750936876376421489271269944393354497977881791256347396217", "price": "0.65", "size": "200", "side": "SELL", "hash": "8d5c3db89a2c66ddbeee09b106433c327b79b17c", "best_bid": "0.519", "best_ask": "0.52"}], "timestamp": "1782707718609", "event_type": "price_change"}}
{"local_timestamp": 1782707717.399405, "slug": "will-lionel-messi-be-the-top-goalscorer-at-the-2026-fifa-world-cup", "data": {"market": "0xd2a8caba5559bc21e14f6b2aa504cb14a1782751658b71409e25b82e432c0a97", "price_changes": [{"asset_id": "19214394437683566921750936876376421489271269944393354497977881791256347396217", "price": "0.26", "size": "0", "side": "BUY", "hash": "1588e04023335ea925c194060ecdf09674671735", "best_bid": "0.519", "best_ask": "0.52"}, {"asset_id": "36586667785814641857008731622413716797407337292495614620493145114086484487337", "price": "0.74", "size": "0", "side": "SELL", "hash": "e9dd61bd00aeb86475cac6cd72331e4d653a474e", "best_bid": "0.48", "best_ask": "0.481"}], "timestamp": "1782707718610", "event_type": "price_change"}}
{"local_timestamp": 1782707717.7733562, "slug": "will-lionel-messi-be-the-top-goalscorer-at-the-2026-fifa-world-cup", "data": {"market": "0xd2a8caba5559bc21e14f6b2aa504cb14a1782751658b71409e25b82e432c0a97", "price_changes": [{"asset_id": "36586667785814641857008731622413716797407337292495614620493145114086484487337", "price": "0.479", "size": "4236.23", "side": "BUY", "hash": "cc3264ec765e3ac446b8ccbf94314339c979e65b", "best_bid": "0.48", "best_ask": "0.481"}, {"asset_id": "19214394437683566921750936876376421489271269944393354497977881791256347396217", "price": "0.521", "size": "4236.23", "side": "SELL", "hash": "43875317e4c4e0bd5d27bc3e0762a47e8a524bae", "best_bid": "0.519", "best_ask": "0.52"}], "timestamp": "1782707719003", "event_type": "price_change"}}
{"local_timestamp": 1782707717.777775, "slug": "will-lionel-messi-be-the-top-goalscorer-at-the-2026-fifa-world-cup", "data": {"market": "0xd2a8caba5559bc21e14f6b2aa504cb14a1782751658b71409e25b82e432c0a97", "price_changes": [{"asset_id": "19214394437683566921750936876376421489271269944393354497977881791256347396217", "price": "0.518", "size": "18340.44", "side": "BUY", "hash": "ba03a2a7ddf7cf296f6c45f227844897a3d26ac1", "best_bid": "0.519", "best_ask": "0.52"}, {"asset_id": "36586667785814641857008731622413716797407337292495614620493145114086484487337", "price": "0.482", "size": "18340.44", "side": "SELL", "hash": "ac266450430cd19cc3abc69b603af7d5bad373ae", "best_bid": "0.48", "best_ask": "0.481"}], "timestamp": "1782707719007", "event_type": "price_change"}}
{"local_timestamp": 1782707718.0084305, "slug": "will-lionel-messi-be-the-top-goalscorer-at-the-2026-fifa-world-cup", "data": {"market": "0xd2a8caba5559bc21e14f6b2aa504cb14a1782751658b71409e25b82e432c0a97", "price_changes": [{"asset_id": "19214394437683566921750936876376421489271269944393354497977881791256347396217", "price": "0.521", "size": "4333.32", "side": "SELL", "hash": "fbfdb0b7f71566d26154e563475929b4be1fd732", "best_bid": "0.519", "best_ask": "0.52"}, {"asset_id": "36586667785814641857008731622413716797407337292495614620493145114086484487337", "price": "0.479", "size": "4333.32", "side": "BUY", "hash": "38a4411444e6575c2fb98bea5d250a9e7d7b6af5", "best_bid": "0.48", "best_ask": "0.481"}], "timestamp": "1782707719239", "event_type": "price_change"}}
{"local_timestamp": 1782707718.0475965, "slug": "will-lionel-messi-be-the-top-goalscorer-at-the-2026-fifa-world-cup", "data": {"market": "0xd2a8caba5559bc21e14f6b2aa504cb14a1782751658b71409e25b82e432c0a97", "price_changes": [{"asset_id": "19214394437683566921750936876376421489271269944393354497977881791256347396217", "price": "0.401", "size": "100", "side": "BUY", "hash": "6ddfcedcc09d9ffe41733d61638714ac9005b718", "best_bid": "0.519", "best_ask": "0.52"}, {"asset_id": "36586667785814641857008731622413716797407337292495614620493145114086484487337", "price": "0.599", "size": "100", "side": "SELL", "hash": "6cd13984472f69ff556f46387ae92959c6f9f967", "best_bid": "0.48", "best_ask": "0.481"}], "timestamp": "1782707719278", "event_type": "price_change"}}
{"local_timestamp": 1782707718.8520324, "slug": "will-lionel-messi-be-the-top-goalscorer-at-the-2026-fifa-world-cup", "data": {"market": "0xd2a8caba5559bc21e14f6b2aa504cb14a1782751658b71409e25b82e432c0a97", "price_changes": [{"asset_id": "19214394437683566921750936876376421489271269944393354497977881791256347396217", "price": "0.26", "size": "3000", "side": "BUY", "hash": "e7b6bb16a446201cbdd59c1639624b2fdc7f3e81", "best_bid": "0.519", "best_ask": "0.52"}, {"asset_id": "36586667785814641857008731622413716797407337292495614620493145114086484487337", "price": "0.74", "size": "3000", "side": "SELL", "hash": "d275045f107d046ce315a5a951b285cc29482b24", "best_bid": "0.48", "best_ask": "0.481"}], "timestamp": "1782707720083", "event_type": "price_change"}}
{"local_timestamp": 1782707718.8536904, "slug": "will-lionel-messi-be-the-top-goalscorer-at-the-2026-fifa-world-cup", "data": {"market": "0xd2a8caba5559bc21e14f6b2aa504cb14a1782751658b71409e25b82e432c0a97", "price_changes": [{"asset_id": "36586667785814641857008731622413716797407337292495614620493145114086484487337", "price": "0.35", "size": "3200", "side": "BUY", "hash": "48a8d49aec679357c6d59d7bb3c16dbf581bc0dd", "best_bid": "0.48", "best_ask": "0.481"}, {"asset_id": "19214394437683566921750936876376421489271269944393354497977881791256347396217", "price": "0.65", "size": "3200", "side": "SELL", "hash": "bf3a0e30c2d3cc606ce60b638133c23452629e64", "best_bid": "0.519", "best_ask": "0.52"}], "timestamp": "1782707720085", "event_type": "price_change"}}
{"local_timestamp": 1782707719.2556229, "slug": "will-lionel-messi-be-the-top-goalscorer-at-the-2026-fifa-world-cup", "data": {"market": "0xd2a8caba5559bc21e14f6b2aa504cb14a1782751658b71409e25b82e432c0a97", "price_changes": [{"asset_id": "19214394437683566921750936876376421489271269944393354497977881791256347396217", "price": "0.511", "size": "2267.5", "side": "BUY", "hash": "fe8580a402a79106de6ecb1a56c478bbe54c6d7b", "best_bid": "0.519", "best_ask": "0.52"}, {"asset_id": "36586667785814641857008731622413716797407337292495614620493145114086484487337", "price": "0.489", "size": "2267.5", "side": "SELL", "hash": "1684dd140e8d61372220137afdd3f740b6c67d24", "best_bid": "0.48", "best_ask": "0.481"}], "timestamp": "1782707720483", "event_type": "price_change"}}
{"local_timestamp": 1782707719.494127, "slug": "will-lionel-messi-be-the-top-goalscorer-at-the-2026-fifa-world-cup", "data": {"market": "0xd2a8caba5559bc21e14f6b2aa504cb14a1782751658b71409e25b82e432c0a97", "price_changes": [{"asset_id": "36586667785814641857008731622413716797407337292495614620493145114086484487337", "price": "0.473", "size": "550", "side": "BUY", "hash": "c72d89a213af1ca7ae838c10e2b4a227809e4ce1", "best_bid": "0.48", "best_ask": "0.481"}, {"asset_id": "19214394437683566921750936876376421489271269944393354497977881791256347396217", "price": "0.527", "size": "550", "side": "SELL", "hash": "5d2ca9ad297ef28e04ee9ff482ac174948cb216a", "best_bid": "0.519", "best_ask": "0.52"}], "timestamp": "1782707720726", "event_type": "price_change"}}
{"local_timestamp": 1782707719.777475, "slug": "will-lionel-messi-be-the-top-goalscorer-at-the-2026-fifa-world-cup", "data": {"market": "0xd2a8caba5559bc21e14f6b2aa504cb14a1782751658b71409e25b82e432c0a97", "price_changes": [{"asset_id": "36586667785814641857008731622413716797407337292495614620493145114086484487337", "price": "0.46", "size": "44023", "side": "BUY", "hash": "e7a1b1aeff55903212c9d403e93e80a0ee93ed52", "best_bid": "0.48", "best_ask": "0.481"}, {"asset_id": "19214394437683566921750936876376421489271269944393354497977881791256347396217", "price": "0.54", "size": "44023", "side": "SELL", "hash": "99955694b5b8cc794c78f9014dabd350cd68f9dc", "best_bid": "0.519", "best_ask": "0.52"}], "timestamp": "1782707721002", "event_type": "price_change"}}
{"local_timestamp": 1782707720.3312025, "slug": "will-lionel-messi-be-the-top-goalscorer-at-the-2026-fifa-world-cup", "data": {"market": "0xd2a8caba5559bc21e14f6b2aa504cb14a1782751658b71409e25b82e432c0a97", "price_changes": [{"asset_id": "19214394437683566921750936876376421489271269944393354497977881791256347396217", "price": "0.26", "size": "0", "side": "BUY", "hash": "9305c648ebb17ba1c9b17e8aec3221bca258086b", "best_bid": "0.519", "best_ask": "0.52"}, {"asset_id": "36586667785814641857008731622413716797407337292495614620493145114086484487337", "price": "0.74", "size": "0", "side": "SELL", "hash": "fe69e591ccac00bc3203ba695e0721bde0c5e7db", "best_bid": "0.48", "best_ask": "0.481"}], "timestamp": "1782707721563", "event_type": "price_change"}}
{"local_timestamp": 1782707720.3320813, "slug": "will-lionel-messi-be-the-top-goalscorer-at-the-2026-fifa-world-cup", "data": {"market": "0xd2a8caba5559bc21e14f6b2aa504cb14a1782751658b71409e25b82e432c0a97", "price_changes": [{"asset_id": "36586667785814641857008731622413716797407337292495614620493145114086484487337", "price": "0.35", "size": "200", "side": "BUY", "hash": "bd5d3d27f1c5a5dd98f611083f95c484f0a5b0d5", "best_bid": "0.48", "best_ask": "0.481"}, {"asset_id": "19214394437683566921750936876376421489271269944393354497977881791256347396217", "price": "0.65", "size": "200", "side": "SELL", "hash": "9a69e0866394cb4713892b6b0336ca3b33b26c2b", "best_bid": "0.519", "best_ask": "0.52"}], "timestamp": "1782707721563", "event_type": "price_change"}}
{"local_timestamp": 1782707720.4281578, "slug": "will-lionel-messi-be-the-top-goalscorer-at-the-2026-fifa-world-cup", "data": {"market": "0xd2a8caba5559bc21e14f6b2aa504cb14a1782751658b71409e25b82e432c0a97", "price_changes": [{"asset_id": "19214394437683566921750936876376421489271269944393354497977881791256347396217", "price": "0.521", "size": "4236.23", "side": "SELL", "hash": "0688cf8eec755939f7fa1f99c161ccece083eef7", "best_bid": "0.519", "best_ask": "0.52"}, {"asset_id": "36586667785814641857008731622413716797407337292495614620493145114086484487337", "price": "0.479", "size": "4236.23", "side": "BUY", "hash": "9e1f36a73233d4fe2a5ef4413096f8006e8c6bf6", "best_bid": "0.48", "best_ask": "0.481"}], "timestamp": "1782707721660", "event_type": "price_change"}}
{"local_timestamp": 1782707720.520667, "slug": "will-lionel-messi-be-the-top-goalscorer-at-the-2026-fifa-world-cup", "data": {"market": "0xd2a8caba5559bc21e14f6b2aa504cb14a1782751658b71409e25b82e432c0a97", "price_changes": [{"asset_id": "19214394437683566921750936876376421489271269944393354497977881791256347396217", "price": "0.511", "size": "2567.5", "side": "BUY", "hash": "feeb106440fc3cdb0bb0777a0b4beec106cfc3c2", "best_bid": "0.519", "best_ask": "0.52"}, {"asset_id": "36586667785814641857008731622413716797407337292495614620493145114086484487337", "price": "0.489", "size": "2567.5", "side": "SELL", "hash": "b6ee4525f910963ee07e6377d6570329e4ecf5ed", "best_bid": "0.48", "best_ask": "0.481"}], "timestamp": "1782707721752", "event_type": "price_change"}}
{"local_timestamp": 1782707720.7446115, "slug": "will-lionel-messi-be-the-top-goalscorer-at-the-2026-fifa-world-cup", "data": {"market": "0xd2a8caba5559bc21e14f6b2aa504cb14a1782751658b71409e25b82e432c0a97", "price_changes": [{"asset_id": "36586667785814641857008731622413716797407337292495614620493145114086484487337", "price": "0.473", "size": "850", "side": "BUY", "hash": "df139dd7008fcb133035d225535348e6e8e0133f", "best_bid": "0.48", "best_ask": "0.481"}, {"asset_id": "19214394437683566921750936876376421489271269944393354497977881791256347396217", "price": "0.527", "size": "850", "side": "SELL", "hash": "845f1f3e9277fb338d235a9bf020a4d2b1d7798d", "best_bid": "0.519", "best_ask": "0.52"}], "timestamp": "1782707721975", "event_type": "price_change"}}
{"local_timestamp": 1782707721.954594, "slug": "will-lionel-messi-be-the-top-goalscorer-at-the-2026-fifa-world-cup", "data": {"market": "0xd2a8caba5559bc21e14f6b2aa504cb14a1782751658b71409e25b82e432c0a97", "price_changes": [{"asset_id": "36586667785814641857008731622413716797407337292495614620493145114086484487337", "price": "0.35", "size": "3200", "side": "BUY", "hash": "45d53b375868e430256ae3f0b43b77362a21aecf", "best_bid": "0.48", "best_ask": "0.481"}, {"asset_id": "19214394437683566921750936876376421489271269944393354497977881791256347396217", "price": "0.65", "size": "3200", "side": "SELL", "hash": "5488282b5d58e21e2cbcf5fca399ca122cf5ec51", "best_bid": "0.519", "best_ask": "0.52"}], "timestamp": "1782707723186", "event_type": "price_change"}}
{"local_timestamp": 1782707721.961642, "slug": "will-lionel-messi-be-the-top-goalscorer-at-the-2026-fifa-world-cup", "data": {"market": "0xd2a8caba5559bc21e14f6b2aa504cb14a1782751658b71409e25b82e432c0a97", "price_changes": [{"asset_id": "19214394437683566921750936876376421489271269944393354497977881791256347396217", "price": "0.26", "size": "3000", "side": "BUY", "hash": "2198dc89a16c924962b2a84d25ccaaa94100007f", "best_bid": "0.519", "best_ask": "0.52"}, {"asset_id": "36586667785814641857008731622413716797407337292495614620493145114086484487337", "price": "0.74", "size": "3000", "side": "SELL", "hash": "08e27c70c05e52c72764fac2a2a364255532d52d", "best_bid": "0.48", "best_ask": "0.481"}], "timestamp": "1782707723193", "event_type": "price_change"}}
{"local_timestamp": 1782707723.3437839, "slug": "will-lionel-messi-be-the-top-goalscorer-at-the-2026-fifa-world-cup", "data": {"market": "0xd2a8caba5559bc21e14f6b2aa504cb14a1782751658b71409e25b82e432c0a97", "price_changes": [{"asset_id": "19214394437683566921750936876376421489271269944393354497977881791256347396217", "price": "0.521", "size": "4333.32", "side": "SELL", "hash": "c9f0d6022079824fa2987ba1efb245f559385228", "best_bid": "0.519", "best_ask": "0.52"}, {"asset_id": "36586667785814641857008731622413716797407337292495614620493145114086484487337", "price": "0.479", "size": "4333.32", "side": "BUY", "hash": "ed4529f201fa944bb278c33ca4c84d719f43a33e", "best_bid": "0.48", "best_ask": "0.481"}], "timestamp": "1782707724574", "event_type": "price_change"}}
{"local_timestamp": 1782707723.3443427, "slug": "will-lionel-messi-be-the-top-goalscorer-at-the-2026-fifa-world-cup", "data": {"market": "0xd2a8caba5559bc21e14f6b2aa504cb14a1782751658b71409e25b82e432c0a97", "price_changes": [{"asset_id": "36586667785814641857008731622413716797407337292495614620493145114086484487337", "price": "0.35", "size": "200", "side": "BUY", "hash": "e7b5317c9cce8f411179f2420a1c38ba4a15ab06", "best_bid": "0.48", "best_ask": "0.481"}, {"asset_id": "19214394437683566921750936876376421489271269944393354497977881791256347396217", "price": "0.65", "size": "200", "side": "SELL", "hash": "5661dc3a6899ff99ed61fa63bc590d13fc07d189", "best_bid": "0.519", "best_ask": "0.52"}], "timestamp": "1782707724574", "event_type": "price_change"}}
{"local_timestamp": 1782707723.344752, "slug": "will-lionel-messi-be-the-top-goalscorer-at-the-2026-fifa-world-cup", "data": {"market": "0xd2a8caba5559bc21e14f6b2aa504cb14a1782751658b71409e25b82e432c0a97", "price_changes": [{"asset_id": "19214394437683566921750936876376421489271269944393354497977881791256347396217", "price": "0.26", "size": "0", "side": "BUY", "hash": "71907de6101af41650682da13d80315c048ac79d", "best_bid": "0.519", "best_ask": "0.52"}, {"asset_id": "36586667785814641857008731622413716797407337292495614620493145114086484487337", "price": "0.74", "size": "0", "side": "SELL", "hash": "1dcd1c047f20d5eaa9ca21ccb8cbb92bff3ea261", "best_bid": "0.48", "best_ask": "0.481"}], "timestamp": "1782707724575", "event_type": "price_change"}}
{"local_timestamp": 1782707724.7764947, "slug": "will-lionel-messi-be-the-top-goalscorer-at-the-2026-fifa-world-cup", "data": {"market": "0xd2a8caba5559bc21e14f6b2aa504cb14a1782751658b71409e25b82e432c0a97", "price_changes": [{"asset_id": "19214394437683566921750936876376421489271269944393354497977881791256347396217", "price": "0.518", "size": "17375.44", "side": "BUY", "hash": "84ba423cf303ba95cfe3357b03df5505624d6f1a", "best_bid": "0.519", "best_ask": "0.52"}, {"asset_id": "36586667785814641857008731622413716797407337292495614620493145114086484487337", "price": "0.482", "size": "17375.44", "side": "SELL", "hash": "90f734bac62cb7e724f4bce41178a2fa75b0a67b", "best_bid": "0.48", "best_ask": "0.481"}], "timestamp": "1782707726001", "event_type": "price_change"}}
{"local_timestamp": 1782707724.927262, "slug": "will-lionel-messi-be-the-top-goalscorer-at-the-2026-fifa-world-cup", "data": {"market": "0xd2a8caba5559bc21e14f6b2aa504cb14a1782751658b71409e25b82e432c0a97", "price_changes": [{"asset_id": "36586667785814641857008731622413716797407337292495614620493145114086484487337", "price": "0.35", "size": "3200", "side": "BUY", "hash": "f786892a396ca7ed19ef5205a3da3397bb184cf7", "best_bid": "0.48", "best_ask": "0.481"}, {"asset_id": "19214394437683566921750936876376421489271269944393354497977881791256347396217", "price": "0.65", "size": "3200", "side": "SELL", "hash": "1615f34f52686005a251ed86e1b282f569fe7b08", "best_bid": "0.519", "best_ask": "0.52"}], "timestamp": "1782707726142", "event_type": "price_change"}}
{"local_timestamp": 1782707724.9278376, "slug": "will-lionel-messi-be-the-top-goalscorer-at-the-2026-fifa-world-cup", "data": {"market": "0xd2a8caba5559bc21e14f6b2aa504cb14a1782751658b71409e25b82e432c0a97", "price_changes": [{"asset_id": "19214394437683566921750936876376421489271269944393354497977881791256347396217", "price": "0.26", "size": "3000", "side": "BUY", "hash": "fa597a2e26aa0666fea6cdf07202388279f5ff04", "best_bid": "0.519", "best_ask": "0.52"}, {"asset_id": "36586667785814641857008731622413716797407337292495614620493145114086484487337", "price": "0.74", "size": "3000", "side": "SELL", "hash": "ebd02fc2e9891e1e0ba1a40877436a3e57505f71", "best_bid": "0.48", "best_ask": "0.481"}], "timestamp": "1782707726152", "event_type": "price_change"}}
{"local_timestamp": 1782707724.9762588, "slug": "will-lionel-messi-be-the-top-goalscorer-at-the-2026-fifa-world-cup", "data": {"market": "0xd2a8caba5559bc21e14f6b2aa504cb14a1782751658b71409e25b82e432c0a97", "price_changes": [{"asset_id": "36586667785814641857008731622413716797407337292495614620493145114086484487337", "price": "0.232", "size": "400", "side": "BUY", "hash": "32242d1986238cdbcbf61818b8af6e104d756677", "best_bid": "0.48", "best_ask": "0.481"}, {"asset_id": "19214394437683566921750936876376421489271269944393354497977881791256347396217", "price": "0.768", "size": "400", "side": "SELL", "hash": "2493682d47afb856810487d960e1819f7d3b08b2", "best_bid": "0.519", "best_ask": "0.52"}], "timestamp": "1782707726206", "event_type": "price_change"}}
{"local_timestamp": 1782707725.0685267, "slug": "will-lionel-messi-be-the-top-goalscorer-at-the-2026-fifa-world-cup", "data": {"market": "0xd2a8caba5559bc21e14f6b2aa504cb14a1782751658b71409e25b82e432c0a97", "price_changes": [{"asset_id": "36586667785814641857008731622413716797407337292495614620493145114086484487337", "price": "0.232", "size": "200", "side": "BUY", "hash": "208d19cf4ecceda1b201364c2429d939cc4259e0", "best_bid": "0.48", "best_ask": "0.481"}, {"asset_id": "19214394437683566921750936876376421489271269944393354497977881791256347396217", "price": "0.768", "size": "200", "side": "SELL", "hash": "52d170d5991eb574f001e87d1491bb8a23b11e15", "best_bid": "0.519", "best_ask": "0.52"}], "timestamp": "1782707726294", "event_type": "price_change"}}
{"local_timestamp": 1782707725.770383, "slug": "will-lionel-messi-be-the-top-goalscorer-at-the-2026-fifa-world-cup", "data": {"market": "0xd2a8caba5559bc21e14f6b2aa504cb14a1782751658b71409e25b82e432c0a97", "price_changes": [{"asset_id": "36586667785814641857008731622413716797407337292495614620493145114086484487337", "price": "0.45", "size": "2111", "side": "BUY", "hash": "5bf43d12af3ec493d27ad1b9c2d9ac80041ae0f3", "best_bid": "0.48", "best_ask": "0.481"}, {"asset_id": "19214394437683566921750936876376421489271269944393354497977881791256347396217", "price": "0.55", "size": "2111", "side": "SELL", "hash": "21038cee79baa24a829d4ca7294e59bee2dc2dba", "best_bid": "0.519", "best_ask": "0.52"}], "timestamp": "1782707727000", "event_type": "price_change"}}
{"local_timestamp": 1782707725.8151715, "slug": "will-lionel-messi-be-the-top-goalscorer-at-the-2026-fifa-world-cup", "data": {"market": "0xd2a8caba5559bc21e14f6b2aa504cb14a1782751658b71409e25b82e432c0a97", "price_changes": [{"asset_id": "19214394437683566921750936876376421489271269944393354497977881791256347396217", "price": "0.521", "size": "4236.23", "side": "SELL", "hash": "78283c4fe0a65062858c243773fd7de2d43061c4", "best_bid": "0.519", "best_ask": "0.52"}, {"asset_id": "36586667785814641857008731622413716797407337292495614620493145114086484487337", "price": "0.479", "size": "4236.23", "side": "BUY", "hash": "43bbc8bdf1c5fd7c567167889e6c4f73b16b58d0", "best_bid": "0.48", "best_ask": "0.481"}], "timestamp": "1782707727047", "event_type": "price_change"}}
{"local_timestamp": 1782707726.3930876, "slug": "will-lionel-messi-be-the-top-goalscorer-at-the-2026-fifa-world-cup", "data": {"market": "0xd2a8caba5559bc21e14f6b2aa504cb14a1782751658b71409e25b82e432c0a97", "price_changes": [{"asset_id": "19214394437683566921750936876376421489271269944393354497977881791256347396217", "price": "0.26", "size": "0", "side": "BUY", "hash": "b30ae0faa8048958a187e6844399811767d4ec6a", "best_bid": "0.519", "best_ask": "0.52"}, {"asset_id": "36586667785814641857008731622413716797407337292495614620493145114086484487337", "price": "0.74", "size": "0", "side": "SELL", "hash": "e5177c3dc7c1924ea559b26d8c35b29bfea1215b", "best_bid": "0.48", "best_ask": "0.481"}], "timestamp": "1782707727624", "event_type": "price_change"}}
{"local_timestamp": 1782707726.3936274, "slug": "will-lionel-messi-be-the-top-goalscorer-at-the-2026-fifa-world-cup", "data": {"market": "0xd2a8caba5559bc21e14f6b2aa504cb14a1782751658b71409e25b82e432c0a97", "price_changes": [{"asset_id": "36586667785814641857008731622413716797407337292495614620493145114086484487337", "price": "0.35", "size": "200", "side": "BUY", "hash": "5d6d87a31b9069408fd3f3866af3ba3dd837d0a5", "best_bid": "0.48", "best_ask": "0.481"}, {"asset_id": "19214394437683566921750936876376421489271269944393354497977881791256347396217", "price": "0.65", "size": "200", "side": "SELL", "hash": "8c3c3fa91faaac621202f0004294957fa7d6526a", "best_bid": "0.519", "best_ask": "0.52"}], "timestamp": "1782707727624", "event_type": "price_change"}}
{"local_timestamp": 1782707726.4980516, "slug": "will-lionel-messi-be-the-top-goalscorer-at-the-2026-fifa-world-cup", "data": {"market": "0xd2a8caba5559bc21e14f6b2aa504cb14a1782751658b71409e25b82e432c0a97", "price_changes": [{"asset_id": "19214394437683566921750936876376421489271269944393354497977881791256347396217", "price": "0.506", "size": "1458.04", "side": "BUY", "hash": "607d506961cf38ea07ad3daab7762d46515cede6", "best_bid": "0.519", "best_ask": "0.52"}, {"asset_id": "36586667785814641857008731622413716797407337292495614620493145114086484487337", "price": "0.494", "size": "1458.04", "side": "SELL", "hash": "6fa72e872320bff071691f3ff1e602182d7d5f38", "best_bid": "0.48", "best_ask": "0.481"}], "timestamp": "1782707727730", "event_type": "price_change"}}
{"local_timestamp": 1782707727.2029166, "slug": "will-lionel-messi-be-the-top-goalscorer-at-the-2026-fifa-world-cup", "data": {"market": "0xd2a8caba5559bc21e14f6b2aa504cb14a1782751658b71409e25b82e432c0a97", "price_changes": [{"asset_id": "19214394437683566921750936876376421489271269944393354497977881791256347396217", "price": "0.402", "size": "100", "side": "BUY", "hash": "d92eefc0d8d9f6cd2718231c043d4f59d8c445cf", "best_bid": "0.519", "best_ask": "0.52"}, {"asset_id": "36586667785814641857008731622413716797407337292495614620493145114086484487337", "price": "0.598", "size": "100", "side": "SELL", "hash": "97d4646e67fb7e90f8e620a2ad23a0c4fc17b8e4", "best_bid": "0.48", "best_ask": "0.481"}], "timestamp": "1782707728435", "event_type": "price_change"}}
{"local_timestamp": 1782707727.3116224, "slug": "will-lionel-messi-be-the-top-goalscorer-at-the-2026-fifa-world-cup", "data": {"market": "0xd2a8caba5559bc21e14f6b2aa504cb14a1782751658b71409e25b82e432c0a97", "price_changes": [{"asset_id": "19214394437683566921750936876376421489271269944393354497977881791256347396217", "price": "0.401", "size": "0", "side": "BUY", "hash": "3d76b061fbf953ae5b7597da53c9c70d78e65356", "best_bid": "0.519", "best_ask": "0.52"}, {"asset_id": "36586667785814641857008731622413716797407337292495614620493145114086484487337", "price": "0.599", "size": "0", "side": "SELL", "hash": "2c5791d7fab3e0d67d3b0c25d0e9ed311fa6ba93", "best_bid": "0.48", "best_ask": "0.481"}], "timestamp": "1782707728543", "event_type": "price_change"}}
{"local_timestamp": 1782707727.5148783, "slug": "will-lionel-messi-be-the-top-goalscorer-at-the-2026-fifa-world-cup", "data": {"market": "0xd2a8caba5559bc21e14f6b2aa504cb14a1782751658b71409e25b82e432c0a97", "price_changes": [{"asset_id": "19214394437683566921750936876376421489271269944393354497977881791256347396217", "price": "0.518", "size": "17625.44", "side": "BUY", "hash": "d8bb83feb3bf5cf05c27dc0ce8c3e90ccb394ecc", "best_bid": "0.519", "best_ask": "0.52"}, {"asset_id": "36586667785814641857008731622413716797407337292495614620493145114086484487337", "price": "0.482", "size": "17625.44", "side": "SELL", "hash": "fc317f0c7e19146a73121147a7d941bdd6c23ad7", "best_bid": "0.48", "best_ask": "0.481"}], "timestamp": "1782707728745", "event_type": "price_change"}}
{"local_timestamp": 1782707727.5507915, "slug": "will-lionel-messi-be-the-top-goalscorer-at-the-2026-fifa-world-cup", "data": {"market": "0xd2a8caba5559bc21e14f6b2aa504cb14a1782751658b71409e25b82e432c0a97", "price_changes": [{"asset_id": "36586667785814641857008731622413716797407337292495614620493145114086484487337", "price": "0.479", "size": "4486.23", "side": "BUY", "hash": "254cccdba4b111872fe74f10793ff7c4d14b0541", "best_bid": "0.48", "best_ask": "0.481"}, {"asset_id": "19214394437683566921750936876376421489271269944393354497977881791256347396217", "price": "0.521", "size": "4486.23", "side": "SELL", "hash": "890d470b606c6258e756f89f7de612a6857c59e6", "best_bid": "0.519", "best_ask": "0.52"}], "timestamp": "1782707728782", "event_type": "price_change"}}
{"local_timestamp": 1782707727.9098284, "slug": "will-lionel-messi-be-the-top-goalscorer-at-the-2026-fifa-world-cup", "data": {"market": "0xd2a8caba5559bc21e14f6b2aa504cb14a1782751658b71409e25b82e432c0a97", "price_changes": [{"asset_id": "19214394437683566921750936876376421489271269944393354497977881791256347396217", "price": "0.26", "size": "3000", "side": "BUY", "hash": "c35ae1a50fdcad5446878b6c4a0383b4d84fc11f", "best_bid": "0.519", "best_ask": "0.52"}, {"asset_id": "36586667785814641857008731622413716797407337292495614620493145114086484487337", "price": "0.74", "size": "3000", "side": "SELL", "hash": "fc68880351f5495c66103111fb8d0ade05a3ebdb", "best_bid": "0.48", "best_ask": "0.481"}], "timestamp": "1782707729141", "event_type": "price_change"}}
{"local_timestamp": 1782707727.922176, "slug": "will-lionel-messi-be-the-top-goalscorer-at-the-2026-fifa-world-cup", "data": {"market": "0xd2a8caba5559bc21e14f6b2aa504cb14a1782751658b71409e25b82e432c0a97", "price_changes": [{"asset_id": "36586667785814641857008731622413716797407337292495614620493145114086484487337", "price": "0.35", "size": "3200", "side": "BUY", "hash": "7758c64044426d1ea6a183860474f3c0639d265d", "best_bid": "0.48", "best_ask": "0.481"}, {"asset_id": "19214394437683566921750936876376421489271269944393354497977881791256347396217", "price": "0.65", "size": "3200", "side": "SELL", "hash": "e8518e3a235f7d65eab4378c7fcd1569f1bab496", "best_bid": "0.519", "best_ask": "0.52"}], "timestamp": "1782707729152", "event_type": "price_change"}}
{"local_timestamp": 1782707728.249503, "slug": "will-lionel-messi-be-the-top-goalscorer-at-the-2026-fifa-world-cup", "data": {"market": "0xd2a8caba5559bc21e14f6b2aa504cb14a1782751658b71409e25b82e432c0a97", "price_changes": [{"asset_id": "19214394437683566921750936876376421489271269944393354497977881791256347396217", "price": "0.521", "size": "4583.32", "side": "SELL", "hash": "6982fc8c6c1ba171839d489f20e176742704586f", "best_bid": "0.519", "best_ask": "0.52"}, {"asset_id": "36586667785814641857008731622413716797407337292495614620493145114086484487337", "price": "0.479", "size": "4583.32", "side": "BUY", "hash": "1a6c113d5edbaa95805f13bd76dee3a829d90d68", "best_bid": "0.48", "best_ask": "0.481"}], "timestamp": "1782707729479", "event_type": "price_change"}}
{"local_timestamp": 1782707728.7738345, "slug": "will-lionel-messi-be-the-top-goalscorer-at-the-2026-fifa-world-cup", "data": {"market": "0xd2a8caba5559bc21e14f6b2aa504cb14a1782751658b71409e25b82e432c0a97", "price_changes": [{"asset_id": "19214394437683566921750936876376421489271269944393354497977881791256347396217", "price": "0.5", "size": "29626", "side": "BUY", "hash": "ac3173e927a1913d5f68192af0484c3ef2af75f4", "best_bid": "0.519", "best_ask": "0.52"}, {"asset_id": "36586667785814641857008731622413716797407337292495614620493145114086484487337", "price": "0.5", "size": "29626", "side": "SELL", "hash": "9cb838983eb30160faf1b07f0ac5fc06a7152775", "best_bid": "0.48", "best_ask": "0.481"}], "timestamp": "1782707730004", "event_type": "price_change"}}
{"local_timestamp": 1782707729.3930378, "slug": "will-lionel-messi-be-the-top-goalscorer-at-the-2026-fifa-world-cup", "data": {"market": "0xd2a8caba5559bc21e14f6b2aa504cb14a1782751658b71409e25b82e432c0a97", "price_changes": [{"asset_id": "19214394437683566921750936876376421489271269944393354497977881791256347396217", "price": "0.26", "size": "0", "side": "BUY", "hash": "f4dd59933f9b2882690329fe5ac118f07465ad27", "best_bid": "0.519", "best_ask": "0.52"}, {"asset_id": "36586667785814641857008731622413716797407337292495614620493145114086484487337", "price": "0.74", "size": "0", "side": "SELL", "hash": "53ba33c3016fdfa084c96aa0398471aa0468c884", "best_bid": "0.48", "best_ask": "0.481"}], "timestamp": "1782707730622", "event_type": "price_change"}}
{"local_timestamp": 1782707729.393882, "slug": "will-lionel-messi-be-the-top-goalscorer-at-the-2026-fifa-world-cup", "data": {"market": "0xd2a8caba5559bc21e14f6b2aa504cb14a1782751658b71409e25b82e432c0a97", "price_changes": [{"asset_id": "36586667785814641857008731622413716797407337292495614620493145114086484487337", "price": "0.35", "size": "200", "side": "BUY", "hash": "f473b59b720fdee94db30f63912bab7194dd52cc", "best_bid": "0.48", "best_ask": "0.481"}, {"asset_id": "19214394437683566921750936876376421489271269944393354497977881791256347396217", "price": "0.65", "size": "200", "side": "SELL", "hash": "650ff7a106a5e7d4eca9be2692135314978038ea", "best_bid": "0.519", "best_ask": "0.52"}], "timestamp": "1782707730623", "event_type": "price_change"}}
{"local_timestamp": 1782707729.9286695, "slug": "will-lionel-messi-be-the-top-goalscorer-at-the-2026-fifa-world-cup", "data": {"market": "0xd2a8caba5559bc21e14f6b2aa504cb14a1782751658b71409e25b82e432c0a97", "price_changes": [{"asset_id": "19214394437683566921750936876376421489271269944393354497977881791256347396217", "price": "0.521", "size": "4486.23", "side": "SELL", "hash": "3ad47c4a43f3a597efe152bc175988595c944bcd", "best_bid": "0.519", "best_ask": "0.52"}, {"asset_id": "36586667785814641857008731622413716797407337292495614620493145114086484487337", "price": "0.479", "size": "4486.23", "side": "BUY", "hash": "f62e0f5e7b5256618d192580b5863e1bce3d4357", "best_bid": "0.48", "best_ask": "0.481"}], "timestamp": "1782707731160", "event_type": "price_change"}}
{"local_timestamp": 1782707730.9045398, "slug": "will-lionel-messi-be-the-top-goalscorer-at-the-2026-fifa-world-cup", "data": {"market": "0xd2a8caba5559bc21e14f6b2aa504cb14a1782751658b71409e25b82e432c0a97", "price_changes": [{"asset_id": "19214394437683566921750936876376421489271269944393354497977881791256347396217", "price": "0.49", "size": "9233", "side": "BUY", "hash": "b7e25cfac11c16a18bda4f84e07da8ce3804919b", "best_bid": "0.519", "best_ask": "0.52"}, {"asset_id": "36586667785814641857008731622413716797407337292495614620493145114086484487337", "price": "0.51", "size": "9233", "side": "SELL", "hash": "581580ae503269f00bc89e01e75ee7943e830218", "best_bid": "0.48", "best_ask": "0.481"}], "timestamp": "1782707732006", "event_type": "price_change"}}
{"local_timestamp": 1782707730.9051404, "slug": "will-lionel-messi-be-the-top-goalscorer-at-the-2026-fifa-world-cup", "data": {"market": "0xd2a8caba5559bc21e14f6b2aa504cb14a1782751658b71409e25b82e432c0a97", "price_changes": [{"asset_id": "36586667785814641857008731622413716797407337292495614620493145114086484487337", "price": "0.35", "size": "3200", "side": "BUY", "hash": "794e3df68f4fe0e8cc1349433e0eeb8bdca5efeb", "best_bid": "0.48", "best_ask": "0.481"}, {"asset_id": "19214394437683566921750936876376421489271269944393354497977881791256347396217", "price": "0.65", "size": "3200", "side": "SELL", "hash": "3993a5c21ce27c1b3e1e72ae96dcf32b2aeac056", "best_bid": "0.519", "best_ask": "0.52"}], "timestamp": "1782707732128", "event_type": "price_change"}}
{"local_timestamp": 1782707730.9056008, "slug": "will-lionel-messi-be-the-top-goalscorer-at-the-2026-fifa-world-cup", "data": {"market": "0xd2a8caba5559bc21e14f6b2aa504cb14a1782751658b71409e25b82e432c0a97", "price_changes": [{"asset_id": "19214394437683566921750936876376421489271269944393354497977881791256347396217", "price": "0.26", "size": "3000", "side": "BUY", "hash": "309df391ab01a76b632df952d52c661640c80576", "best_bid": "0.519", "best_ask": "0.52"}, {"asset_id": "36586667785814641857008731622413716797407337292495614620493145114086484487337", "price": "0.74", "size": "3000", "side": "SELL", "hash": "676978b844f64d7040ead5d9ca62e5f40f94d8c1", "best_bid": "0.48", "best_ask": "0.481"}], "timestamp": "1782707732130", "event_type": "price_change"}}
{"local_timestamp": 1782707732.370008, "slug": "will-lionel-messi-be-the-top-goalscorer-at-the-2026-fifa-world-cup", "data": {"market": "0xd2a8caba5559bc21e14f6b2aa504cb14a1782751658b71409e25b82e432c0a97", "price_changes": [{"asset_id": "19214394437683566921750936876376421489271269944393354497977881791256347396217", "price": "0.26", "size": "0", "side": "BUY", "hash": "1c8755747705449e80c0cc59ee9b3091d2265714", "best_bid": "0.519", "best_ask": "0.52"}, {"asset_id": "36586667785814641857008731622413716797407337292495614620493145114086484487337", "price": "0.74", "size": "0", "side": "SELL", "hash": "a58feed4cbfaf72bc14f3be48da6650c6e7a0ffb", "best_bid": "0.48", "best_ask": "0.481"}], "timestamp": "1782707733601", "event_type": "price_change"}}
{"local_timestamp": 1782707732.370592, "slug": "will-lionel-messi-be-the-top-goalscorer-at-the-2026-fifa-world-cup", "data": {"market": "0xd2a8caba5559bc21e14f6b2aa504cb14a1782751658b71409e25b82e432c0a97", "price_changes": [{"asset_id": "36586667785814641857008731622413716797407337292495614620493145114086484487337", "price": "0.35", "size": "200", "side": "BUY", "hash": "5bd699b97938ab8437332b72066d1526933bd9ff", "best_bid": "0.48", "best_ask": "0.481"}, {"asset_id": "19214394437683566921750936876376421489271269944393354497977881791256347396217", "price": "0.65", "size": "200", "side": "SELL", "hash": "22e577a776fb1fc2b348dc9bf43785f41264f3ad", "best_bid": "0.519", "best_ask": "0.52"}], "timestamp": "1782707733601", "event_type": "price_change"}}
{"local_timestamp": 1782707732.5263062, "slug": "will-lionel-messi-be-the-top-goalscorer-at-the-2026-fifa-world-cup", "data": {"market": "0xd2a8caba5559bc21e14f6b2aa504cb14a1782751658b71409e25b82e432c0a97", "price_changes": [{"asset_id": "19214394437683566921750936876376421489271269944393354497977881791256347396217", "price": "0.521", "size": "4583.32", "side": "SELL", "hash": "f9d23c6d8c6a62faaa15f1bfbe603eb7fba5e890", "best_bid": "0.519", "best_ask": "0.52"}, {"asset_id": "36586667785814641857008731622413716797407337292495614620493145114086484487337", "price": "0.479", "size": "4583.32", "side": "BUY", "hash": "89bbe7f8efd96e957f58955d78bf1f17fe58f275", "best_bid": "0.48", "best_ask": "0.481"}], "timestamp": "1782707733757", "event_type": "price_change"}}
{"local_timestamp": 1782707733.8143184, "slug": "will-lionel-messi-be-the-top-goalscorer-at-the-2026-fifa-world-cup", "data": {"market": "0xd2a8caba5559bc21e14f6b2aa504cb14a1782751658b71409e25b82e432c0a97", "price_changes": [{"asset_id": "36586667785814641857008731622413716797407337292495614620493145114086484487337", "price": "0.232", "size": "400", "side": "BUY", "hash": "532a3bd2987b98eebf37eb67335cc555c10bc931", "best_bid": "0.48", "best_ask": "0.481"}, {"asset_id": "19214394437683566921750936876376421489271269944393354497977881791256347396217", "price": "0.768", "size": "400", "side": "SELL", "hash": "101b1d397e61047b407c401ab2856d39c1adebe5", "best_bid": "0.519", "best_ask": "0.52"}], "timestamp": "1782707735046", "event_type": "price_change"}}
{"local_timestamp": 1782707733.9098268, "slug": "will-lionel-messi-be-the-top-goalscorer-at-the-2026-fifa-world-cup", "data": {"market": "0xd2a8caba5559bc21e14f6b2aa504cb14a1782751658b71409e25b82e432c0a97", "price_changes": [{"asset_id": "36586667785814641857008731622413716797407337292495614620493145114086484487337", "price": "0.35", "size": "3200", "side": "BUY", "hash": "ab99bf343527c120e82a4de271c07c7e9bd5e78a", "best_bid": "0.48", "best_ask": "0.481"}, {"asset_id": "19214394437683566921750936876376421489271269944393354497977881791256347396217", "price": "0.65", "size": "3200", "side": "SELL", "hash": "207fd633026cd706c10dbc271f2d7365a3acb3cf", "best_bid": "0.519", "best_ask": "0.52"}], "timestamp": "1782707735136", "event_type": "price_change"}}
{"local_timestamp": 1782707733.9113305, "slug": "will-lionel-messi-be-the-top-goalscorer-at-the-2026-fifa-world-cup", "data": {"market": "0xd2a8caba5559bc21e14f6b2aa504cb14a1782751658b71409e25b82e432c0a97", "price_changes": [{"asset_id": "19214394437683566921750936876376421489271269944393354497977881791256347396217", "price": "0.26", "size": "3000", "side": "BUY", "hash": "ae5ba1bf89e55f7e94051fff90a1e1e138383a89", "best_bid": "0.519", "best_ask": "0.52"}, {"asset_id": "36586667785814641857008731622413716797407337292495614620493145114086484487337", "price": "0.74", "size": "3000", "side": "SELL", "hash": "f8025f2e541f1093b78c08fb184699afa5097f43", "best_bid": "0.48", "best_ask": "0.481"}], "timestamp": "1782707735142", "event_type": "price_change"}}
{"local_timestamp": 1782707734.2268229, "slug": "will-lionel-messi-be-the-top-goalscorer-at-the-2026-fifa-world-cup", "data": {"market": "0xd2a8caba5559bc21e14f6b2aa504cb14a1782751658b71409e25b82e432c0a97", "price_changes": [{"asset_id": "36586667785814641857008731622413716797407337292495614620493145114086484487337", "price": "0.232", "size": "200", "side": "BUY", "hash": "a9e577249b22d7d2639d4fada485997d261aaa5c", "best_bid": "0.48", "best_ask": "0.481"}, {"asset_id": "19214394437683566921750936876376421489271269944393354497977881791256347396217", "price": "0.768", "size": "200", "side": "SELL", "hash": "3d6db11c44d307b489481f4aeab8d565352ff1a0", "best_bid": "0.519", "best_ask": "0.52"}], "timestamp": "1782707735458", "event_type": "price_change"}}
{"local_timestamp": 1782707735.0630198, "slug": "will-lionel-messi-be-the-top-goalscorer-at-the-2026-fifa-world-cup", "data": {"market": "0xd2a8caba5559bc21e14f6b2aa504cb14a1782751658b71409e25b82e432c0a97", "price_changes": [{"asset_id": "19214394437683566921750936876376421489271269944393354497977881791256347396217", "price": "0.402", "size": "200", "side": "BUY", "hash": "0490a7ad582c5a44aada57ae0a9bcb5a2b2e47a9", "best_bid": "0.519", "best_ask": "0.52"}, {"asset_id": "36586667785814641857008731622413716797407337292495614620493145114086484487337", "price": "0.598", "size": "200", "side": "SELL", "hash": "95e07e30d9e14c512a064f19b92228c940a7086e", "best_bid": "0.48", "best_ask": "0.481"}], "timestamp": "1782707736294", "event_type": "price_change"}}
{"local_timestamp": 1782707735.0785956, "slug": "will-lionel-messi-be-the-top-goalscorer-at-the-2026-fifa-world-cup", "data": {"market": "0xd2a8caba5559bc21e14f6b2aa504cb14a1782751658b71409e25b82e432c0a97", "price_changes": [{"asset_id": "19214394437683566921750936876376421489271269944393354497977881791256347396217", "price": "0.521", "size": "4486.23", "side": "SELL", "hash": "40dfa0f2d7087f033905650e9ce7e637ba563aab", "best_bid": "0.519", "best_ask": "0.52"}, {"asset_id": "36586667785814641857008731622413716797407337292495614620493145114086484487337", "price": "0.479", "size": "4486.23", "side": "BUY", "hash": "90326242c45ca2e436d6efc657141b593d205816", "best_bid": "0.48", "best_ask": "0.481"}], "timestamp": "1782707736311", "event_type": "price_change"}}
{"local_timestamp": 1782707735.1087484, "slug": "will-lionel-messi-be-the-top-goalscorer-at-the-2026-fifa-world-cup", "data": {"market": "0xd2a8caba5559bc21e14f6b2aa504cb14a1782751658b71409e25b82e432c0a97", "price_changes": [{"asset_id": "19214394437683566921750936876376421489271269944393354497977881791256347396217", "price": "0.402", "size": "100", "side": "BUY", "hash": "c25762d1f5c7df2572e599f6717380eab5759ada", "best_bid": "0.519", "best_ask": "0.52"}, {"asset_id": "36586667785814641857008731622413716797407337292495614620493145114086484487337", "price": "0.598", "size": "100", "side": "SELL", "hash": "45d4d4ccacd1e75129c14e231fa19bd6ab20b9cf", "best_bid": "0.48", "best_ask": "0.481"}], "timestamp": "1782707736339", "event_type": "price_change"}}
{"local_timestamp": 1782707735.3621905, "slug": "will-lionel-messi-be-the-top-goalscorer-at-the-2026-fifa-world-cup", "data": {"market": "0xd2a8caba5559bc21e14f6b2aa504cb14a1782751658b71409e25b82e432c0a97", "price_changes": [{"asset_id": "36586667785814641857008731622413716797407337292495614620493145114086484487337", "price": "0.35", "size": "200", "side": "BUY", "hash": "01d22d154af930dd840e0c3603629b7133143825", "best_bid": "0.48", "best_ask": "0.481"}, {"asset_id": "19214394437683566921750936876376421489271269944393354497977881791256347396217", "price": "0.65", "size": "200", "side": "SELL", "hash": "fd15d95b1e27f3abe0565171feadafab88714e18", "best_bid": "0.519", "best_ask": "0.52"}], "timestamp": "1782707736592", "event_type": "price_change"}}
{"local_timestamp": 1782707735.362771, "slug": "will-lionel-messi-be-the-top-goalscorer-at-the-2026-fifa-world-cup", "data": {"market": "0xd2a8caba5559bc21e14f6b2aa504cb14a1782751658b71409e25b82e432c0a97", "price_changes": [{"asset_id": "19214394437683566921750936876376421489271269944393354497977881791256347396217", "price": "0.26", "size": "0", "side": "BUY", "hash": "347e013f48c807cce9fa2f8849b5d172b4de5282", "best_bid": "0.519", "best_ask": "0.52"}, {"asset_id": "36586667785814641857008731622413716797407337292495614620493145114086484487337", "price": "0.74", "size": "0", "side": "SELL", "hash": "16e743ef596a972e2b96b1703d9b56429e4d189d", "best_bid": "0.48", "best_ask": "0.481"}], "timestamp": "1782707736592", "event_type": "price_change"}}
{"local_timestamp": 1782707735.530316, "slug": "will-lionel-messi-be-the-top-goalscorer-at-the-2026-fifa-world-cup", "data": {"market": "0xd2a8caba5559bc21e14f6b2aa504cb14a1782751658b71409e25b82e432c0a97", "price_changes": [{"asset_id": "36586667785814641857008731622413716797407337292495614620493145114086484487337", "price": "0.46", "size": "44361", "side": "BUY", "hash": "41ecfd5a43a3305c7128211466d5ceb2039e7bb2", "best_bid": "0.48", "best_ask": "0.481"}, {"asset_id": "19214394437683566921750936876376421489271269944393354497977881791256347396217", "price": "0.54", "size": "44361", "side": "SELL", "hash": "bbce45f37751230441b03e22e9f93a4f5477954f", "best_bid": "0.519", "best_ask": "0.52"}], "timestamp": "1782707736762", "event_type": "price_change"}}
{"local_timestamp": 1782707735.7717066, "slug": "will-lionel-messi-be-the-top-goalscorer-at-the-2026-fifa-world-cup", "data": {"market": "0xd2a8caba5559bc21e14f6b2aa504cb14a1782751658b71409e25b82e432c0a97", "price_changes": [{"asset_id": "19214394437683566921750936876376421489271269944393354497977881791256347396217", "price": "0.498", "size": "5200", "side": "BUY", "hash": "f570af2e1c8fa8a88f6fc4532dc48d21f4e2cf56", "best_bid": "0.519", "best_ask": "0.52"}, {"asset_id": "36586667785814641857008731622413716797407337292495614620493145114086484487337", "price": "0.502", "size": "5200", "side": "SELL", "hash": "a47990cfc76e652ac9a73e204c2e5c9c034e489e", "best_bid": "0.48", "best_ask": "0.481"}], "timestamp": "1782707737000", "event_type": "price_change"}}
{"local_timestamp": 1782707736.8662791, "slug": "will-lionel-messi-be-the-top-goalscorer-at-the-2026-fifa-world-cup", "data": {"market": "0xd2a8caba5559bc21e14f6b2aa504cb14a1782751658b71409e25b82e432c0a97", "price_changes": [{"asset_id": "19214394437683566921750936876376421489271269944393354497977881791256347396217", "price": "0.26", "size": "3000", "side": "BUY", "hash": "05507e160ab7e38734f020319ce1ea198d19eaf4", "best_bid": "0.519", "best_ask": "0.52"}, {"asset_id": "36586667785814641857008731622413716797407337292495614620493145114086484487337", "price": "0.74", "size": "3000", "side": "SELL", "hash": "435d87c19648223e81bb0433c5c742b99f75cece", "best_bid": "0.48", "best_ask": "0.481"}], "timestamp": "1782707738097", "event_type": "price_change"}}
{"local_timestamp": 1782707736.8843307, "slug": "will-lionel-messi-be-the-top-goalscorer-at-the-2026-fifa-world-cup", "data": {"market": "0xd2a8caba5559bc21e14f6b2aa504cb14a1782751658b71409e25b82e432c0a97", "price_changes": [{"asset_id": "36586667785814641857008731622413716797407337292495614620493145114086484487337", "price": "0.35", "size": "3200", "side": "BUY", "hash": "0547edc834f64aa5efe4fde455cd249d168028c0", "best_bid": "0.48", "best_ask": "0.481"}, {"asset_id": "19214394437683566921750936876376421489271269944393354497977881791256347396217", "price": "0.65", "size": "3200", "side": "SELL", "hash": "d24836917539e90f33adf858ad3e6f6d1cbbb123", "best_bid": "0.519", "best_ask": "0.52"}], "timestamp": "1782707738117", "event_type": "price_change"}}
{"local_timestamp": 1782707737.533226, "slug": "will-lionel-messi-be-the-top-goalscorer-at-the-2026-fifa-world-cup", "data": {"market": "0xd2a8caba5559bc21e14f6b2aa504cb14a1782751658b71409e25b82e432c0a97", "price_changes": [{"asset_id": "19214394437683566921750936876376421489271269944393354497977881791256347396217", "price": "0.521", "size": "4583.32", "side": "SELL", "hash": "4913525bebf8f17b93a532cc811a55bff0494849", "best_bid": "0.519", "best_ask": "0.52"}, {"asset_id": "36586667785814641857008731622413716797407337292495614620493145114086484487337", "price": "0.479", "size": "4583.32", "side": "BUY", "hash": "4f8b9247cf0f14347066f60440766f87149eeac8", "best_bid": "0.48", "best_ask": "0.481"}], "timestamp": "1782707738765", "event_type": "price_change"}}
{"local_timestamp": 1782707737.6242263, "slug": "will-lionel-messi-be-the-top-goalscorer-at-the-2026-fifa-world-cup", "data": {"market": "0xd2a8caba5559bc21e14f6b2aa504cb14a1782751658b71409e25b82e432c0a97", "price_changes": [{"asset_id": "36586667785814641857008731622413716797407337292495614620493145114086484487337", "price": "0.479", "size": "4208.32", "side": "BUY", "hash": "6dbf99966d5b583c1f36ab9a72a74ee914d0adfc", "best_bid": "0.48", "best_ask": "0.481"}, {"asset_id": "19214394437683566921750936876376421489271269944393354497977881791256347396217", "price": "0.521", "size": "4208.32", "side": "SELL", "hash": "99452766eda5806f49ac6bf8388a63860079c7d6", "best_bid": "0.519", "best_ask": "0.52"}], "timestamp": "1782707738855", "event_type": "price_change"}}
{"local_timestamp": 1782707737.6573207, "slug": "will-lionel-messi-be-the-top-goalscorer-at-the-2026-fifa-world-cup", "data": {"market": "0xd2a8caba5559bc21e14f6b2aa504cb14a1782751658b71409e25b82e432c0a97", "price_changes": [{"asset_id": "36586667785814641857008731622413716797407337292495614620493145114086484487337", "price": "0.479", "size": "4583.32", "side": "BUY", "hash": "3fddd477363bd10012aefaf25e705d0979ade73b", "best_bid": "0.48", "best_ask": "0.481"}, {"asset_id": "19214394437683566921750936876376421489271269944393354497977881791256347396217", "price": "0.521", "size": "4583.32", "side": "SELL", "hash": "309b8b63257752c56a39c911cbf867915bd1434a", "best_bid": "0.519", "best_ask": "0.52"}], "timestamp": "1782707738884", "event_type": "price_change"}}
{"local_timestamp": 1782707738.018909, "slug": "will-lionel-messi-be-the-top-goalscorer-at-the-2026-fifa-world-cup", "data": {"market": "0xd2a8caba5559bc21e14f6b2aa504cb14a1782751658b71409e25b82e432c0a97", "price_changes": [{"asset_id": "19214394437683566921750936876376421489271269944393354497977881791256347396217", "price": "0.5", "size": "29964", "side": "BUY", "hash": "e5cab93fa56f85c1706580441a79e7d07d176d39", "best_bid": "0.519", "best_ask": "0.52"}, {"asset_id": "36586667785814641857008731622413716797407337292495614620493145114086484487337", "price": "0.5", "size": "29964", "side": "SELL", "hash": "59e25f8f8ffcaf9e6a43642e00c0580f448cc4dc", "best_bid": "0.48", "best_ask": "0.481"}], "timestamp": "1782707739251", "event_type": "price_change"}}
{"local_timestamp": 1782707738.3763103, "slug": "will-lionel-messi-be-the-top-goalscorer-at-the-2026-fifa-world-cup", "data": {"market": "0xd2a8caba5559bc21e14f6b2aa504cb14a1782751658b71409e25b82e432c0a97", "price_changes": [{"asset_id": "36586667785814641857008731622413716797407337292495614620493145114086484487337", "price": "0.35", "size": "200", "side": "BUY", "hash": "90dda05f85a63f6cbbee6cba0573bc92434f961f", "best_bid": "0.48", "best_ask": "0.481"}, {"asset_id": "19214394437683566921750936876376421489271269944393354497977881791256347396217", "price": "0.65", "size": "200", "side": "SELL", "hash": "4c536dee4c74c259b806605d813f77306cd16dc7", "best_bid": "0.519", "best_ask": "0.52"}], "timestamp": "1782707739608", "event_type": "price_change"}}
{"local_timestamp": 1782707738.3770516, "slug": "will-lionel-messi-be-the-top-goalscorer-at-the-2026-fifa-world-cup", "data": {"market": "0xd2a8caba5559bc21e14f6b2aa504cb14a1782751658b71409e25b82e432c0a97", "price_changes": [{"asset_id": "19214394437683566921750936876376421489271269944393354497977881791256347396217", "price": "0.26", "size": "0", "side": "BUY", "hash": "d4e0b607bc9cac5019627bb819654650bf7d3e79", "best_bid": "0.519", "best_ask": "0.52"}, {"asset_id": "36586667785814641857008731622413716797407337292495614620493145114086484487337", "price": "0.74", "size": "0", "side": "SELL", "hash": "9e1de66e6b0df2ac2103e593044dec9b6b7adc12", "best_bid": "0.48", "best_ask": "0.481"}], "timestamp": "1782707739609", "event_type": "price_change"}}
{"local_timestamp": 1782707739.6611965, "slug": "will-lionel-messi-be-the-top-goalscorer-at-the-2026-fifa-world-cup", "data": {"market": "0xd2a8caba5559bc21e14f6b2aa504cb14a1782751658b71409e25b82e432c0a97", "price_changes": [{"asset_id": "36586667785814641857008731622413716797407337292495614620493145114086484487337", "price": "0.46", "size": "44561", "side": "BUY", "hash": "cb54cd4786fb440b289785218ed977991ff88f5c", "best_bid": "0.48", "best_ask": "0.481"}, {"asset_id": "19214394437683566921750936876376421489271269944393354497977881791256347396217", "price": "0.54", "size": "44561", "side": "SELL", "hash": "217b653d9f54dc6c6b4d3095b960b048a3373dab", "best_bid": "0.519", "best_ask": "0.52"}], "timestamp": "1782707740891", "event_type": "price_change"}}
{"local_timestamp": 1782707739.8332372, "slug": "will-lionel-messi-be-the-top-goalscorer-at-the-2026-fifa-world-cup", "data": {"market": "0xd2a8caba5559bc21e14f6b2aa504cb14a1782751658b71409e25b82e432c0a97", "price_changes": [{"asset_id": "19214394437683566921750936876376421489271269944393354497977881791256347396217", "price": "0.26", "size": "3000", "side": "BUY", "hash": "eda59edc04434a57ffca8a0c928346d6cf81b7c9", "best_bid": "0.519", "best_ask": "0.52"}, {"asset_id": "36586667785814641857008731622413716797407337292495614620493145114086484487337", "price": "0.74", "size": "3000", "side": "SELL", "hash": "4e57ab53c79044c67ec3f900fad1630777b538d0", "best_bid": "0.48", "best_ask": "0.481"}], "timestamp": "1782707741065", "event_type": "price_change"}}
{"local_timestamp": 1782707739.921977, "slug": "will-lionel-messi-be-the-top-goalscorer-at-the-2026-fifa-world-cup", "data": {"market": "0xd2a8caba5559bc21e14f6b2aa504cb14a1782751658b71409e25b82e432c0a97", "price_changes": [{"asset_id": "36586667785814641857008731622413716797407337292495614620493145114086484487337", "price": "0.35", "size": "3200", "side": "BUY", "hash": "32a43ba12439a12ed1463554a14cd1ab7c470911", "best_bid": "0.48", "best_ask": "0.481"}, {"asset_id": "19214394437683566921750936876376421489271269944393354497977881791256347396217", "price": "0.65", "size": "3200", "side": "SELL", "hash": "ecaf446784479b907fc55c67f6958d4b3a377841", "best_bid": "0.519", "best_ask": "0.52"}], "timestamp": "1782707741153", "event_type": "price_change"}}
{"local_timestamp": 1782707740.7820778, "slug": "will-lionel-messi-be-the-top-goalscorer-at-the-2026-fifa-world-cup", "data": {"market": "0xd2a8caba5559bc21e14f6b2aa504cb14a1782751658b71409e25b82e432c0a97", "price_changes": [{"asset_id": "36586667785814641857008731622413716797407337292495614620493145114086484487337", "price": "0.479", "size": "4365.09", "side": "BUY", "hash": "509fc21e09e80f9d6b4ad835d6d54b715108baa4", "best_bid": "0.48", "best_ask": "0.481"}, {"asset_id": "19214394437683566921750936876376421489271269944393354497977881791256347396217", "price": "0.521", "size": "4365.09", "side": "SELL", "hash": "bd952b282d06750d8a5b4ad6943f8bd297df1285", "best_bid": "0.519", "best_ask": "0.52"}], "timestamp": "1782707742013", "event_type": "price_change"}}
{"local_timestamp": 1782707740.7852292, "slug": "will-lionel-messi-be-the-top-goalscorer-at-the-2026-fifa-world-cup", "data": {"market": "0xd2a8caba5559bc21e14f6b2aa504cb14a1782751658b71409e25b82e432c0a97", "price_changes": [{"asset_id": "19214394437683566921750936876376421489271269944393354497977881791256347396217", "price": "0.518", "size": "17298.33", "side": "BUY", "hash": "bd952b282d06750d8a5b4ad6943f8bd297df1285", "best_bid": "0.519", "best_ask": "0.52"}, {"asset_id": "36586667785814641857008731622413716797407337292495614620493145114086484487337", "price": "0.482", "size": "17298.33", "side": "SELL", "hash": "509fc21e09e80f9d6b4ad835d6d54b715108baa4", "best_bid": "0.48", "best_ask": "0.481"}], "timestamp": "1782707742013", "event_type": "price_change"}}
{"local_timestamp": 1782707740.8147492, "slug": "will-lionel-messi-be-the-top-goalscorer-at-the-2026-fifa-world-cup", "data": {"market": "0xd2a8caba5559bc21e14f6b2aa504cb14a1782751658b71409e25b82e432c0a97", "price_changes": [{"asset_id": "36586667785814641857008731622413716797407337292495614620493145114086484487337", "price": "0.46", "size": "44761", "side": "BUY", "hash": "3cc6a6dc6b919b4f74f4cfd6976cbf3d0431c1f6", "best_bid": "0.48", "best_ask": "0.481"}, {"asset_id": "19214394437683566921750936876376421489271269944393354497977881791256347396217", "price": "0.54", "size": "44761", "side": "SELL", "hash": "6c646058cd8f7edc99011a99d6376b3d9b4fdb6d", "best_bid": "0.519", "best_ask": "0.52"}], "timestamp": "1782707742047", "event_type": "price_change"}}
{"local_timestamp": 1782707740.82081, "slug": "will-lionel-messi-be-the-top-goalscorer-at-the-2026-fifa-world-cup", "data": {"market": "0xd2a8caba5559bc21e14f6b2aa504cb14a1782751658b71409e25b82e432c0a97", "price_changes": [{"asset_id": "19214394437683566921750936876376421489271269944393354497977881791256347396217", "price": "0.5", "size": "30164", "side": "BUY", "hash": "34c95e01159f1e1b7bbd9b8325d9d08c31869dda", "best_bid": "0.519", "best_ask": "0.52"}, {"asset_id": "36586667785814641857008731622413716797407337292495614620493145114086484487337", "price": "0.5", "size": "30164", "side": "SELL", "hash": "19eecc03e6e37c40c8cf80d18106cafb2fa787fd", "best_bid": "0.48", "best_ask": "0.481"}], "timestamp": "1782707742052", "event_type": "price_change"}}
{"local_timestamp": 1782707741.1849153, "slug": "will-lionel-messi-be-the-top-goalscorer-at-the-2026-fifa-world-cup", "data": {"market": "0xd2a8caba5559bc21e14f6b2aa504cb14a1782751658b71409e25b82e432c0a97", "price_changes": [{"asset_id": "19214394437683566921750936876376421489271269944393354497977881791256347396217", "price": "0.521", "size": "4268", "side": "SELL", "hash": "4b0b9ff3c61f607bda66cefb894b975b15aa8f58", "best_bid": "0.519", "best_ask": "0.52"}, {"asset_id": "36586667785814641857008731622413716797407337292495614620493145114086484487337", "price": "0.479", "size": "4268", "side": "BUY", "hash": "e7925ffe1657e0f9922de318f5e179225edf252b", "best_bid": "0.48", "best_ask": "0.481"}], "timestamp": "1782707742416", "event_type": "price_change"}}
{"local_timestamp": 1782707741.291316, "slug": "will-lionel-messi-be-the-top-goalscorer-at-the-2026-fifa-world-cup", "data": {"market": "0xd2a8caba5559bc21e14f6b2aa504cb14a1782751658b71409e25b82e432c0a97", "price_changes": [{"asset_id": "36586667785814641857008731622413716797407337292495614620493145114086484487337", "price": "0.48", "size": "446.3", "side": "BUY", "hash": "3a05e2b6c295ae895bcfa88f69228fe0f9bddb18", "best_bid": "0.48", "best_ask": "0.481"}, {"asset_id": "19214394437683566921750936876376421489271269944393354497977881791256347396217", "price": "0.52", "size": "446.3", "side": "SELL", "hash": "baae447e929234fbe7a7340e975c02e4f7598814", "best_bid": "0.519", "best_ask": "0.52"}], "timestamp": "1782707742523", "event_type": "price_change"}}
{"local_timestamp": 1782707741.2951505, "slug": "will-lionel-messi-be-the-top-goalscorer-at-the-2026-fifa-world-cup", "data": {"market": "0xd2a8caba5559bc21e14f6b2aa504cb14a1782751658b71409e25b82e432c0a97", "price_changes": [{"asset_id": "19214394437683566921750936876376421489271269944393354497977881791256347396217", "price": "0.519", "size": "909.93", "side": "BUY", "hash": "f9b2ca5cd2968bc8b0183862e21bd3a763fb12bd", "best_bid": "0.519", "best_ask": "0.52"}, {"asset_id": "36586667785814641857008731622413716797407337292495614620493145114086484487337", "price": "0.481", "size": "909.93", "side": "SELL", "hash": "eaad34bef0277768455d310aa47e372e51cacbbb", "best_bid": "0.48", "best_ask": "0.481"}], "timestamp": "1782707742527", "event_type": "price_change"}}
{"local_timestamp": 1782707741.3564668, "slug": "will-lionel-messi-be-the-top-goalscorer-at-the-2026-fifa-world-cup", "data": {"market": "0xd2a8caba5559bc21e14f6b2aa504cb14a1782751658b71409e25b82e432c0a97", "price_changes": [{"asset_id": "36586667785814641857008731622413716797407337292495614620493145114086484487337", "price": "0.35", "size": "200", "side": "BUY", "hash": "3083a12f630ae627b619be545b26062f64b053f8", "best_bid": "0.48", "best_ask": "0.481"}, {"asset_id": "19214394437683566921750936876376421489271269944393354497977881791256347396217", "price": "0.65", "size": "200", "side": "SELL", "hash": "000c8b5be7efda6ca62d95eefe5fcc98f976fa5c", "best_bid": "0.519", "best_ask": "0.52"}], "timestamp": "1782707742588", "event_type": "price_change"}}
{"local_timestamp": 1782707741.3586721, "slug": "will-lionel-messi-be-the-top-goalscorer-at-the-2026-fifa-world-cup", "data": {"market": "0xd2a8caba5559bc21e14f6b2aa504cb14a1782751658b71409e25b82e432c0a97", "price_changes": [{"asset_id": "19214394437683566921750936876376421489271269944393354497977881791256347396217", "price": "0.26", "size": "0", "side": "BUY", "hash": "817b29a1700cb6ea7a08d1498919f8c5478e9ec6", "best_bid": "0.519", "best_ask": "0.52"}, {"asset_id": "36586667785814641857008731622413716797407337292495614620493145114086484487337", "price": "0.74", "size": "0", "side": "SELL", "hash": "558e198f137ce47627808e0b471a52fe7d448b97", "best_bid": "0.48", "best_ask": "0.481"}], "timestamp": "1782707742588", "event_type": "price_change"}}
{"local_timestamp": 1782707742.8917627, "slug": "will-lionel-messi-be-the-top-goalscorer-at-the-2026-fifa-world-cup", "data": {"market": "0xd2a8caba5559bc21e14f6b2aa504cb14a1782751658b71409e25b82e432c0a97", "price_changes": [{"asset_id": "36586667785814641857008731622413716797407337292495614620493145114086484487337", "price": "0.232", "size": "400", "side": "BUY", "hash": "ebbd6ebfe70e3abc615d7ac3e064e5f457f1d13c", "best_bid": "0.48", "best_ask": "0.481"}, {"asset_id": "19214394437683566921750936876376421489271269944393354497977881791256347396217", "price": "0.768", "size": "400", "side": "SELL", "hash": "01ad0b343fbb5aa445c5d9dd28b2c2a5939ed4fa", "best_bid": "0.519", "best_ask": "0.52"}], "timestamp": "1782707744121", "event_type": "price_change"}}
{"local_timestamp": 1782707742.9265866, "slug": "will-lionel-messi-be-the-top-goalscorer-at-the-2026-fifa-world-cup", "data": {"market": "0xd2a8caba5559bc21e14f6b2aa504cb14a1782751658b71409e25b82e432c0a97", "price_changes": [{"asset_id": "19214394437683566921750936876376421489271269944393354497977881791256347396217", "price": "0.26", "size": "3000", "side": "BUY", "hash": "bb3dea807ac679510c3bbfb8c973fe6a338c2b49", "best_bid": "0.519", "best_ask": "0.52"}, {"asset_id": "36586667785814641857008731622413716797407337292495614620493145114086484487337", "price": "0.74", "size": "3000", "side": "SELL", "hash": "f53c6d764c9e200edfc69309e8d10f1ab97f1b7e", "best_bid": "0.48", "best_ask": "0.481"}], "timestamp": "1782707744155", "event_type": "price_change"}}
{"local_timestamp": 1782707742.9287906, "slug": "will-lionel-messi-be-the-top-goalscorer-at-the-2026-fifa-world-cup", "data": {"market": "0xd2a8caba5559bc21e14f6b2aa504cb14a1782751658b71409e25b82e432c0a97", "price_changes": [{"asset_id": "36586667785814641857008731622413716797407337292495614620493145114086484487337", "price": "0.35", "size": "3200", "side": "BUY", "hash": "87185897c90a54f92f84e22383a6c51c4033dee0", "best_bid": "0.48", "best_ask": "0.481"}, {"asset_id": "19214394437683566921750936876376421489271269944393354497977881791256347396217", "price": "0.65", "size": "3200", "side": "SELL", "hash": "b1016b494ef39c83d59bb74ce545d46cf35e9741", "best_bid": "0.519", "best_ask": "0.52"}], "timestamp": "1782707744157", "event_type": "price_change"}}
{"local_timestamp": 1782707742.9407527, "slug": "will-lionel-messi-be-the-top-goalscorer-at-the-2026-fifa-world-cup", "data": {"market": "0xd2a8caba5559bc21e14f6b2aa504cb14a1782751658b71409e25b82e432c0a97", "price_changes": [{"asset_id": "36586667785814641857008731622413716797407337292495614620493145114086484487337", "price": "0.232", "size": "200", "side": "BUY", "hash": "6421f2a788d87e5b0566b5c3d2ce35570b623c6f", "best_bid": "0.48", "best_ask": "0.481"}, {"asset_id": "19214394437683566921750936876376421489271269944393354497977881791256347396217", "price": "0.768", "size": "200", "side": "SELL", "hash": "3ddb2a0214e843aa47399f0852427a1ae06feb24", "best_bid": "0.519", "best_ask": "0.52"}], "timestamp": "1782707744170", "event_type": "price_change"}}
{"local_timestamp": 1782707743.1801152, "slug": "will-lionel-messi-be-the-top-goalscorer-at-the-2026-fifa-world-cup", "data": {"market": "0xd2a8caba5559bc21e14f6b2aa504cb14a1782751658b71409e25b82e432c0a97", "price_changes": [{"asset_id": "19214394437683566921750936876376421489271269944393354497977881791256347396217", "price": "0.498", "size": "5646.52", "side": "BUY", "hash": "76f24f2f39f1dd049b706575e9ea92e0a2f0ad8e", "best_bid": "0.519", "best_ask": "0.52"}, {"asset_id": "36586667785814641857008731622413716797407337292495614620493145114086484487337", "price": "0.502", "size": "5646.52", "side": "SELL", "hash": "d0a564124bcd14c4b34a58f2b86c7ef49af2be77", "best_bid": "0.48", "best_ask": "0.481"}], "timestamp": "1782707744411", "event_type": "price_change"}}
{"local_timestamp": 1782707743.8749962, "slug": "will-lionel-messi-be-the-top-goalscorer-at-the-2026-fifa-world-cup", "data": {"market": "0xd2a8caba5559bc21e14f6b2aa504cb14a1782751658b71409e25b82e432c0a97", "price_changes": [{"asset_id": "19214394437683566921750936876376421489271269944393354497977881791256347396217", "price": "0.521", "size": "4365.09", "side": "SELL", "hash": "4ec1f68e1f377914e130438b7f71c0276bfd451f", "best_bid": "0.519", "best_ask": "0.52"}, {"asset_id": "36586667785814641857008731622413716797407337292495614620493145114086484487337", "price": "0.479", "size": "4365.09", "side": "BUY", "hash": "b12971e5e9194275e2faaafb4e5839a34f62178e", "best_bid": "0.48", "best_ask": "0.481"}], "timestamp": "1782707745105", "event_type": "price_change"}}
{"local_timestamp": 1782707744.3778167, "slug": "will-lionel-messi-be-the-top-goalscorer-at-the-2026-fifa-world-cup", "data": {"market": "0xd2a8caba5559bc21e14f6b2aa504cb14a1782751658b71409e25b82e432c0a97", "price_changes": [{"asset_id": "19214394437683566921750936876376421489271269944393354497977881791256347396217", "price": "0.26", "size": "0", "side": "BUY", "hash": "815fbe85574dbef80d4b69dde86449681302d560", "best_bid": "0.519", "best_ask": "0.52"}, {"asset_id": "36586667785814641857008731622413716797407337292495614620493145114086484487337", "price": "0.74", "size": "0", "side": "SELL", "hash": "b9b827ad695f17fff1c2074fdf7b4da181854d9f", "best_bid": "0.48", "best_ask": "0.481"}], "timestamp": "1782707745610", "event_type": "price_change"}}
{"local_timestamp": 1782707744.3794303, "slug": "will-lionel-messi-be-the-top-goalscorer-at-the-2026-fifa-world-cup", "data": {"market": "0xd2a8caba5559bc21e14f6b2aa504cb14a1782751658b71409e25b82e432c0a97", "price_changes": [{"asset_id": "36586667785814641857008731622413716797407337292495614620493145114086484487337", "price": "0.35", "size": "200", "side": "BUY", "hash": "3c6090e3f12b8acc8c5d0450f3104b84a8cde51d", "best_bid": "0.48", "best_ask": "0.481"}, {"asset_id": "19214394437683566921750936876376421489271269944393354497977881791256347396217", "price": "0.65", "size": "200", "side": "SELL", "hash": "46795c2af86bb101ffdca17ca069579b66bdd615", "best_bid": "0.519", "best_ask": "0.52"}], "timestamp": "1782707745610", "event_type": "price_change"}}
{"local_timestamp": 1782707745.7362018, "slug": "will-lionel-messi-be-the-top-goalscorer-at-the-2026-fifa-world-cup", "data": {"market": "0xd2a8caba5559bc21e14f6b2aa504cb14a1782751658b71409e25b82e432c0a97", "price_changes": [{"asset_id": "36586667785814641857008731622413716797407337292495614620493145114086484487337", "price": "0.47", "size": "19378", "side": "BUY", "hash": "bd50b24033d76a5d921a74b180b91af4c3793a7d", "best_bid": "0.48", "best_ask": "0.481"}, {"asset_id": "19214394437683566921750936876376421489271269944393354497977881791256347396217", "price": "0.53", "size": "19378", "side": "SELL", "hash": "9680ef0250f28c35cfc017e919b53be197a93294", "best_bid": "0.519", "best_ask": "0.52"}], "timestamp": "1782707746940", "event_type": "price_change"}}
{"local_timestamp": 1782707745.935719, "slug": "will-lionel-messi-be-the-top-goalscorer-at-the-2026-fifa-world-cup", "data": {"market": "0xd2a8caba5559bc21e14f6b2aa504cb14a1782751658b71409e25b82e432c0a97", "price_changes": [{"asset_id": "36586667785814641857008731622413716797407337292495614620493145114086484487337", "price": "0.35", "size": "3200", "side": "BUY", "hash": "5f9c2014fcd044d7fbbc507bb81a657a4f7b9669", "best_bid": "0.48", "best_ask": "0.481"}, {"asset_id": "19214394437683566921750936876376421489271269944393354497977881791256347396217", "price": "0.65", "size": "3200", "side": "SELL", "hash": "30da1e591abc8ae35a31bf8e3b9dbd9d2ae01361", "best_bid": "0.519", "best_ask": "0.52"}], "timestamp": "1782707747163", "event_type": "price_change"}}
{"local_timestamp": 1782707745.9480674, "slug": "will-lionel-messi-be-the-top-goalscorer-at-the-2026-fifa-world-cup", "data": {"market": "0xd2a8caba5559bc21e14f6b2aa504cb14a1782751658b71409e25b82e432c0a97", "price_changes": [{"asset_id": "19214394437683566921750936876376421489271269944393354497977881791256347396217", "price": "0.26", "size": "3000", "side": "BUY", "hash": "9a05b89f546a8649c70b1329972365467d06e9db", "best_bid": "0.519", "best_ask": "0.52"}, {"asset_id": "36586667785814641857008731622413716797407337292495614620493145114086484487337", "price": "0.74", "size": "3000", "side": "SELL", "hash": "06faeaff327d024b6cdc6bf144ef5ff3b08e509b", "best_bid": "0.48", "best_ask": "0.481"}], "timestamp": "1782707747174", "event_type": "price_change"}}
{"local_timestamp": 1782707746.2488344, "slug": "will-lionel-messi-be-the-top-goalscorer-at-the-2026-fifa-world-cup", "data": {"market": "0xd2a8caba5559bc21e14f6b2aa504cb14a1782751658b71409e25b82e432c0a97", "price_changes": [{"asset_id": "19214394437683566921750936876376421489271269944393354497977881791256347396217", "price": "0.521", "size": "4268", "side": "SELL", "hash": "eef6c0884ea6d2bef91408149214538e20df6454", "best_bid": "0.519", "best_ask": "0.52"}, {"asset_id": "36586667785814641857008731622413716797407337292495614620493145114086484487337", "price": "0.479", "size": "4268", "side": "BUY", "hash": "0fc7fa13cce79ea25a614ebd5bbdc04b9312db70", "best_bid": "0.48", "best_ask": "0.481"}], "timestamp": "1782707747480", "event_type": "price_change"}}
{"local_timestamp": 1782707746.5025878, "slug": "will-lionel-messi-be-the-top-goalscorer-at-the-2026-fifa-world-cup", "data": {"market": "0xd2a8caba5559bc21e14f6b2aa504cb14a1782751658b71409e25b82e432c0a97", "price_changes": [{"asset_id": "19214394437683566921750936876376421489271269944393354497977881791256347396217", "price": "0.518", "size": "18263.33", "side": "BUY", "hash": "14ceb451f37966b747e38cafb0e655de0b65b623", "best_bid": "0.519", "best_ask": "0.52"}, {"asset_id": "36586667785814641857008731622413716797407337292495614620493145114086484487337", "price": "0.482", "size": "18263.33", "side": "SELL", "hash": "455370ce7c079c003e4c82475ca3050bf2704b4d", "best_bid": "0.48", "best_ask": "0.481"}], "timestamp": "1782707747735", "event_type": "price_change"}}
{"local_timestamp": 1782707746.7871902, "slug": "will-lionel-messi-be-the-top-goalscorer-at-the-2026-fifa-world-cup", "data": {"market": "0xd2a8caba5559bc21e14f6b2aa504cb14a1782751658b71409e25b82e432c0a97", "price_changes": [{"asset_id": "36586667785814641857008731622413716797407337292495614620493145114086484487337", "price": "0.002", "size": "1007.31", "side": "BUY", "hash": "6c2fdd49b0623215abf06e448b4093bab08235d5", "best_bid": "0.48", "best_ask": "0.481"}, {"asset_id": "19214394437683566921750936876376421489271269944393354497977881791256347396217", "price": "0.998", "size": "1007.31", "side": "SELL", "hash": "99628efae4c087cb3438d2ddbfeea3aaa892326b", "best_bid": "0.519", "best_ask": "0.52"}], "timestamp": "1782707748006", "event_type": "price_change"}}
{"local_timestamp": 1782707746.7880628, "slug": "will-lionel-messi-be-the-top-goalscorer-at-the-2026-fifa-world-cup", "data": {"market": "0xd2a8caba5559bc21e14f6b2aa504cb14a1782751658b71409e25b82e432c0a97", "price_changes": [{"asset_id": "19214394437683566921750936876376421489271269944393354497977881791256347396217", "price": "0.002", "size": "3250", "side": "BUY", "hash": "bf248e9ca6f2706956c90d4f39b5b4b146c897c6", "best_bid": "0.519", "best_ask": "0.52"}, {"asset_id": "36586667785814641857008731622413716797407337292495614620493145114086484487337", "price": "0.998", "size": "3250", "side": "SELL", "hash": "46d3df00fb081267558fb31ccaf87e42ca9321cb", "best_bid": "0.48", "best_ask": "0.481"}], "timestamp": "1782707748007", "event_type": "price_change"}}
{"local_timestamp": 1782707747.368293, "slug": "will-lionel-messi-be-the-top-goalscorer-at-the-2026-fifa-world-cup", "data": {"market": "0xd2a8caba5559bc21e14f6b2aa504cb14a1782751658b71409e25b82e432c0a97", "price_changes": [{"asset_id": "36586667785814641857008731622413716797407337292495614620493145114086484487337", "price": "0.35", "size": "200", "side": "BUY", "hash": "dbfb87ce91d64b2927e88370735beb9abfdb790a", "best_bid": "0.48", "best_ask": "0.481"}, {"asset_id": "19214394437683566921750936876376421489271269944393354497977881791256347396217", "price": "0.65", "size": "200", "side": "SELL", "hash": "f0aa5569cf1d416b6ae404825b15147b99f48e16", "best_bid": "0.519", "best_ask": "0.52"}], "timestamp": "1782707748600", "event_type": "price_change"}}
{"local_timestamp": 1782707747.368832, "slug": "will-lionel-messi-be-the-top-goalscorer-at-the-2026-fifa-world-cup", "data": {"market": "0xd2a8caba5559bc21e14f6b2aa504cb14a1782751658b71409e25b82e432c0a97", "price_changes": [{"asset_id": "19214394437683566921750936876376421489271269944393354497977881791256347396217", "price": "0.26", "size": "0", "side": "BUY", "hash": "c1acb70c5319a781f176f8d3faa33737073699f1", "best_bid": "0.519", "best_ask": "0.52"}, {"asset_id": "36586667785814641857008731622413716797407337292495614620493145114086484487337", "price": "0.74", "size": "0", "side": "SELL", "hash": "91f1a0b60e8ec6c959f726b9a32e0e4b93b10f91", "best_bid": "0.48", "best_ask": "0.481"}], "timestamp": "1782707748600", "event_type": "price_change"}}
{"local_timestamp": 1782707747.8336465, "slug": "will-lionel-messi-be-the-top-goalscorer-at-the-2026-fifa-world-cup", "data": {"market": "0xd2a8caba5559bc21e14f6b2aa504cb14a1782751658b71409e25b82e432c0a97", "price_changes": [{"asset_id": "19214394437683566921750936876376421489271269944393354497977881791256347396217", "price": "0.26", "size": "3000", "side": "BUY", "hash": "16398cd4d00b979bf5296295d970e8791b764b4b", "best_bid": "0.519", "best_ask": "0.52"}, {"asset_id": "36586667785814641857008731622413716797407337292495614620493145114086484487337", "price": "0.74", "size": "3000", "side": "SELL", "hash": "9bb665c09f8e955010273ba6417ee56b33e1cdb2", "best_bid": "0.48", "best_ask": "0.481"}], "timestamp": "1782707749048", "event_type": "price_change"}}
{"local_timestamp": 1782707747.8342013, "slug": "will-lionel-messi-be-the-top-goalscorer-at-the-2026-fifa-world-cup", "data": {"market": "0xd2a8caba5559bc21e14f6b2aa504cb14a1782751658b71409e25b82e432c0a97", "price_changes": [{"asset_id": "36586667785814641857008731622413716797407337292495614620493145114086484487337", "price": "0.35", "size": "3200", "side": "BUY", "hash": "e5319a75fac6a989ef7ff6a2514a399e24b8f1c5", "best_bid": "0.48", "best_ask": "0.481"}, {"asset_id": "19214394437683566921750936876376421489271269944393354497977881791256347396217", "price": "0.65", "size": "3200", "side": "SELL", "hash": "31ccb7708cf0f0a950b6e3f15876b5131582e29d", "best_bid": "0.519", "best_ask": "0.52"}], "timestamp": "1782707749062", "event_type": "price_change"}}
{"local_timestamp": 1782707748.2078094, "slug": "will-lionel-messi-be-the-top-goalscorer-at-the-2026-fifa-world-cup", "data": {"market": "0xd2a8caba5559bc21e14f6b2aa504cb14a1782751658b71409e25b82e432c0a97", "price_changes": [{"asset_id": "19214394437683566921750936876376421489271269944393354497977881791256347396217", "price": "0.521", "size": "4365.09", "side": "SELL", "hash": "1547f2de1433f2d3f3e2aac7c51657ae937e8cfe", "best_bid": "0.519", "best_ask": "0.52"}, {"asset_id": "36586667785814641857008731622413716797407337292495614620493145114086484487337", "price": "0.479", "size": "4365.09", "side": "BUY", "hash": "1e8e844d47298349598dc5041fe6a361513d501a", "best_bid": "0.48", "best_ask": "0.481"}], "timestamp": "1782707749433", "event_type": "price_change"}}
{"local_timestamp": 1782707748.8622122, "slug": "will-lionel-messi-be-the-top-goalscorer-at-the-2026-fifa-world-cup", "data": {"market": "0xd2a8caba5559bc21e14f6b2aa504cb14a1782751658b71409e25b82e432c0a97", "price_changes": [{"asset_id": "36586667785814641857008731622413716797407337292495614620493145114086484487337", "price": "0.35", "size": "200", "side": "BUY", "hash": "74737ec24797153acd80fb712d62edc3ea522d5c", "best_bid": "0.48", "best_ask": "0.481"}, {"asset_id": "19214394437683566921750936876376421489271269944393354497977881791256347396217", "price": "0.65", "size": "200", "side": "SELL", "hash": "4aad68ac06edb51d3df780d1b04fe99ad36f50ad", "best_bid": "0.519", "best_ask": "0.52"}], "timestamp": "1782707750093", "event_type": "price_change"}}
{"local_timestamp": 1782707748.8635726, "slug": "will-lionel-messi-be-the-top-goalscorer-at-the-2026-fifa-world-cup", "data": {"market": "0xd2a8caba5559bc21e14f6b2aa504cb14a1782751658b71409e25b82e432c0a97", "price_changes": [{"asset_id": "19214394437683566921750936876376421489271269944393354497977881791256347396217", "price": "0.26", "size": "0", "side": "BUY", "hash": "71bd08fc9d60f1878c93f23c3bcd850ffb8e69f6", "best_bid": "0.519", "best_ask": "0.52"}, {"asset_id": "36586667785814641857008731622413716797407337292495614620493145114086484487337", "price": "0.74", "size": "0", "side": "SELL", "hash": "5a2032088b2b8b71429d721afbfe644f5e1c94b4", "best_bid": "0.48", "best_ask": "0.481"}], "timestamp": "1782707750094", "event_type": "price_change"}}
{"local_timestamp": 1782707749.7841682, "slug": "will-lionel-messi-be-the-top-goalscorer-at-the-2026-fifa-world-cup", "data": {"market": "0xd2a8caba5559bc21e14f6b2aa504cb14a1782751658b71409e25b82e432c0a97", "price_changes": [{"asset_id": "36586667785814641857008731622413716797407337292495614620493145114086484487337", "price": "0.623", "size": "0", "side": "SELL", "hash": "4d435dea96e0ff297d14d0271f9be4736558daae", "best_bid": "0.48", "best_ask": "0.481"}, {"asset_id": "19214394437683566921750936876376421489271269944393354497977881791256347396217", "price": "0.377", "size": "0", "side": "BUY", "hash": "a3403c74ab00119d10d23faa73ed06b7dfb82d8f", "best_bid": "0.519", "best_ask": "0.52"}], "timestamp": "1782707751015", "event_type": "price_change"}}
{"local_timestamp": 1782707750.4077728, "slug": "will-lionel-messi-be-the-top-goalscorer-at-the-2026-fifa-world-cup", "data": {"market": "0xd2a8caba5559bc21e14f6b2aa504cb14a1782751658b71409e25b82e432c0a97", "price_changes": [{"asset_id": "19214394437683566921750936876376421489271269944393354497977881791256347396217", "price": "0.26", "size": "3000", "side": "BUY", "hash": "ea2362757be3ecbc16e58de78747b3e29567007e", "best_bid": "0.519", "best_ask": "0.52"}, {"asset_id": "36586667785814641857008731622413716797407337292495614620493145114086484487337", "price": "0.74", "size": "3000", "side": "SELL", "hash": "5717845cfe5611d087e34e3ec12df6ae9f3194e8", "best_bid": "0.48", "best_ask": "0.481"}], "timestamp": "1782707751633", "event_type": "price_change"}}
{"local_timestamp": 1782707750.408449, "slug": "will-lionel-messi-be-the-top-goalscorer-at-the-2026-fifa-world-cup", "data": {"market": "0xd2a8caba5559bc21e14f6b2aa504cb14a1782751658b71409e25b82e432c0a97", "price_changes": [{"asset_id": "36586667785814641857008731622413716797407337292495614620493145114086484487337", "price": "0.35", "size": "3200", "side": "BUY", "hash": "cb93c749b97fdd72b3c959dcbb8dbf2ae610e2e0", "best_bid": "0.48", "best_ask": "0.481"}, {"asset_id": "19214394437683566921750936876376421489271269944393354497977881791256347396217", "price": "0.65", "size": "3200", "side": "SELL", "hash": "56f322db2dbdb8f499efe8471c1bcf88be08903c", "best_bid": "0.519", "best_ask": "0.52"}], "timestamp": "1782707751636", "event_type": "price_change"}}
{"local_timestamp": 1782707750.4629729, "slug": "will-lionel-messi-be-the-top-goalscorer-at-the-2026-fifa-world-cup", "data": {"market": "0xd2a8caba5559bc21e14f6b2aa504cb14a1782751658b71409e25b82e432c0a97", "price_changes": [{"asset_id": "19214394437683566921750936876376421489271269944393354497977881791256347396217", "price": "0.521", "size": "4268", "side": "SELL", "hash": "227e3336fa5a597ecf04c237ec7e9d26fda6a463", "best_bid": "0.519", "best_ask": "0.52"}, {"asset_id": "36586667785814641857008731622413716797407337292495614620493145114086484487337", "price": "0.479", "size": "4268", "side": "BUY", "hash": "32163aa09e5ee2d3bca00053f46cc1aa7885a9e6", "best_bid": "0.48", "best_ask": "0.481"}], "timestamp": "1782707751695", "event_type": "price_change"}}
{"local_timestamp": 1782707751.7980564, "slug": "will-lionel-messi-be-the-top-goalscorer-at-the-2026-fifa-world-cup", "data": {"market": "0xd2a8caba5559bc21e14f6b2aa504cb14a1782751658b71409e25b82e432c0a97", "price_changes": [{"asset_id": "19214394437683566921750936876376421489271269944393354497977881791256347396217", "price": "0.518", "size": "18879.69", "side": "BUY", "hash": "59414b748254ed9060df2da1d5de067b3349a778", "best_bid": "0.519", "best_ask": "0.52"}, {"asset_id": "36586667785814641857008731622413716797407337292495614620493145114086484487337", "price": "0.482", "size": "18879.69", "side": "SELL", "hash": "b559e6960aa5657ab8eb4059077cb591ba011495", "best_bid": "0.48", "best_ask": "0.481"}], "timestamp": "1782707753029", "event_type": "price_change"}}
{"local_timestamp": 1782707751.8250308, "slug": "will-lionel-messi-be-the-top-goalscorer-at-the-2026-fifa-world-cup", "data": {"market": "0xd2a8caba5559bc21e14f6b2aa504cb14a1782751658b71409e25b82e432c0a97", "price_changes": [{"asset_id": "36586667785814641857008731622413716797407337292495614620493145114086484487337", "price": "0.479", "size": "4683.1", "side": "BUY", "hash": "0d38633b7b7d15207756fa5b004ae28a76e6b168", "best_bid": "0.48", "best_ask": "0.481"}, {"asset_id": "19214394437683566921750936876376421489271269944393354497977881791256347396217", "price": "0.521", "size": "4683.1", "side": "SELL", "hash": "d5956e1cdcb52964fa66cbfefdd6c061730d2f5b", "best_bid": "0.519", "best_ask": "0.52"}], "timestamp": "1782707753057", "event_type": "price_change"}}
{"local_timestamp": 1782707751.8689134, "slug": "will-lionel-messi-be-the-top-goalscorer-at-the-2026-fifa-world-cup", "data": {"market": "0xd2a8caba5559bc21e14f6b2aa504cb14a1782751658b71409e25b82e432c0a97", "price_changes": [{"asset_id": "19214394437683566921750936876376421489271269944393354497977881791256347396217", "price": "0.26", "size": "0", "side": "BUY", "hash": "b20e08ce1929cc38d50f2b673cbc0acada9cc50e", "best_bid": "0.519", "best_ask": "0.52"}, {"asset_id": "36586667785814641857008731622413716797407337292495614620493145114086484487337", "price": "0.74", "size": "0", "side": "SELL", "hash": "e387f388820eddb9e004557e1422571447e49550", "best_bid": "0.48", "best_ask": "0.481"}], "timestamp": "1782707753101", "event_type": "price_change"}}
{"local_timestamp": 1782707751.8714194, "slug": "will-lionel-messi-be-the-top-goalscorer-at-the-2026-fifa-world-cup", "data": {"market": "0xd2a8caba5559bc21e14f6b2aa504cb14a1782751658b71409e25b82e432c0a97", "price_changes": [{"asset_id": "36586667785814641857008731622413716797407337292495614620493145114086484487337", "price": "0.35", "size": "200", "side": "BUY", "hash": "f85d6d114de522ddac20107cf2ff420558b4a8c2", "best_bid": "0.48", "best_ask": "0.481"}, {"asset_id": "19214394437683566921750936876376421489271269944393354497977881791256347396217", "price": "0.65", "size": "200", "side": "SELL", "hash": "ecd942bc9b561e670621ee6ff4ef4aae4889f9a3", "best_bid": "0.519", "best_ask": "0.52"}], "timestamp": "1782707753101", "event_type": "price_change"}}
{"local_timestamp": 1782707752.4499178, "slug": "will-lionel-messi-be-the-top-goalscorer-at-the-2026-fifa-world-cup", "data": {"market": "0xd2a8caba5559bc21e14f6b2aa504cb14a1782751658b71409e25b82e432c0a97", "price_changes": [{"asset_id": "36586667785814641857008731622413716797407337292495614620493145114086484487337", "price": "0.232", "size": "400", "side": "BUY", "hash": "90c22f83b3c512f654a52c855b65d4dc48a0edc4", "best_bid": "0.48", "best_ask": "0.481"}, {"asset_id": "19214394437683566921750936876376421489271269944393354497977881791256347396217", "price": "0.768", "size": "400", "side": "SELL", "hash": "4bcbc5f4348ec0f08e314fa413cf7b6bbece571d", "best_bid": "0.519", "best_ask": "0.52"}], "timestamp": "1782707753682", "event_type": "price_change"}}
{"local_timestamp": 1782707752.5736566, "slug": "will-lionel-messi-be-the-top-goalscorer-at-the-2026-fifa-world-cup", "data": {"market": "0xd2a8caba5559bc21e14f6b2aa504cb14a1782751658b71409e25b82e432c0a97", "price_changes": [{"asset_id": "36586667785814641857008731622413716797407337292495614620493145114086484487337", "price": "0.232", "size": "200", "side": "BUY", "hash": "0a3dacb878a900244f72074ee96738ace328f75f", "best_bid": "0.48", "best_ask": "0.481"}, {"asset_id": "19214394437683566921750936876376421489271269944393354497977881791256347396217", "price": "0.768", "size": "200", "side": "SELL", "hash": "469033c378a0159a8b1fcaf7cc7cc57d3319c32e", "best_bid": "0.519", "best_ask": "0.52"}], "timestamp": "1782707753798", "event_type": "price_change"}}
{"local_timestamp": 1782707752.6185222, "slug": "will-lionel-messi-be-the-top-goalscorer-at-the-2026-fifa-world-cup", "data": {"market": "0xd2a8caba5559bc21e14f6b2aa504cb14a1782751658b71409e25b82e432c0a97", "price_changes": [{"asset_id": "19214394437683566921750936876376421489271269944393354497977881791256347396217", "price": "0.514", "size": "0", "side": "BUY", "hash": "5d89a3cd295a455d96446a7f15e0a24eddfdae93", "best_bid": "0.519", "best_ask": "0.52"}, {"asset_id": "36586667785814641857008731622413716797407337292495614620493145114086484487337", "price": "0.486", "size": "0", "side": "SELL", "hash": "9f1f842a7e2ce6b7dbfd60a93a20f69dc28000d6", "best_bid": "0.48", "best_ask": "0.481"}], "timestamp": "1782707753850", "event_type": "price_change"}}
{"local_timestamp": 1782707752.6192029, "slug": "will-lionel-messi-be-the-top-goalscorer-at-the-2026-fifa-world-cup", "data": {"market": "0xd2a8caba5559bc21e14f6b2aa504cb14a1782751658b71409e25b82e432c0a97", "price_changes": [{"asset_id": "36586667785814641857008731622413716797407337292495614620493145114086484487337", "price": "0.475", "size": "6937.77", "side": "BUY", "hash": "e39ea6c2d12a2b119a4e742ff75f667e30bce11d", "best_bid": "0.48", "best_ask": "0.481"}, {"asset_id": "19214394437683566921750936876376421489271269944393354497977881791256347396217", "price": "0.525", "size": "6937.77", "side": "SELL", "hash": "776a33545ae4e01205bdc10068c692492a55bd63", "best_bid": "0.519", "best_ask": "0.52"}], "timestamp": "1782707753850", "event_type": "price_change"}}
{"local_timestamp": 1782707752.686429, "slug": "will-lionel-messi-be-the-top-goalscorer-at-the-2026-fifa-world-cup", "data": {"market": "0xd2a8caba5559bc21e14f6b2aa504cb14a1782751658b71409e25b82e432c0a97", "price_changes": [{"asset_id": "36586667785814641857008731622413716797407337292495614620493145114086484487337", "price": "0.477", "size": "250", "side": "BUY", "hash": "060423237916ad22ded032e17d271ff23d4c468d", "best_bid": "0.48", "best_ask": "0.481"}, {"asset_id": "19214394437683566921750936876376421489271269944393354497977881791256347396217", "price": "0.523", "size": "250", "side": "SELL", "hash": "8635df310568847773be81229156bdd21578f951", "best_bid": "0.519", "best_ask": "0.52"}], "timestamp": "1782707753918", "event_type": "price_change"}}
{"local_timestamp": 1782707752.6902528, "slug": "will-lionel-messi-be-the-top-goalscorer-at-the-2026-fifa-world-cup", "data": {"market": "0xd2a8caba5559bc21e14f6b2aa504cb14a1782751658b71409e25b82e432c0a97", "price_changes": [{"asset_id": "19214394437683566921750936876376421489271269944393354497977881791256347396217", "price": "0.516", "size": "1218", "side": "BUY", "hash": "f789a2c4675a106de6cca2334cfe0f60f57fd6e9", "best_bid": "0.519", "best_ask": "0.52"}, {"asset_id": "36586667785814641857008731622413716797407337292495614620493145114086484487337", "price": "0.484", "size": "1218", "side": "SELL", "hash": "9c179a6f2854aa38db6b630e267ed20aee9a396c", "best_bid": "0.48", "best_ask": "0.481"}], "timestamp": "1782707753922", "event_type": "price_change"}}
{"local_timestamp": 1782707752.7902155, "slug": "will-lionel-messi-be-the-top-goalscorer-at-the-2026-fifa-world-cup", "data": {"market": "0xd2a8caba5559bc21e14f6b2aa504cb14a1782751658b71409e25b82e432c0a97", "price_changes": [{"asset_id": "36586667785814641857008731622413716797407337292495614620493145114086484487337", "price": "0.447", "size": "2508.44", "side": "BUY", "hash": "a8f4b405ec8684ebca486e426bfcc71847f8ee01", "best_bid": "0.48", "best_ask": "0.481"}, {"asset_id": "19214394437683566921750936876376421489271269944393354497977881791256347396217", "price": "0.553", "size": "2508.44", "side": "SELL", "hash": "368f5fe7782c3c7c84a4656aaab2c72ddce6ba18", "best_bid": "0.519", "best_ask": "0.52"}], "timestamp": "1782707754012", "event_type": "price_change"}}
{"local_timestamp": 1782707752.7908435, "slug": "will-lionel-messi-be-the-top-goalscorer-at-the-2026-fifa-world-cup", "data": {"market": "0xd2a8caba5559bc21e14f6b2aa504cb14a1782751658b71409e25b82e432c0a97", "price_changes": [{"asset_id": "19214394437683566921750936876376421489271269944393354497977881791256347396217", "price": "0.486", "size": "1446.92", "side": "BUY", "hash": "6d2f483ea2b8ce56caf524880e32fcca5d198b48", "best_bid": "0.519", "best_ask": "0.52"}, {"asset_id": "36586667785814641857008731622413716797407337292495614620493145114086484487337", "price": "0.514", "size": "1446.92", "side": "SELL", "hash": "f543bfbf0d60e847557661985baaea3fa00918c0", "best_bid": "0.48", "best_ask": "0.481"}], "timestamp": "1782707754014", "event_type": "price_change"}}
{"local_timestamp": 1782707752.902543, "slug": "will-lionel-messi-be-the-top-goalscorer-at-the-2026-fifa-world-cup", "data": {"market": "0xd2a8caba5559bc21e14f6b2aa504cb14a1782751658b71409e25b82e432c0a97", "price_changes": [{"asset_id": "19214394437683566921750936876376421489271269944393354497977881791256347396217", "price": "0.511", "size": "2267.5", "side": "BUY", "hash": "0bdff08435b2c4b29f0d340273d9344abbb87ea7", "best_bid": "0.519", "best_ask": "0.52"}, {"asset_id": "36586667785814641857008731622413716797407337292495614620493145114086484487337", "price": "0.489", "size": "2267.5", "side": "SELL", "hash": "b47640ae832883bf322d9e20dd57095715bd0eda", "best_bid": "0.48", "best_ask": "0.481"}], "timestamp": "1782707754135", "event_type": "price_change"}}
{"local_timestamp": 1782707752.9038043, "slug": "will-lionel-messi-be-the-top-goalscorer-at-the-2026-fifa-world-cup", "data": {"market": "0xd2a8caba5559bc21e14f6b2aa504cb14a1782751658b71409e25b82e432c0a97", "price_changes": [{"asset_id": "19214394437683566921750936876376421489271269944393354497977881791256347396217", "price": "0.511", "size": "1967.5", "side": "BUY", "hash": "10523303fca45e362bffaf4fc3e0fc7d06e9a9c8", "best_bid": "0.519", "best_ask": "0.52"}, {"asset_id": "36586667785814641857008731622413716797407337292495614620493145114086484487337", "price": "0.489", "size": "1967.5", "side": "SELL", "hash": "7249c0fabfc3c786bc0bb796faa31be897fbae17", "best_bid": "0.48", "best_ask": "0.481"}], "timestamp": "1782707754136", "event_type": "price_change"}}
{"local_timestamp": 1782707752.9095914, "slug": "will-lionel-messi-be-the-top-goalscorer-at-the-2026-fifa-world-cup", "data": {"market": "0xd2a8caba5559bc21e14f6b2aa504cb14a1782751658b71409e25b82e432c0a97", "price_changes": [{"asset_id": "19214394437683566921750936876376421489271269944393354497977881791256347396217", "price": "0.521", "size": "4780.19", "side": "SELL", "hash": "0c93ebd0fd7bfbee95384d5b9a33285cee1e8c27", "best_bid": "0.519", "best_ask": "0.52"}, {"asset_id": "36586667785814641857008731622413716797407337292495614620493145114086484487337", "price": "0.479", "size": "4780.19", "side": "BUY", "hash": "13909bb8083bd65143e48fcdd7a6a311dc50eee3", "best_bid": "0.48", "best_ask": "0.481"}], "timestamp": "1782707754142", "event_type": "price_change"}}
{"local_timestamp": 1782707753.409874, "slug": "will-lionel-messi-be-the-top-goalscorer-at-the-2026-fifa-world-cup", "data": {"market": "0xd2a8caba5559bc21e14f6b2aa504cb14a1782751658b71409e25b82e432c0a97", "price_changes": [{"asset_id": "36586667785814641857008731622413716797407337292495614620493145114086484487337", "price": "0.35", "size": "3200", "side": "BUY", "hash": "eec9bf8634a176cf7baf369890327cda9a5a359d", "best_bid": "0.48", "best_ask": "0.481"}, {"asset_id": "19214394437683566921750936876376421489271269944393354497977881791256347396217", "price": "0.65", "size": "3200", "side": "SELL", "hash": "4533f0ab0c206a4fad62993a5038d6d89a91c90b", "best_bid": "0.519", "best_ask": "0.52"}], "timestamp": "1782707754642", "event_type": "price_change"}}
{"local_timestamp": 1782707753.4116077, "slug": "will-lionel-messi-be-the-top-goalscorer-at-the-2026-fifa-world-cup", "data": {"market": "0xd2a8caba5559bc21e14f6b2aa504cb14a1782751658b71409e25b82e432c0a97", "price_changes": [{"asset_id": "19214394437683566921750936876376421489271269944393354497977881791256347396217", "price": "0.26", "size": "3000", "side": "BUY", "hash": "4a5c96b6d06a3ef6a68a65e4fcdb84e5b7b12de7", "best_bid": "0.519", "best_ask": "0.52"}, {"asset_id": "36586667785814641857008731622413716797407337292495614620493145114086484487337", "price": "0.74", "size": "3000", "side": "SELL", "hash": "a6d47338f8707659f7d6b94b508cb8aed1f9daf9", "best_bid": "0.48", "best_ask": "0.481"}], "timestamp": "1782707754644", "event_type": "price_change"}}
{"local_timestamp": 1782707754.4625952, "slug": "will-lionel-messi-be-the-top-goalscorer-at-the-2026-fifa-world-cup", "data": {"market": "0xd2a8caba5559bc21e14f6b2aa504cb14a1782751658b71409e25b82e432c0a97", "price_changes": [{"asset_id": "19214394437683566921750936876376421489271269944393354497977881791256347396217", "price": "0.521", "size": "4683.1", "side": "SELL", "hash": "2fcccb55646b4b3777aa5020d01b9e2e0fdd558f", "best_bid": "0.519", "best_ask": "0.52"}, {"asset_id": "36586667785814641857008731622413716797407337292495614620493145114086484487337", "price": "0.479", "size": "4683.1", "side": "BUY", "hash": "c7cfd1654b2df1776f43491eaf841acbf21db2c2", "best_bid": "0.48", "best_ask": "0.481"}], "timestamp": "1782707755693", "event_type": "price_change"}}
{"local_timestamp": 1782707754.8810637, "slug": "will-lionel-messi-be-the-top-goalscorer-at-the-2026-fifa-world-cup", "data": {"market": "0xd2a8caba5559bc21e14f6b2aa504cb14a1782751658b71409e25b82e432c0a97", "price_changes": [{"asset_id": "19214394437683566921750936876376421489271269944393354497977881791256347396217", "price": "0.26", "size": "0", "side": "BUY", "hash": "84cd389b9358356d40ced4f8a056df0d8e01afa0", "best_bid": "0.519", "best_ask": "0.52"}, {"asset_id": "36586667785814641857008731622413716797407337292495614620493145114086484487337", "price": "0.74", "size": "0", "side": "SELL", "hash": "372033b2ec89f3792f10c3d73bcfeec81fefd309", "best_bid": "0.48", "best_ask": "0.481"}], "timestamp": "1782707756113", "event_type": "price_change"}}
{"local_timestamp": 1782707754.8817558, "slug": "will-lionel-messi-be-the-top-goalscorer-at-the-2026-fifa-world-cup", "data": {"market": "0xd2a8caba5559bc21e14f6b2aa504cb14a1782751658b71409e25b82e432c0a97", "price_changes": [{"asset_id": "36586667785814641857008731622413716797407337292495614620493145114086484487337", "price": "0.35", "size": "200", "side": "BUY", "hash": "cfd9cf3a62931841e1fe62146d882f13b15b5d47", "best_bid": "0.48", "best_ask": "0.481"}, {"asset_id": "19214394437683566921750936876376421489271269944393354497977881791256347396217", "price": "0.65", "size": "200", "side": "SELL", "hash": "4abae3187171dd70582d0d150e9931cd5c241baa", "best_bid": "0.519", "best_ask": "0.52"}], "timestamp": "1782707756113", "event_type": "price_change"}}
{"local_timestamp": 1782707755.7463913, "slug": "will-lionel-messi-be-the-top-goalscorer-at-the-2026-fifa-world-cup", "data": {"market": "0xd2a8caba5559bc21e14f6b2aa504cb14a1782751658b71409e25b82e432c0a97", "price_changes": [{"asset_id": "36586667785814641857008731622413716797407337292495614620493145114086484487337", "price": "0.002", "size": "13507.31", "side": "BUY", "hash": "785dee4f92faa1ec752b03fd29d138d49bf55b9b", "best_bid": "0.48", "best_ask": "0.481"}, {"asset_id": "19214394437683566921750936876376421489271269944393354497977881791256347396217", "price": "0.998", "size": "13507.31", "side": "SELL", "hash": "f544293c748967fb2894a60feaf65922b2ad7f93", "best_bid": "0.519", "best_ask": "0.52"}], "timestamp": "1782707756979", "event_type": "price_change"}}
{"local_timestamp": 1782707755.7712584, "slug": "will-lionel-messi-be-the-top-goalscorer-at-the-2026-fifa-world-cup", "data": {"market": "0xd2a8caba5559bc21e14f6b2aa504cb14a1782751658b71409e25b82e432c0a97", "price_changes": [{"asset_id": "19214394437683566921750936876376421489271269944393354497977881791256347396217", "price": "0.002", "size": "28250", "side": "BUY", "hash": "2d4f3892d07cace85af3e3fcc87747a1d6ff0b46", "best_bid": "0.519", "best_ask": "0.52"}, {"asset_id": "36586667785814641857008731622413716797407337292495614620493145114086484487337", "price": "0.998", "size": "28250", "side": "SELL", "hash": "cfd6f190b09a49a6c34845e0732a00b770ad3baa", "best_bid": "0.48", "best_ask": "0.481"}], "timestamp": "1782707757001", "event_type": "price_change"}}
{"local_timestamp": 1782707756.3534117, "slug": "will-lionel-messi-be-the-top-goalscorer-at-the-2026-fifa-world-cup", "data": {"market": "0xd2a8caba5559bc21e14f6b2aa504cb14a1782751658b71409e25b82e432c0a97", "price_changes": [{"asset_id": "36586667785814641857008731622413716797407337292495614620493145114086484487337", "price": "0.35", "size": "3200", "side": "BUY", "hash": "13a76260e9bd1328a704d11a05661c31982eeee2", "best_bid": "0.48", "best_ask": "0.481"}, {"asset_id": "19214394437683566921750936876376421489271269944393354497977881791256347396217", "price": "0.65", "size": "3200", "side": "SELL", "hash": "1920e6937c9a29e3ba011d586eccfa2507a14712", "best_bid": "0.519", "best_ask": "0.52"}], "timestamp": "1782707757581", "event_type": "price_change"}}
{"local_timestamp": 1782707756.36903, "slug": "will-lionel-messi-be-the-top-goalscorer-at-the-2026-fifa-world-cup", "data": {"market": "0xd2a8caba5559bc21e14f6b2aa504cb14a1782751658b71409e25b82e432c0a97", "price_changes": [{"asset_id": "19214394437683566921750936876376421489271269944393354497977881791256347396217", "price": "0.26", "size": "3000", "side": "BUY", "hash": "4ce46970512a6bcca53b84946da3d8f495401be0", "best_bid": "0.519", "best_ask": "0.52"}, {"asset_id": "36586667785814641857008731622413716797407337292495614620493145114086484487337", "price": "0.74", "size": "3000", "side": "SELL", "hash": "eaf249c3319cd955c77ee8cc2bb3986dc0e26e2d", "best_bid": "0.48", "best_ask": "0.481"}], "timestamp": "1782707757601", "event_type": "price_change"}}
{"local_timestamp": 1782707757.8171196, "slug": "will-lionel-messi-be-the-top-goalscorer-at-the-2026-fifa-world-cup", "data": {"market": "0xd2a8caba5559bc21e14f6b2aa504cb14a1782751658b71409e25b82e432c0a97", "price_changes": [{"asset_id": "19214394437683566921750936876376421489271269944393354497977881791256347396217", "price": "0.521", "size": "4780.19", "side": "SELL", "hash": "38027bda5e0bf0a5ab1b9f58063f86a09a6f237b", "best_bid": "0.519", "best_ask": "0.52"}, {"asset_id": "36586667785814641857008731622413716797407337292495614620493145114086484487337", "price": "0.479", "size": "4780.19", "side": "BUY", "hash": "2f68e8666ca8d170c46a99c8a3a2f9e13c7d2a4d", "best_bid": "0.48", "best_ask": "0.481"}], "timestamp": "1782707759049", "event_type": "price_change"}}
{"local_timestamp": 1782707757.8625362, "slug": "will-lionel-messi-be-the-top-goalscorer-at-the-2026-fifa-world-cup", "data": {"market": "0xd2a8caba5559bc21e14f6b2aa504cb14a1782751658b71409e25b82e432c0a97", "price_changes": [{"asset_id": "19214394437683566921750936876376421489271269944393354497977881791256347396217", "price": "0.26", "size": "0", "side": "BUY", "hash": "5bd1c14f460805baec9defce6e6dfc71ef04b66f", "best_bid": "0.519", "best_ask": "0.52"}, {"asset_id": "36586667785814641857008731622413716797407337292495614620493145114086484487337", "price": "0.74", "size": "0", "side": "SELL", "hash": "ee624c2fb47e866a4c3c9bc87270a71f60846c2e", "best_bid": "0.48", "best_ask": "0.481"}], "timestamp": "1782707759095", "event_type": "price_change"}}
{"local_timestamp": 1782707757.864807, "slug": "will-lionel-messi-be-the-top-goalscorer-at-the-2026-fifa-world-cup", "data": {"market": "0xd2a8caba5559bc21e14f6b2aa504cb14a1782751658b71409e25b82e432c0a97", "price_changes": [{"asset_id": "36586667785814641857008731622413716797407337292495614620493145114086484487337", "price": "0.35", "size": "200", "side": "BUY", "hash": "7f8ba4364be751939f051df3d3e01f08b5fcb97c", "best_bid": "0.48", "best_ask": "0.481"}, {"asset_id": "19214394437683566921750936876376421489271269944393354497977881791256347396217", "price": "0.65", "size": "200", "side": "SELL", "hash": "02eb4ff19d742cd8d0a3a0d9e6aad4feab342534", "best_bid": "0.519", "best_ask": "0.52"}], "timestamp": "1782707759095", "event_type": "price_change"}}
{"local_timestamp": 1782707759.182705, "slug": "will-lionel-messi-be-the-top-goalscorer-at-the-2026-fifa-world-cup", "data": {"market": "0xd2a8caba5559bc21e14f6b2aa504cb14a1782751658b71409e25b82e432c0a97", "price_changes": [{"asset_id": "36586667785814641857008731622413716797407337292495614620493145114086484487337", "price": "0.447", "size": "3364.93", "side": "BUY", "hash": "f97932d6cd0930a42aa7abadf92c2692528bb175", "best_bid": "0.48", "best_ask": "0.481"}, {"asset_id": "19214394437683566921750936876376421489271269944393354497977881791256347396217", "price": "0.553", "size": "3364.93", "side": "SELL", "hash": "fc52f2bdc0fbbfac64c5327981c87ff706461ca4", "best_bid": "0.519", "best_ask": "0.52"}], "timestamp": "1782707760416", "event_type": "price_change"}}
{"local_timestamp": 1782707759.344649, "slug": "will-lionel-messi-be-the-top-goalscorer-at-the-2026-fifa-world-cup", "data": {"market": "0xd2a8caba5559bc21e14f6b2aa504cb14a1782751658b71409e25b82e432c0a97", "price_changes": [{"asset_id": "19214394437683566921750936876376421489271269944393354497977881791256347396217", "price": "0.26", "size": "3000", "side": "BUY", "hash": "80add32ba080db62c1251b7644341bc0c60eb6d8", "best_bid": "0.519", "best_ask": "0.52"}, {"asset_id": "36586667785814641857008731622413716797407337292495614620493145114086484487337", "price": "0.74", "size": "3000", "side": "SELL", "hash": "3a4cd9457d298cf9c2433560aca4625675e261dc", "best_bid": "0.48", "best_ask": "0.481"}], "timestamp": "1782707760563", "event_type": "price_change"}}
{"local_timestamp": 1782707759.34524, "slug": "will-lionel-messi-be-the-top-goalscorer-at-the-2026-fifa-world-cup", "data": {"market": "0xd2a8caba5559bc21e14f6b2aa504cb14a1782751658b71409e25b82e432c0a97", "price_changes": [{"asset_id": "36586667785814641857008731622413716797407337292495614620493145114086484487337", "price": "0.35", "size": "3200", "side": "BUY", "hash": "6ffc4487e699c9a5acec993d9fff9b132e9bfc66", "best_bid": "0.48", "best_ask": "0.481"}, {"asset_id": "19214394437683566921750936876376421489271269944393354497977881791256347396217", "price": "0.65", "size": "3200", "side": "SELL", "hash": "b8cbbab25edd0ca8257a17c5a0d5b111b6f58eb4", "best_bid": "0.519", "best_ask": "0.52"}], "timestamp": "1782707760567", "event_type": "price_change"}}
{"local_timestamp": 1782707759.4732726, "slug": "will-lionel-messi-be-the-top-goalscorer-at-the-2026-fifa-world-cup", "data": {"market": "0xd2a8caba5559bc21e14f6b2aa504cb14a1782751658b71409e25b82e432c0a97", "price_changes": [{"asset_id": "19214394437683566921750936876376421489271269944393354497977881791256347396217", "price": "0.486", "size": "2234.64", "side": "BUY", "hash": "b91dd0221b8210d9bdc659a6f97ee7b0202b520f", "best_bid": "0.519", "best_ask": "0.52"}, {"asset_id": "36586667785814641857008731622413716797407337292495614620493145114086484487337", "price": "0.514", "size": "2234.64", "side": "SELL", "hash": "1727cfc57dd1b88d0cc25fd44db788c0e19899e2", "best_bid": "0.48", "best_ask": "0.481"}], "timestamp": "1782707760706", "event_type": "price_change"}}
{"local_timestamp": 1782707759.5787349, "slug": "will-lionel-messi-be-the-top-goalscorer-at-the-2026-fifa-world-cup", "data": {"market": "0xd2a8caba5559bc21e14f6b2aa504cb14a1782751658b71409e25b82e432c0a97", "price_changes": [{"asset_id": "19214394437683566921750936876376421489271269944393354497977881791256347396217", "price": "0.521", "size": "4683.1", "side": "SELL", "hash": "b2f957f342f0f347ae264e2bc0664b742a25dfba", "best_bid": "0.519", "best_ask": "0.52"}, {"asset_id": "36586667785814641857008731622413716797407337292495614620493145114086484487337", "price": "0.479", "size": "4683.1", "side": "BUY", "hash": "4b4f4f5b83c1b2dfc0414ab4ecfff51d0abf21ca", "best_bid": "0.48", "best_ask": "0.481"}], "timestamp": "1782707760810", "event_type": "price_change"}}
{"local_timestamp": 1782707760.8626242, "slug": "will-lionel-messi-be-the-top-goalscorer-at-the-2026-fifa-world-cup", "data": {"market": "0xd2a8caba5559bc21e14f6b2aa504cb14a1782751658b71409e25b82e432c0a97", "price_changes": [{"asset_id": "36586667785814641857008731622413716797407337292495614620493145114086484487337", "price": "0.35", "size": "200", "side": "BUY", "hash": "7bc753e9ec145f3e8c8ffe797ae7222081d56320", "best_bid": "0.48", "best_ask": "0.481"}, {"asset_id": "19214394437683566921750936876376421489271269944393354497977881791256347396217", "price": "0.65", "size": "200", "side": "SELL", "hash": "7c90a7ce6ae85034256de6da0f1c060937370929", "best_bid": "0.519", "best_ask": "0.52"}], "timestamp": "1782707762086", "event_type": "price_change"}}
{"local_timestamp": 1782707760.8632154, "slug": "will-lionel-messi-be-the-top-goalscorer-at-the-2026-fifa-world-cup", "data": {"market": "0xd2a8caba5559bc21e14f6b2aa504cb14a1782751658b71409e25b82e432c0a97", "price_changes": [{"asset_id": "19214394437683566921750936876376421489271269944393354497977881791256347396217", "price": "0.26", "size": "0", "side": "BUY", "hash": "75437bd6099c3814e788b03d0f69cac0fd105651", "best_bid": "0.519", "best_ask": "0.52"}, {"asset_id": "36586667785814641857008731622413716797407337292495614620493145114086484487337", "price": "0.74", "size": "0", "side": "SELL", "hash": "797efa4ef948c857c4a211bfb19cd52555677a45", "best_bid": "0.48", "best_ask": "0.481"}], "timestamp": "1782707762087", "event_type": "price_change"}}
{"local_timestamp": 1782707762.27336, "slug": "will-lionel-messi-be-the-top-goalscorer-at-the-2026-fifa-world-cup", "data": {"market": "0xd2a8caba5559bc21e14f6b2aa504cb14a1782751658b71409e25b82e432c0a97", "price_changes": [{"asset_id": "19214394437683566921750936876376421489271269944393354497977881791256347396217", "price": "0.521", "size": "4780.19", "side": "SELL", "hash": "3d257104132ceee5f6fd974693727a5302b56851", "best_bid": "0.519", "best_ask": "0.52"}, {"asset_id": "36586667785814641857008731622413716797407337292495614620493145114086484487337", "price": "0.479", "size": "4780.19", "side": "BUY", "hash": "30e471fc5087be7f48e390138f59215039e4a890", "best_bid": "0.48", "best_ask": "0.481"}], "timestamp": "1782707763505", "event_type": "price_change"}}
{"local_timestamp": 1782707762.411473, "slug": "will-lionel-messi-be-the-top-goalscorer-at-the-2026-fifa-world-cup", "data": {"market": "0xd2a8caba5559bc21e14f6b2aa504cb14a1782751658b71409e25b82e432c0a97", "price_changes": [{"asset_id": "36586667785814641857008731622413716797407337292495614620493145114086484487337", "price": "0.35", "size": "3200", "side": "BUY", "hash": "eba6cc56882495badd0e27a38881ee288af9c6f8", "best_bid": "0.48", "best_ask": "0.481"}, {"asset_id": "19214394437683566921750936876376421489271269944393354497977881791256347396217", "price": "0.65", "size": "3200", "side": "SELL", "hash": "ffab52645b445a2cba468a379ca01d3c8cab7539", "best_bid": "0.519", "best_ask": "0.52"}], "timestamp": "1782707763644", "event_type": "price_change"}}
{"local_timestamp": 1782707762.4206212, "slug": "will-lionel-messi-be-the-top-goalscorer-at-the-2026-fifa-world-cup", "data": {"market": "0xd2a8caba5559bc21e14f6b2aa504cb14a1782751658b71409e25b82e432c0a97", "price_changes": [{"asset_id": "19214394437683566921750936876376421489271269944393354497977881791256347396217", "price": "0.26", "size": "3000", "side": "BUY", "hash": "bfc275dae6272d73dddb0f826a21d367b29b006a", "best_bid": "0.519", "best_ask": "0.52"}, {"asset_id": "36586667785814641857008731622413716797407337292495614620493145114086484487337", "price": "0.74", "size": "3000", "side": "SELL", "hash": "4f56ad25500c768ab73308dcbbb2a2b1a2b736de", "best_bid": "0.48", "best_ask": "0.481"}], "timestamp": "1782707763653", "event_type": "price_change"}}
{"local_timestamp": 1782707763.8051867, "slug": "will-lionel-messi-be-the-top-goalscorer-at-the-2026-fifa-world-cup", "data": {"market": "0xd2a8caba5559bc21e14f6b2aa504cb14a1782751658b71409e25b82e432c0a97", "price_changes": [{"asset_id": "19214394437683566921750936876376421489271269944393354497977881791256347396217", "price": "0.521", "size": "4683.1", "side": "SELL", "hash": "64b404da0f4eae5a9a41618211f0e359906f7624", "best_bid": "0.519", "best_ask": "0.52"}, {"asset_id": "36586667785814641857008731622413716797407337292495614620493145114086484487337", "price": "0.479", "size": "4683.1", "side": "BUY", "hash": "67b393e51160013f13aeccd268d657a487201588", "best_bid": "0.48", "best_ask": "0.481"}], "timestamp": "1782707765037", "event_type": "price_change"}}
{"local_timestamp": 1782707763.861291, "slug": "will-lionel-messi-be-the-top-goalscorer-at-the-2026-fifa-world-cup", "data": {"market": "0xd2a8caba5559bc21e14f6b2aa504cb14a1782751658b71409e25b82e432c0a97", "price_changes": [{"asset_id": "19214394437683566921750936876376421489271269944393354497977881791256347396217", "price": "0.26", "size": "0", "side": "BUY", "hash": "3b8067eb50b539813fe93c602b8956a21f0d24f8", "best_bid": "0.519", "best_ask": "0.52"}, {"asset_id": "36586667785814641857008731622413716797407337292495614620493145114086484487337", "price": "0.74", "size": "0", "side": "SELL", "hash": "d79d372abc2986a5344f3e97e685f479e16ae872", "best_bid": "0.48", "best_ask": "0.481"}], "timestamp": "1782707765094", "event_type": "price_change"}}
{"local_timestamp": 1782707763.8623576, "slug": "will-lionel-messi-be-the-top-goalscorer-at-the-2026-fifa-world-cup", "data": {"market": "0xd2a8caba5559bc21e14f6b2aa504cb14a1782751658b71409e25b82e432c0a97", "price_changes": [{"asset_id": "36586667785814641857008731622413716797407337292495614620493145114086484487337", "price": "0.35", "size": "200", "side": "BUY", "hash": "7cb5ddf51af57170756aea51d3b34155e4dda306", "best_bid": "0.48", "best_ask": "0.481"}, {"asset_id": "19214394437683566921750936876376421489271269944393354497977881791256347396217", "price": "0.65", "size": "200", "side": "SELL", "hash": "26218c2cbae1d2c048ec0361eb6755c91b7f4bb8", "best_bid": "0.519", "best_ask": "0.52"}], "timestamp": "1782707765094", "event_type": "price_change"}}
{"local_timestamp": 1782707764.789977, "slug": "will-lionel-messi-be-the-top-goalscorer-at-the-2026-fifa-world-cup", "data": {"market": "0xd2a8caba5559bc21e14f6b2aa504cb14a1782751658b71409e25b82e432c0a97", "price_changes": [{"asset_id": "19214394437683566921750936876376421489271269944393354497977881791256347396217", "price": "0.5", "size": "29964", "side": "BUY", "hash": "88593c0cbac56b53576327e8f9ca7f3e0267ac89", "best_bid": "0.519", "best_ask": "0.52"}, {"asset_id": "36586667785814641857008731622413716797407337292495614620493145114086484487337", "price": "0.5", "size": "29964", "side": "SELL", "hash": "66fb587a87a34f0133d8b20c23a7a511242803dc", "best_bid": "0.48", "best_ask": "0.481"}], "timestamp": "1782707766001", "event_type": "price_change"}}
{"local_timestamp": 1782707764.9896467, "slug": "will-lionel-messi-be-the-top-goalscorer-at-the-2026-fifa-world-cup", "data": {"market": "0xd2a8caba5559bc21e14f6b2aa504cb14a1782751658b71409e25b82e432c0a97", "price_changes": [{"asset_id": "36586667785814641857008731622413716797407337292495614620493145114086484487337", "price": "0.35", "size": "3200", "side": "BUY", "hash": "02fbc5c5ce7e82b1f04174c58242b1a50890e99c", "best_bid": "0.48", "best_ask": "0.481"}, {"asset_id": "19214394437683566921750936876376421489271269944393354497977881791256347396217", "price": "0.65", "size": "3200", "side": "SELL", "hash": "d4a1882dffef00f64d08336742c8c92c9fb2f55e", "best_bid": "0.519", "best_ask": "0.52"}], "timestamp": "1782707766222", "event_type": "price_change"}}
{"local_timestamp": 1782707764.9981556, "slug": "will-lionel-messi-be-the-top-goalscorer-at-the-2026-fifa-world-cup", "data": {"market": "0xd2a8caba5559bc21e14f6b2aa504cb14a1782751658b71409e25b82e432c0a97", "price_changes": [{"asset_id": "19214394437683566921750936876376421489271269944393354497977881791256347396217", "price": "0.26", "size": "3000", "side": "BUY", "hash": "819203bdaf3d448f6852bde1de1dfe1caa60c0af", "best_bid": "0.519", "best_ask": "0.52"}, {"asset_id": "36586667785814641857008731622413716797407337292495614620493145114086484487337", "price": "0.74", "size": "3000", "side": "SELL", "hash": "7aa3a7c825a6b7620db274fadd5bff71affe42ec", "best_bid": "0.48", "best_ask": "0.481"}], "timestamp": "1782707766230", "event_type": "price_change"}}
{"local_timestamp": 1782707765.368521, "slug": "will-lionel-messi-be-the-top-goalscorer-at-the-2026-fifa-world-cup", "data": {"market": "0xd2a8caba5559bc21e14f6b2aa504cb14a1782751658b71409e25b82e432c0a97", "price_changes": [{"asset_id": "36586667785814641857008731622413716797407337292495614620493145114086484487337", "price": "0.35", "size": "200", "side": "BUY", "hash": "95f3ccedad455bc66cd5022274ad240ff7c615c1", "best_bid": "0.48", "best_ask": "0.481"}, {"asset_id": "19214394437683566921750936876376421489271269944393354497977881791256347396217", "price": "0.65", "size": "200", "side": "SELL", "hash": "1c8ef0ca0b72dca0bd2a931853abcaef23c497f4", "best_bid": "0.519", "best_ask": "0.52"}], "timestamp": "1782707766600", "event_type": "price_change"}}
